
# Created by Ruins mod version 16.5 Ingame Parser
# authoring Player: lafuller

weight=1
embed_into_distance=5
acceptable_target_blocks=
unacceptable_target_blocks=flowing_water,water,flowing_lava,lava,ice,bedrock,netherrack,nether_brick,nether_brick_fence,soul_sand,quartz_ore,end_stone,obsidian,iron_bars,cloud,flesh,ash_block,slime_grass,slime_congealed,slime_dirt
dimensions=12,20,20
allowable_overhang=0
max_leveling=7
leveling_buffer=-1
preserve_water=0
preserve_lava=0

rule1=0,100,preserveBlock
rule2=0,100,minecraft:double_stone_slab-9
rule3=0,100,minecraft:sandstone_stairs-0
rule4=0,100,minecraft:sandstone-0
rule5=0,100,minecraft:sandstone_stairs-2
rule6=0,100,minecraft:sandstone_stairs-3
rule7=0,100,minecraft:sandstone_stairs-1
rule8=0,100,minecraft:trapdoor-11
rule9=0,100,bookshelf,pumpkin,melon_block,hay_block,ChestGenHook:chests/spawn_bonus_chest:5-5
rule10=0,100,minecraft:stone-4
rule11=0,100,minecraft:stone_slab-1
rule12=0,100,minecraft:trapdoor-8
rule13=0,100,minecraft:wooden_slab-9
rule14=0,100,minecraft:trapdoor-10
rule15=0,100,minecraft:dirt-0
rule16=0,100,minecraft:ladder-4
rule17=0,100,minecraft:ladder-3
rule18=0,100,minecraft:spruce_stairs-6
rule19=0,100,minecraft:crafting_table-0
rule20=0,100,minecraft:sandstone-2
rule21=0,100,minecraft:carpet-7
rule22=0,100,minecraft:trapdoor-1
rule23=0,100,minecraft:spruce_stairs-7
rule24=0,100,minecraft:spruce_fence-0
rule25=0,100,minecraft:jungle_door-1
rule26=0,100,minecraft:jungle_door-3
rule27=0,100,minecraft:ladder-5
rule28=0,100,minecraft:spruce_stairs-3
rule29=0,100,minecraft:spruce_stairs-2
rule30=0,100,minecraft:jungle_door-9
rule31=0,100,minecraft:jungle_door-8
rule32=0,100,minecraft:trapdoor-3
rule33=0,100,minecraft:wooden_slab-1
rule34=0,100,minecraft:double_stone_slab-1
rule35=0,100,minecraft:stone_slab-9
rule36=0,100,minecraft:trapdoor-9
rule37=0,100,minecraft:sandstone_stairs-6
rule38=0,100,minecraft:sandstone_stairs-5
rule39=0,100,minecraft:sandstone_stairs-4
rule40=0,100,minecraft:trapdoor-0

layer
1,1,2,2,2,2,1,1,1,1,1,1,1,1,1,1,1,1,1,1
1,1,2,2,2,2,2,2,2,1,1,1,1,1,1,1,1,1,1,1
3,2,2,2,2,2,2,2,2,2,2,2,1,1,1,1,1,1,1,1
4,2,2,2,2,2,2,2,2,2,2,2,4,1,1,1,1,1,1,1
4,2,2,2,2,2,2,2,2,2,2,2,4,3,3,3,3,5,1,1
4,2,2,2,2,2,2,2,2,2,2,2,4,4,4,4,4,5,1,1
4,4,2,2,2,2,2,2,2,2,2,4,4,4,4,4,4,5,1,1
4,4,2,2,2,2,2,2,2,2,4,4,4,4,4,4,4,5,1,1
2,2,2,2,2,2,2,2,2,2,4,4,4,4,4,2,2,2,2,1
2,2,2,2,2,2,2,4,4,4,4,4,4,4,2,2,2,2,2,1
2,2,2,2,2,2,2,4,4,4,4,4,4,4,2,2,2,2,2,2
2,2,2,2,2,4,4,4,4,4,4,4,4,4,2,2,2,2,2,2
2,2,2,2,2,4,4,4,4,4,4,4,4,2,2,2,2,2,2,2
1,2,2,2,2,4,4,4,4,4,4,4,4,2,2,2,2,2,2,2
1,2,2,2,2,4,4,4,4,4,2,2,2,2,2,2,2,2,2,2
1,1,1,1,6,7,7,6,4,4,2,2,2,2,2,2,2,2,2,1
1,1,1,1,1,1,1,6,4,4,2,2,2,2,2,2,2,2,2,1
1,1,1,1,1,1,1,7,4,4,2,2,2,2,2,2,2,2,2,1
1,1,1,1,1,1,1,1,4,4,2,2,2,2,2,2,2,1,1,1
1,1,1,1,1,1,1,1,4,4,4,4,2,2,2,2,2,1,1,1
endlayer

layer
1,1,2,2,2,2,1,1,1,1,1,1,1,1,1,1,1,1,1,1
1,1,2,2,2,2,2,2,2,1,1,1,1,1,1,1,1,1,1,1
1,2,2,2,2,2,2,2,2,2,2,2,1,1,1,1,1,1,1,1
3,2,2,2,2,2,2,2,2,2,2,2,4,1,1,1,1,1,1,1
4,2,2,2,2,2,2,2,2,2,2,2,4,1,1,1,1,1,1,1
4,2,2,2,2,2,2,2,2,2,2,2,4,3,3,3,5,1,1,1
4,4,2,2,2,2,2,2,2,2,2,4,4,4,4,4,5,1,1,1
4,4,2,2,2,2,2,2,2,2,4,4,4,4,4,4,5,1,1,1
2,2,2,2,2,2,2,2,2,2,4,4,4,4,4,2,2,2,2,1
2,2,2,2,2,2,2,4,4,4,4,4,4,4,2,2,2,2,2,1
2,2,2,2,2,2,2,4,4,4,4,4,4,4,2,2,2,2,2,2
2,2,2,2,2,4,4,4,4,4,4,4,4,4,2,2,2,2,2,2
2,2,2,2,2,4,4,4,4,4,4,4,4,2,2,2,2,2,2,2
1,2,2,2,2,4,4,4,4,4,4,4,4,2,2,2,2,2,2,2
1,2,2,2,2,7,7,7,7,4,2,2,2,2,2,2,2,2,2,2
1,1,1,1,1,1,1,1,6,4,2,2,2,2,2,2,2,2,2,1
1,1,1,1,1,1,1,1,6,4,2,2,2,2,2,2,2,2,2,1
1,1,1,1,1,1,1,1,3,4,2,2,2,2,2,2,2,2,2,1
1,1,1,1,1,1,1,1,4,4,2,2,2,2,2,2,2,1,1,1
1,1,1,1,1,1,1,1,4,4,4,4,2,2,2,2,2,1,1,1
endlayer

layer
1,1,2,2,2,2,1,1,1,1,1,1,1,1,1,1,1,1,1,1
1,1,2,9,8,2,4,4,4,1,1,1,1,1,1,1,1,1,1,1
1,2,12,0,0,11,4,10,9,2,2,2,1,1,1,1,1,1,1,1
1,2,12,0,0,3,4,0,0,0,13,2,4,1,1,1,1,1,1,1
3,2,12,0,0,4,4,0,0,0,13,2,4,1,1,1,1,1,1,1
4,2,2,0,0,4,4,0,0,0,13,2,4,1,1,1,1,1,1,1
4,4,2,14,14,4,4,0,0,0,2,4,4,3,3,5,1,1,1,1
4,4,2,4,4,4,4,16,0,2,4,4,15,4,4,5,1,1,1,1
2,2,2,4,4,4,2,2,2,2,4,4,4,4,15,2,2,2,2,1
2,13,0,0,6,4,2,15,15,15,4,4,4,4,2,13,0,17,2,1
2,13,0,0,6,2,2,15,4,4,4,15,15,4,2,13,0,0,10,2
2,13,0,0,2,4,4,15,4,4,4,4,4,4,2,13,0,0,9,2
2,2,0,0,2,4,4,15,4,4,4,4,4,2,2,4,4,4,4,2
1,2,9,19,2,4,7,7,7,4,4,4,4,2,9,0,18,13,13,2
1,2,2,2,2,1,1,1,1,4,2,2,2,2,0,0,0,0,0,2
1,1,1,1,1,1,1,1,1,4,2,13,0,10,4,16,0,0,2,1
1,1,1,1,1,1,1,1,1,4,2,13,0,0,11,4,0,0,2,1
1,1,1,1,1,1,1,1,1,4,2,13,0,0,11,20,2,2,2,1
1,1,1,1,1,1,1,1,3,4,2,2,2,4,4,20,2,1,1,1
1,1,1,1,1,1,1,1,4,4,4,4,2,2,2,2,2,1,1,1
endlayer

layer
1,1,2,2,2,2,1,1,1,1,1,1,1,1,1,1,1,1,1,1
1,1,2,0,0,2,4,4,4,1,1,1,1,1,1,1,1,1,1,1
1,2,21,0,0,0,4,0,0,2,2,2,1,1,1,1,1,1,1,1
1,2,21,0,0,0,4,0,0,0,21,2,4,1,1,1,1,1,1,1
1,2,21,0,0,3,4,0,0,0,21,2,4,1,1,1,1,1,1,1
3,2,2,0,0,4,4,0,0,0,21,2,4,1,1,1,1,1,1,1
4,4,2,14,14,4,4,0,0,0,2,4,4,1,1,1,1,1,1,1
4,4,2,4,4,4,4,16,0,2,4,4,1,1,1,1,1,1,1,1
2,2,2,4,5,11,2,2,2,2,7,7,1,1,1,2,2,2,2,1
2,21,0,0,0,11,2,1,1,1,1,1,1,4,2,21,0,17,2,1
2,21,0,0,0,2,2,1,1,1,1,1,1,4,2,21,0,0,0,2
2,21,0,0,2,4,4,1,1,1,1,6,4,4,2,21,0,0,0,2
2,2,0,0,2,4,7,1,1,11,11,6,4,2,2,4,4,4,4,2
1,2,21,0,2,4,1,1,1,4,4,4,4,2,0,0,0,0,0,2
1,2,2,2,2,1,1,1,1,4,2,2,2,2,0,0,0,0,0,2
1,1,1,1,1,1,1,1,1,4,2,21,0,0,4,16,0,0,2,1
1,1,1,1,1,1,1,1,1,4,2,21,0,0,0,4,0,0,2,1
1,1,1,1,1,1,1,1,1,4,2,21,0,0,0,0,2,2,2,1
1,1,1,1,1,1,1,1,1,4,2,2,2,4,5,0,2,1,1,1
1,1,1,1,1,1,1,1,1,6,4,4,2,2,2,2,2,1,1,1
endlayer

layer
1,1,2,2,2,2,1,1,1,1,1,1,1,1,1,1,1,1,1,1
1,1,2,0,0,2,4,4,4,1,1,1,1,1,1,1,1,1,1,1
1,2,0,0,0,0,4,0,0,2,2,2,1,1,1,1,1,1,1,1
1,2,0,0,0,0,4,0,0,0,0,2,4,1,1,1,1,1,1,1
1,2,0,0,0,0,4,0,0,0,0,2,4,1,1,1,1,1,1,1
1,2,2,0,0,3,4,0,0,0,0,2,4,1,1,1,1,1,1,1
3,4,2,0,0,4,4,0,0,0,2,4,4,1,1,1,1,1,1,1
4,4,2,4,4,4,4,16,0,2,7,7,1,1,1,1,1,1,1,1
2,2,2,5,0,0,2,2,2,2,1,1,1,1,1,2,2,2,2,1
2,0,0,0,0,0,2,1,1,1,1,1,1,4,2,0,0,17,2,1
2,0,0,0,0,2,2,1,1,1,1,1,1,4,2,0,0,0,22,2
2,0,0,0,2,4,7,1,1,1,1,1,6,4,2,0,0,0,22,2
2,3,0,0,2,4,1,1,1,1,1,1,6,2,2,4,4,4,4,2
1,2,0,0,2,4,1,1,1,1,6,4,4,2,0,0,0,0,0,2
1,2,2,2,2,1,1,1,1,3,4,2,2,2,0,0,0,0,0,2
1,1,1,1,1,1,1,1,1,4,2,0,0,0,4,16,0,0,2,1
1,1,1,1,1,1,1,1,1,4,2,0,0,0,0,4,0,0,2,1
1,1,1,1,1,1,1,1,1,4,2,0,0,0,0,0,2,2,2,1
1,1,1,1,1,1,1,1,1,7,2,2,2,5,0,0,2,1,1,1
1,1,1,1,1,1,1,1,1,1,1,1,2,2,2,2,2,1,1,1
endlayer

layer
1,1,2,2,2,2,1,1,1,1,1,1,1,1,1,1,1,1,1,1
1,1,2,13,13,2,4,4,4,1,1,1,1,1,1,1,1,1,1,1
1,2,13,13,13,0,4,13,13,2,2,2,1,1,1,1,1,1,1,1
1,2,13,13,13,0,4,13,13,13,13,2,4,1,1,1,1,1,1,1
1,2,13,13,13,0,4,13,13,13,13,2,4,1,1,1,1,1,1,1
1,2,2,13,13,0,4,13,13,13,13,2,7,1,1,1,1,1,1,1
1,4,2,13,13,11,4,13,13,13,2,1,1,1,1,1,1,1,1,1
1,6,2,4,4,4,4,16,13,2,1,1,1,1,1,1,1,1,1,1
2,2,11,0,0,0,2,2,2,2,1,1,1,1,1,2,2,2,2,1
2,13,13,13,13,13,2,1,1,1,1,1,1,4,2,13,13,17,2,1
2,13,13,13,13,2,2,1,1,1,1,1,1,4,2,13,13,13,13,2
2,13,13,13,2,5,1,1,1,1,1,1,1,6,2,13,13,13,13,2
2,13,13,13,2,4,1,1,1,1,1,1,1,2,2,4,4,4,4,2
1,2,13,13,2,20,1,1,1,1,1,6,4,2,13,13,13,13,13,2
1,2,2,2,2,1,1,1,1,1,2,2,2,2,13,13,13,13,13,2
1,1,1,1,1,1,1,1,1,3,2,13,23,13,4,16,13,13,2,1
1,1,1,1,1,1,1,1,1,4,2,13,23,13,13,4,13,13,2,1
1,1,1,1,1,1,1,1,1,7,2,13,23,13,13,13,2,2,2,1
1,1,1,1,1,1,1,1,1,1,2,2,11,0,0,0,2,1,1,1
1,1,1,1,1,1,1,1,1,1,1,1,2,2,2,2,2,1,1,1
endlayer

layer
1,1,20,2,2,20,1,1,1,1,1,1,1,1,1,1,1,1,1,1
1,1,4,8,8,2,4,4,4,1,1,1,1,1,1,1,1,1,1,1
1,20,0,0,0,0,4,13,13,2,2,20,1,1,1,1,1,1,1,1
1,2,0,0,0,0,4,0,0,0,0,2,24,1,1,1,1,1,1,1
1,2,0,0,0,0,4,0,0,0,0,25,1,1,1,1,1,1,1,1
1,20,2,0,0,0,4,0,0,0,0,20,1,1,1,1,1,1,1,1
1,1,26,0,0,0,4,0,0,0,4,1,1,1,1,1,1,1,1,1
1,1,4,20,20,20,20,16,0,4,1,1,1,1,1,1,1,1,1,1
20,2,0,0,0,0,2,2,2,20,1,1,1,1,1,20,2,2,20,1
2,0,0,0,24,24,2,1,1,1,1,1,1,24,20,0,27,17,2,1
2,0,0,0,0,2,20,1,1,1,1,1,1,1,26,0,0,0,0,20
2,0,0,0,20,1,1,1,1,1,1,1,1,1,2,0,0,0,0,2
20,0,0,0,25,1,1,1,1,1,1,1,1,20,2,4,4,4,4,2
1,2,13,13,20,24,1,1,1,1,1,1,1,26,0,0,0,0,0,2
1,20,2,4,4,1,1,1,1,1,20,2,2,2,0,0,0,0,0,20
1,1,1,1,1,1,1,1,1,1,2,29,24,28,4,16,0,0,4,1
1,1,1,1,1,1,1,1,1,1,26,0,0,0,0,20,0,0,4,1
1,1,1,1,1,1,1,1,1,1,2,0,0,0,0,0,2,4,4,1
1,1,1,1,1,1,1,1,1,1,20,2,0,0,0,0,2,1,1,1
1,1,1,1,1,1,1,1,1,1,1,1,20,2,2,2,20,1,1,1
endlayer

layer
1,1,4,2,0,2,1,1,1,1,1,1,1,1,1,1,1,1,1,1
1,1,4,0,0,2,4,0,4,1,1,1,1,1,1,1,1,1,1,1
1,2,0,0,0,0,20,0,0,2,0,2,1,1,1,1,1,1,1,1
1,0,0,0,0,0,4,0,0,0,0,2,1,1,1,1,1,1,1,1
1,2,0,0,0,0,4,0,0,0,0,30,1,1,1,1,1,1,1,1
1,2,2,0,0,0,4,0,0,0,0,2,1,1,1,1,1,1,1,1
1,1,31,0,0,0,4,0,0,0,4,1,1,1,1,1,1,1,1,1
1,1,4,20,20,20,20,16,0,4,1,1,1,1,1,1,1,1,1,1
2,2,0,0,0,0,2,4,0,2,1,1,1,1,1,2,0,2,2,1
2,0,0,0,21,21,0,1,1,1,1,1,1,24,2,0,0,17,2,1
0,0,0,0,0,2,2,1,1,1,1,1,1,1,30,0,0,0,0,2
2,0,0,0,2,1,1,1,1,1,1,1,1,1,2,0,0,0,0,2
2,0,0,0,31,1,1,1,1,1,1,1,1,20,2,4,4,4,4,4
1,4,0,0,20,24,1,1,1,1,1,1,1,31,0,0,0,0,0,0
1,4,4,0,4,1,1,1,1,1,2,2,2,2,0,0,0,0,0,4
1,1,1,1,1,1,1,1,1,1,2,0,21,0,4,16,0,0,4,1
1,1,1,1,1,1,1,1,1,1,31,0,0,0,0,20,0,0,0,1
1,1,1,1,1,1,1,1,1,1,2,0,0,0,0,0,2,4,4,1
1,1,1,1,1,1,1,1,1,1,2,2,0,0,0,0,2,1,1,1
1,1,1,1,1,1,1,1,1,1,1,1,2,2,0,2,2,1,1,1
endlayer

layer
1,1,4,2,2,20,1,1,1,1,1,1,1,1,1,1,1,1,1,1
1,1,4,32,32,2,4,4,4,1,1,1,1,1,1,1,1,1,1,1
1,20,0,0,0,0,20,0,0,2,2,20,1,1,1,1,1,1,1,1
1,2,0,0,0,0,4,0,0,0,0,2,1,1,1,1,1,1,1,1
1,2,0,0,0,0,4,0,0,0,0,2,1,1,1,1,1,1,1,1
1,20,2,0,0,0,4,0,0,0,0,20,1,1,1,1,1,1,1,1
1,13,4,0,0,0,4,0,0,0,4,1,1,1,1,1,1,1,1,1
1,13,4,20,20,20,20,0,0,4,1,1,1,1,1,1,1,1,1,1
20,2,0,0,0,0,2,2,2,20,1,1,1,1,1,20,2,2,20,1
2,0,0,0,0,0,2,1,1,1,1,1,1,33,20,0,0,0,2,1
2,0,0,0,0,2,20,1,1,1,1,1,1,33,2,0,0,0,0,20
2,0,0,0,20,1,1,1,1,1,1,1,1,33,2,0,0,0,0,2
20,0,0,0,20,1,1,1,1,1,1,1,1,4,2,4,4,4,4,2
1,4,0,0,2,24,1,1,1,1,1,1,1,4,0,0,0,0,0,2
1,4,4,4,20,1,1,1,1,1,20,2,2,2,0,0,0,0,0,20
1,1,1,1,1,1,1,1,1,1,2,0,0,0,4,0,0,0,4,1
1,1,1,1,1,1,1,1,1,1,2,0,0,0,0,20,0,0,4,1
1,1,1,1,1,1,1,1,1,1,2,0,0,0,0,0,2,4,4,1
1,1,1,1,1,1,1,1,1,1,20,2,0,0,0,0,2,1,1,1
1,1,1,1,1,1,1,1,1,1,1,1,20,2,2,2,20,1,1,1
endlayer

layer
1,1,6,4,4,5,1,1,1,1,1,1,1,1,1,1,1,1,1,1
1,1,4,0,0,2,4,11,11,1,1,1,1,1,1,1,1,1,1,1
1,2,0,0,0,0,20,35,35,34,20,11,1,1,1,1,1,1,1,1
1,2,0,0,0,0,20,35,35,36,35,11,1,1,1,1,1,1,1,1
1,2,0,0,0,0,20,35,35,35,35,11,1,1,1,1,1,1,1,1
1,2,2,0,0,0,20,35,35,35,5,1,1,1,1,1,1,1,1,1
1,1,4,0,0,0,20,35,0,35,5,1,1,1,1,1,1,1,1,1
1,1,4,20,20,20,20,35,35,34,1,1,1,1,1,1,1,1,1,1
3,2,0,0,0,0,2,7,7,7,1,1,1,1,1,3,3,3,3,1
2,0,0,0,0,0,2,1,1,1,1,1,1,1,6,13,13,13,5,1
2,0,0,0,0,2,7,1,1,1,1,1,1,1,6,13,12,13,35,5
2,0,0,0,2,33,1,1,1,1,1,1,1,1,6,13,13,13,35,5
2,0,0,0,2,33,1,1,1,1,1,1,1,11,7,20,20,20,20,2
1,4,0,0,2,33,1,1,1,1,1,1,1,11,22,37,0,0,0,4
1,6,4,4,4,1,1,1,1,1,3,3,3,11,11,37,0,0,0,4
1,1,1,1,1,1,1,1,1,1,6,20,20,20,20,37,0,0,4,1
1,1,1,1,1,1,1,1,1,1,6,35,8,35,35,2,0,0,4,1
1,1,1,1,1,1,1,1,1,1,6,35,35,35,36,2,4,4,4,1
1,1,1,1,1,1,1,1,1,1,6,7,35,35,35,20,5,1,1,1
1,1,1,1,1,1,1,1,1,1,1,1,7,7,7,7,7,1,1,1
endlayer

layer
1,1,1,3,3,0,1,1,1,1,1,1,1,1,1,1,1,1,1,1
1,1,4,0,0,5,1,1,1,1,1,1,1,1,1,1,1,1,1,1
1,6,38,0,0,38,5,1,1,1,1,1,1,1,1,1,1,1,1,1
1,6,0,0,0,35,5,1,1,1,1,1,1,1,1,1,1,1,1,1
1,6,39,13,13,13,5,1,1,1,1,1,1,1,1,1,1,1,1,1
1,7,6,13,36,13,5,11,11,11,1,1,1,1,1,1,1,1,1,1
1,1,6,13,13,13,5,11,40,11,1,1,1,1,1,1,1,1,1,1
1,1,7,7,7,7,11,11,11,11,1,1,1,1,1,1,1,1,1,1
1,6,35,35,35,5,11,1,1,1,1,1,1,1,1,1,1,1,1,1
11,6,35,8,35,5,11,1,1,1,1,1,1,1,1,1,1,1,1,1
11,6,35,35,35,5,1,1,1,1,1,1,1,1,1,1,1,1,1,1
11,5,7,7,5,1,1,1,1,1,1,1,1,1,1,1,1,1,1,1
11,5,40,6,5,1,1,1,1,1,1,1,1,1,1,3,3,3,3,11
1,3,3,3,11,1,1,1,1,1,1,1,1,1,1,6,11,11,6,11
1,1,11,11,1,1,1,1,1,1,1,1,1,1,1,6,11,22,6,11
1,1,1,1,1,1,1,1,1,1,1,1,1,1,1,6,11,11,6,1
1,1,1,1,1,1,1,1,1,1,1,1,1,1,1,7,7,7,7,1
1,1,1,1,1,1,1,1,1,1,1,1,1,1,1,1,1,1,1,1
1,1,1,1,1,1,1,1,1,1,1,1,1,1,1,1,1,1,1,1
1,1,1,1,1,1,1,1,1,1,1,1,1,1,1,1,1,1,1,1
endlayer

layer
1,1,1,1,1,1,1,1,1,1,1,1,1,1,1,1,1,1,1,1
1,1,11,11,11,1,1,1,1,1,1,1,1,1,1,1,1,1,1,1
1,1,11,40,11,1,1,1,1,1,1,1,1,1,1,1,1,1,1,1
1,1,11,11,11,1,1,1,1,1,1,1,1,1,1,1,1,1,1,1
1,1,1,1,1,1,1,1,1,1,1,1,1,1,1,1,1,1,1,1
1,1,1,1,1,1,1,1,1,1,1,1,1,1,1,1,1,1,1,1
1,1,1,1,1,1,1,1,1,1,1,1,1,1,1,1,1,1,1,1
1,1,1,1,1,1,1,1,1,1,1,1,1,1,1,1,1,1,1,1
1,1,1,1,1,1,1,1,1,1,1,1,1,1,1,1,1,1,1,1
1,1,1,1,1,1,1,1,1,1,1,1,1,1,1,1,1,1,1,1
1,1,1,1,1,1,1,1,1,1,1,1,1,1,1,1,1,1,1,1
1,1,1,1,1,1,1,1,1,1,1,1,1,1,1,1,1,1,1,1
1,1,1,1,1,1,1,1,1,1,1,1,1,1,1,1,1,1,1,1
1,1,1,1,1,1,1,1,1,1,1,1,1,1,1,1,1,1,1,1
1,1,1,1,1,1,1,1,1,1,1,1,1,1,1,1,1,1,1,1
1,1,1,1,1,1,1,1,1,1,1,1,1,1,1,1,1,1,1,1
1,1,1,1,1,1,1,1,1,1,1,1,1,1,1,1,1,1,1,1
1,1,1,1,1,1,1,1,1,1,1,1,1,1,1,1,1,1,1,1
1,1,1,1,1,1,1,1,1,1,1,1,1,1,1,1,1,1,1,1
1,1,1,1,1,1,1,1,1,1,1,1,1,1,1,1,1,1,1,1
endlayer

