
# Created by Ruins mod version 16.5 Ingame Parser
# authoring Player: lafuller

weight=1
embed_into_distance=5
acceptable_target_blocks=
unacceptable_target_blocks=flowing_water,water,flowing_lava,lava,ice,bedrock,netherrack,nether_brick,nether_brick_fence,soul_sand,quartz_ore,end_stone,obsidian,iron_bars,cloud,flesh,ash_block,slime_grass,slime_congealed,slime_dirt
dimensions=11,21,20
allowable_overhang=0
max_leveling=7
leveling_buffer=-1
preserve_water=0
preserve_lava=0

rule1=0,100,preserveBlock
rule2=0,100,minecraft:double_stone_slab-9
rule3=0,100,minecraft:sandstone-0
rule4=0,100,minecraft:sandstone-2
rule5=0,100,minecraft:sandstone_stairs-0
rule6=0,100,minecraft:sandstone_stairs-1
rule7=0,100,minecraft:sandstone_stairs-2
rule8=0,100,bookshelf,pumpkin,melon_block,hay_block,ChestGenHook:chests/spawn_bonus_chest:5-2
rule9=0,100,minecraft:ladder-2
rule10=0,100,minecraft:wooden_slab-9
rule11=0,100,minecraft:spruce_stairs-7
rule12=0,100,minecraft:spruce_stairs-6
rule13=0,100,bookshelf,pumpkin,melon_block,hay_block,ChestGenHook:chests/stronghold_crossing:5-5
rule14=0,100,bookshelf,pumpkin,melon_block,hay_block,ChestGenHook:chests/stronghold_library:5-4
rule15=0,100,minecraft:ladder-3
rule16=0,100,minecraft:ladder-5
rule17=0,100,bookshelf,pumpkin,melon_block,hay_block,ChestGenHook:chests/jungle_temple:5-3
rule18=0,100,minecraft:dirt-0
rule19=0,100,minecraft:sandstone_stairs-3
rule20=0,100,minecraft:carpet-7
rule21=0,100,minecraft:carpet-8
rule22=0,100,minecraft:sandstone_stairs-7
rule23=0,100,minecraft:sandstone_stairs-6
rule24=0,100,minecraft:spruce_stairs-5
rule25=0,100,minecraft:sandstone_stairs-5
rule26=0,100,minecraft:spruce_stairs-4
rule27=0,100,minecraft:spruce_fence-0
rule28=0,100,minecraft:jungle_door-1
rule29=0,100,minecraft:jungle_door-3
rule30=0,100,minecraft:jungle_door-2
rule31=0,100,minecraft:jungle_door-0
rule32=0,100,minecraft:ladder-4
rule33=0,100,minecraft:jungle_door-8
rule34=0,100,minecraft:jungle_door-9
rule35=0,100,minecraft:wooden_slab-1
rule36=0,100,minecraft:stone_slab-9
rule37=0,100,minecraft:trapdoor-9
rule38=0,100,minecraft:stone_slab-1
rule39=0,100,minecraft:trapdoor-11
rule40=0,100,minecraft:hay_block-0
rule41=0,100,minecraft:trapdoor-8
rule42=0,100,minecraft:trapdoor-3
rule43=0,100,minecraft:trapdoor-1
rule44=0,100,minecraft:trapdoor-2

layer
1,1,1,1,1,1,1,1,1,1,2,2,2,2,2,2,2,2,2,1
1,1,1,1,1,1,1,1,1,1,4,3,2,4,3,3,3,3,2,1
3,3,3,3,4,3,2,2,2,2,4,3,2,4,3,3,3,3,2,1
2,2,2,2,2,2,2,2,3,3,3,3,2,3,3,3,3,3,2,4
2,3,3,3,3,3,2,2,2,2,2,2,2,3,3,3,3,3,3,3
2,3,3,3,3,3,2,2,2,2,2,2,2,3,3,3,3,3,3,3
2,3,3,3,3,3,2,2,2,2,2,2,2,3,3,3,3,2,2,3
2,3,3,3,3,3,2,2,2,2,2,3,3,3,3,3,2,3,3,3
2,3,3,3,3,3,2,2,2,2,2,3,3,3,3,3,2,3,1,1
2,2,2,2,2,2,3,3,3,3,2,3,3,3,3,3,2,4,1,1
2,2,2,2,2,3,3,3,3,3,2,3,3,3,3,3,2,4,1,1
4,3,4,3,2,3,3,3,3,3,2,3,3,3,3,3,2,2,1,1
2,3,4,3,2,3,3,3,3,3,2,2,2,2,2,2,2,1,1,1
1,2,2,2,2,3,3,3,3,3,2,2,2,2,2,2,2,1,1,1
1,3,2,2,2,2,2,2,2,2,2,2,2,2,2,3,3,1,1,1
1,3,2,3,3,3,3,3,2,2,2,2,2,2,2,3,2,1,1,1
1,3,2,3,3,3,3,3,2,2,2,2,2,3,2,1,1,1,1,1
1,3,2,3,3,3,3,3,2,2,2,2,1,1,1,1,1,1,1,1
1,3,2,3,3,3,3,3,2,3,3,2,1,1,1,1,1,1,1,1
1,3,2,3,3,3,4,4,2,3,3,1,1,1,1,1,1,1,1,1
1,3,2,2,2,2,2,2,2,2,3,1,1,1,1,1,1,1,1,1
endlayer

layer
1,1,1,1,1,1,1,1,1,1,5,2,2,2,2,2,2,2,2,1
1,1,1,1,1,1,1,1,1,1,4,3,2,4,3,3,3,3,2,1
3,3,3,3,4,3,2,2,5,5,4,3,2,4,3,3,3,3,2,1
2,2,2,2,2,2,2,2,3,3,3,3,2,3,3,3,3,3,2,4
2,3,3,3,3,3,2,2,2,2,2,2,2,3,3,3,3,3,3,3
2,3,3,3,3,3,2,2,2,2,2,2,2,3,3,3,3,3,3,3
2,3,3,3,3,3,2,2,2,2,2,2,2,3,3,3,3,2,2,3
2,3,3,3,3,3,2,2,2,2,2,3,3,3,3,3,2,3,3,3
2,3,3,3,3,3,2,2,2,2,2,3,3,3,3,3,2,3,1,1
2,2,2,2,2,2,3,3,3,3,2,3,3,3,3,3,2,4,1,1
2,2,2,2,2,3,3,3,3,3,2,3,3,3,3,3,2,4,1,1
4,3,4,3,2,3,3,3,3,3,2,3,3,3,3,3,2,6,1,1
6,3,4,3,2,3,3,3,3,3,2,2,2,2,2,2,2,1,1,1
1,2,2,2,2,3,3,3,3,3,2,2,2,2,2,2,2,1,1,1
1,3,2,2,2,2,2,2,2,2,2,2,2,2,2,3,3,1,1,1
1,3,2,3,3,3,3,3,2,2,2,2,2,2,2,3,6,1,1,1
1,3,2,3,3,3,3,3,2,2,2,2,2,3,7,1,1,1,1,1
1,3,2,3,3,3,3,3,2,2,2,2,1,1,1,1,1,1,1,1
1,3,2,3,3,3,3,3,2,3,3,6,1,1,1,1,1,1,1,1
1,3,2,3,3,3,4,4,2,3,3,1,1,1,1,1,1,1,1,1
1,3,2,2,2,2,2,2,2,2,3,1,1,1,1,1,1,1,1,1
endlayer

layer
1,1,1,1,1,1,1,1,1,1,1,2,2,2,2,2,2,2,2,1
1,1,1,1,1,1,1,1,1,1,5,3,2,2,0,0,0,0,2,1
4,4,4,3,3,4,2,2,1,1,4,3,2,2,0,0,0,0,2,1
2,0,0,0,2,2,2,2,5,5,4,3,2,0,0,0,0,0,2,4
2,0,0,0,0,3,2,2,2,2,2,2,2,0,0,0,0,0,0,3
2,9,0,0,0,3,2,2,2,2,2,2,2,8,0,0,0,0,0,3
2,3,0,0,0,10,2,2,2,2,2,2,2,3,3,4,5,5,2,4
2,3,0,0,0,10,2,2,2,2,2,3,3,3,3,3,2,3,3,3
2,3,14,0,0,10,2,2,2,2,2,13,12,10,11,3,2,3,1,1
2,2,2,2,2,2,0,0,0,0,2,0,0,0,0,3,2,4,1,1
2,2,2,2,2,8,0,0,0,0,2,0,0,0,0,3,2,6,1,1
6,3,4,3,2,0,0,0,0,0,2,9,0,0,0,3,2,1,1,1
1,3,4,3,2,0,0,0,0,0,2,2,2,2,2,2,2,1,1,1
1,2,2,2,2,0,0,0,0,15,2,2,2,2,2,2,2,1,1,1
1,4,2,2,2,2,2,2,2,2,2,2,2,2,2,3,6,1,1,1
1,3,2,2,2,16,0,0,2,2,2,2,2,2,2,3,1,1,1,1
1,3,2,2,0,0,0,0,2,2,2,2,7,1,1,1,1,1,1,1
1,3,2,0,0,0,0,0,2,2,2,6,1,1,1,1,1,1,1,1
1,3,2,0,0,0,0,17,2,3,3,1,1,1,1,1,1,1,1,1
1,3,2,10,10,10,4,4,2,3,3,1,1,1,1,1,1,1,1,1
1,3,2,2,2,2,2,2,2,2,3,1,1,1,1,1,1,1,1,1
endlayer

layer
1,1,1,1,1,1,1,1,1,1,1,2,2,2,2,2,2,2,2,1
1,1,1,1,1,1,1,1,1,1,1,6,18,2,0,0,0,0,2,1
4,3,3,3,3,3,3,4,1,1,1,19,18,2,0,0,0,0,2,1
2,0,0,0,2,2,18,3,1,1,1,3,2,0,0,0,0,0,2,3
2,0,0,0,0,3,18,3,5,5,5,2,2,0,0,0,0,0,0,3
2,9,0,0,0,3,2,2,2,2,2,2,2,0,0,0,0,0,0,3
2,3,0,0,0,20,2,2,18,18,3,2,2,3,3,7,0,0,2,4
2,3,0,0,0,20,2,2,2,2,2,3,3,3,3,3,2,4,3,3
2,3,0,0,0,21,2,2,2,2,2,0,20,20,21,3,2,4,1,1
6,2,2,2,2,2,0,0,0,0,2,0,0,0,0,3,2,6,1,1
1,19,2,2,2,0,0,0,0,0,2,0,0,0,0,3,2,1,1,1
1,5,18,3,2,0,0,0,0,0,2,9,0,0,0,3,2,1,1,1
1,4,18,3,2,0,0,0,0,0,2,2,2,2,2,2,2,1,1,1
1,4,18,2,2,0,0,0,0,15,2,2,2,2,2,2,6,1,1,1
1,4,2,2,2,2,2,2,2,2,2,2,18,18,18,3,1,1,1,1
1,4,2,2,2,16,0,0,2,2,2,2,2,2,3,3,1,1,1,1
1,3,2,2,0,0,0,0,2,2,6,7,1,1,1,1,1,1,1,1
1,3,2,0,0,0,0,0,2,2,1,1,1,1,1,1,1,1,1,1
1,3,2,0,0,0,0,0,2,3,1,1,1,1,1,1,1,1,1,1
1,3,2,21,20,20,4,4,2,2,1,1,1,1,1,1,1,1,1,1
1,3,2,2,2,2,2,2,2,7,1,1,1,1,1,1,1,1,1,1
endlayer

layer
1,1,1,1,1,1,1,1,1,1,1,1,19,2,2,2,2,2,2,1
1,1,1,1,1,1,1,1,1,1,1,1,1,2,0,0,0,0,2,1
3,3,3,3,4,1,1,1,1,1,1,1,1,2,0,0,0,0,2,1
2,0,0,0,2,2,1,1,1,1,1,5,2,0,0,0,0,0,2,4
2,0,0,0,0,3,1,1,1,1,1,2,2,0,0,0,0,0,0,3
2,9,0,0,0,3,2,5,1,1,1,2,2,0,0,0,0,0,0,3
2,3,0,0,0,0,2,7,1,1,5,2,2,3,7,0,0,0,2,3
2,3,0,0,0,0,2,2,2,2,2,3,3,3,3,3,2,4,3,3
6,4,0,0,0,0,2,2,2,2,2,0,0,0,0,3,6,6,1,1
1,2,2,2,2,2,0,0,0,0,2,0,0,0,0,3,1,1,1,1
1,1,19,2,2,0,0,0,0,0,2,0,0,0,0,3,1,1,1,1
1,1,1,2,2,0,0,0,0,0,2,9,0,0,0,3,1,1,1,1
1,1,1,2,2,0,0,0,0,0,2,2,2,2,2,2,1,1,1,1
1,1,1,2,2,0,0,0,0,15,2,2,2,2,2,7,1,1,1,1
1,1,2,2,2,2,2,2,2,2,2,6,1,1,1,1,1,1,1,1
1,1,2,2,2,16,0,0,2,2,6,7,1,1,1,1,1,1,1,1
1,5,2,2,0,0,0,0,2,2,1,1,1,1,1,1,1,1,1,1
1,3,2,0,0,0,0,0,2,2,1,1,1,1,1,1,1,1,1,1
1,3,2,0,0,0,0,0,2,2,1,1,1,1,1,1,1,1,1,1
1,3,2,0,0,0,4,4,2,6,1,1,1,1,1,1,1,1,1,1
1,6,2,2,2,4,1,1,1,1,1,1,1,1,1,1,1,1,1,1
endlayer

layer
1,1,1,1,1,1,1,1,1,1,1,1,1,19,2,4,2,2,4,1
1,1,1,1,1,1,1,1,1,1,1,1,1,5,2,10,10,10,2,1
4,3,4,4,3,1,1,1,1,1,1,1,1,2,2,10,10,10,2,1
4,10,10,12,2,2,1,1,1,1,1,1,2,2,10,10,10,10,10,4
2,10,10,12,22,2,1,1,1,1,1,5,2,10,10,10,10,10,10,3
2,9,10,12,22,2,7,1,1,1,1,6,2,10,10,10,10,10,10,3
4,2,10,12,10,22,2,1,1,1,1,19,2,7,0,0,0,22,4,4
1,19,23,12,10,10,2,5,4,4,2,2,2,2,2,2,2,6,3,7
1,5,23,12,10,10,2,2,4,4,2,10,10,10,10,2,1,1,1,1
1,2,2,2,2,2,2,2,2,2,2,10,10,10,10,2,1,1,1,1
1,1,1,19,2,10,10,11,25,10,2,24,24,24,24,2,1,1,1,1
1,1,1,2,2,10,10,11,10,10,2,9,10,10,10,2,1,1,1,1
1,1,1,2,2,10,10,11,10,10,2,2,2,2,2,2,1,1,1,1
1,1,1,4,2,10,10,11,10,15,2,6,19,2,7,1,1,1,1,1
1,1,4,2,2,2,2,2,2,2,4,1,1,1,1,1,1,1,1,1
1,1,2,4,2,16,10,10,2,7,1,1,1,1,1,1,1,1,1,1
1,1,2,2,26,26,26,26,2,5,1,1,1,1,1,1,1,1,1,1
1,5,4,10,10,10,10,10,2,2,1,1,1,1,1,1,1,1,1,1
1,3,2,10,10,10,10,10,2,6,1,1,1,1,1,1,1,1,1,1
1,6,2,10,10,10,2,2,2,1,1,1,1,1,1,1,1,1,1,1
1,1,4,2,2,4,1,1,1,1,1,1,1,1,1,1,1,1,1,1
endlayer

layer
1,1,1,1,1,1,1,1,1,1,1,1,1,1,2,2,2,2,2,1
1,1,1,1,1,1,1,1,1,1,1,1,1,1,3,0,0,0,2,1
4,3,3,3,4,1,1,1,1,1,1,1,1,1,3,9,0,0,3,1
2,0,0,0,2,27,1,1,1,1,1,1,3,3,0,0,0,0,0,4
2,0,0,0,28,1,1,1,1,1,1,1,4,0,0,0,0,0,0,3
2,9,0,0,4,1,1,1,1,1,1,1,29,0,0,0,0,0,0,3
2,3,0,0,0,4,4,1,1,1,1,1,2,0,0,0,0,2,30,4
1,1,3,0,0,0,2,1,1,27,2,4,4,3,3,3,2,1,1,1
1,1,29,0,0,0,2,1,1,1,29,0,0,0,0,3,1,1,1,1
1,27,2,2,2,2,3,3,1,1,2,0,0,0,0,3,1,1,1,1
1,1,1,1,4,0,0,0,3,31,2,0,0,0,0,3,1,1,1,1
1,1,1,1,29,0,0,0,0,0,2,9,0,0,0,3,1,1,1,1
1,1,1,1,4,0,0,0,0,0,2,2,4,30,4,2,1,1,1,1
1,1,1,27,2,0,0,0,32,15,2,1,1,1,1,1,1,1,1,1
1,1,1,1,2,2,2,2,2,4,2,1,1,1,1,1,1,1,1,1
1,1,1,1,4,16,0,0,2,1,1,1,1,1,1,1,1,1,1,1
1,1,2,3,0,0,0,0,4,1,1,1,1,1,1,1,1,1,1,1
1,1,2,0,0,0,0,0,28,1,1,1,1,1,1,1,1,1,1,1
1,1,29,0,0,0,0,0,4,1,1,1,1,1,1,1,1,1,1,1
1,1,2,0,0,0,3,3,2,1,1,1,1,1,1,1,1,1,1,1
1,1,2,2,2,2,1,1,1,1,1,1,1,1,1,1,1,1,1,1
endlayer

layer
1,1,1,1,1,1,1,1,1,1,1,1,1,1,4,2,0,2,4,1
1,1,1,1,1,1,1,1,1,1,1,1,1,1,0,0,0,0,2,1
4,3,0,3,4,1,1,1,1,1,1,1,1,1,3,9,0,0,3,1
4,0,0,0,4,27,1,1,1,1,1,1,3,3,0,0,0,0,0,3
0,0,0,0,33,1,1,1,1,1,1,1,4,0,0,0,0,0,0,0
3,0,0,0,4,1,1,1,1,1,1,1,34,0,0,0,0,0,0,3
2,3,0,0,0,4,4,1,1,1,1,1,2,0,0,0,0,2,33,4
1,1,3,0,0,0,0,1,1,27,4,4,4,3,3,3,2,1,1,1
1,1,34,0,0,0,2,1,1,1,34,0,0,0,0,3,1,1,1,1
1,27,3,2,2,2,3,3,1,1,2,0,0,0,0,3,1,1,1,1
1,1,1,1,4,0,0,0,3,33,2,0,0,0,0,0,1,1,1,1
1,1,1,1,33,0,0,0,0,0,2,0,0,0,0,3,1,1,1,1
1,1,1,1,4,0,0,0,0,0,2,2,4,33,4,2,1,1,1,1
1,1,1,27,2,0,0,0,32,0,2,1,1,1,1,1,1,1,1,1
1,1,1,1,2,2,2,2,2,2,4,1,1,1,1,1,1,1,1,1
1,1,1,1,4,0,0,0,2,1,1,1,1,1,1,1,1,1,1,1
1,1,3,3,0,0,0,0,4,1,1,1,1,1,1,1,1,1,1,1
1,1,2,0,0,0,0,0,33,1,1,1,1,1,1,1,1,1,1,1
1,1,33,0,0,0,0,0,4,1,1,1,1,1,1,1,1,1,1,1
1,1,2,0,0,0,3,3,2,1,1,1,1,1,1,1,1,1,1,1
1,1,4,2,0,2,1,1,1,1,1,1,1,1,1,1,1,1,1,1
endlayer

layer
1,1,1,1,1,1,1,1,1,1,1,1,1,1,2,2,2,2,2,1
1,1,1,1,1,1,1,1,1,1,1,1,1,1,3,35,35,35,2,1
3,3,3,3,3,1,1,1,1,1,1,1,1,1,3,0,0,0,2,1
2,0,0,0,2,35,1,1,1,1,1,1,4,3,0,0,0,0,0,3
2,0,0,0,4,35,1,1,1,1,1,1,2,0,0,0,0,0,0,3
2,0,0,0,4,35,1,1,1,1,1,1,2,0,0,0,0,0,0,3
2,3,0,0,0,4,2,1,1,1,1,1,2,0,0,0,0,2,2,3
1,10,3,0,0,0,2,1,1,27,2,4,4,3,3,3,2,1,1,1
1,26,3,0,0,0,2,1,1,1,2,0,0,0,0,3,1,1,1,1
1,35,2,2,2,2,3,3,1,1,2,0,0,0,0,3,1,1,1,1
1,1,1,1,2,0,0,0,3,3,2,0,0,0,0,3,1,1,1,1
1,1,1,1,4,0,0,0,0,35,2,0,0,0,0,3,1,1,1,1
1,1,1,1,2,0,0,0,0,35,2,2,2,4,2,2,1,1,1,1
1,1,1,27,2,0,0,0,0,35,2,1,1,1,1,1,1,1,1,1
1,1,1,1,2,2,2,2,2,2,2,1,1,1,1,1,1,1,1,1
1,1,1,1,4,0,0,0,2,1,1,1,1,1,1,1,1,1,1,1
1,1,4,3,0,0,0,0,2,1,1,1,1,1,1,1,1,1,1,1
1,1,2,0,0,0,0,0,4,1,1,1,1,1,1,1,1,1,1,1
1,1,2,0,0,0,0,0,2,1,1,1,1,1,1,1,1,1,1,1
1,1,2,0,0,0,3,3,2,1,1,1,1,1,1,1,1,1,1,1
1,1,2,2,2,2,1,1,1,1,1,1,1,1,1,1,1,1,1,1
endlayer

layer
1,1,1,1,1,1,1,1,1,1,1,1,1,1,2,4,2,2,4,1
1,1,1,1,1,1,1,1,1,1,1,1,1,1,4,0,0,0,2,1
4,3,3,3,4,1,1,1,1,1,1,1,1,1,4,0,0,0,2,1
4,0,0,0,2,1,1,1,1,1,1,1,2,4,25,25,25,25,25,4
2,0,0,0,3,1,1,1,1,1,1,1,2,0,0,0,22,36,36,3
2,0,0,0,4,1,1,1,1,1,1,1,2,0,0,0,22,36,0,3
4,4,25,25,25,4,2,1,1,1,1,1,2,0,0,0,22,3,3,4
1,1,4,36,37,36,2,35,35,35,2,4,4,4,4,4,2,1,1,1
1,1,4,36,36,36,2,35,1,35,2,0,0,0,0,4,1,1,1,1
1,1,2,2,2,2,4,4,35,35,2,0,0,0,0,3,1,1,1,1
1,1,1,35,2,0,0,22,4,4,2,0,0,0,0,3,1,1,1,1
1,1,1,35,2,0,0,22,0,0,2,0,0,0,0,4,1,1,1,1
1,1,1,35,2,0,0,22,0,0,2,2,2,2,2,2,1,1,1,1
1,1,1,35,2,0,0,22,0,0,2,1,1,1,1,1,1,1,1,1
1,1,1,35,2,2,2,2,2,2,4,1,1,1,1,1,1,1,1,1
1,1,1,35,19,23,0,0,2,1,1,1,1,1,1,1,1,1,1,1
1,1,5,5,19,23,0,0,2,1,1,1,1,1,1,1,1,1,1,1
1,1,19,36,36,23,0,0,2,1,1,1,1,1,1,1,1,1,1,1
1,1,19,36,37,23,0,0,2,1,1,1,1,1,1,1,1,1,1,1
1,1,19,36,36,23,4,4,2,1,1,1,1,1,1,1,1,1,1,1
1,1,19,6,6,7,1,1,1,1,1,1,1,1,1,1,1,1,1,1
endlayer

layer
1,1,1,1,1,1,1,1,1,1,1,1,1,1,38,5,5,5,38,1
1,1,1,1,1,1,1,1,1,1,1,1,1,1,19,10,10,10,7,1
38,5,38,5,38,1,1,1,1,1,1,1,1,1,19,10,39,10,7,1
19,36,36,36,7,1,1,1,1,1,1,1,1,5,5,3,6,6,38,1
38,36,41,36,38,1,1,1,1,1,1,1,19,40,40,40,7,1,1,1
19,36,36,36,7,1,1,1,1,1,1,1,19,40,42,40,7,1,1,1
38,6,38,6,38,1,1,1,1,1,1,1,19,40,40,40,7,1,1,1
1,1,1,1,0,1,1,1,1,1,1,38,5,3,6,6,1,1,1,1
1,1,1,1,1,1,1,1,1,1,38,4,6,6,4,38,1,1,1,1
1,1,1,1,19,5,5,7,1,1,19,7,42,38,19,7,1,1,1,1
1,1,1,1,19,35,35,7,5,5,19,7,38,38,19,7,1,1,1,1
1,1,1,1,19,35,43,4,36,36,7,4,5,5,4,38,1,1,1,1
1,1,1,1,19,35,35,4,37,36,7,38,6,6,38,1,1,1,1,1
1,1,1,1,19,35,35,4,36,36,7,1,1,1,1,1,1,1,1,1
1,1,1,1,6,6,6,6,6,6,6,1,1,1,1,1,1,1,1,1
1,1,1,1,1,38,38,38,1,1,1,1,1,1,1,1,1,1,1,1
1,1,1,1,1,38,38,38,38,1,1,1,1,1,1,1,1,1,1,1
1,1,1,1,1,38,44,38,38,1,1,1,1,1,1,1,1,1,1,1
1,1,1,1,0,38,38,38,38,1,1,1,1,1,1,1,1,1,1,1
1,1,1,1,1,38,38,38,1,1,1,1,1,1,1,1,1,1,1,1
1,1,1,1,1,1,1,1,1,1,1,1,1,1,1,1,1,1,1,1
endlayer

