
# Created by Ruins mod version 16.5 Ingame Parser
# authoring Player: lafuller

weight=1
embed_into_distance=5
acceptable_target_blocks=
unacceptable_target_blocks=flowing_water,water,flowing_lava,lava,ice,bedrock,netherrack,nether_brick,nether_brick_fence,soul_sand,quartz_ore,end_stone,obsidian,iron_bars,cloud,flesh,ash_block,slime_grass,slime_congealed,slime_dirt
dimensions=11,22,21
allowable_overhang=0
max_leveling=7
leveling_buffer=-1
preserve_water=0
preserve_lava=0

rule1=0,100,preserveBlock
rule2=0,100,minecraft:sandstone-0
rule3=0,100,minecraft:double_stone_slab-9
rule4=0,100,minecraft:sandstone_stairs-3
rule5=0,100,minecraft:sandstone_stairs-2
rule6=0,100,minecraft:sandstone-2
rule7=0,100,minecraft:sandstone_stairs-0
rule8=0,100,minecraft:sandstone_stairs-1
rule9=0,100,minecraft:ladder-2
rule10=0,100,bookshelf,pumpkin,melon_block,hay_block,ChestGenHook:chests/spawn_bonus_chest:5-5
rule11=0,100,minecraft:trapdoor-11
rule12=0,100,bookshelf,pumpkin,melon_block,hay_block,ChestGenHook:chests/stronghold_library:5-3
rule13=0,100,minecraft:spruce_fence-0
rule14=0,100,minecraft:trapdoor-10
rule15=0,100,minecraft:spruce_stairs-7
rule16=0,100,minecraft:wooden_slab-9
rule17=0,100,minecraft:spruce_stairs-6
rule18=0,100,bookshelf,pumpkin,melon_block,hay_block,ChestGenHook:chests/village_blacksmith:5-2
rule19=0,100,minecraft:ladder-3
rule20=0,100,minecraft:trapdoor-9
rule21=0,100,minecraft:carpet-8
rule22=0,100,minecraft:carpet-7
rule23=0,100,minecraft:trapdoor-3
rule24=0,100,minecraft:trapdoor-1
rule25=0,100,minecraft:stone_slab-9
rule26=0,100,minecraft:stone_slab-1
rule27=0,100,minecraft:sandstone_stairs-4
rule28=0,100,minecraft:jungle_door-3
rule29=0,100,minecraft:jungle_door-1
rule30=0,100,minecraft:jungle_door-0
rule31=0,100,minecraft:trapdoor-8
rule32=0,100,minecraft:jungle_door-2
rule33=0,100,minecraft:ladder-5
rule34=0,100,minecraft:jungle_door-8
rule35=0,100,bookshelf,pumpkin,melon_block,hay_block,ChestGenHook:chests/stronghold_crossing:5-4
rule36=0,100,minecraft:jungle_door-9
rule37=0,100,minecraft:spruce_stairs-4
rule38=0,100,minecraft:spruce_stairs-3
rule39=0,100,minecraft:trapdoor-0
rule40=0,100,minecraft:wooden_slab-1
rule41=0,100,minecraft:sandstone_stairs-6
rule42=0,100,minecraft:sandstone_stairs-5
rule43=0,100,minecraft:sandstone_stairs-7
rule44=0,100,minecraft:trapdoor-6
rule45=0,100,minecraft:spruce_stairs-0
rule46=0,100,minecraft:spruce_stairs-1
rule47=0,100,minecraft:hay_block-0
rule48=0,100,minecraft:spruce_stairs-2
rule49=0,100,minecraft:trapdoor-2
rule50=0,100,minecraft:double_stone_slab-1
rule51=0,100,minecraft:trapdoor-7
rule52=0,100,minecraft:planks-1

layer
1,1,1,1,1,3,2,3,3,3,3,3,3,3,3,2,1,1,1,1,1
1,3,2,2,2,2,2,3,3,2,2,2,2,2,3,2,1,1,1,1,1
1,3,3,3,3,3,3,3,3,2,2,2,2,2,3,2,1,1,1,1,1
1,2,3,2,2,2,2,2,2,2,2,2,2,2,3,2,2,5,1,1,1
1,6,3,2,2,2,2,2,2,2,2,2,2,2,3,2,2,2,2,2,2
1,6,3,2,2,2,2,2,2,2,2,2,2,2,3,2,2,2,2,2,2
3,6,3,2,2,2,2,2,2,3,3,3,3,3,3,3,3,3,3,3,6
2,2,3,2,2,2,2,2,2,2,2,2,2,3,2,2,2,2,2,3,6
3,3,3,3,3,3,3,3,3,2,2,2,2,3,2,2,2,2,2,3,6
3,6,6,6,6,6,3,2,2,2,2,2,2,3,2,2,2,2,2,3,2
3,6,6,6,6,6,3,2,2,2,3,1,2,3,2,2,2,2,2,3,2
3,6,6,6,6,6,3,2,2,1,1,1,2,3,2,2,2,2,2,3,2
3,6,6,6,6,6,3,2,2,1,1,1,2,3,3,2,2,2,2,2,3
3,6,6,6,6,6,3,2,2,1,1,1,2,2,3,2,2,2,2,2,3
3,3,3,3,3,3,3,3,2,1,1,7,2,2,3,2,2,2,2,2,3
2,3,6,6,6,6,6,3,2,1,1,2,2,2,3,2,2,2,2,2,3
2,3,6,6,6,6,6,3,2,1,1,2,2,2,3,2,2,2,2,2,3
1,3,6,6,6,6,6,3,2,7,1,2,2,2,3,2,2,2,2,2,3
1,3,6,6,6,6,6,3,2,2,1,2,2,3,6,3,3,3,3,3,3
1,3,6,6,6,6,6,3,2,2,1,3,2,3,3,2,2,2,2,2,2
1,3,3,3,3,3,3,3,3,2,1,1,1,1,1,3,3,1,1,1,1
1,2,2,2,2,1,1,1,1,1,1,1,1,1,1,1,1,1,1,1,1
endlayer

layer
1,1,1,1,1,4,2,3,3,3,3,3,3,3,3,2,1,1,1,1,1
1,3,2,2,2,2,2,3,3,2,2,2,2,2,3,2,1,1,1,1,1
1,3,3,3,3,3,3,3,3,2,2,2,2,2,3,2,1,1,1,1,1
1,2,3,2,2,2,2,2,2,2,2,2,2,2,3,2,2,5,1,1,1
1,6,3,2,2,2,2,2,2,2,2,2,2,2,3,2,2,2,2,2,2
1,6,3,2,2,2,2,2,2,2,2,2,2,2,3,2,2,2,2,2,2
7,6,3,2,2,2,2,2,2,3,3,3,3,3,3,3,3,3,3,3,6
2,2,3,2,2,2,2,2,2,2,2,2,2,3,2,2,2,2,2,3,6
3,3,3,3,3,3,3,3,3,2,2,2,2,3,2,2,2,2,2,3,6
3,6,6,6,6,6,3,2,2,2,2,2,2,3,2,2,2,2,2,3,2
3,6,6,6,6,6,3,2,2,2,5,1,2,3,2,2,2,2,2,3,2
3,6,6,6,6,6,3,2,2,1,1,1,2,3,2,2,2,2,2,3,2
3,6,6,6,6,6,3,2,2,1,1,1,2,3,3,2,2,2,2,2,3
3,6,6,6,6,6,3,2,2,1,1,1,2,2,3,2,2,2,2,2,3
3,3,3,3,3,3,3,3,2,1,1,7,2,2,3,2,2,2,2,2,3
2,3,6,6,6,6,6,3,2,1,1,2,2,2,3,2,2,2,2,2,3
2,3,6,6,6,6,6,3,2,1,1,2,2,2,3,2,2,2,2,2,3
3,3,6,6,6,6,6,3,2,7,1,2,2,2,3,2,2,2,2,2,3
1,3,6,6,6,6,6,3,2,2,1,2,2,3,6,3,3,3,3,3,3
1,3,6,6,6,6,6,3,2,2,1,8,2,3,3,2,2,2,2,2,2
1,3,3,3,3,3,3,3,3,2,1,1,1,1,1,8,8,1,1,1,1
1,2,2,2,2,1,1,1,1,1,1,1,1,1,1,1,1,1,1,1,1
endlayer

layer
1,1,1,1,1,1,4,3,3,3,3,3,3,3,3,2,1,1,1,1,1
1,3,2,2,2,2,2,3,3,9,0,0,0,2,3,2,1,1,1,1,1
1,3,3,3,3,3,3,3,3,9,0,0,0,2,3,2,1,1,1,1,1
1,8,3,11,11,10,6,6,6,2,0,0,0,2,3,2,5,1,1,1,1
1,1,3,0,0,0,0,13,8,2,0,0,0,12,3,2,2,2,2,2,2
1,1,3,0,0,0,0,0,0,2,17,16,15,14,3,2,2,2,2,2,8
1,1,3,0,0,0,0,0,0,3,3,3,3,3,3,3,3,2,2,3,1
7,7,3,0,0,0,0,0,0,2,2,2,2,3,11,0,0,0,2,3,1
3,3,3,3,3,3,3,3,3,2,2,2,2,3,0,0,0,0,2,3,1
3,6,6,6,6,6,3,2,2,2,2,2,2,3,0,0,0,0,8,3,7
3,6,6,6,6,6,3,2,2,5,1,1,2,3,0,0,0,0,0,3,2
3,6,6,6,6,6,3,2,2,1,1,1,2,3,18,0,0,0,0,16,2
3,6,6,6,6,6,3,2,2,1,1,1,2,3,3,0,0,0,0,16,3
3,6,6,6,6,6,3,2,2,1,1,1,2,2,3,0,0,0,0,16,3
3,3,6,6,3,3,3,3,2,1,1,1,2,2,3,2,2,2,2,2,3
2,8,13,3,3,3,3,3,2,1,1,7,2,2,3,16,0,0,0,0,3
2,0,0,0,0,0,12,3,2,1,1,4,2,2,3,16,0,0,0,0,3
3,0,0,0,0,0,0,3,2,1,1,4,2,2,3,16,0,0,0,0,3
1,3,0,0,0,0,0,3,2,7,1,8,2,2,6,3,3,3,9,19,3
1,3,0,0,0,0,20,3,2,2,1,1,2,3,2,5,1,2,2,2,2
1,3,3,3,3,3,3,3,3,2,1,1,1,1,1,1,1,1,1,1,1
1,2,2,2,2,1,1,1,1,1,1,1,1,1,1,1,1,1,1,1,1
endlayer

layer
1,1,1,1,1,1,1,7,3,3,3,3,3,3,3,2,1,1,1,1,1
1,2,3,2,2,2,3,3,3,9,0,0,0,2,3,8,1,1,1,1,1
1,8,3,3,3,3,3,3,3,9,0,0,0,2,3,1,1,1,1,1,1
1,1,3,0,0,0,6,6,8,2,0,0,0,2,3,1,1,1,1,1,1
1,1,3,0,0,0,0,13,0,2,0,0,0,0,3,2,2,2,2,5,1
1,1,3,0,0,0,0,0,0,2,22,22,21,0,3,2,2,2,2,2,1
1,1,3,0,0,0,0,0,0,3,3,3,3,3,3,3,3,2,2,3,1
1,1,3,0,0,0,0,0,0,2,2,2,2,3,0,0,0,0,2,3,1
7,3,3,3,3,3,3,3,3,3,2,2,2,3,0,0,0,0,8,3,1
3,6,6,6,6,6,3,3,1,4,3,2,2,3,0,0,0,0,0,3,1
3,6,6,6,6,6,3,2,1,1,1,1,2,3,0,0,0,0,0,3,7
3,6,6,6,6,6,3,2,1,1,1,1,2,3,0,0,0,0,0,22,2
3,6,6,6,6,6,3,2,1,1,1,1,2,3,3,0,0,0,0,22,3
3,6,6,6,6,6,3,3,7,1,1,1,2,3,3,0,0,0,0,21,3
3,8,6,3,3,3,3,3,3,1,1,1,2,2,3,2,2,2,2,2,3
2,0,13,3,3,3,3,3,3,1,1,1,8,2,3,21,0,0,0,0,3
2,0,0,0,0,0,0,3,2,1,1,1,4,2,3,22,0,0,0,0,3
3,0,0,0,0,0,0,3,2,1,1,1,4,3,3,22,0,0,0,0,3
1,3,0,0,0,0,0,3,2,1,1,1,7,3,3,3,3,3,9,19,3
1,3,0,0,0,0,0,3,3,7,1,1,2,2,5,1,1,2,2,2,2
1,3,3,3,3,3,3,3,3,2,1,1,1,1,1,1,1,1,1,1,1
1,2,2,2,2,1,1,1,1,1,1,1,1,1,1,1,1,1,1,1,1
endlayer

layer
1,1,1,1,1,1,1,1,3,3,3,3,3,3,5,1,1,1,1,1,1
1,1,4,3,3,3,5,1,3,9,0,0,0,2,3,1,1,1,1,1,1
1,1,3,3,3,3,3,3,3,9,0,0,0,2,3,1,1,1,1,1,1
1,1,3,23,23,23,6,5,0,2,0,0,0,2,3,1,1,1,1,1,1
1,1,3,0,0,0,0,13,0,2,0,0,0,0,3,2,2,2,5,1,1
1,1,3,0,0,0,0,0,0,2,0,0,0,24,3,2,2,2,2,2,1
1,1,3,0,0,0,0,0,0,3,3,3,3,3,3,3,3,2,2,3,1
1,1,3,0,0,0,0,0,0,3,3,3,3,3,23,0,0,0,8,3,1
1,3,3,3,3,3,3,3,2,3,3,3,3,3,0,0,0,0,0,3,1
7,2,6,6,6,6,3,3,1,1,4,3,3,3,0,0,0,0,0,3,1
2,2,6,6,6,6,3,3,1,1,1,1,3,3,0,0,0,0,0,3,1
2,2,6,6,6,6,3,3,1,1,1,1,2,3,0,0,0,0,0,25,7
3,6,6,6,6,6,3,2,1,1,1,1,2,3,3,0,0,0,0,25,3
3,26,6,6,6,6,3,5,1,1,1,1,2,3,3,0,0,0,0,25,3
3,0,6,6,6,2,3,5,1,1,1,1,8,3,3,2,2,2,2,2,3
3,0,13,3,3,3,3,7,7,1,1,1,1,3,3,0,0,0,0,0,3
3,0,0,0,0,0,0,3,3,1,1,1,1,3,3,0,0,0,0,0,3
3,0,0,0,0,0,0,3,3,1,1,1,1,3,3,0,0,0,0,0,3
1,3,0,0,0,0,0,3,3,1,1,1,1,8,3,3,3,3,9,19,3
1,3,0,0,0,0,24,3,2,1,1,1,1,1,1,1,1,2,2,2,2
1,3,3,3,3,3,3,3,8,1,1,1,1,1,1,1,1,1,1,1,1
1,2,2,2,2,1,1,1,1,1,1,1,1,1,1,1,1,1,1,1,1
endlayer

layer
1,1,1,1,1,1,1,1,6,3,3,6,3,3,1,1,1,1,1,1,1
1,1,1,4,3,5,1,1,3,9,16,16,16,3,7,1,1,1,1,1,1
1,1,6,3,3,3,3,3,3,9,16,16,16,3,2,1,1,1,1,1,1
1,1,3,3,3,3,5,0,0,3,16,16,16,3,6,1,1,1,1,1,1
1,1,3,3,3,3,7,13,0,3,16,16,16,16,3,2,2,5,1,1,1
1,1,6,3,3,3,3,27,27,3,16,16,16,16,3,2,2,2,2,2,1
1,1,3,3,3,3,3,3,3,3,3,3,3,3,3,16,16,16,8,2,1
1,1,3,3,3,3,3,3,3,3,3,3,3,16,16,16,16,16,0,3,1
1,3,3,3,3,3,3,3,6,2,8,8,3,16,16,16,16,16,0,3,1
1,3,0,0,0,16,3,8,1,1,1,1,3,16,16,16,16,16,0,6,1
1,28,0,0,0,16,2,1,1,1,1,1,3,3,27,27,27,27,27,3,1
1,3,0,0,0,16,2,1,1,1,1,1,2,2,16,16,16,16,2,3,1
3,3,0,0,0,2,3,1,1,1,1,1,2,6,16,16,16,16,2,2,7
3,0,0,0,0,3,1,1,1,1,1,1,8,2,16,16,16,16,2,2,2
2,0,0,0,0,29,1,1,1,1,1,1,1,3,3,16,16,16,2,2,3
2,0,13,0,0,3,1,1,1,1,1,1,1,3,3,16,16,16,16,16,6
2,3,3,3,3,3,3,3,1,1,1,1,1,3,2,16,16,16,16,16,3
1,6,3,3,3,3,3,3,7,1,1,1,1,8,3,16,16,16,16,16,3
1,3,3,3,3,3,3,3,2,1,1,1,1,1,6,3,3,6,9,19,6
1,3,3,3,3,3,3,3,8,1,1,1,1,1,1,1,1,2,2,2,6
1,6,3,3,6,3,3,6,1,1,1,1,1,1,1,1,1,1,1,1,1
1,6,2,2,2,1,1,1,1,1,1,1,1,1,1,1,1,1,1,1,1
endlayer

layer
1,1,1,1,1,1,1,1,2,3,3,3,3,3,1,1,1,1,1,1,1
1,1,1,1,1,1,1,1,2,9,0,0,0,2,1,1,1,1,1,1,1
1,1,13,1,1,6,3,3,2,9,0,0,0,29,1,1,1,1,1,1,1
1,1,3,2,30,2,0,0,0,2,0,0,0,2,6,1,1,1,1,1,1
1,1,3,31,0,0,0,13,13,2,0,0,0,16,2,1,1,1,1,1,1
1,1,3,0,0,0,0,0,0,2,0,0,0,16,2,6,30,6,2,2,1
1,1,3,0,0,0,0,0,0,6,2,32,3,3,2,0,0,0,0,2,1
1,1,3,16,16,16,2,2,32,2,1,1,2,0,33,0,0,0,0,3,1
1,3,3,3,3,3,3,1,1,1,1,1,2,0,0,0,0,0,0,3,1
1,2,0,0,0,21,3,1,1,1,1,1,2,0,0,0,0,0,0,3,1
1,34,0,0,0,22,2,1,1,1,1,1,2,6,2,2,2,2,2,3,1
1,2,0,0,0,22,2,1,1,1,1,1,1,3,0,0,0,0,2,1,1
3,2,0,0,0,2,6,1,1,1,1,1,1,6,0,0,0,0,29,1,1
3,0,0,0,0,2,1,1,1,1,1,1,1,2,18,0,0,0,2,1,1
0,0,0,0,0,34,1,1,1,1,1,1,1,6,6,0,0,0,2,2,3
2,0,0,0,0,2,1,1,1,1,1,1,1,1,2,0,0,0,0,0,3
2,2,2,2,2,2,2,6,1,1,1,1,1,1,28,0,0,0,0,0,3
1,3,31,0,0,0,0,2,1,1,1,1,1,1,3,0,0,0,0,0,3
1,3,0,0,0,0,0,29,1,1,1,1,1,1,3,3,3,3,9,19,3
1,3,0,0,0,0,0,3,1,1,1,1,1,1,1,1,1,2,2,2,6
1,3,35,19,3,3,3,3,1,1,1,1,1,1,1,1,1,1,1,1,1
1,2,2,2,2,1,1,1,1,1,1,1,1,1,1,1,1,1,1,1,1
endlayer

layer
1,1,1,1,1,1,1,1,2,3,2,0,2,3,1,1,1,1,1,1,1
1,1,1,1,1,1,1,1,2,0,0,0,0,2,1,1,1,1,1,1,1
1,1,13,1,1,6,0,2,2,0,0,0,0,36,1,1,1,1,1,1,1
1,1,3,2,34,2,0,0,0,2,0,0,0,2,6,1,1,1,1,1,1
1,1,2,0,0,0,0,0,0,2,0,0,0,0,2,1,1,1,1,1,1
1,1,0,0,0,0,0,0,0,2,0,0,0,0,2,6,34,6,0,2,1
1,1,2,0,0,0,0,0,0,6,2,34,3,3,3,0,0,0,0,2,1
1,1,3,21,22,22,2,2,34,2,1,1,2,0,33,0,0,0,0,3,1
1,3,3,3,3,3,3,1,1,1,1,1,0,0,0,0,0,0,0,0,1
1,2,0,0,0,0,3,1,1,1,1,1,2,0,0,0,0,0,0,3,1
1,2,0,0,0,0,0,1,1,1,1,1,2,6,2,2,2,2,2,2,1
1,2,0,0,0,0,2,1,1,1,1,1,1,3,0,0,0,0,2,1,1
2,2,0,0,0,2,6,1,1,1,1,1,1,0,0,0,0,0,34,1,1
3,0,0,0,0,2,1,1,1,1,1,1,1,2,0,0,0,0,2,1,1
2,0,0,0,0,2,1,1,1,1,1,1,1,2,6,0,0,0,2,2,2
2,0,0,0,0,2,1,1,1,1,1,1,1,1,6,0,0,0,0,0,3
2,2,2,2,2,2,2,6,1,1,1,1,1,1,34,0,0,0,0,0,2
1,3,0,0,0,0,0,2,1,1,1,1,1,1,3,0,0,0,0,0,0
1,0,0,0,0,0,0,34,1,1,1,1,1,1,6,3,0,3,0,0,6
1,3,0,0,0,0,0,3,1,1,1,1,1,1,1,1,1,2,2,2,2
1,2,0,19,3,0,3,6,1,1,1,1,1,1,1,1,1,1,1,1,1
1,2,2,0,2,1,1,1,1,1,1,1,1,1,1,1,1,1,1,1,1
endlayer

layer
1,1,1,1,1,1,1,1,2,3,3,3,3,3,1,1,1,1,1,1,1
1,1,1,1,1,1,1,1,2,0,0,0,0,2,1,1,1,1,1,1,1
1,1,38,37,37,3,3,3,3,0,0,0,0,2,1,1,1,1,1,1,1
1,1,3,2,2,2,0,0,0,2,0,0,0,2,6,1,1,1,1,1,1
1,1,3,0,0,0,0,0,0,2,0,0,0,0,2,1,1,1,1,1,1
1,1,3,0,0,0,0,0,0,2,0,0,0,0,2,2,6,2,2,2,1
1,1,3,0,0,0,0,0,0,3,6,3,3,3,3,0,0,0,0,2,1
1,1,3,0,0,0,2,2,2,2,1,1,2,39,0,0,0,0,0,3,1
1,3,3,3,3,3,3,1,1,1,1,1,2,39,0,0,0,0,0,3,1
1,2,0,0,0,0,3,1,1,1,1,1,2,39,0,0,0,0,0,3,1
1,2,0,0,0,0,3,1,1,1,1,1,2,3,2,2,2,2,2,3,1
1,2,0,0,0,0,6,1,1,1,1,1,1,3,0,0,0,0,2,1,1
3,2,0,0,0,2,3,1,1,1,1,1,1,3,0,0,0,0,3,1,1
3,0,0,0,0,2,40,1,1,1,1,1,1,2,0,0,0,0,2,1,1
3,0,0,0,0,2,40,1,1,1,1,1,1,2,3,0,0,0,2,2,3
2,0,0,0,0,2,40,1,1,1,1,1,1,1,6,0,0,0,0,0,3
2,2,2,2,2,2,2,3,1,1,1,1,1,1,3,0,0,0,0,0,3
1,3,40,0,0,0,0,6,1,1,1,1,1,1,3,0,0,0,0,0,3
1,3,40,0,0,0,0,3,1,1,1,1,1,1,3,3,3,3,0,0,3
1,3,40,0,0,0,0,3,1,1,1,1,1,1,1,1,1,2,2,2,2
1,3,40,19,3,3,3,3,1,1,1,1,1,1,1,1,1,1,1,1,1
1,2,2,2,2,1,1,1,1,1,1,1,1,1,1,1,1,1,1,1,1
endlayer

layer
1,1,1,1,1,1,1,1,7,7,3,6,3,3,1,1,1,1,1,1,1
1,1,1,1,1,1,1,1,4,41,0,0,0,2,1,1,1,1,1,1,1
1,1,1,1,1,2,6,3,3,41,0,0,0,2,1,1,1,1,1,1,1
1,1,3,2,2,2,25,25,25,2,42,42,42,2,6,1,1,1,1,1,1
1,1,3,0,0,43,25,25,25,2,0,0,0,0,2,1,1,1,1,1,1
1,1,2,0,0,43,25,11,25,2,0,0,0,0,2,7,7,7,7,5,1
1,1,2,0,0,43,25,25,25,3,3,3,3,3,2,0,0,25,25,5,1
1,1,2,0,0,43,2,2,2,2,40,40,2,0,0,0,0,25,25,5,1
1,3,3,3,3,3,3,1,1,1,1,1,2,0,0,0,0,25,25,5,1
1,2,0,0,0,0,3,1,1,1,1,1,2,0,0,0,0,25,25,5,1
1,2,0,0,0,0,3,1,1,1,1,1,2,3,42,42,42,42,2,8,1
1,2,0,0,0,0,3,1,1,1,1,1,1,3,0,0,0,0,2,40,1
7,2,27,27,27,2,3,1,1,1,1,1,1,6,0,0,0,0,2,40,1
4,25,25,25,25,5,1,1,1,1,1,1,1,2,0,0,0,0,2,40,1
4,25,11,25,25,5,1,1,1,1,1,1,1,2,2,27,27,27,2,2,3
4,25,25,25,25,5,1,1,1,1,1,1,1,1,3,25,25,43,0,0,6
8,2,2,2,2,2,2,2,1,1,1,1,1,1,3,25,0,43,0,0,3
1,6,0,0,0,0,0,2,1,1,1,1,1,1,3,25,25,43,0,0,3
1,3,0,0,0,0,0,3,1,1,1,1,1,1,6,3,3,6,0,0,6
1,3,0,0,0,0,0,3,1,1,1,1,1,1,1,1,1,2,2,2,6
1,6,0,0,6,3,3,6,1,1,1,1,1,1,1,1,1,1,1,1,1
1,6,2,2,2,1,1,1,1,1,1,1,1,1,1,1,1,1,1,1,1
endlayer

layer
1,1,1,1,1,1,1,1,1,1,26,26,26,1,1,1,1,1,1,1,1
1,1,1,1,1,1,1,1,1,26,26,26,26,26,1,1,1,1,1,1,1
1,1,1,1,1,1,1,1,1,26,26,44,26,26,1,1,1,1,1,1,1
1,1,26,45,45,26,1,1,1,4,7,7,7,7,5,1,1,1,1,1,1
1,1,46,47,47,46,1,1,1,4,40,40,40,40,5,1,1,1,1,1,1
1,1,38,47,47,48,1,0,1,4,40,40,40,40,5,1,1,1,1,1,1
1,1,45,47,47,45,1,1,1,4,8,8,8,8,8,26,26,1,1,1,1
1,1,26,46,46,26,1,1,1,1,1,1,26,26,26,26,26,1,1,1,1
1,1,7,26,26,7,1,1,1,1,1,1,26,26,26,49,26,1,1,1,1
1,4,50,50,50,50,5,1,1,1,1,1,26,26,26,26,26,1,1,1,1
1,26,50,26,51,50,26,1,1,1,1,1,1,40,48,45,45,38,40,1,1
1,4,50,50,50,50,5,1,1,1,1,1,1,46,47,47,47,47,46,1,1
1,1,8,26,26,8,1,1,1,1,1,1,1,38,47,51,47,47,48,1,1
1,1,1,1,1,1,1,1,1,1,1,1,1,45,47,47,47,47,45,1,1
1,1,0,1,1,1,1,1,1,1,1,1,1,40,48,46,46,38,40,1,1
1,1,1,1,1,1,1,1,1,1,1,1,1,1,26,50,50,50,50,26,26
1,40,38,40,40,40,48,40,1,1,1,1,1,1,26,50,23,50,50,50,26
1,45,37,37,37,37,37,45,1,1,1,1,1,1,26,50,50,50,39,50,26
1,40,16,16,11,16,16,40,1,1,1,1,1,1,1,26,50,50,50,50,26
1,40,16,16,16,16,16,45,1,1,1,1,1,1,1,1,1,50,50,26,1
1,46,16,16,52,52,52,40,1,1,1,1,1,1,1,1,1,1,1,1,1
1,40,38,40,40,1,1,1,1,1,1,1,1,1,1,1,1,1,1,1,1
endlayer

