
# Created by Ruins mod version 16.7 Ingame Parser
# authoring Player: lafuller

weight=1
embed_into_distance=7
acceptable_target_blocks=
unacceptable_target_blocks=flowing_water,water,flowing_lava,lava,ice,bedrock,netherrack,nether_brick,nether_brick_fence,soul_sand,quartz_ore,gravel,end_stone,obsidian,iron_bars,cloud,flesh,ash_block,slime_grass,slime_congealed,slime_dirt
dimensions=17,7,7
allowable_overhang=0
max_leveling=4
leveling_buffer=-1
preserve_water=0
preserve_lava=0

rule1=0,100,minecraft:stonebrick-0
rule2=0,100,minecraft:stone_slab-13
rule3=0,100,minecraft:sea_lantern-0
rule4=0,100,minecraft:stone_brick_stairs-4
rule5=0,100,minecraft:stone_brick_stairs-0
rule6=0,100,minecraft:stone_brick_stairs-6
rule7=0,100,minecraft:stone_brick_stairs-7
rule8=0,100,minecraft:cobblestone_wall-0
rule9=0,100,minecraft:stone_brick_stairs-2
rule10=0,100,minecraft:stone_brick_stairs-3
rule11=0,100,minecraft:stone_brick_stairs-5
rule12=0,100,minecraft:stone_brick_stairs-1
rule13=0,100,minecraft:stone_slab-5
rule14=0,100,minecraft:water-0
rule15=0,100,preserveBlock

layer
1,1,1,1,1,1,1
1,1,1,1,1,1,1
1,1,1,1,1,1,1
1,1,1,1,1,1,1
1,1,1,1,1,1,1
1,1,1,1,1,1,1
1,1,1,1,1,1,1
endlayer

layer
1,1,1,1,1,1,1
1,1,1,1,1,1,1
1,1,1,1,1,1,1
1,1,1,1,1,1,1
1,1,1,1,1,1,1
1,1,1,1,1,1,1
1,1,1,1,1,1,1
endlayer

layer
1,1,1,1,1,1,1
1,1,1,1,1,1,1
1,1,1,1,1,1,1
1,1,1,1,1,1,1
1,1,1,1,1,1,1
1,1,1,1,1,1,1
1,1,1,1,1,1,1
endlayer

layer
1,1,1,1,1,1,1
1,1,1,1,1,1,1
1,1,1,1,1,1,1
1,1,1,1,1,1,1
1,1,1,1,1,1,1
1,1,1,1,1,1,1
1,1,1,1,1,1,1
endlayer

layer
2,1,1,1,1,1,2
1,1,1,1,1,1,1
1,1,1,1,1,1,1
1,1,1,1,1,1,1
1,1,1,1,1,1,1
1,1,1,1,1,1,1
2,1,1,1,1,1,2
endlayer

layer
2,1,1,1,1,1,2
1,1,1,1,1,1,1
1,1,1,1,1,1,1
1,1,1,3,1,1,1
1,1,1,1,1,1,1
1,1,1,1,1,1,1
2,1,1,1,1,1,2
endlayer

layer
4,4,1,5,1,4,4
7,1,1,1,1,1,6
1,1,8,8,8,1,1
10,1,8,8,8,1,9
1,1,8,8,8,1,1
7,1,1,1,1,1,6
7,11,1,12,1,11,11
endlayer

layer
4,4,9,0,10,4,4
7,1,9,13,10,1,6
12,12,14,14,14,12,12
0,13,14,14,14,13,0
5,5,14,14,14,5,5
7,1,9,13,10,1,6
7,11,9,0,10,11,11
endlayer

layer
15,5,0,0,0,5,15
10,1,0,0,0,1,9
0,0,0,0,0,0,0
0,0,0,0,0,0,0
0,0,0,0,0,0,0
10,1,0,0,0,1,9
15,12,0,0,0,12,15
endlayer

layer
15,8,0,0,0,8,15
8,1,0,0,0,1,8
0,0,0,0,0,0,0
0,0,0,0,0,0,0
0,0,0,0,0,0,0
8,1,0,0,0,1,8
15,8,0,0,0,8,15
endlayer

layer
15,4,0,0,0,4,15
7,1,0,0,0,1,6
0,0,0,0,0,0,0
0,0,0,0,0,0,0
0,0,0,0,0,0,0
7,1,0,0,0,1,6
15,11,0,0,0,11,15
endlayer

layer
15,4,0,0,0,4,15
7,1,0,0,0,1,6
0,0,0,0,0,0,0
0,0,0,0,0,0,0
0,0,0,0,0,0,0
7,1,0,0,0,1,6
15,11,0,0,0,11,15
endlayer

layer
15,10,2,0,2,9,15
5,1,6,0,7,1,5
2,11,0,0,0,11,2
0,0,0,0,0,0,0
2,4,0,0,0,4,2
12,1,6,0,7,1,12
15,10,2,0,2,9,15
endlayer

layer
15,1,13,13,13,1,15
1,1,1,1,1,1,1
13,1,2,0,2,1,13
13,1,0,0,0,1,13
13,1,2,0,2,1,13
1,1,1,1,1,1,1
15,1,13,13,13,1,15
endlayer

layer
15,5,15,15,15,5,15
10,1,5,13,5,1,9
15,10,0,0,0,9,15
15,13,0,0,0,13,15
15,10,0,0,0,9,15
10,1,12,13,12,1,9
15,12,15,15,15,12,15
endlayer

layer
15,15,15,15,15,15,15
15,4,4,0,4,6,15
15,7,1,2,1,6,15
15,0,2,0,2,0,15
15,7,1,2,1,6,15
15,11,11,0,11,11,15
15,15,15,15,15,15,15
endlayer

layer
15,15,0,0,0,15,15
15,0,13,0,13,0,15
0,13,1,0,1,13,0
0,0,0,0,0,0,0
0,13,1,0,1,13,0
15,0,13,0,13,0,15
15,15,0,0,0,15,15
endlayer

