
# Created by Ruins mod version 16.7 Ingame Parser
# authoring Player: lafuller

weight=1
embed_into_distance=4
acceptable_target_blocks=water
unacceptable_target_blocks=
biomesToSpawnIn=ocean,deep ocean,ocean oil field,kelp forest
dimensions=23,24,24
allowable_overhang=0
max_leveling=0
leveling_buffer=-1
preserve_water=0
preserve_lava=0

rule1=0,100,preserveBlock
rule2=0,100,minecraft:planks-5
rule3=0,100,minecraft:log-0
rule4=0,100,minecraft:spruce_stairs-2
rule5=0,100,minecraft:wooden_slab-9
rule6=0,100,minecraft:carpet-7
rule7=0,100,minecraft:carpet-8
rule8=0,100,minecraft:wooden_slab-13
rule9=0,100,minecraft:planks-1
rule10=0,100,minecraft:spruce_stairs-4
rule11=0,100,minecraft:spruce_stairs-6
rule12=0,100,minecraft:spruce_stairs-3
rule13=0,100,minecraft:spruce_stairs-1
rule14=0,100,minecraft:spruce_stairs-7
rule15=0,100,ChestGenHook:chests/stronghold_crossing:5-2
rule16=0,100,minecraft:spruce_stairs-5
rule17=0,100,minecraft:spruce_stairs-0
rule18=0,100,minecraft:trapdoor-14
rule19=0,100,ChestGenHook:chests/stronghold_corridor:5-5
rule20=0,100,minecraft:trapdoor-12
rule21=0,100,minecraft:trapdoor-13
rule22=0,100,minecraft:trapdoor-15
rule23=0,100,minecraft:dark_oak_stairs-0
rule24=0,100,minecraft:dark_oak_stairs-2
rule25=0,100,minecraft:trapdoor-8
rule26=0,100,minecraft:wooden_slab-1
rule27=0,100,minecraft:trapdoor-11
rule28=0,100,minecraft:dark_oak_stairs-3
rule29=0,100,minecraft:trapdoor-9
rule30=0,100,minecraft:trapdoor-10
rule31=0,100,minecraft:dark_oak_stairs-1
rule32=0,100,minecraft:ladder-5
rule33=0,100,minecraft:spruce_fence-0
rule34=0,100,minecraft:spruce_door-1
rule35=0,100,ChestGenHook:chests/stronghold_library:5-3
rule36=0,100,minecraft:crafting_table-0
rule37=0,100,minecraft:wooden_slab-5
rule38=0,100,minecraft:spruce_door-9
rule39=0,100,minecraft:dark_oak_fence-0
rule40=0,100,minecraft:bookshelf-0
rule41=0,100,minecraft:wool-0
rule42=0,100,minecraft:log-12
rule43=0,100,minecraft:log-8
rule44=0,100,minecraft:log-4
rule45=0,100,minecraft:trapdoor-0

layer
1,1,1,1,1,1,1,1,1,1,1,1,1,1,1,1,1,1,1,1,1,1,1,1
1,1,1,1,1,1,1,1,1,1,1,1,1,1,1,1,1,1,1,1,1,1,1,1
1,1,1,1,1,1,1,1,1,1,1,1,1,1,1,1,1,1,1,1,1,1,1,1
1,1,1,1,1,1,1,1,1,1,1,1,1,1,1,1,1,1,1,1,1,1,1,1
1,1,1,1,1,1,1,1,1,1,1,1,1,1,1,1,1,1,2,2,1,1,1,1
1,1,1,1,1,1,1,1,1,1,1,1,1,1,1,1,1,2,2,2,1,1,1,1
1,1,1,1,1,1,1,1,1,1,1,1,1,1,1,2,2,2,2,1,1,1,1,1
1,1,1,1,1,1,1,1,1,1,1,1,1,1,2,2,2,2,1,1,1,1,1,1
1,1,1,1,1,1,1,1,1,1,1,1,2,2,2,2,2,2,1,1,1,1,1,1
1,1,1,1,1,1,1,1,1,1,1,2,2,2,2,2,2,1,1,1,1,1,1,1
1,1,1,1,1,1,1,1,1,1,2,2,2,2,2,2,1,1,1,1,1,1,1,1
1,1,1,1,1,1,1,1,1,2,2,2,2,2,2,1,1,1,1,1,1,1,1,1
1,1,1,1,1,1,1,1,2,2,2,2,2,2,2,1,1,1,1,1,1,1,1,1
1,1,1,1,1,1,1,2,2,2,2,2,2,2,1,1,1,1,1,1,1,1,1,1
1,1,1,1,1,1,2,2,2,2,2,2,2,1,1,1,1,1,1,1,1,1,1,1
1,1,1,1,1,2,2,2,2,2,2,2,1,1,1,1,1,1,1,1,1,1,1,1
1,1,1,1,1,2,2,2,2,2,2,1,1,1,1,1,1,1,1,1,1,1,1,1
1,1,1,1,1,2,2,2,2,2,1,1,1,1,1,1,1,1,1,1,1,1,1,1
1,1,1,1,1,1,2,2,2,1,1,1,1,1,1,1,1,1,1,1,1,1,1,1
1,1,1,1,1,1,1,1,1,1,1,1,1,1,1,1,1,1,1,1,1,1,1,1
1,1,1,1,1,1,1,1,1,1,1,1,1,1,1,1,1,1,1,1,1,1,1,1
1,1,1,1,1,1,1,1,1,1,1,1,1,1,1,1,1,1,1,1,1,1,1,1
1,1,1,1,1,1,1,1,1,1,1,1,1,1,1,1,1,1,1,1,1,1,1,1
1,1,1,1,1,1,1,1,1,1,1,1,1,1,1,1,1,1,1,1,1,1,1,1
endlayer

layer
1,1,1,1,1,1,1,1,1,1,1,1,1,1,1,1,1,1,1,1,1,1,1,1
1,1,1,1,1,1,1,1,1,1,1,1,1,1,1,1,1,1,1,1,1,1,1,1
1,1,1,1,1,1,1,1,1,1,1,1,1,1,1,1,1,1,1,2,2,2,1,1
1,1,1,1,1,1,1,1,1,1,1,1,1,1,1,1,1,2,2,2,2,2,1,1
1,1,1,1,1,1,1,1,1,1,1,1,1,1,1,1,2,2,2,2,2,2,1,1
1,1,1,1,1,1,1,1,1,1,1,1,1,1,1,2,2,2,2,2,2,1,1,1
1,1,1,1,1,1,1,1,1,1,1,1,1,1,2,2,2,2,2,2,2,1,1,1
1,1,1,1,1,1,1,1,1,1,1,1,2,2,2,2,2,2,2,2,1,1,1,1
1,1,1,1,1,1,1,1,1,1,1,2,4,0,0,3,2,2,2,1,1,1,1,1
1,1,1,1,1,1,1,1,1,1,2,0,0,0,0,5,2,2,1,1,1,1,1,1
1,1,1,1,1,1,1,1,1,2,0,0,0,0,0,5,2,1,1,1,1,1,1,1
1,1,1,1,1,1,1,1,2,0,0,0,0,0,0,2,2,1,1,1,1,1,1,1
1,1,1,1,1,1,1,2,0,0,0,0,0,0,0,2,1,1,1,1,1,1,1,1
1,1,1,1,1,1,2,0,0,0,3,0,0,0,2,1,1,1,1,1,1,1,1,1
1,1,1,1,1,2,0,0,0,0,0,0,0,2,1,1,1,1,1,1,1,1,1,1
1,1,1,1,2,5,0,0,0,0,0,0,2,1,1,1,1,1,1,1,1,1,1,1
1,1,1,1,2,5,0,0,0,0,0,2,1,1,1,1,1,1,1,1,1,1,1,1
1,1,1,1,2,5,0,0,0,0,2,1,1,1,1,1,1,1,1,1,1,1,1,1
1,1,1,1,2,2,5,5,5,2,1,1,1,1,1,1,1,1,1,1,1,1,1,1
1,1,1,1,1,2,2,2,2,1,1,1,1,1,1,1,1,1,1,1,1,1,1,1
1,1,1,1,1,1,1,1,1,1,1,1,1,1,1,1,1,1,1,1,1,1,1,1
1,1,1,1,1,1,1,1,1,1,1,1,1,1,1,1,1,1,1,1,1,1,1,1
1,1,1,1,1,1,1,1,1,1,1,1,1,1,1,1,1,1,1,1,1,1,1,1
1,1,1,1,1,1,1,1,1,1,1,1,1,1,1,1,1,1,1,1,1,1,1,1
endlayer

layer
1,1,1,1,1,1,1,1,1,1,1,1,1,1,1,1,1,1,1,1,1,1,1,1
1,1,1,1,1,1,1,1,1,1,1,1,1,1,1,1,1,1,1,1,2,2,1,1
1,1,1,1,1,1,1,1,1,1,1,1,1,1,1,1,1,1,2,2,2,2,2,1
1,1,1,1,1,1,1,1,1,1,1,1,1,1,1,1,2,2,2,2,2,2,2,1
1,1,1,1,1,1,1,1,1,1,1,1,1,1,1,2,2,2,2,2,2,2,1,1
1,1,1,1,1,1,1,1,1,1,1,1,1,1,2,2,2,2,2,2,2,2,1,1
1,1,1,1,1,1,1,1,1,1,1,1,1,2,2,2,2,2,2,2,2,1,1,1
1,1,1,1,1,1,1,1,1,1,1,2,2,2,2,2,2,2,2,2,2,1,1,1
1,1,1,1,1,1,1,1,1,1,2,4,0,0,0,3,2,2,2,2,1,1,1,1
1,1,1,1,1,1,1,1,1,2,0,0,0,0,0,0,2,2,2,1,1,1,1,1
1,1,1,1,1,1,1,1,2,0,0,0,0,0,0,6,2,2,1,1,1,1,1,1
1,1,1,1,1,1,1,2,0,0,0,0,0,0,0,6,2,2,1,1,1,1,1,1
1,1,1,1,1,1,2,0,0,0,0,0,0,0,0,7,2,1,1,1,1,1,1,1
1,1,1,1,1,2,0,0,0,0,3,0,0,0,0,2,1,1,1,1,1,1,1,1
1,1,1,1,2,7,0,0,0,0,0,0,0,0,2,1,1,1,1,1,1,1,1,1
1,1,1,1,2,6,0,0,0,0,0,0,0,2,1,1,1,1,1,1,1,1,1,1
1,1,1,2,2,6,0,0,0,0,0,0,2,1,1,1,1,1,1,1,1,1,1,1
1,1,1,2,2,0,0,0,0,0,0,2,1,1,1,1,1,1,1,1,1,1,1,1
1,1,1,2,2,0,6,6,7,0,2,1,1,1,1,1,1,1,1,1,1,1,1,1
1,1,1,2,2,2,2,2,2,2,1,1,1,1,1,1,1,1,1,1,1,1,1,1
1,1,1,1,2,2,2,2,1,1,1,1,1,1,1,1,1,1,1,1,1,1,1,1
1,1,1,1,1,1,1,1,1,1,1,1,1,1,1,1,1,1,1,1,1,1,1,1
1,1,1,1,1,1,1,1,1,1,1,1,1,1,1,1,1,1,1,1,1,1,1,1
1,1,1,1,1,1,1,1,1,1,1,1,1,1,1,1,1,1,1,1,1,1,1,1
endlayer

layer
1,1,1,1,1,1,1,1,1,1,1,1,1,1,1,1,1,1,1,1,1,2,1,1
1,1,1,1,1,1,1,1,1,1,1,1,1,1,1,1,1,1,1,2,2,2,2,1
1,1,1,1,1,1,1,1,1,1,1,1,1,1,1,1,1,2,2,2,2,2,2,2
1,1,1,1,1,1,1,1,1,1,1,1,1,1,1,1,2,2,2,2,2,2,2,1
1,1,1,1,1,1,1,1,1,1,1,1,1,1,2,2,2,2,2,2,2,2,2,1
1,1,1,1,1,1,1,1,1,1,1,1,1,2,2,2,2,2,2,2,2,2,1,1
1,1,1,1,1,1,1,1,1,1,1,1,2,2,2,2,2,2,2,2,2,2,1,1
1,1,1,1,1,1,1,1,1,1,2,2,2,2,2,2,2,2,2,2,2,1,1,1
1,1,1,1,1,1,1,1,1,2,4,0,0,0,5,3,2,2,2,2,1,1,1,1
1,1,1,1,1,1,1,1,2,2,5,5,5,5,5,5,2,2,2,2,1,1,1,1
1,1,1,1,1,1,1,2,2,5,5,5,5,5,5,5,2,2,2,1,1,1,1,1
1,1,1,1,1,1,2,2,5,5,5,5,5,5,5,5,2,2,1,1,1,1,1,1
1,1,1,1,1,2,2,5,5,5,5,5,5,5,5,5,2,2,1,1,1,1,1,1
1,1,1,1,2,2,5,5,5,5,3,5,5,5,5,2,2,1,1,1,1,1,1,1
1,1,1,1,2,5,5,5,5,5,5,5,5,5,2,2,1,1,1,1,1,1,1,1
1,1,1,2,2,5,5,5,5,5,5,5,5,2,2,1,1,1,1,1,1,1,1,1
1,1,1,2,2,5,5,5,5,5,5,5,2,2,1,1,1,1,1,1,1,1,1,1
1,1,2,2,2,5,5,5,5,5,5,2,2,1,1,1,1,1,1,1,1,1,1,1
1,1,2,2,2,5,5,5,5,5,2,2,1,1,1,1,1,1,1,1,1,1,1,1
1,1,2,2,2,2,2,2,2,2,2,1,1,1,1,1,1,1,1,1,1,1,1,1
1,1,1,2,2,2,2,2,2,1,1,1,1,1,1,1,1,1,1,1,1,1,1,1
1,1,1,1,2,2,2,1,1,1,1,1,1,1,1,1,1,1,1,1,1,1,1,1
1,1,1,1,1,1,1,1,1,1,1,1,1,1,1,1,1,1,1,1,1,1,1,1
1,1,1,1,1,1,1,1,1,1,1,1,1,1,1,1,1,1,1,1,1,1,1,1
endlayer

layer
1,1,1,1,1,1,1,1,1,1,1,1,1,1,1,1,1,1,1,10,9,9,2,8
1,1,1,1,1,1,1,1,1,1,1,1,1,1,1,1,1,10,9,9,9,9,9,2
1,1,1,1,1,1,1,1,1,1,1,1,1,1,1,1,10,9,9,9,9,9,9,9
1,1,1,1,1,1,1,1,1,1,1,1,1,1,1,10,9,9,9,9,9,9,9,9
1,1,1,1,1,1,1,1,1,1,1,1,1,1,9,9,9,9,9,9,9,9,9,11
1,1,1,1,1,1,1,1,1,1,1,1,10,9,9,9,9,9,9,9,9,9,9,1
1,1,1,1,1,1,1,1,1,1,10,9,9,9,9,9,13,13,12,9,9,9,11,1
1,1,1,1,1,1,1,1,1,10,9,9,9,9,9,9,0,0,12,9,9,11,1,1
1,1,1,1,1,1,1,1,14,9,0,0,0,0,9,3,0,0,12,9,11,1,1,1
1,1,1,1,1,1,1,14,9,0,0,0,0,0,0,0,0,0,9,9,1,1,1,1
1,1,1,1,1,1,14,9,0,0,0,0,0,0,0,0,0,0,9,1,1,1,1,1
1,1,1,1,1,14,9,0,0,0,0,0,0,0,0,0,0,0,11,1,1,1,1,1
1,1,1,1,14,9,0,0,0,0,0,0,0,0,0,0,0,9,1,1,1,1,1,1
1,1,1,14,9,0,0,0,0,0,3,0,0,0,0,0,9,11,1,1,1,1,1,1
1,1,14,9,15,0,0,0,0,0,0,0,0,0,0,9,11,1,1,1,1,1,1,1
1,1,14,9,0,0,0,0,0,0,0,0,11,5,9,11,1,1,1,1,1,1,1,1
1,14,9,0,0,0,0,0,0,0,17,9,9,9,16,1,1,1,1,1,1,1,1,1
1,9,9,0,0,0,0,0,0,0,12,9,9,16,1,1,1,1,1,1,1,1,1,1
1,9,9,0,0,0,0,0,0,0,12,9,16,1,1,1,1,1,1,1,1,1,1,1
1,14,9,0,0,0,0,0,0,0,9,16,1,1,1,1,1,1,1,1,1,1,1,1
1,1,9,0,0,0,0,0,0,9,1,1,1,1,1,1,1,1,1,1,1,1,1,1
1,1,1,9,9,9,9,9,16,1,1,1,1,1,1,1,1,1,1,1,1,1,1,1
1,1,1,1,16,9,9,16,1,1,1,1,1,1,1,1,1,1,1,1,1,1,1,1
1,1,1,1,1,1,1,1,1,1,1,1,1,1,1,1,1,1,1,1,1,1,1,1
endlayer

layer
1,1,1,1,1,1,1,1,1,1,1,1,1,1,1,1,1,1,10,9,12,13,9,2
1,1,1,1,1,1,1,1,1,1,1,1,1,1,1,1,18,9,9,9,0,0,9,9
1,1,1,1,1,1,1,1,1,1,1,1,1,1,1,18,9,9,19,0,0,0,0,12
1,1,1,1,1,1,1,1,1,1,1,1,1,1,18,9,9,0,0,0,0,0,0,13
1,1,1,1,1,1,1,1,1,1,1,1,18,9,9,9,0,0,0,0,0,0,9,9
1,1,1,1,1,1,1,1,1,1,18,9,9,9,9,4,0,0,0,0,0,0,9,11
1,1,1,1,1,1,1,1,1,1,9,9,9,9,9,4,0,0,0,0,0,9,9,1
1,1,1,1,1,1,1,1,21,9,9,9,9,9,9,9,0,0,0,0,9,9,20,1
1,1,1,1,1,1,1,21,9,0,0,0,0,0,9,3,0,0,0,9,9,20,1,1
1,1,1,1,1,1,21,9,0,0,0,0,0,0,0,0,0,0,9,9,20,1,1,1
1,1,1,1,1,21,9,0,0,0,0,0,0,0,0,0,0,0,9,9,1,1,1,1
1,1,1,1,21,9,0,0,0,0,0,0,0,0,0,0,0,0,9,20,1,1,1,1
1,1,1,1,9,9,0,0,0,0,0,0,0,0,0,0,0,9,9,1,1,1,1,1
1,1,1,9,9,0,0,0,0,0,3,0,0,0,0,0,9,9,20,1,1,1,1,1
1,1,9,9,0,0,0,0,0,0,0,0,0,0,0,0,9,1,1,1,1,1,1,1
1,14,9,9,0,0,0,0,0,0,0,0,6,6,7,9,22,1,1,1,1,1,1,1
1,9,7,0,0,0,0,0,0,0,0,9,9,9,9,20,1,1,1,1,1,1,1,1
1,9,6,0,0,0,0,0,0,0,0,12,9,9,22,1,1,1,1,1,1,1,1,1
1,9,6,0,0,0,0,0,0,0,0,9,9,22,1,1,1,1,1,1,1,1,1,1
1,9,0,0,0,0,0,0,0,0,9,9,22,1,1,1,1,1,1,1,1,1,1,1
1,9,0,0,0,0,0,0,0,9,16,1,1,1,1,1,1,1,1,1,1,1,1,1
1,1,9,0,0,6,6,7,9,9,1,1,1,1,1,1,1,1,1,1,1,1,1,1
1,1,1,9,9,9,9,9,16,1,1,1,1,1,1,1,1,1,1,1,1,1,1,1
1,1,1,1,1,1,1,1,1,1,1,1,1,1,1,1,1,1,1,1,1,1,1,1
endlayer

layer
1,1,1,1,1,1,1,1,1,1,1,1,1,1,1,1,1,1,17,9,9,9,23,1
1,1,1,1,1,1,1,1,1,1,1,1,1,1,1,1,1,17,9,9,0,0,9,24
1,1,1,1,1,1,1,1,1,1,1,1,1,1,1,1,17,9,0,0,0,0,0,9
1,1,1,1,1,1,1,1,1,1,1,1,1,1,1,9,9,0,0,0,0,0,0,9
1,1,1,1,1,1,1,1,1,1,1,1,1,17,9,9,0,0,0,0,0,0,9,9
1,1,1,1,1,1,1,1,1,1,1,17,9,9,9,0,0,0,0,0,0,0,9,4
1,1,1,1,1,1,1,1,1,1,17,9,9,9,0,0,0,0,0,0,0,9,4,1
1,1,1,1,1,1,1,1,1,17,9,9,9,9,17,4,0,0,0,0,9,4,1,1
1,1,1,1,1,1,1,1,12,9,0,0,0,0,9,3,0,0,0,9,9,1,1,1
1,1,1,1,1,1,1,12,9,0,0,0,0,0,0,0,0,0,9,9,1,1,1,1
1,1,1,1,1,1,23,9,0,0,0,0,0,0,0,0,0,0,9,4,1,1,1,1
1,1,1,1,1,9,0,0,0,0,0,0,0,0,0,0,0,0,9,1,1,1,1,1
1,1,1,1,9,9,0,0,0,0,0,0,0,0,0,0,0,9,4,1,1,1,1,1
1,1,1,9,9,0,0,0,0,0,3,0,0,0,0,0,9,4,1,1,1,1,1,1
1,1,9,9,0,0,0,0,0,0,0,0,0,0,0,9,4,1,1,1,1,1,1,1
1,9,9,9,0,0,0,0,0,0,0,14,10,10,10,13,1,1,1,1,1,1,1,1
1,9,0,0,0,0,0,0,0,0,0,13,9,9,13,1,1,1,1,1,1,1,1,1
13,0,0,0,0,0,0,0,0,0,0,0,9,24,1,1,1,1,1,1,1,1,1,1
9,0,0,0,0,0,0,0,0,0,0,9,9,1,1,1,1,1,1,1,1,1,1,1
13,0,0,0,0,0,0,0,0,0,9,9,1,1,1,1,1,1,1,1,1,1,1,1
9,0,0,0,0,0,0,0,0,9,9,1,1,1,1,1,1,1,1,1,1,1,1,1
5,9,0,0,0,0,0,0,9,9,1,1,1,1,1,1,1,1,1,1,1,1,1,1
1,1,9,0,0,0,0,9,9,1,1,1,1,1,1,1,1,1,1,1,1,1,1,1
1,1,5,9,12,9,12,16,1,1,1,1,1,1,1,1,1,1,1,1,1,1,1,1
endlayer

layer
1,1,1,1,1,1,1,1,1,1,1,1,1,1,1,1,1,1,1,9,9,23,1,1
1,1,1,1,1,1,1,1,1,1,1,1,1,1,1,1,1,1,9,9,5,5,9,1
1,1,1,1,1,1,1,1,1,1,1,1,1,1,1,1,1,9,0,0,0,0,5,24
1,1,1,1,1,1,1,1,1,1,1,1,1,1,1,17,9,0,0,0,0,0,5,9
1,1,1,1,1,1,1,1,1,1,1,1,1,1,17,9,0,0,0,0,0,0,9,9
1,1,1,1,1,1,1,1,1,1,1,1,1,17,9,0,0,0,0,0,0,0,9,1
1,1,1,1,1,1,1,1,1,1,1,9,9,9,25,0,0,0,0,0,0,9,1,1
1,1,1,1,1,1,1,1,1,1,12,9,9,9,25,0,0,0,0,0,9,1,1,1
1,1,1,1,1,1,1,1,1,23,9,5,5,5,26,3,0,0,0,9,4,1,1,1
1,1,1,1,1,1,1,1,28,5,5,5,27,27,5,5,5,5,9,4,1,1,1,1
1,1,1,1,1,1,1,23,5,5,5,25,20,21,29,5,5,5,4,1,1,1,1,1
1,1,1,1,1,23,9,5,5,5,5,25,20,21,29,5,5,9,1,1,1,1,1,1
1,1,1,1,28,9,5,5,5,5,5,5,30,30,5,5,9,1,1,1,1,1,1,1
1,1,1,9,9,5,5,5,5,5,3,5,5,5,5,5,13,1,1,1,1,1,1,1
1,1,9,9,5,5,5,5,5,5,5,5,5,5,5,24,1,1,1,1,1,1,1,1
1,9,9,9,5,5,5,5,5,5,5,13,9,9,24,1,1,1,1,1,1,1,1,1
9,9,5,5,5,5,5,5,5,5,27,29,9,24,1,1,1,1,1,1,1,1,1,1
9,5,5,5,5,5,5,5,5,5,30,29,9,1,1,1,1,1,1,1,1,1,1,1
9,5,5,5,5,5,5,5,5,5,5,9,31,1,1,1,1,1,1,1,1,1,1,1
9,5,5,5,5,5,5,5,5,5,9,24,1,1,1,1,1,1,1,1,1,1,1,1
9,5,5,5,5,5,5,5,5,9,9,1,1,1,1,1,1,1,1,1,1,1,1,1
9,9,5,5,5,5,5,5,9,9,1,1,1,1,1,1,1,1,1,1,1,1,1,1
1,9,9,5,5,5,5,9,9,1,1,1,1,1,1,1,1,1,1,1,1,1,1,1
1,1,9,9,9,9,9,9,1,1,1,1,1,1,1,1,1,1,1,1,1,1,1,1
endlayer

layer
1,1,1,1,1,1,1,1,1,1,1,1,1,1,1,1,1,1,1,23,2,1,1,1
1,1,1,1,1,1,1,1,1,1,1,1,1,1,1,1,1,1,28,9,9,9,26,1
1,1,1,1,1,1,1,1,1,1,1,1,1,1,1,1,1,23,9,5,5,5,9,1
1,1,1,1,1,1,1,1,1,1,1,1,1,1,1,1,23,9,0,0,0,5,9,2
1,1,1,1,1,1,1,1,1,1,1,1,1,1,1,9,9,5,0,0,0,5,9,24
1,1,1,1,1,1,1,1,1,1,1,1,1,1,9,9,5,5,5,0,0,9,24,1
1,1,1,1,1,1,1,1,1,1,1,1,23,28,0,26,5,27,5,5,9,24,1,1
1,1,1,1,1,1,1,1,1,1,1,2,0,0,0,26,5,5,5,9,24,1,1,1
1,1,1,1,1,1,1,1,1,1,2,0,0,0,0,3,26,26,9,9,1,1,1,1
1,1,1,1,1,1,1,1,1,9,0,0,0,0,0,32,0,26,9,1,1,1,1,1
1,1,1,1,1,1,1,1,9,0,0,0,0,0,0,0,0,31,1,1,1,1,1,1
1,1,1,1,1,1,9,9,0,0,0,0,0,0,0,0,0,24,1,1,1,1,1,1
1,1,1,1,33,9,9,0,0,0,0,0,0,0,0,0,2,1,1,1,1,1,1,1
1,1,1,28,9,0,34,0,0,0,3,0,0,0,0,2,1,1,1,1,1,1,1,1
1,1,23,9,0,0,0,9,0,0,32,0,0,0,9,1,1,1,1,1,1,1,1,1
1,9,9,0,0,0,0,0,9,0,0,0,0,9,1,1,1,1,1,1,1,1,1,1
9,9,0,0,0,0,0,0,35,9,0,0,9,1,1,1,1,1,1,1,1,1,1,1
9,16,0,0,0,0,0,0,0,9,0,0,9,1,1,1,1,1,1,1,1,1,1,1
9,5,0,0,0,0,0,16,16,9,9,9,1,1,1,1,1,1,1,1,1,1,1,1
9,10,0,0,0,0,0,5,5,9,9,1,1,1,1,1,1,1,1,1,1,1,1,1
9,9,0,0,0,0,0,10,10,9,24,1,1,1,1,1,1,1,1,1,1,1,1,1
28,9,0,0,0,0,0,36,9,31,1,1,1,1,1,1,1,1,1,1,1,1,1,1
1,37,9,9,11,5,14,9,9,1,1,1,1,1,1,1,1,1,1,1,1,1,1,1
1,1,31,9,9,9,9,9,1,1,1,1,1,1,1,1,1,1,1,1,1,1,1,1
endlayer

layer
1,1,1,1,1,1,1,1,1,1,1,1,1,1,1,1,1,1,1,1,23,1,1,1
1,1,1,1,1,1,1,1,1,1,1,1,1,1,1,1,1,1,1,12,9,9,1,1
1,1,1,1,1,1,1,1,1,1,1,1,1,1,1,1,1,1,9,9,9,9,9,1
1,1,1,1,1,1,1,1,1,1,1,1,1,1,1,1,1,9,5,5,9,9,9,24
1,1,1,1,1,1,1,1,1,1,1,1,1,1,1,23,9,9,5,5,5,9,13,1
1,1,1,1,1,1,1,1,1,1,1,1,1,1,37,31,0,26,26,5,5,9,1,1
1,1,1,1,1,1,1,1,1,1,1,1,0,0,0,0,0,0,26,9,9,1,1,1
1,1,1,1,1,1,1,1,1,1,1,0,0,0,0,0,0,0,0,9,1,1,1,1
1,1,1,1,1,1,1,1,1,1,0,0,0,0,0,3,0,0,28,24,1,1,1,1
1,1,1,1,1,1,1,1,1,23,0,0,0,0,0,32,0,0,37,1,1,1,1,1
1,1,1,1,1,1,1,1,23,0,0,0,0,0,0,0,0,0,1,1,1,1,1,1
1,1,1,1,1,1,23,28,0,0,0,0,0,0,0,0,0,0,1,1,1,1,1,1
1,1,1,1,1,9,9,0,0,0,0,0,0,0,0,0,0,1,1,1,1,1,1,1
1,1,1,39,9,0,38,0,0,0,3,0,0,0,0,0,1,1,1,1,1,1,1,1
1,1,33,9,0,0,0,9,0,0,32,0,0,0,24,1,1,1,1,1,1,1,1,1
1,28,22,0,0,0,0,0,9,0,0,0,0,24,1,1,1,1,1,1,1,1,1,1
23,9,0,0,0,0,0,0,0,9,0,0,31,1,1,1,1,1,1,1,1,1,1,1
13,7,0,0,0,0,0,0,0,9,10,10,24,1,1,1,1,1,1,1,1,1,1,1
9,6,0,0,0,0,0,6,6,40,9,9,1,1,1,1,1,1,1,1,1,1,1,1
17,6,0,0,0,0,0,6,6,40,9,1,1,1,1,1,1,1,1,1,1,1,1,1
9,0,0,0,0,0,0,7,7,9,39,1,1,1,1,1,1,1,1,1,1,1,1,1
39,9,0,0,0,0,0,0,21,33,1,1,1,1,1,1,1,1,1,1,1,1,1,1
1,33,9,0,6,6,7,9,31,1,1,1,1,1,1,1,1,1,1,1,1,1,1,1
1,1,39,9,4,9,12,24,1,1,1,1,1,1,1,1,1,1,1,1,1,1,1,1
endlayer

layer
1,1,1,1,1,1,1,1,1,1,1,1,1,1,1,1,1,1,1,1,1,1,1,1
1,1,1,1,1,1,1,1,1,1,1,1,1,1,1,1,1,1,1,1,23,23,1,1
1,1,1,1,1,1,1,1,1,1,1,1,1,1,1,1,1,1,23,31,0,0,24,1
1,1,1,1,1,1,1,1,1,1,1,1,1,1,1,1,1,28,0,0,39,0,24,1
1,1,1,1,1,1,1,1,1,1,1,1,1,1,1,1,31,31,0,0,0,28,1,1
1,1,1,1,1,1,1,1,1,1,1,1,1,1,0,0,0,0,0,0,0,24,1,1
1,1,1,1,1,1,1,1,1,1,1,1,0,0,0,0,0,0,0,28,31,1,1,1
1,1,1,1,1,1,1,1,1,1,1,0,0,0,0,0,0,0,0,28,1,1,1,1
1,1,1,1,1,1,1,1,1,1,0,0,0,0,0,3,0,0,0,1,1,1,1,1
1,1,1,1,1,1,1,1,1,0,0,0,0,0,0,32,0,0,0,1,1,1,1,1
1,1,1,1,1,1,1,1,0,0,0,0,0,0,0,0,0,0,1,1,1,1,1,1
1,1,1,1,1,1,1,0,0,0,0,0,0,0,0,0,0,0,1,1,1,1,1,1
1,1,1,1,1,23,37,0,0,0,0,0,0,0,0,0,0,1,1,1,1,1,1,1
1,1,1,1,23,9,9,0,0,0,3,0,0,0,0,0,1,1,1,1,1,1,1,1
1,1,1,9,0,0,0,9,0,0,32,0,0,0,0,1,1,1,1,1,1,1,1,1
1,33,9,0,0,0,0,0,9,0,0,0,0,0,1,1,1,1,1,1,1,1,1,1
1,9,0,0,0,0,0,0,0,9,0,0,0,1,1,1,1,1,1,1,1,1,1,1
9,0,0,0,0,0,0,0,0,9,9,37,1,1,1,1,1,1,1,1,1,1,1,1
9,0,0,0,0,0,0,0,0,0,9,24,1,1,1,1,1,1,1,1,1,1,1,1
9,0,0,0,0,0,0,0,0,0,24,1,1,1,1,1,1,1,1,1,1,1,1,1
28,5,0,0,0,0,0,0,0,9,1,1,1,1,1,1,1,1,1,1,1,1,1,1
1,28,0,0,0,0,0,0,9,1,1,1,1,1,1,1,1,1,1,1,1,1,1,1
1,1,31,5,0,0,0,9,1,1,1,1,1,1,1,1,1,1,1,1,1,1,1,1
1,1,1,31,9,9,9,1,1,1,1,1,1,1,1,1,1,1,1,1,1,1,1,1
endlayer

layer
1,1,1,1,1,1,1,1,1,1,1,1,1,1,1,1,1,1,1,1,1,1,1,1
1,1,1,1,1,1,1,1,1,1,1,1,1,1,1,1,1,1,1,1,0,41,1,1
1,1,1,1,1,1,1,1,1,1,1,1,1,1,1,1,1,1,0,0,0,0,0,1
1,1,1,1,1,1,1,1,1,1,1,1,1,1,1,1,1,0,0,0,39,0,0,1
1,1,1,1,1,1,1,1,1,1,1,1,1,1,1,1,0,0,0,0,0,0,1,1
1,1,1,1,1,1,1,1,1,1,1,1,1,1,0,0,0,0,0,0,0,0,1,1
1,1,1,1,1,1,1,1,1,1,1,1,0,0,0,0,0,0,0,0,0,1,1,1
1,1,1,1,1,1,1,1,1,1,1,0,0,0,0,0,0,0,0,0,1,1,1,1
1,1,1,1,1,1,1,1,1,1,0,0,0,0,0,3,0,0,0,1,1,1,1,1
1,1,1,1,1,1,1,1,1,0,0,0,0,0,0,32,0,0,0,1,1,1,1,1
1,1,1,1,1,1,1,1,0,0,0,0,0,0,0,0,0,0,1,1,1,1,1,1
1,1,1,1,1,1,1,0,0,0,0,0,0,0,0,0,0,0,1,1,1,1,1,1
1,1,1,1,1,1,0,0,0,0,0,0,0,0,0,0,0,1,1,1,1,1,1,1
1,1,1,1,1,37,23,0,0,0,3,0,0,0,0,0,1,1,1,1,1,1,1,1
1,1,1,23,9,9,9,2,0,0,32,0,0,0,0,1,1,1,1,1,1,1,1,1
1,1,28,9,9,9,9,9,2,0,0,0,0,0,1,1,1,1,1,1,1,1,1,1
1,39,9,9,9,9,9,9,9,2,0,0,0,1,1,1,1,1,1,1,1,1,1,1
39,9,9,9,9,9,9,9,9,9,24,0,1,1,1,1,1,1,1,1,1,1,1,1
28,9,9,9,9,9,9,9,9,9,37,1,1,1,1,1,1,1,1,1,1,1,1,1
28,9,9,9,9,9,9,9,9,9,1,1,1,1,1,1,1,1,1,1,1,1,1,1
39,9,9,9,9,9,9,9,9,24,1,1,1,1,1,1,1,1,1,1,1,1,1,1
1,33,9,9,9,9,9,9,31,1,1,1,1,1,1,1,1,1,1,1,1,1,1,1
1,1,33,9,9,9,9,39,1,1,1,1,1,1,1,1,1,1,1,1,1,1,1,1
1,1,1,39,31,31,39,1,1,1,1,1,1,1,1,1,1,1,1,1,1,1,1,1
endlayer

layer
1,1,1,1,1,1,1,1,1,1,1,1,1,1,1,1,1,1,1,1,1,1,1,1
1,1,1,1,1,1,1,1,1,1,1,1,1,1,1,1,1,1,1,1,0,41,1,1
1,1,1,1,1,1,1,1,1,1,1,1,1,1,1,1,1,1,0,0,41,33,0,1
1,1,1,1,1,1,1,1,1,1,1,1,1,1,1,1,1,0,0,0,39,0,0,1
1,1,1,1,1,1,1,1,1,1,1,1,1,1,1,1,0,0,0,0,0,0,1,1
1,1,1,1,1,1,1,1,1,1,1,1,1,1,0,0,0,0,0,0,0,0,1,1
1,1,1,1,1,1,1,1,1,1,1,1,0,0,0,0,0,0,0,0,0,1,1,1
1,1,1,1,1,1,1,1,1,1,1,0,0,0,0,0,0,0,0,0,1,1,1,1
1,1,1,1,1,1,1,1,1,1,0,0,0,0,0,3,0,0,0,1,1,1,1,1
1,1,1,1,1,1,1,1,1,0,0,0,0,0,0,32,0,0,0,1,1,1,1,1
1,1,1,1,1,1,1,1,0,0,0,0,0,0,0,0,0,0,1,1,1,1,1,1
1,1,1,1,1,1,1,0,0,0,0,0,0,0,0,0,0,0,1,1,1,1,1,1
1,1,1,1,1,1,0,0,0,0,0,0,0,0,0,0,0,1,1,1,1,1,1,1
1,1,1,1,1,0,0,0,0,0,3,0,0,0,0,0,1,1,1,1,1,1,1,1
1,1,1,1,23,23,0,0,0,0,32,0,0,0,0,1,1,1,1,1,1,1,1,1
1,1,1,2,31,0,0,0,0,0,0,0,0,0,1,1,1,1,1,1,1,1,1,1
1,1,2,0,0,0,0,39,0,0,0,0,0,1,1,1,1,1,1,1,1,1,1,1
1,28,24,0,0,0,0,0,0,0,0,0,1,1,1,1,1,1,1,1,1,1,1,1
1,2,0,0,0,0,0,0,0,2,0,1,1,1,1,1,1,1,1,1,1,1,1,1
1,28,24,0,39,0,0,0,28,2,1,1,1,1,1,1,1,1,1,1,1,1,1,1
1,1,2,0,0,0,0,0,2,1,1,1,1,1,1,1,1,1,1,1,1,1,1,1
1,1,2,2,23,0,23,2,1,1,1,1,1,1,1,1,1,1,1,1,1,1,1,1
1,1,1,1,31,2,31,1,1,1,1,1,1,1,1,1,1,1,1,1,1,1,1,1
1,1,1,1,1,1,1,1,1,1,1,1,1,1,1,1,1,1,1,1,1,1,1,1
endlayer

layer
1,1,1,1,1,1,1,1,1,1,1,1,1,1,1,1,1,1,1,1,1,1,1,1
1,1,1,1,1,1,1,1,1,1,1,1,1,1,1,1,1,1,1,1,0,41,1,1
1,1,1,1,1,1,1,1,1,1,1,1,1,1,1,1,1,1,0,41,41,33,0,1
1,1,1,1,1,1,1,1,1,1,1,1,1,1,1,1,1,0,0,0,39,0,0,1
1,1,1,1,1,1,1,1,1,1,1,1,1,1,1,1,0,0,0,0,0,0,1,1
1,1,1,1,1,1,1,1,1,1,1,1,1,1,0,0,0,0,0,0,0,0,1,1
1,1,1,1,1,1,1,1,1,1,1,1,0,0,0,0,0,0,0,0,0,1,1,1
1,1,1,1,1,1,1,1,1,1,1,0,0,0,0,0,0,0,0,0,1,1,1,1
1,1,1,1,1,1,1,1,1,1,0,0,0,0,0,3,0,0,0,1,1,1,1,1
1,1,1,1,1,1,1,1,1,0,0,0,0,0,0,32,0,0,0,1,1,1,1,1
1,1,1,1,1,1,1,1,0,0,0,0,0,0,0,0,0,0,1,1,1,1,1,1
1,1,1,1,1,1,1,0,0,0,0,0,0,0,0,0,0,0,1,1,1,1,1,1
1,1,1,1,1,1,0,0,0,0,0,0,0,0,0,0,0,1,1,1,1,1,1,1
1,1,1,1,1,0,0,0,0,0,3,0,0,0,0,0,1,1,1,1,1,1,1,1
1,1,1,1,33,33,0,0,0,0,32,0,0,0,0,1,1,1,1,1,1,1,1,1
1,1,1,33,33,0,0,0,0,0,0,0,0,0,1,1,1,1,1,1,1,1,1,1
1,1,33,0,0,0,0,45,0,0,0,0,0,1,1,1,1,1,1,1,1,1,1,1
1,33,33,0,0,0,0,0,0,0,0,0,1,1,1,1,1,1,1,1,1,1,1,1
1,33,33,0,0,0,0,0,0,33,0,1,1,1,1,1,1,1,1,1,1,1,1,1
1,0,33,0,39,0,0,0,33,33,1,1,1,1,1,1,1,1,1,1,1,1,1,1
1,0,33,0,0,0,0,0,33,1,1,1,1,1,1,1,1,1,1,1,1,1,1,1
1,1,0,33,33,33,33,33,1,1,1,1,1,1,1,1,1,1,1,1,1,1,1,1
1,1,1,0,33,33,0,1,1,1,1,1,1,1,1,1,1,1,1,1,1,1,1,1
1,1,1,1,1,1,1,1,1,1,1,1,1,1,1,1,1,1,1,1,1,1,1,1
endlayer

layer
1,1,1,1,1,1,1,1,1,1,1,1,1,1,1,1,1,1,1,1,1,1,1,1
1,1,1,1,1,1,1,1,1,1,1,1,1,1,1,1,1,1,1,1,41,41,1,1
1,1,1,1,1,1,1,1,1,1,1,1,1,1,1,1,1,1,0,41,33,33,0,1
1,1,1,1,1,1,1,1,1,1,1,1,1,1,1,1,1,0,0,0,39,0,0,1
1,1,1,1,1,1,1,1,1,1,1,1,1,1,1,1,0,0,0,0,0,0,1,1
1,1,1,1,1,1,1,1,1,1,1,1,1,1,0,0,0,0,0,0,0,0,1,1
1,1,1,1,1,1,1,1,1,1,1,1,0,0,0,0,0,0,0,0,0,1,1,1
1,1,1,1,1,1,1,1,1,1,1,0,0,0,0,0,0,0,0,0,1,1,1,1
1,1,1,1,1,1,1,1,1,1,0,0,0,0,0,3,0,0,0,1,1,1,1,1
1,1,1,1,1,1,1,1,1,0,0,0,0,0,0,32,0,0,0,1,1,1,1,1
1,1,1,1,1,1,1,1,0,0,0,0,0,0,0,0,0,0,1,1,1,1,1,1
1,1,1,1,1,1,1,0,0,0,0,0,0,0,0,0,0,0,1,1,1,1,1,1
1,1,1,1,1,1,0,0,0,0,0,0,0,0,0,0,0,1,1,1,1,1,1,1
1,1,1,1,1,0,0,0,0,0,3,0,0,0,0,0,1,1,1,1,1,1,1,1
1,1,1,1,0,0,0,0,0,0,32,0,0,0,0,1,1,1,1,1,1,1,1,1
1,1,1,0,0,0,0,0,0,0,0,0,0,0,1,1,1,1,1,1,1,1,1,1
1,1,0,0,0,0,0,0,0,0,0,0,0,1,1,1,1,1,1,1,1,1,1,1
1,0,0,0,0,0,0,0,0,0,0,0,1,1,1,1,1,1,1,1,1,1,1,1
1,0,0,0,0,0,0,0,0,0,0,1,1,1,1,1,1,1,1,1,1,1,1,1
1,0,0,0,39,0,0,0,0,0,1,1,1,1,1,1,1,1,1,1,1,1,1,1
1,0,0,0,0,0,0,0,0,1,1,1,1,1,1,1,1,1,1,1,1,1,1,1
1,1,0,0,0,0,0,0,1,1,1,1,1,1,1,1,1,1,1,1,1,1,1,1
1,1,1,0,0,0,0,1,1,1,1,1,1,1,1,1,1,1,1,1,1,1,1,1
1,1,1,1,1,1,1,1,1,1,1,1,1,1,1,1,1,1,1,1,1,1,1,1
endlayer

layer
1,1,1,1,1,1,1,1,1,1,1,1,1,1,1,1,1,1,1,1,1,1,1,1
1,1,1,1,1,1,1,1,1,1,1,1,1,1,1,1,1,1,1,1,41,0,1,1
1,1,1,1,1,1,1,1,1,1,1,1,1,1,1,1,1,1,1,41,33,0,0,1
1,1,1,1,1,1,1,1,1,1,1,1,1,1,1,1,1,1,0,0,33,0,1,1
1,1,1,1,1,1,1,1,1,1,1,1,1,1,1,1,0,0,0,0,0,0,1,1
1,1,1,1,1,1,1,1,1,1,1,1,1,1,1,0,0,0,0,0,0,1,1,1
1,1,1,1,1,1,1,1,1,1,1,1,1,0,0,0,0,0,0,0,1,1,1,1
1,1,1,1,1,1,1,1,1,1,1,1,0,0,0,0,0,0,0,0,1,1,1,1
1,1,1,1,1,1,1,1,1,1,1,0,0,0,0,3,0,0,0,1,1,1,1,1
1,1,1,1,1,1,1,1,1,1,0,0,0,0,0,32,0,0,1,1,1,1,1,1
1,1,1,1,1,1,1,1,1,0,0,0,0,0,0,0,0,0,1,1,1,1,1,1
1,1,1,1,1,1,1,1,0,0,0,0,0,0,0,0,0,1,1,1,1,1,1,1
1,1,1,1,1,1,1,0,0,0,0,0,0,0,0,0,1,1,1,1,1,1,1,1
1,1,1,1,1,0,0,0,0,0,3,0,0,0,0,1,1,1,1,1,1,1,1,1
1,1,1,1,0,0,0,0,0,0,32,0,0,0,1,1,1,1,1,1,1,1,1,1
1,1,1,0,0,0,0,0,0,0,0,0,0,1,1,1,1,1,1,1,1,1,1,1
1,1,0,0,0,0,0,0,0,0,0,0,1,1,1,1,1,1,1,1,1,1,1,1
1,1,0,0,0,0,0,0,0,0,0,1,1,1,1,1,1,1,1,1,1,1,1,1
1,0,0,0,0,0,0,0,0,0,0,1,1,1,1,1,1,1,1,1,1,1,1,1
1,0,0,0,39,0,0,0,0,0,1,1,1,1,1,1,1,1,1,1,1,1,1,1
1,1,0,0,0,0,0,0,0,1,1,1,1,1,1,1,1,1,1,1,1,1,1,1
1,1,0,0,0,0,0,0,1,1,1,1,1,1,1,1,1,1,1,1,1,1,1,1
1,1,1,1,0,0,1,1,1,1,1,1,1,1,1,1,1,1,1,1,1,1,1,1
1,1,1,1,1,1,1,1,1,1,1,1,1,1,1,1,1,1,1,1,1,1,1,1
endlayer

layer
1,1,1,1,1,1,1,1,1,1,1,1,1,1,1,1,1,1,1,1,1,1,1,1
1,1,1,1,1,1,1,1,1,1,1,1,1,1,1,1,1,1,1,41,41,0,1,1
1,1,1,1,1,1,1,1,1,1,1,1,1,1,1,1,1,1,41,33,33,0,0,1
1,1,1,1,1,1,1,1,1,1,1,1,1,1,1,1,1,1,0,0,33,0,1,1
1,1,1,1,1,1,1,1,1,1,1,1,1,1,1,1,0,0,0,0,0,0,1,1
1,1,1,1,1,1,1,1,1,1,1,1,1,1,1,0,0,0,0,0,0,1,1,1
1,1,1,1,1,1,1,1,1,1,1,1,1,0,0,0,0,0,0,0,1,1,1,1
1,1,1,1,1,1,1,1,1,1,1,1,0,0,0,0,0,0,0,0,1,1,1,1
1,1,1,1,1,1,1,1,1,1,1,0,0,0,0,3,0,0,0,1,1,1,1,1
1,1,1,1,1,1,1,1,1,1,0,0,0,0,0,32,0,0,1,1,1,1,1,1
1,1,1,1,1,1,1,1,1,0,0,0,0,0,0,0,0,0,1,1,1,1,1,1
1,1,1,1,1,1,1,1,0,0,0,0,0,0,0,0,0,1,1,1,1,1,1,1
1,1,1,1,1,1,1,0,0,0,0,0,0,0,0,0,1,1,1,1,1,1,1,1
1,1,1,1,1,0,0,0,0,0,3,0,0,0,0,1,1,1,1,1,1,1,1,1
1,1,1,1,0,0,0,0,0,0,32,0,0,0,1,1,1,1,1,1,1,1,1,1
1,1,1,0,0,0,0,0,0,0,0,0,0,1,1,1,1,1,1,1,1,1,1,1
1,1,0,0,0,0,0,0,0,0,0,0,1,1,1,1,1,1,1,1,1,1,1,1
1,1,0,0,0,0,0,0,0,0,0,1,1,1,1,1,1,1,1,1,1,1,1,1
1,0,0,0,0,0,0,0,0,0,0,1,1,1,1,1,1,1,1,1,1,1,1,1
1,0,0,0,39,0,0,0,0,0,1,1,1,1,1,1,1,1,1,1,1,1,1,1
1,1,0,0,0,0,0,0,0,1,1,1,1,1,1,1,1,1,1,1,1,1,1,1
1,1,0,0,0,0,0,0,1,1,1,1,1,1,1,1,1,1,1,1,1,1,1,1
1,1,1,1,0,0,1,1,1,1,1,1,1,1,1,1,1,1,1,1,1,1,1,1
1,1,1,1,1,1,1,1,1,1,1,1,1,1,1,1,1,1,1,1,1,1,1,1
endlayer

layer
1,1,1,1,1,1,1,1,1,1,1,1,1,1,1,1,1,1,1,1,1,1,1,1
1,1,1,1,1,1,1,1,1,1,1,1,1,1,1,1,1,1,41,41,0,0,1,1
1,1,1,1,1,1,1,1,1,1,1,1,1,1,1,1,1,1,41,33,0,0,0,1
1,1,1,1,1,1,1,1,1,1,1,1,1,1,1,1,1,1,0,0,33,0,1,1
1,1,1,1,1,1,1,1,1,1,1,1,1,1,1,1,0,0,0,0,0,0,1,1
1,1,1,1,1,1,1,1,1,1,1,1,1,1,1,0,0,0,0,0,0,1,1,1
1,1,1,1,1,1,1,1,1,1,1,1,1,0,0,0,0,0,0,0,1,1,1,1
1,1,1,1,1,1,1,1,1,1,1,1,0,0,0,0,0,0,0,0,1,1,1,1
1,1,1,1,1,1,1,1,1,1,1,0,0,0,0,3,0,0,0,1,1,1,1,1
1,1,1,1,1,1,1,1,1,1,0,0,0,0,0,32,0,0,1,1,1,1,1,1
1,1,1,1,1,1,1,1,1,0,0,0,0,0,0,0,0,0,1,1,1,1,1,1
1,1,1,1,1,1,1,1,0,0,0,0,0,0,0,0,0,1,1,1,1,1,1,1
1,1,1,1,1,1,1,0,0,0,0,0,0,0,0,0,1,1,1,1,1,1,1,1
1,1,1,1,1,0,0,0,0,0,3,0,0,0,0,1,1,1,1,1,1,1,1,1
1,1,1,1,0,0,0,0,0,0,32,0,0,0,1,1,1,1,1,1,1,1,1,1
1,1,1,0,0,0,0,0,0,0,0,0,0,1,1,1,1,1,1,1,1,1,1,1
1,1,0,0,0,0,0,0,0,0,0,0,1,1,1,1,1,1,1,1,1,1,1,1
1,1,0,0,0,0,0,0,0,0,0,1,1,1,1,1,1,1,1,1,1,1,1,1
1,0,0,0,0,0,0,0,0,0,0,1,1,1,1,1,1,1,1,1,1,1,1,1
1,0,0,0,39,0,0,0,0,0,1,1,1,1,1,1,1,1,1,1,1,1,1,1
1,1,0,0,0,0,0,0,0,1,1,1,1,1,1,1,1,1,1,1,1,1,1,1
1,1,0,0,0,0,0,0,1,1,1,1,1,1,1,1,1,1,1,1,1,1,1,1
1,1,1,1,0,0,1,1,1,1,1,1,1,1,1,1,1,1,1,1,1,1,1,1
1,1,1,1,1,1,1,1,1,1,1,1,1,1,1,1,1,1,1,1,1,1,1,1
endlayer

layer
1,1,1,1,1,1,1,1,1,1,1,1,1,1,1,1,1,1,1,1,1,1,1,1
1,1,1,1,1,1,1,1,1,1,1,1,1,1,1,1,1,1,1,41,0,1,1,1
1,1,1,1,1,1,1,1,1,1,1,41,41,1,1,1,1,1,41,33,0,0,1,1
1,1,1,1,1,1,1,1,1,1,1,1,41,41,1,1,1,1,0,0,33,0,1,1
1,1,1,1,1,1,1,1,1,1,1,1,1,41,41,1,1,0,0,0,0,0,1,1
1,1,1,1,1,1,1,1,1,1,1,1,1,1,41,41,0,0,0,0,0,1,1,1
1,1,1,1,1,1,1,1,1,1,1,1,1,0,0,41,41,0,0,0,1,1,1,1
1,1,1,1,1,1,41,41,1,1,1,1,0,0,0,0,41,41,0,1,1,1,1,1
1,1,1,1,1,1,1,41,41,1,1,0,0,0,0,3,0,41,41,1,1,1,1,1
1,1,1,1,1,1,1,1,41,41,0,0,0,0,0,32,0,0,41,41,1,1,1,1
1,1,1,1,1,1,1,1,1,41,41,0,0,0,0,0,0,0,1,41,41,1,1,1
1,1,1,1,1,1,1,1,0,0,41,41,0,0,0,0,0,1,1,1,41,41,1,1
1,1,1,1,1,1,1,0,0,0,0,41,41,0,0,0,1,1,1,1,1,41,1,1
1,1,1,1,1,1,0,0,0,0,3,0,41,41,0,1,1,1,1,1,1,1,1,1
1,1,1,1,1,0,0,0,0,0,32,0,0,41,41,1,1,1,1,1,1,1,1,1
1,41,1,1,0,0,0,0,0,0,0,0,0,1,41,41,1,1,1,1,1,1,1,1
1,41,41,0,0,0,0,0,0,0,0,0,1,1,1,41,41,1,1,1,1,1,1,1
1,1,41,41,0,0,0,0,0,0,0,1,1,1,1,1,41,1,1,1,1,1,1,1
1,1,0,41,41,0,0,0,0,0,1,1,1,1,1,1,1,1,1,1,1,1,1,1
1,1,0,0,39,41,0,0,0,1,1,1,1,1,1,1,1,1,1,1,1,1,1,1
1,1,0,0,0,41,41,0,1,1,1,1,1,1,1,1,1,1,1,1,1,1,1,1
1,1,1,0,0,0,41,41,1,1,1,1,1,1,1,1,1,1,1,1,1,1,1,1
1,1,1,1,1,1,1,41,41,1,1,1,1,1,1,1,1,1,1,1,1,1,1,1
1,1,1,1,1,1,1,1,1,1,1,1,1,1,1,1,1,1,1,1,1,1,1,1
endlayer

layer
1,1,1,1,1,1,1,1,1,1,1,1,1,1,1,1,1,1,1,1,1,1,1,1
1,1,1,1,1,1,1,1,1,1,1,1,1,1,1,1,1,1,1,1,1,1,1,1
1,1,1,1,1,1,1,1,1,1,1,41,1,1,1,1,1,1,41,33,1,1,1,1
1,1,1,1,1,1,1,1,1,1,1,41,41,1,1,1,1,1,0,0,1,1,1,1
1,1,1,1,1,1,1,1,1,1,1,1,41,41,1,1,1,0,0,0,0,1,1,1
1,1,1,1,1,1,1,1,1,1,1,1,1,41,41,0,0,0,0,0,1,1,1,1
1,1,1,1,1,1,1,1,1,1,1,1,1,1,41,41,0,0,0,0,1,1,1,1
1,1,1,1,1,1,41,1,1,1,1,1,1,0,0,41,41,0,0,1,1,1,1,1
1,1,1,1,1,1,41,41,1,1,1,1,0,0,0,3,41,41,0,1,1,1,1,1
1,1,1,1,1,1,1,41,41,1,1,0,0,0,0,32,0,41,41,1,1,1,1,1
1,1,1,1,1,1,1,1,41,41,0,0,0,0,0,0,0,1,41,41,1,1,1,1
1,1,1,1,1,1,1,1,1,41,41,0,0,0,0,0,1,1,1,41,41,1,1,1
1,1,1,1,1,1,1,1,0,0,41,41,0,0,0,1,1,1,1,1,41,41,1,1
1,1,1,1,1,1,1,0,0,0,3,41,41,0,1,1,1,1,1,1,1,1,1,1
1,1,1,1,1,1,0,0,0,0,32,0,41,41,1,1,1,1,1,1,1,1,1,1
1,1,1,1,1,0,0,0,0,0,0,0,1,41,41,1,1,1,1,1,1,1,1,1
1,41,41,41,0,0,0,0,0,0,0,1,1,1,41,41,1,1,1,1,1,1,1,1
1,1,0,41,41,0,0,0,0,0,1,1,1,1,1,41,41,1,1,1,1,1,1,1
1,1,0,0,41,41,0,0,0,1,1,1,1,1,1,1,1,1,1,1,1,1,1,1
1,1,0,0,33,41,41,0,1,1,1,1,1,1,1,1,1,1,1,1,1,1,1,1
1,1,1,0,0,0,41,41,1,1,1,1,1,1,1,1,1,1,1,1,1,1,1,1
1,1,1,1,0,0,0,41,1,1,1,1,1,1,1,1,1,1,1,1,1,1,1,1
1,1,1,1,1,1,1,41,1,1,1,1,1,1,1,1,1,1,1,1,1,1,1,1
1,1,1,1,1,1,1,1,1,1,1,1,1,1,1,1,1,1,1,1,1,1,1,1
endlayer

layer
1,1,1,1,1,1,1,1,1,1,1,1,1,1,1,1,1,1,1,1,1,1,1,1
1,1,1,1,1,1,1,1,1,1,1,1,1,1,1,1,1,1,1,1,1,1,1,1
1,1,1,1,1,1,1,1,1,1,1,39,1,1,1,1,1,1,1,1,1,1,1,1
1,1,1,1,1,1,1,1,1,1,43,42,39,1,1,1,1,1,1,1,1,1,1,1
1,1,1,1,1,1,1,1,1,1,1,42,42,39,1,1,1,1,1,1,1,1,1,1
1,1,1,1,1,1,1,1,1,1,1,1,42,42,39,1,1,0,0,1,1,1,1,1
1,1,1,1,1,1,1,1,1,1,1,1,1,42,42,39,0,0,0,1,1,1,1,1
1,1,1,1,1,1,39,1,1,1,1,1,1,33,42,42,39,0,1,1,1,1,1,1
1,1,1,1,1,43,42,39,1,1,1,1,0,33,26,3,42,39,1,1,1,1,1,1
1,1,1,1,1,1,42,42,39,1,1,0,0,33,26,32,42,42,39,1,1,1,1,1
1,1,1,1,1,1,1,42,42,39,0,0,0,0,33,33,33,42,42,39,1,1,1,1
1,1,1,1,1,1,1,1,42,42,39,0,0,0,0,0,1,1,42,42,39,1,1,1
1,1,1,1,1,1,1,1,33,42,42,39,0,0,0,1,1,1,1,42,42,39,1,1
1,1,1,1,1,1,1,1,33,26,3,42,39,0,1,1,1,1,1,1,44,1,1,1
1,1,1,1,1,1,1,0,33,26,32,42,42,39,1,1,1,1,1,1,1,1,1,1
1,1,1,1,1,1,0,0,0,33,33,33,42,42,39,1,1,1,1,1,1,1,1,1
1,33,33,1,1,0,0,0,0,0,1,1,1,42,42,39,1,1,1,1,1,1,1,1
1,1,33,33,0,0,0,0,0,1,1,1,1,1,42,42,39,1,1,1,1,1,1,1
1,1,1,33,33,0,0,0,1,1,1,1,1,1,1,44,1,1,1,1,1,1,1,1
1,1,1,0,33,33,0,1,1,1,1,1,1,1,1,1,1,1,1,1,1,1,1,1
1,1,1,1,0,33,33,1,1,1,1,1,1,1,1,1,1,1,1,1,1,1,1,1
1,1,1,1,1,1,33,33,1,1,1,1,1,1,1,1,1,1,1,1,1,1,1,1
1,1,1,1,1,1,1,33,1,1,1,1,1,1,1,1,1,1,1,1,1,1,1,1
1,1,1,1,1,1,1,1,1,1,1,1,1,1,1,1,1,1,1,1,1,1,1,1
endlayer

layer
1,1,1,1,1,1,1,1,1,1,1,1,1,1,1,1,1,1,1,1,1,1,1,1
1,1,1,1,1,1,1,1,1,1,1,1,1,1,1,1,1,1,1,1,1,1,1,1
1,1,1,1,1,1,1,1,1,1,1,1,1,1,1,1,1,1,1,1,1,1,1,1
1,1,1,1,1,1,1,1,1,1,1,1,1,1,1,1,1,1,1,1,1,1,1,1
1,1,1,1,1,1,1,1,1,1,1,1,1,1,1,1,1,1,1,1,1,1,1,1
1,1,1,1,1,1,1,1,1,1,1,1,1,1,1,1,1,1,1,1,1,1,1,1
1,1,1,1,1,1,1,1,1,1,1,1,1,1,33,33,1,1,1,1,1,1,1,1
1,1,1,1,1,1,1,1,1,1,1,1,1,33,0,0,0,1,1,1,1,1,1,1
1,1,1,1,1,1,1,1,1,1,1,1,1,33,0,3,0,33,1,1,1,1,1,1
1,1,1,1,1,1,1,1,1,1,1,1,0,33,0,0,0,33,1,1,1,1,1,1
1,1,1,1,1,1,1,1,1,1,1,0,0,0,33,33,33,1,1,1,1,1,1,1
1,1,1,1,1,1,1,1,1,33,33,0,0,0,0,1,1,1,1,1,1,1,1,1
1,1,1,1,1,1,1,1,33,0,0,0,0,0,1,1,1,1,1,1,1,1,1,1
1,1,1,1,1,1,1,1,33,0,3,0,33,1,1,1,1,1,1,1,1,1,1,1
1,1,1,1,1,1,1,1,33,0,0,0,33,1,1,1,1,1,1,1,1,1,1,1
1,1,1,1,1,1,1,0,0,33,33,33,1,1,1,1,1,1,1,1,1,1,1,1
1,1,1,1,1,1,0,0,0,1,1,1,1,1,1,1,1,1,1,1,1,1,1,1
1,1,1,1,1,0,0,0,1,1,1,1,1,1,1,1,1,1,1,1,1,1,1,1
1,1,1,1,0,0,0,1,1,1,1,1,1,1,1,1,1,1,1,1,1,1,1,1
1,1,1,1,33,0,1,1,1,1,1,1,1,1,1,1,1,1,1,1,1,1,1,1
1,1,1,1,1,1,1,1,1,1,1,1,1,1,1,1,1,1,1,1,1,1,1,1
1,1,1,1,1,1,1,1,1,1,1,1,1,1,1,1,1,1,1,1,1,1,1,1
1,1,1,1,1,1,1,1,1,1,1,1,1,1,1,1,1,1,1,1,1,1,1,1
1,1,1,1,1,1,1,1,1,1,1,1,1,1,1,1,1,1,1,1,1,1,1,1
endlayer

layer
1,1,1,1,1,1,1,1,1,1,1,1,1,1,1,1,1,1,1,1,1,1,1,1
1,1,1,1,1,1,1,1,1,1,1,1,1,1,1,1,1,1,1,1,1,1,1,1
1,1,1,1,1,1,1,1,1,1,1,1,1,1,1,1,1,1,1,1,1,1,1,1
1,1,1,1,1,1,1,1,1,1,1,1,1,1,1,1,1,1,1,1,1,1,1,1
1,1,1,1,1,1,1,1,1,1,1,1,1,1,1,1,1,1,1,1,1,1,1,1
1,1,1,1,1,1,1,1,1,1,1,1,1,1,1,1,1,1,1,1,1,1,1,1
1,1,1,1,1,1,1,1,1,1,1,1,1,1,1,1,1,1,1,1,1,1,1,1
1,1,1,1,1,1,1,1,1,1,1,1,1,1,0,0,0,1,1,1,1,1,1,1
1,1,1,1,1,1,1,1,1,1,1,1,1,1,0,3,0,1,1,1,1,1,1,1
1,1,1,1,1,1,1,1,1,1,1,1,1,1,0,0,0,1,1,1,1,1,1,1
1,1,1,1,1,1,1,1,1,1,1,1,0,0,1,1,1,1,1,1,1,1,1,1
1,1,1,1,1,1,1,1,1,1,1,0,0,0,1,1,1,1,1,1,1,1,1,1
1,1,1,1,1,1,1,1,1,0,0,0,0,1,1,1,1,1,1,1,1,1,1,1
1,1,1,1,1,1,1,1,1,0,3,0,1,1,1,1,1,1,1,1,1,1,1,1
1,1,1,1,1,1,1,1,1,0,0,0,1,1,1,1,1,1,1,1,1,1,1,1
1,1,1,1,1,1,1,1,1,1,1,1,1,1,1,1,1,1,1,1,1,1,1,1
1,1,1,1,1,1,1,1,1,1,1,1,1,1,1,1,1,1,1,1,1,1,1,1
1,1,1,1,1,1,1,1,1,1,1,1,1,1,1,1,1,1,1,1,1,1,1,1
1,1,1,1,1,1,1,1,1,1,1,1,1,1,1,1,1,1,1,1,1,1,1,1
1,1,1,1,1,1,1,1,1,1,1,1,1,1,1,1,1,1,1,1,1,1,1,1
1,1,1,1,1,1,1,1,1,1,1,1,1,1,1,1,1,1,1,1,1,1,1,1
1,1,1,1,1,1,1,1,1,1,1,1,1,1,1,1,1,1,1,1,1,1,1,1
1,1,1,1,1,1,1,1,1,1,1,1,1,1,1,1,1,1,1,1,1,1,1,1
1,1,1,1,1,1,1,1,1,1,1,1,1,1,1,1,1,1,1,1,1,1,1,1
endlayer


