
# Created by Ruins mod version 16.7 Ingame Parser
# authoring Player: lafuller

weight=1
embed_into_distance=3
acceptable_target_blocks=
unacceptable_target_blocks=stonebrick,cobblestone,stone,stone_brick_stairs,planks,wooden_slab,dark_oak_fence,dark_oak_stairs,flowing_water,water,flowing_lava,lava,ice,bedrock,netherrack,nether_brick,nether_brick_fence,soul_sand,quartz_ore,end_stone,obsidian,iron_bars,cloud,flesh,ash_block,slime_grass,slime_congealed,slime_dirt
dimensions=9,7,9
allowable_overhang=0
max_leveling=3
leveling_buffer=-1
preserve_water=0
preserve_lava=0

rule1=0,100,minecraft:stone_brick_stairs-0
rule2=0,100,minecraft:stone_brick_stairs-2
rule3=0,100,minecraft:cobblestone-0
rule4=0,100,minecraft:stone_brick_stairs-3
rule5=0,100,minecraft:dirt-0
rule6=0,100,minecraft:stone_brick_stairs-1
rule7=0,100,preserveBlock
rule8=0,100,minecraft:stone-6
rule9=0,100,minecraft:stone-5
rule10=0,100,minecraft:farmland-7
rule11=0,100,minecraft:water-0
rule12=0,100,minecraft:cobblestone_wall-0
rule13=0,100,minecraft:fence-0
rule14=0,100,minecraft:fence_gate-2
rule15=0,100,minecraft:fence_gate-3
rule16=0,100,potatoes-3,carrots-3,wheat-3,potatoes-5,carrots-5,wheat-5

layer
1,4,3,3,3,3,3,2,1
3,3,3,3,3,3,3,3,3
3,3,5,5,5,5,5,3,3
3,3,5,5,5,5,5,3,3
3,3,5,5,5,5,5,3,3
3,3,3,3,3,3,3,3,3
6,4,3,3,3,3,3,2,6
endlayer

layer
7,7,4,3,3,3,2,7,7
1,8,3,3,3,3,3,8,1
3,3,5,5,5,5,5,3,3
3,3,5,5,5,5,5,3,3
3,3,5,5,5,5,5,3,3
6,8,3,3,3,3,3,8,6
7,7,4,3,3,3,2,7,7
endlayer

layer
7,7,7,4,1,2,7,7,7
7,9,3,3,3,3,3,9,7
1,3,3,3,3,3,3,3,1
4,3,3,3,3,3,3,3,2
6,3,3,3,3,3,3,3,6
7,9,3,3,3,3,3,9,7
7,7,7,4,6,2,7,7,7
endlayer

layer
7,7,7,7,7,7,7,7,7
7,8,1,1,1,1,1,8,7
7,4,10,10,10,10,10,2,7
7,4,10,10,11,10,10,2,7
7,4,10,10,10,10,10,2,7
7,8,6,6,6,6,6,8,7
7,7,7,7,7,7,7,7,7
endlayer

layer
7,7,7,0,0,0,7,7,7
7,9,0,0,0,0,0,9,7
7,0,16,16,16,16,16,0,7
0,0,16,16,0,16,16,0,0
7,0,16,16,16,16,16,0,7
7,9,0,0,0,0,0,9,7
7,7,7,0,0,0,7,7,7
endlayer

layer
7,7,0,0,0,0,0,7,7
7,12,0,0,0,0,0,12,7
0,0,0,0,0,0,0,0,0
0,0,0,0,0,0,0,0,0
0,0,0,0,0,0,0,0,0
7,12,0,0,0,0,0,12,7
7,7,0,0,0,0,0,7,7
endlayer

layer
7,0,0,0,0,0,0,0,7
0,13,0,0,0,0,0,13,0
0,0,0,0,0,0,0,0,0
0,0,0,0,0,0,0,0,0
0,0,0,0,0,0,0,0,0
0,13,0,0,0,0,0,13,0
7,0,0,0,0,0,0,0,7
endlayer

layer
0,0,0,0,0,0,0,0,0
0,13,0,0,0,0,0,13,0
0,0,0,0,0,0,0,0,0
0,0,0,0,0,0,0,0,0
0,0,0,0,0,0,0,0,0
0,13,0,0,0,0,0,13,0
0,0,0,0,0,0,0,0,0
endlayer

layer
0,14,14,14,14,14,14,14,0
15,13,13,13,13,13,13,13,15
0,14,14,14,14,14,14,14,0
0,14,14,14,14,14,14,14,0
0,14,14,14,14,14,14,14,0
15,13,13,13,13,13,13,13,15
0,14,14,14,14,14,14,14,0
endlayer

