
# Created by Ruins mod version 16.5 Ingame Parser
# authoring Player: lafuller

weight=1
embed_into_distance=5
acceptable_target_blocks=
unacceptable_target_blocks=flowing_water,water,flowing_lava,lava,ice,bedrock,netherrack,nether_brick,nether_brick_fence,soul_sand,quartz_ore,end_stone,obsidian,iron_bars,cloud,flesh,ash_block,slime_grass,slime_congealed,slime_dirt
dimensions=12,16,20
allowable_overhang=0
max_leveling=7
leveling_buffer=-1
preserve_water=0
preserve_lava=0

rule1=0,100,preserveBlock
rule2=0,100,minecraft:double_stone_slab-9
rule3=0,100,minecraft:sandstone-2
rule4=0,100,minecraft:sandstone-0
rule5=0,100,minecraft:sandstone_stairs-2
rule6=0,100,minecraft:sandstone_stairs-0
rule7=0,100,minecraft:sandstone_stairs-3
rule8=0,100,bookshelf,pumpkin,melon_block,hay_block,ChestGenHook:chests/spawn_bonus_chest:5-5
rule9=0,100,minecraft:ladder-3
rule10=0,100,minecraft:ladder-2
rule11=0,100,minecraft:trapdoor-8
rule12=0,100,bookshelf,pumpkin,melon_block,hay_block,ChestGenHook:chests/stronghold_crossing:5-2
rule13=0,100,minecraft:ladder-5
rule14=0,100,minecraft:trapdoor-10
rule15=0,100,bookshelf,pumpkin,melon_block,hay_block,ChestGenHook:chests/village_blacksmith:5-4
rule16=0,100,bookshelf,pumpkin,melon_block,hay_block,ChestGenHook:chests/stronghold_library:5-3
rule17=0,100,minecraft:ladder-4
rule18=0,100,minecraft:dirt-0
rule19=0,100,minecraft:trapdoor-0
rule20=0,100,minecraft:trapdoor-2
rule21=0,100,minecraft:sandstone_stairs-1
rule22=0,100,minecraft:wooden_slab-9
rule23=0,100,minecraft:spruce_stairs-5
rule24=0,100,minecraft:sandstone_stairs-4
rule25=0,100,minecraft:spruce_stairs-4
rule26=0,100,minecraft:sandstone_stairs-6
rule27=0,100,minecraft:spruce_stairs-6
rule28=0,100,minecraft:spruce_stairs-7
rule29=0,100,minecraft:spruce_fence-0
rule30=0,100,minecraft:jungle_door-1
rule31=0,100,minecraft:jungle_door-0
rule32=0,100,minecraft:jungle_door-2
rule33=0,100,minecraft:jungle_door-3
rule34=0,100,minecraft:jungle_door-8
rule35=0,100,minecraft:jungle_door-9
rule36=0,100,minecraft:carpet-8
rule37=0,100,minecraft:carpet-7
rule38=0,100,minecraft:wooden_slab-1
rule39=0,100,minecraft:stone_slab-9
rule40=0,100,minecraft:trapdoor-9
rule41=0,100,minecraft:sandstone_stairs-7
rule42=0,100,minecraft:sandstone_stairs-5
rule43=0,100,minecraft:trapdoor-11
rule44=0,100,minecraft:stone_slab-1
rule45=0,100,minecraft:trapdoor-3
rule46=0,100,minecraft:hay_block-0

layer
1,2,4,3,4,3,4,4,4,4,3,1,2,2,2,2,1,1,1,1
4,4,4,4,4,4,4,4,4,4,4,4,4,4,4,4,1,1,1,1
4,4,4,4,4,4,4,4,4,2,2,2,2,2,2,4,1,1,1,1
4,4,4,4,4,4,4,4,4,4,3,3,3,2,2,4,1,1,1,1
4,2,4,4,4,2,4,4,4,4,3,3,3,2,4,4,4,3,4,4
4,2,4,4,4,3,4,4,4,4,3,3,3,2,4,4,4,2,2,3
4,2,4,4,4,3,4,4,4,4,4,4,3,2,2,2,2,2,2,4
3,2,4,4,4,3,4,4,4,4,4,4,4,4,4,4,4,4,2,3
1,1,3,4,4,3,4,2,2,2,2,3,4,4,4,4,4,4,2,3
1,1,3,4,4,3,2,4,4,4,4,3,4,4,4,4,4,4,2,4
1,1,4,4,4,2,2,4,4,4,4,4,4,4,4,4,4,4,2,1
1,1,4,4,4,4,2,4,4,4,4,4,4,4,4,4,4,4,2,1
1,1,2,4,4,4,2,4,4,4,4,4,4,4,4,4,4,4,2,1
1,1,2,4,4,2,2,4,4,4,4,4,4,4,4,4,4,4,3,1
1,1,4,4,4,2,2,2,2,2,2,2,2,4,4,4,4,4,4,1
1,1,4,4,4,4,3,4,4,4,3,4,4,4,4,4,4,4,4,1
endlayer

layer
1,7,4,3,4,3,4,4,4,4,3,1,7,6,6,5,1,1,1,1
4,4,4,4,4,4,4,4,4,4,4,4,4,4,4,4,1,1,1,1
4,4,4,4,4,4,4,4,4,2,2,2,2,2,2,4,1,1,1,1
4,4,4,4,4,4,4,4,4,4,3,3,3,2,2,4,1,1,1,1
4,2,4,4,4,2,4,4,4,4,3,3,3,2,4,4,4,3,4,4
4,2,4,4,4,3,4,4,4,4,3,3,3,2,4,4,4,2,2,3
4,2,4,4,4,3,4,4,4,4,4,4,3,2,2,2,2,2,2,4
3,2,4,4,4,3,4,4,4,4,4,4,4,4,4,4,4,4,2,3
1,1,3,4,4,3,4,2,2,2,2,3,4,4,4,4,4,4,2,3
1,1,3,4,4,3,2,4,4,4,4,3,4,4,4,4,4,4,2,4
1,1,4,4,4,2,2,4,4,4,4,4,4,4,4,4,4,4,2,1
1,1,4,4,4,4,2,4,4,4,4,4,4,4,4,4,4,4,2,1
1,1,7,4,4,4,2,4,4,4,4,4,4,4,4,4,4,4,2,1
1,1,7,4,4,2,2,4,4,4,4,4,4,4,4,4,4,4,3,1
1,1,4,4,4,2,2,2,2,2,2,2,2,4,4,4,4,4,4,1
1,1,4,4,4,4,3,4,4,4,3,4,4,4,4,4,4,4,4,1
endlayer

layer
1,1,7,4,3,3,4,3,4,4,4,1,1,1,1,1,1,1,1,1
3,4,4,4,4,4,0,0,0,8,4,4,3,6,6,4,1,1,1,1
3,4,4,4,4,4,0,0,0,0,2,2,2,2,2,3,1,1,1,1
4,0,0,0,0,4,0,0,0,0,3,3,3,2,2,4,1,1,1,1
3,0,0,0,0,4,0,0,0,0,3,3,3,2,4,4,4,4,3,3
3,0,0,0,0,0,4,0,0,0,9,3,3,2,4,4,4,2,2,4
4,10,0,0,0,0,4,0,0,0,0,4,3,2,2,2,2,2,2,4
4,2,0,0,0,0,4,0,0,0,0,4,11,0,0,0,0,0,2,4
1,1,3,0,0,0,4,2,2,2,2,3,11,0,0,0,0,0,2,4
1,1,4,0,0,0,2,0,0,0,13,3,12,0,0,0,0,0,2,3
1,1,4,15,14,14,2,0,0,0,0,0,4,3,0,0,0,0,2,1
1,1,4,4,4,4,2,0,0,0,0,0,16,4,4,0,0,0,2,1
1,1,1,4,4,4,2,0,0,0,0,0,0,0,4,17,0,0,2,1
1,1,1,4,4,2,2,0,0,0,0,0,0,0,4,4,4,4,4,1
1,1,6,4,4,2,2,2,2,2,2,2,2,4,4,4,4,4,4,1
1,1,3,3,4,4,4,4,4,4,3,4,4,4,4,4,4,4,5,1
endlayer

layer
1,1,1,7,4,4,3,3,3,4,3,1,1,1,1,1,1,1,1,1
3,4,4,4,4,4,0,0,0,0,4,4,1,1,1,1,1,1,1,1
3,4,4,4,4,4,0,0,0,0,2,2,2,6,6,3,1,1,1,1
4,0,0,0,0,4,0,0,0,0,3,4,3,2,3,3,1,1,1,1
3,0,0,0,0,4,0,0,0,0,3,3,3,18,18,4,4,4,3,4
4,0,0,0,0,0,4,0,0,0,9,3,3,2,4,4,4,2,2,3
4,10,0,0,0,0,4,0,0,0,0,4,3,2,2,2,3,2,2,4
3,4,0,0,0,0,4,0,0,0,0,4,0,0,0,0,0,0,2,4
1,1,3,0,0,0,4,2,2,2,2,3,0,0,0,0,0,0,3,4
1,1,3,0,0,0,2,0,0,0,13,3,0,0,0,0,0,0,2,3
1,1,4,0,0,0,2,0,0,0,0,0,4,3,0,0,0,0,2,1
1,1,2,4,4,4,2,0,0,0,0,0,0,4,4,0,0,0,2,1
1,1,1,4,4,4,2,0,0,0,0,0,0,0,4,17,0,0,2,1
1,1,1,3,18,2,2,0,0,0,0,0,0,0,4,4,4,4,3,1
1,1,1,3,18,2,2,2,2,2,2,2,2,4,4,4,4,4,4,1
1,1,1,7,3,4,4,3,3,3,4,4,4,4,4,4,4,5,1,1
endlayer

layer
1,1,1,1,7,4,3,4,4,3,3,1,1,1,1,1,1,1,1,1
7,4,4,4,3,4,0,0,0,0,4,3,1,1,1,1,1,1,1,1
3,4,4,4,4,4,0,0,0,0,2,4,5,1,1,1,1,1,1,1
4,0,0,0,0,4,0,0,0,0,3,4,6,1,1,6,1,1,1,1
4,0,0,0,0,4,0,0,0,0,3,3,3,1,1,3,4,4,4,5
4,0,0,0,0,0,4,0,0,0,9,3,3,2,2,2,2,2,2,4
4,10,0,0,0,0,4,0,0,0,0,4,3,2,2,2,3,2,2,3
4,4,0,0,0,0,4,0,0,0,0,4,19,0,0,0,0,0,2,3
1,1,4,0,0,0,4,2,2,2,2,3,19,0,0,0,0,0,3,4
1,1,3,0,0,0,2,0,0,0,13,3,19,0,0,0,0,0,2,3
1,1,3,20,20,20,2,0,0,0,0,0,4,3,0,0,0,0,2,1
1,1,2,2,2,2,2,0,0,0,0,0,0,4,4,0,0,0,2,1
1,1,1,4,4,2,2,0,0,0,0,0,0,0,4,17,0,0,2,1
1,1,1,21,1,2,2,0,0,0,0,0,0,0,4,4,4,4,3,1
1,1,1,1,1,2,2,2,2,2,2,2,2,4,4,4,4,4,1,1
1,1,1,1,1,7,4,4,4,4,3,4,4,3,3,3,5,1,1,1
endlayer

layer
1,1,1,1,1,4,4,4,4,4,4,1,1,1,1,1,1,1,1,1
1,7,3,5,1,4,22,22,22,22,4,3,1,1,1,1,1,1,1,1
4,4,4,4,4,4,22,22,22,22,3,4,1,1,1,1,1,1,1,1
4,22,22,22,22,4,23,23,23,23,2,5,1,1,1,1,1,1,1,1
4,25,25,25,25,2,24,22,22,22,2,2,1,1,1,1,7,3,5,1
3,22,22,22,22,22,2,24,22,22,9,2,6,2,2,2,2,2,4,4
3,10,22,22,22,22,2,26,22,22,22,2,2,2,2,2,3,2,3,3
4,3,24,22,22,22,2,26,22,22,22,2,22,22,27,22,22,22,2,4
1,1,2,25,25,25,2,2,2,2,2,2,22,22,27,22,22,22,3,4
1,1,2,22,22,22,2,22,28,22,13,2,22,22,27,22,22,22,3,4
1,1,2,22,22,22,2,22,28,22,22,28,2,2,27,22,22,22,2,1
1,1,4,2,2,2,2,22,28,22,22,28,22,22,4,22,22,22,2,1
1,1,1,21,3,2,2,22,28,22,22,28,22,22,2,17,22,22,3,1
1,1,1,1,1,2,2,22,28,22,22,28,22,22,4,4,4,4,4,1
1,1,1,1,1,21,3,2,2,3,2,2,3,4,4,21,7,4,1,1
1,1,1,1,1,1,3,4,4,4,3,3,3,5,1,1,1,1,1,1
endlayer

layer
1,1,1,1,1,3,3,3,4,4,3,1,1,1,1,1,1,1,1,1
1,1,1,1,1,4,0,0,0,0,4,29,1,1,1,1,1,1,1,1
3,4,31,4,4,4,0,0,0,0,30,1,1,1,1,1,1,1,1,1
4,0,0,0,0,4,0,0,0,0,4,1,1,1,1,1,1,1,1,1
4,0,0,0,0,2,4,0,0,0,4,3,1,1,1,1,1,1,1,1
4,0,0,0,0,0,22,4,0,0,9,4,1,1,1,3,4,3,4,3
4,10,0,0,0,0,22,4,10,0,0,4,4,31,2,3,0,0,0,4
3,2,4,0,0,0,22,4,0,0,0,4,0,0,0,0,0,0,0,4
1,1,4,0,0,0,4,2,2,2,2,2,0,0,0,0,0,0,0,4
1,1,4,0,0,0,4,0,0,0,13,4,0,17,0,0,0,0,2,3
1,1,4,0,0,0,4,0,0,0,0,0,4,4,0,0,0,0,2,1
1,1,3,4,32,4,3,0,0,0,0,0,0,0,4,0,0,0,2,1
1,1,1,1,1,1,4,0,0,0,0,0,0,0,2,17,0,0,2,1
1,1,1,1,1,1,33,0,0,0,0,0,0,0,4,4,32,4,3,1
1,1,1,1,1,1,4,0,0,0,2,2,32,4,4,1,1,29,1,1
1,1,1,1,1,1,3,3,6,4,3,1,1,1,1,1,1,1,1,1
endlayer

layer
1,1,1,1,1,3,4,4,0,4,3,1,1,1,1,1,1,1,1,1
1,1,1,1,1,4,0,0,0,0,4,29,1,1,1,1,1,1,1,1
3,4,35,4,4,4,0,0,0,0,34,1,1,1,1,1,1,1,1,1
4,0,0,0,0,4,0,0,0,0,4,1,1,1,1,1,1,1,1,1
3,0,0,0,0,4,4,0,0,0,4,3,1,1,1,1,1,1,1,1
0,0,0,0,0,0,36,4,0,0,0,3,1,1,1,3,4,0,4,3
4,0,0,0,0,0,37,4,10,0,0,4,4,34,2,3,0,0,0,4
3,2,4,0,0,0,37,4,22,22,22,4,11,0,0,0,0,0,0,0
1,1,4,0,0,0,4,2,2,2,2,2,11,0,0,0,0,0,0,4
1,1,0,0,0,0,4,0,0,0,0,4,11,17,0,0,0,0,2,3
1,1,4,0,0,0,4,0,0,0,0,0,4,4,0,0,0,0,4,1
1,1,3,4,35,4,3,0,0,0,0,0,0,0,4,0,0,0,0,1
1,1,1,1,1,1,4,0,0,0,0,0,0,0,4,0,0,0,3,1
1,1,1,1,1,1,34,0,0,0,0,0,0,0,4,4,34,4,3,1
1,1,1,1,1,1,4,0,0,0,4,2,35,4,4,1,1,29,1,1
1,1,1,1,1,1,4,4,0,4,4,1,1,1,1,1,1,1,1,1
endlayer

layer
1,1,1,1,1,4,4,3,3,3,4,1,1,1,1,1,1,1,1,1
1,1,1,1,1,4,0,0,0,0,4,29,1,1,1,1,1,1,1,1
4,4,4,4,4,4,0,0,0,0,4,1,1,1,1,1,1,1,1,1
4,0,0,0,0,4,0,0,0,0,4,1,1,1,1,1,1,1,1,1
3,0,0,0,0,2,4,0,0,0,4,4,1,1,1,1,1,1,1,1
3,0,0,0,0,0,0,4,0,0,0,4,22,22,22,4,4,4,4,3
3,0,0,0,0,0,0,4,0,0,0,4,4,2,2,2,0,0,0,4
4,2,4,0,0,0,0,4,37,37,36,4,0,0,0,0,0,0,0,4
1,1,4,0,0,0,4,2,2,2,2,2,0,0,0,0,0,0,0,4
1,1,3,0,0,0,4,0,0,0,0,4,0,0,0,0,0,0,2,4
1,1,4,0,0,0,4,0,0,0,0,0,4,4,0,0,0,0,2,1
1,1,4,4,3,4,2,0,0,0,0,0,0,0,4,0,0,0,2,1
1,1,1,1,1,1,3,0,0,0,0,0,0,0,2,0,0,0,2,1
1,1,1,1,1,1,3,0,0,0,0,0,0,0,4,4,3,4,4,1
1,1,1,1,1,1,4,0,0,0,2,2,2,4,4,1,1,29,1,1
1,1,1,1,1,1,3,4,4,4,3,1,1,1,1,1,1,1,1,1
endlayer

layer
1,1,1,1,1,3,4,4,4,4,3,1,1,1,1,1,1,1,1,1
1,1,1,1,1,4,0,0,0,0,4,38,1,1,1,1,1,1,1,1
3,4,4,4,4,4,0,0,0,0,4,38,1,1,1,1,1,1,1,1
4,0,0,0,39,4,0,0,0,0,4,38,1,1,1,1,1,1,1,1
4,0,0,0,39,4,4,24,24,24,4,3,1,1,1,1,1,1,1,1
4,0,0,0,39,0,0,4,0,0,0,3,1,1,1,7,6,6,6,5
4,0,0,0,39,0,0,4,0,0,0,4,4,2,2,2,0,0,0,5
3,4,4,39,39,39,39,4,0,0,0,4,39,39,39,26,0,0,0,5
1,1,4,0,0,0,4,2,2,2,2,4,39,40,39,26,0,0,0,5
1,1,4,0,0,0,3,0,0,0,41,4,39,39,39,24,24,24,3,5
1,1,4,0,0,0,3,0,0,0,41,42,4,4,4,26,0,0,2,1
1,1,3,4,4,4,2,0,0,0,41,0,0,0,4,26,0,0,2,1
1,1,1,1,1,1,7,42,42,42,42,0,0,0,2,26,0,0,3,1
1,1,1,1,1,1,7,39,43,39,41,0,0,0,4,4,4,4,3,1
1,1,1,1,1,1,7,39,39,39,2,3,4,4,3,38,38,38,1,1
1,1,1,1,1,1,21,21,21,21,5,1,1,1,1,1,1,1,1,1
endlayer

layer
1,1,1,1,1,3,3,3,3,3,3,1,1,1,1,1,1,1,1,1
1,1,1,1,1,3,44,44,44,44,3,1,1,1,1,1,1,1,1,1
6,6,6,6,6,3,44,45,44,44,3,1,1,1,1,1,1,1,1,1
7,0,0,0,5,3,44,44,44,44,3,1,1,1,1,1,1,1,1,1
7,0,0,0,5,3,3,3,3,3,3,6,1,1,1,1,1,1,1,1
7,0,0,0,5,44,44,7,38,38,38,5,1,1,1,1,1,1,1,1
7,0,0,0,5,20,44,7,38,45,38,5,1,1,1,1,44,44,44,1
7,21,3,3,3,3,3,7,38,38,38,5,1,1,1,1,44,45,44,1
1,1,3,0,0,0,3,21,21,21,21,21,1,0,1,1,44,44,44,1
1,1,3,0,0,0,3,5,21,21,44,1,1,1,6,6,6,6,6,1
1,1,3,0,0,0,3,5,45,7,44,44,1,1,7,46,46,46,5,1
1,1,3,3,3,3,3,6,6,7,44,6,6,5,7,46,19,46,5,1
1,1,1,1,1,1,1,44,44,44,44,7,11,5,7,46,46,46,5,1
1,1,1,1,1,1,1,1,0,1,44,21,21,21,21,21,21,21,21,1
1,1,1,1,1,1,1,1,1,1,1,1,1,1,1,1,1,1,1,1
1,1,1,1,1,1,1,1,1,1,1,1,1,1,1,1,1,1,1,1
endlayer

layer
1,1,1,1,1,1,1,1,1,1,1,1,1,1,1,1,1,1,1,1
1,1,1,1,1,1,1,1,1,1,1,1,1,1,1,1,1,1,1,1
1,1,1,1,1,1,1,0,1,1,1,1,1,1,1,1,1,1,1,1
1,44,44,44,1,1,1,1,1,1,1,1,1,1,1,1,1,1,1,1
1,44,19,44,1,1,1,1,1,1,1,1,1,1,1,1,1,1,1,1
1,44,44,44,1,1,1,1,1,1,1,1,1,1,1,1,1,1,1,1
1,44,44,44,1,0,1,1,1,0,1,1,1,1,1,1,1,1,1,1
1,1,1,6,6,6,1,1,1,1,1,1,1,1,1,1,1,0,1,1
1,1,7,38,38,38,5,1,1,1,1,1,1,0,1,1,1,1,1,1
1,1,7,38,19,38,5,1,1,1,1,1,1,1,1,1,1,1,1,1
1,1,7,38,38,38,5,1,0,1,1,1,1,1,1,1,1,1,1,1
1,1,1,21,21,21,1,1,1,1,1,1,1,1,1,1,0,1,1,1
1,1,1,1,1,1,1,1,1,1,1,1,0,1,1,1,1,1,1,1
1,1,1,1,1,1,1,1,0,1,1,1,1,1,1,1,1,1,1,1
1,1,1,1,1,1,1,1,1,1,1,1,1,1,1,1,1,1,1,1
1,1,1,1,1,1,1,1,1,1,1,1,1,1,1,1,1,1,1,1
endlayer

