
# Created by Ruins mod version 16.5 Ingame Parser
# authoring Player: lafuller

weight=1
embed_into_distance=9
acceptable_target_blocks=
unacceptable_target_blocks=dirt,stone,flowing_lava,lava,ice,bedrock,netherrack,nether_brick,nether_brick_fence,soul_sand,quartz_ore,gravel,end_stone,obsidian,iron_bars,cloud,flesh,ash_block,slime_grass,slime_congealed,slime_dirt
biomesToSpawnIn=swampland,wetland,marsh,lush swamp
dimensions=19,9,9
allowable_overhang=0
max_leveling=4
leveling_buffer=-1
preserve_water=0
preserve_lava=0

rule1=0,100,preserveBlock
rule2=0,100,minecraft:log2-12
rule3=0,100,minecraft:trapdoor-0
rule4=0,100,minecraft:spruce_stairs-0
rule5=0,100,minecraft:spruce_stairs-7
rule6=0,100,minecraft:spruce_fence-0
rule7=0,100,minecraft:spruce_stairs-2
rule8=0,100,minecraft:ladder-2
rule9=0,100,minecraft:double_wooden_slab-1
rule10=0,100,minecraft:spruce_stairs-1
rule11=0,100,minecraft:wooden_slab-9
rule12=0,100,minecraft:spruce_stairs-4
rule13=0,100,minecraft:spruce_stairs-5
rule14=0,100,minecraft:spruce_stairs-6
rule15=0,100,minecraft:dark_oak_stairs-6
rule16=0,100,minecraft:dark_oak_stairs-5
rule17=0,100,minecraft:dark_oak_stairs-0
rule18=0,100,minecraft:dark_oak_stairs-1
rule19=0,100,minecraft:cauldron-0
rule20=0,100,minecraft:sticky_piston-1

rule21=0,100,IInventory;hopper;cooked_fish#3#0#0+feather#1#0#1-3,IInventory;hopper;rabbit_stew#1#0#0+glowstone_dust#2#0#1-3,IInventory;hopper;slime_ball#3#0#0+bread#1#0#1-3,IInventory;hopper;apple#2#0#0+redstone#2#0#2-3,IInventory;hopper;cooked_fish#2#1#0+glass_bottle#1#0#1-3,IInventory;hopper;slime_ball#2#0#0+baked_potato#2#0#1-3
rule22=0,100,IInventory;dropper;milk_bucket#1#0#4+gunpowder#4#0#6-1,IInventory;dropper;gunpowder#3#0#1+spruce_boat#1#0#6-1,IInventory;dropper;slime_ball#2#0#3+lead#1#0#5-1,IInventory;dropper;shears#1#0#0+gunpowder#1#0#5-1,IInventory;dropper;glass_bottle#3#0#2+gunpowder#2#0#7-1,IInventory;dropper;redstone#2#0#3+slime_ball#3#0#8-1

rule23=0,100,minecraft:jungle_door-1
rule24=0,100,minecraft:dark_oak_stairs-7
rule25=0,100,minecraft:spruce_stairs-3
rule26=0,100,minecraft:bookshelf-0,air,air
rule27=0,100,minecraft:trapdoor-10
rule28=0,100,minecraft:dark_oak_stairs-4
rule29=0,100,minecraft:dark_oak_stairs-2
rule30=0,100,IInventory;furnace;coal#3#0#1-5
rule31=0,100,minecraft:brewing_stand-0,air,air
rule32=0,100,minecraft:carpet-7
rule33=0,100,minecraft:double_wooden_slab-5
rule34=0,100,minecraft:jungle_door-8
rule35=0,100,minecraft:spruce_fence_gate-1
rule36=0,100,minecraft:dark_oak_stairs-3
rule37=0,100,minecraft:cobblestone_wall-0
rule38=0,100,minecraft:spruce_fence_gate-0
rule39=0,100,minecraft:spruce_fence_gate-3
rule40=0,100,minecraft:spruce_fence_gate-5
rule41=0,100,minecraft:wooden_slab-5
rule42=0,100,minecraft:wooden_slab-13
rule43=0,100,minecraft:wooden_slab-1
rule44=0,100,minecraft:planks-5

layer
1,1,1,1,1,1,1,1,1
1,1,1,1,1,1,1,1,1
1,2,1,1,1,1,2,1,1
1,1,1,1,1,1,1,1,1
1,1,1,1,1,1,1,1,1
1,1,1,1,1,1,1,1,1
1,2,1,1,1,1,2,1,1
1,1,1,1,1,1,1,1,1
1,1,1,1,1,1,1,1,1
endlayer

layer
1,1,1,1,1,1,1,1,1
1,1,1,1,1,1,1,1,1
1,2,1,1,1,1,2,1,1
1,1,1,1,1,1,1,1,1
1,1,1,1,1,1,1,1,1
1,1,1,1,1,1,1,1,1
1,2,1,1,1,1,2,1,1
1,1,1,1,1,1,1,1,1
1,1,1,1,1,1,1,1,1
endlayer

layer
1,1,1,1,1,1,1,1,1
1,1,1,1,1,1,1,1,1
1,2,1,1,1,1,2,1,1
1,1,1,1,1,1,1,1,1
1,1,1,1,1,1,1,1,1
1,1,1,1,1,1,1,1,1
1,2,1,1,1,1,2,1,1
1,1,1,1,1,1,1,1,1
1,1,1,1,1,1,1,1,1
endlayer

layer
1,1,1,1,1,1,1,1,1
1,1,1,1,1,1,1,1,1
1,2,1,1,1,1,2,1,1
1,1,1,1,1,1,1,1,1
1,1,1,1,1,1,1,1,1
1,1,1,1,1,1,1,1,1
1,2,1,1,1,1,2,1,1
1,1,1,1,1,1,1,1,1
1,1,1,1,1,1,1,1,1
endlayer

layer
1,1,1,1,1,1,1,1,1
1,1,1,1,1,1,1,1,1
1,2,1,1,1,1,2,1,1
1,1,1,1,1,1,1,1,1
1,1,1,1,1,1,1,1,1
1,1,1,1,1,1,1,1,1
1,2,1,1,1,1,2,1,1
1,1,1,1,1,1,1,1,1
1,1,1,1,1,1,1,1,1
endlayer

layer
1,1,1,1,1,1,1,1,1
1,1,1,1,1,1,1,1,1
1,2,1,1,1,1,2,1,1
1,1,1,1,1,1,1,1,1
1,1,1,1,1,1,1,1,1
1,1,1,1,1,1,1,1,1
1,2,1,1,1,1,2,1,1
1,1,1,1,1,1,1,1,1
1,1,1,1,1,1,1,1,1
endlayer

layer
1,1,1,1,1,1,1,1,1
1,1,1,1,1,1,1,1,1
1,2,1,1,1,1,2,1,1
1,1,1,1,1,1,1,1,1
1,1,1,1,1,1,1,1,1
1,1,1,1,1,1,1,1,1
1,2,1,1,1,1,2,1,1
1,1,1,1,1,1,1,1,1
1,1,1,1,1,1,1,1,1
endlayer

layer
1,1,1,1,1,1,1,1,1
1,1,1,1,1,1,1,1,1
1,2,1,1,1,1,2,1,1
1,1,1,1,1,1,1,1,1
1,1,1,1,1,1,1,1,1
1,1,1,1,1,1,1,1,1
1,2,1,1,1,1,2,1,1
1,1,1,1,1,1,1,1,1
1,1,1,1,1,1,1,1,1
endlayer

layer
1,1,1,1,1,1,1,1,1
1,1,1,1,1,1,1,1,1
1,2,1,1,1,1,2,1,1
1,1,1,1,1,1,1,1,1
1,1,1,1,1,1,1,1,1
1,1,1,1,1,1,1,1,1
1,2,1,1,1,1,2,1,1
1,1,1,1,1,1,1,1,1
1,1,1,1,1,1,1,1,1
endlayer

layer
1,1,1,1,1,1,1,1,1
1,1,1,1,1,1,1,1,1
1,2,1,1,1,1,2,1,1
1,1,1,1,1,1,6,5,3
1,1,1,1,1,1,1,5,3
1,1,1,1,1,1,6,5,3
1,2,1,1,1,1,2,1,1
1,1,1,1,1,1,1,1,1
1,1,1,1,1,1,1,1,1
endlayer

layer
1,1,1,1,1,1,1,1,1
1,1,1,1,1,1,1,1,1
1,2,6,6,6,6,2,1,0
1,6,1,1,1,6,6,9,8
1,6,1,1,1,1,6,9,8
1,6,1,1,1,6,6,9,8
1,2,6,6,6,6,2,1,0
1,6,1,1,1,1,1,1,1
1,1,1,1,1,1,1,1,1
endlayer

layer
1,1,11,11,11,0,0,1,1
1,11,12,12,12,12,6,1,1
5,2,13,13,13,13,2,12,0
5,5,14,11,11,5,14,7,0
5,5,14,11,11,5,14,7,0
5,5,14,11,11,5,14,7,0
5,2,12,12,12,5,2,14,0
1,6,13,13,13,13,14,1,1
1,1,1,0,0,0,1,1,1
endlayer

layer
1,0,16,15,6,0,0,0,1
0,12,16,18,18,17,6,0,0
5,22,21,20,19,0,9,6,0
9,0,0,0,0,0,7,0,0
24,0,0,0,0,0,23,0,0
24,0,0,0,0,0,7,0,0
24,27,27,27,0,26,25,6,0
13,7,10,25,9,10,14,0,1
1,1,0,0,0,0,0,1,1
endlayer

layer
0,0,28,15,28,0,0,0,0
28,16,28,18,29,28,16,0,0
29,32,0,31,30,0,28,15,0
33,0,0,0,0,0,7,0,0
24,0,0,0,0,0,34,0,0
29,0,0,0,0,0,9,0,0
33,32,32,32,0,0,16,15,0
6,15,16,16,16,16,18,0,0
1,0,0,0,0,0,0,0,1
endlayer

layer
0,0,28,28,28,0,0,0,0
36,35,24,28,16,35,28,28,0
24,0,0,0,37,0,24,15,0
29,0,0,0,0,0,9,16,0
24,0,0,0,0,0,38,0,0
15,0,0,0,0,0,14,28,0
24,0,0,0,0,0,5,15,0
6,33,39,39,16,16,33,16,0
0,40,0,0,40,0,0,0,0
endlayer

layer
0,41,17,17,41,41,0,0,0
41,17,36,17,28,28,41,0,0
36,42,0,0,37,0,16,17,0
17,0,0,0,0,0,24,15,0
38,0,0,0,0,0,15,15,0
38,0,0,0,0,0,24,15,0
24,24,16,18,16,16,15,18,0
43,16,16,18,16,16,16,0,0
0,41,33,33,41,0,0,0,0
endlayer

layer
0,0,0,0,0,0,0,0,0
0,41,17,17,29,0,0,0,0
41,41,44,16,44,17,17,0,0
33,33,11,11,11,24,29,0,0
42,33,11,11,11,24,29,0,0
42,33,28,28,28,33,29,0,0
41,33,18,33,33,18,41,0,0
0,0,41,18,41,41,0,0,0
0,0,0,0,0,0,0,0,0
endlayer

layer
0,0,0,0,0,0,0,0,0
0,0,0,0,0,0,0,0,0
0,0,0,0,37,0,0,0,0
0,0,41,41,41,41,0,0,0
0,41,41,41,41,41,0,0,0
0,41,41,41,41,41,0,0,0
0,0,0,0,0,0,0,0,0
0,0,0,0,0,0,0,0,0
0,0,0,0,0,0,0,0,0
endlayer

layer
0,0,0,0,0,0,0,0,0
0,0,0,0,0,0,0,0,0
0,0,0,0,37,0,0,0,0
0,0,0,0,0,0,0,0,0
0,0,0,0,0,0,0,0,0
0,0,0,0,0,0,0,0,0
0,0,0,0,0,0,0,0,0
0,0,0,0,0,0,0,0,0
0,0,0,0,0,0,0,0,0
endlayer

