
# Created by Ruins mod version 16.5 Ingame Parser
# authoring Player: lafuller

weight=1
embed_into_distance=5
acceptable_target_blocks=
unacceptable_target_blocks=flowing_water,water,flowing_lava,lava,ice,bedrock,netherrack,nether_brick,nether_brick_fence,soul_sand,quartz_ore,end_stone,obsidian,iron_bars,cloud,flesh,ash_block,slime_grass,slime_congealed,slime_dirt
dimensions=12,26,17
allowable_overhang=0
max_leveling=7
leveling_buffer=-1
preserve_water=0
preserve_lava=0

rule1=0,100,preserveBlock
rule2=0,100,minecraft:sandstone-0
rule3=0,100,minecraft:sandstone-2
rule4=0,100,minecraft:sandstone_stairs-0
rule5=0,100,minecraft:double_stone_slab-9
rule6=0,100,minecraft:sandstone_stairs-3
rule7=0,100,minecraft:sandstone_stairs-2
rule8=0,100,minecraft:sandstone_stairs-1
rule9=0,100,minecraft:trapdoor-11
rule10=0,100,minecraft:trapdoor-8
rule11=0,100,bookshelf,pumpkin,melon_block,hay_block,ChestGenHook:chests/stronghold_corridor:5-3
rule12=0,100,minecraft:ladder-4
rule13=0,100,minecraft:trapdoor-10
rule14=0,100,bookshelf,pumpkin,melon_block,hay_block,ChestGenHook:chests/stronghold_library:5-2
rule15=0,100,minecraft:ladder-3
rule16=0,100,minecraft:dirt-0
rule17=0,100,minecraft:trapdoor-0
rule18=0,100,minecraft:trapdoor-2
rule19=0,100,minecraft:trapdoor-3
rule20=0,100,minecraft:wooden_slab-9
rule21=0,100,minecraft:jungle_door-3
rule22=0,100,minecraft:jungle_door-1
rule23=0,100,minecraft:ladder-2
rule24=0,100,minecraft:jungle_door-0
rule25=0,100,minecraft:ladder-5
rule26=0,100,minecraft:trapdoor-9
rule27=0,100,minecraft:sandstone_stairs-6
rule28=0,100,minecraft:jungle_door-2
rule29=0,100,minecraft:jungle_door-8
rule30=0,100,minecraft:jungle_door-9
rule31=0,100,minecraft:trapdoor-1
rule32=0,100,minecraft:carpet-8
rule33=0,100,minecraft:carpet-7
rule34=0,100,minecraft:wooden_slab-1
rule35=0,100,minecraft:stone_slab-9
rule36=0,100,minecraft:sandstone_stairs-7
rule37=0,100,minecraft:sandstone_stairs-5
rule38=0,100,minecraft:hay_block-4
rule39=0,100,minecraft:sandstone_stairs-4
rule40=0,100,minecraft:spruce_stairs-0
rule41=0,100,minecraft:spruce_stairs-2
rule42=0,100,minecraft:hay_block-0
rule43=0,100,minecraft:spruce_stairs-3
rule44=0,100,minecraft:spruce_stairs-1
rule45=0,100,minecraft:stone_slab-1

layer
1,2,3,2,2,2,3,3,2,2,1,1,1,1,1,1,1
1,2,5,5,5,5,5,5,5,5,5,1,1,1,1,1,1
1,2,5,2,2,2,2,2,5,2,3,1,1,1,1,1,1
1,2,5,2,2,2,2,2,5,2,2,3,1,1,1,1,1
1,2,5,2,2,2,2,2,5,2,2,3,5,1,1,1,1
1,3,3,2,2,2,2,2,5,2,3,3,3,1,1,1,1
1,3,2,2,2,2,2,2,5,5,5,5,5,1,1,1,1
5,3,2,5,5,5,5,5,5,5,5,5,5,1,1,1,1
5,2,2,2,3,5,2,2,2,2,2,5,2,5,1,1,1
5,2,2,2,3,5,2,2,2,2,2,5,2,2,1,1,1
2,2,2,2,3,5,2,2,2,2,2,5,2,2,1,1,1
5,5,5,5,5,5,2,2,2,2,2,5,5,5,1,1,1
5,2,2,2,2,2,5,2,2,2,2,5,5,5,5,5,5
5,2,2,2,2,2,5,5,5,5,5,5,5,5,3,3,5
5,2,2,2,2,2,5,2,2,2,2,2,5,5,5,3,5
5,2,2,2,2,2,5,2,2,2,2,2,5,5,2,3,1
5,2,2,2,2,2,5,2,2,2,2,2,5,2,2,2,1
5,5,5,5,5,5,5,2,2,2,2,2,5,2,2,2,1
5,2,2,2,2,5,5,2,2,2,2,2,5,5,5,5,2
2,2,3,3,3,5,5,5,5,5,5,5,5,5,5,5,2
2,2,3,3,3,5,5,5,5,5,2,2,2,2,2,5,2
5,1,1,2,2,3,3,2,2,5,2,2,2,2,2,5,2
1,1,1,1,1,3,3,2,2,5,2,2,2,2,2,5,2
1,1,1,1,1,3,2,2,2,5,2,2,2,2,2,5,1
1,1,1,1,1,3,2,2,2,5,2,2,2,3,3,5,1
1,1,1,1,5,3,2,2,5,5,5,5,5,5,5,5,1
endlayer

layer
1,2,3,2,2,2,3,3,2,2,1,1,1,1,1,1,1
1,2,5,5,5,5,5,5,5,5,4,1,1,1,1,1,1
1,2,5,2,2,2,2,2,5,2,3,1,1,1,1,1,1
1,2,5,2,2,2,2,2,5,2,2,3,1,1,1,1,1
1,2,5,2,2,2,2,2,5,2,2,3,4,1,1,1,1
1,3,3,2,2,2,2,2,5,2,3,3,3,1,1,1,1
1,3,2,2,2,2,2,2,5,5,5,5,5,1,1,1,1
4,3,2,5,5,5,5,5,5,5,5,5,5,1,1,1,1
6,2,2,2,3,5,2,2,2,2,2,5,2,4,1,1,1
6,2,2,2,3,5,2,2,2,2,2,5,2,2,1,1,1
2,2,2,2,3,5,2,2,2,2,2,5,2,2,1,1,1
5,5,5,5,5,5,2,2,2,2,2,5,5,5,1,1,1
5,2,2,2,2,2,5,2,2,2,2,5,5,5,4,4,7
5,2,2,2,2,2,5,5,5,5,5,5,5,5,3,3,7
5,2,2,2,2,2,5,2,2,2,2,2,5,5,5,3,8
5,2,2,2,2,2,5,2,2,2,2,2,5,5,2,3,1
5,2,2,2,2,2,5,2,2,2,2,2,5,2,2,2,1
5,5,5,5,5,5,5,2,2,2,2,2,5,2,2,2,1
5,2,2,2,2,5,5,2,2,2,2,2,5,5,5,5,2
2,2,3,3,3,5,5,5,5,5,5,5,5,5,5,5,2
2,2,3,3,3,5,5,5,5,5,2,2,2,2,2,5,2
8,1,1,2,2,3,3,2,2,5,2,2,2,2,2,5,2
1,1,1,1,1,3,3,2,2,5,2,2,2,2,2,5,2
1,1,1,1,1,3,2,2,2,5,2,2,2,2,2,5,1
1,1,1,1,1,3,2,2,2,5,2,2,2,3,3,5,1
1,1,1,1,6,3,2,2,5,5,5,5,5,5,5,5,1
endlayer

layer
1,2,3,2,2,3,1,6,3,3,1,1,1,1,1,1,1
1,2,5,5,5,5,5,5,5,5,1,1,1,1,1,1,1
1,2,5,9,0,0,0,0,5,2,4,1,1,1,1,1,1
1,2,5,10,0,0,0,0,5,2,3,3,1,1,1,1,1
1,3,5,2,0,0,0,0,5,2,2,3,1,1,1,1,1
1,3,3,2,0,0,0,0,5,2,3,3,4,1,1,1,1
1,3,2,2,12,0,0,11,5,5,5,5,5,1,1,1,1
1,2,2,5,5,5,5,5,5,5,5,5,5,1,1,1,1
1,8,2,2,3,5,0,0,0,0,0,5,2,1,1,1,1
1,6,2,2,3,5,0,0,0,0,0,5,2,4,1,1,1
2,2,2,2,3,5,0,0,0,0,0,5,2,2,1,1,1
5,5,5,5,5,5,12,0,0,0,0,5,5,5,1,1,1
5,10,0,0,0,0,5,13,0,0,11,5,5,5,1,1,1
5,10,0,0,0,0,5,5,5,5,5,5,5,5,1,1,1
5,14,0,0,0,0,5,10,0,0,0,0,5,5,5,4,1
1,2,0,0,0,15,5,5,0,0,0,0,5,5,2,3,1
4,2,0,0,0,3,5,0,0,0,0,0,5,2,2,2,1
5,5,5,5,5,5,5,0,0,0,0,0,5,2,2,2,1
5,2,2,2,2,5,5,14,0,0,0,0,5,5,5,5,3
3,2,3,3,3,5,5,5,5,12,0,0,3,5,5,5,2
8,2,3,3,3,5,5,5,5,5,2,2,9,9,9,5,2
1,1,1,2,2,3,3,2,2,0,0,0,0,0,0,5,2
1,1,1,1,1,3,3,2,2,0,0,0,0,0,0,5,3
1,1,1,1,1,3,3,2,2,0,0,0,0,0,11,5,1
1,1,1,1,1,3,2,2,2,12,0,0,0,3,3,5,1
1,1,1,1,1,6,2,2,5,5,5,5,5,5,5,7,1
endlayer

layer
1,2,3,2,2,2,1,1,6,3,1,1,1,1,1,1,1
1,2,5,5,5,5,5,5,5,3,1,1,1,1,1,1,1
1,2,5,0,0,0,0,0,5,5,1,1,1,1,1,1,1
1,2,5,0,0,0,0,0,5,2,4,3,1,1,1,1,1
1,3,5,2,0,0,0,0,5,2,16,3,1,1,1,1,1
1,3,16,2,0,0,0,0,5,2,16,3,1,1,1,1,1
1,3,16,2,12,0,0,0,5,5,5,3,4,1,1,1,1
1,8,2,5,5,5,5,5,5,5,5,5,5,1,1,1,1
1,1,8,2,3,5,0,0,0,0,0,5,5,1,1,1,1
1,1,6,2,3,5,0,0,0,0,0,5,2,1,1,1,1
3,3,3,3,3,5,0,0,0,0,0,5,2,4,1,1,1
5,5,5,5,5,5,12,0,0,0,0,5,5,2,1,1,1
5,0,0,0,0,0,5,0,0,0,0,5,5,5,1,1,1
5,0,0,0,0,0,5,5,5,5,5,5,5,5,1,1,1
5,0,0,0,0,0,5,0,0,0,0,0,5,5,2,1,1
1,2,0,0,0,15,5,5,0,0,0,0,5,5,2,4,1
1,2,0,0,0,3,5,0,0,0,0,0,5,2,2,2,1
4,5,5,5,5,5,5,0,0,0,0,0,5,2,2,2,1
5,5,2,2,2,5,5,0,0,0,0,0,5,5,5,2,2
8,6,16,16,3,5,5,5,5,12,0,0,5,5,5,5,2
1,6,3,3,3,3,2,5,5,5,2,2,0,0,0,5,2
1,1,1,3,3,2,16,2,2,0,0,0,0,0,0,5,2
1,1,1,1,1,2,16,2,2,0,0,0,0,0,0,5,3
1,1,1,1,1,2,2,3,2,0,0,0,0,0,0,5,1
1,1,1,1,1,8,8,3,5,12,0,0,0,3,3,5,1
1,1,1,1,1,1,6,3,5,5,5,5,5,5,7,1,1
endlayer

layer
1,4,2,2,3,3,1,1,1,1,1,1,1,1,1,1,1
1,3,5,5,5,5,5,5,5,1,1,1,1,1,1,1,1
1,2,5,17,0,0,0,0,5,4,1,1,1,1,1,1,1
1,2,5,17,0,0,0,0,5,5,1,1,1,1,1,1,1
1,8,5,2,0,0,0,0,5,5,1,1,1,1,1,1,1
1,1,1,2,0,0,0,0,5,5,1,1,1,1,1,1,1
1,1,1,2,12,0,0,0,5,5,7,1,1,1,1,1,1
1,1,1,5,5,5,5,5,5,5,5,5,4,1,1,1,1
1,1,1,3,2,5,0,0,0,0,0,5,5,1,1,1,1
1,1,1,6,3,5,0,0,0,0,0,5,5,1,1,1,1
6,3,3,3,2,5,0,0,0,0,0,5,5,1,1,1,1
5,5,5,5,5,5,12,0,0,0,0,5,5,4,1,1,1
5,17,0,0,0,0,3,18,0,0,0,5,5,2,1,1,1
5,17,0,0,0,0,5,5,5,5,5,5,5,2,1,1,1
5,17,0,0,0,0,5,17,0,0,0,0,5,5,3,1,1
1,2,0,0,0,15,3,5,0,0,0,0,5,5,2,1,1
1,2,0,0,0,3,5,0,0,0,0,0,5,5,2,4,1
1,5,5,5,5,5,5,0,0,0,0,0,5,5,2,3,1
1,6,5,5,5,5,5,0,0,0,0,0,5,5,2,2,3
1,1,1,1,3,2,5,5,5,12,0,0,5,5,5,5,2
1,1,1,1,6,3,2,2,5,5,2,2,19,19,19,5,2
1,1,1,1,1,1,1,2,5,0,0,0,0,0,0,5,2
1,1,1,1,1,1,1,2,5,0,0,0,0,0,0,5,3
1,1,1,1,1,1,1,3,5,0,0,0,0,0,0,5,1
1,1,1,1,1,1,1,8,5,12,0,0,0,3,3,5,1
1,1,1,1,1,1,1,1,2,5,5,5,5,7,1,1,1
endlayer

layer
1,1,2,2,2,2,1,1,1,1,1,1,1,1,1,1,1
1,4,3,5,5,3,5,5,3,1,1,1,1,1,1,1,1
1,2,5,20,20,20,20,20,5,1,1,1,1,1,1,1,1
1,8,5,20,20,20,20,20,5,4,1,1,1,1,1,1,1
1,1,3,5,20,20,20,5,5,5,1,1,1,1,1,1,1
1,1,1,5,20,20,20,5,5,7,1,1,1,1,1,1,1
1,1,1,5,12,20,20,5,5,7,1,1,1,1,1,1,1
1,1,1,5,5,5,5,5,5,5,5,3,1,1,1,1,1
1,1,1,1,6,5,20,20,20,20,20,5,4,1,1,1,1
1,1,1,1,6,5,20,20,20,20,20,5,5,1,1,1,1
1,6,2,2,2,5,20,20,20,20,20,5,5,1,1,1,1
3,5,5,3,5,5,12,20,20,20,20,5,5,1,1,1,1
5,20,20,20,5,5,5,20,20,20,20,20,2,4,1,1,1
5,20,20,20,20,20,5,5,20,20,20,20,3,2,1,1,1
3,20,20,20,20,20,5,5,20,20,20,20,5,2,3,1,1
1,5,20,20,20,15,5,5,20,20,20,20,5,5,3,1,1
1,5,20,20,20,5,20,20,20,20,20,20,5,5,3,1,1
1,5,5,5,5,5,20,20,20,20,20,20,5,5,7,1,1
1,1,6,5,8,2,20,20,20,20,20,20,5,2,2,2,3
1,1,1,1,1,2,3,5,5,12,20,20,5,20,20,3,2
1,1,1,1,1,6,2,2,2,5,5,5,20,20,20,5,2
1,1,1,1,1,1,1,2,5,20,20,20,20,20,20,5,2
1,1,1,1,1,1,1,2,5,20,20,20,20,20,20,3,2
1,1,1,1,1,1,1,8,5,20,20,20,20,5,5,5,1
1,1,1,1,1,1,1,1,2,12,20,20,5,8,5,5,1
1,1,1,1,1,1,1,1,2,3,5,5,3,1,1,1,1
endlayer

layer
1,1,3,2,2,3,1,1,1,1,1,1,1,1,1,1,1
1,1,5,0,0,5,5,5,5,1,1,1,1,1,1,1,1
1,1,21,0,0,0,0,0,6,1,1,1,1,1,1,1,1
1,1,5,0,0,0,0,0,2,1,1,1,1,1,1,1,1
1,1,5,2,0,0,0,2,3,1,1,1,1,1,1,1,1
1,1,1,2,23,0,0,22,1,1,1,1,1,1,1,1,1
1,1,1,2,12,0,0,2,1,1,1,1,1,1,1,1,1
1,1,1,5,5,5,5,5,5,5,5,5,1,1,1,1,1
1,1,1,1,1,5,0,0,0,0,0,5,1,1,1,1,1
1,1,1,1,1,21,0,0,0,0,0,22,1,1,1,1,1
1,1,1,1,1,5,0,0,0,12,0,3,1,1,1,1,1
5,5,24,5,5,3,12,0,3,2,2,3,3,1,1,1,1
5,0,0,0,2,2,2,3,0,25,0,0,2,1,1,1,1
5,0,0,0,0,0,26,2,0,0,0,0,22,1,1,1,1
5,0,0,0,0,0,26,2,0,0,0,0,5,1,1,1,1
1,2,0,0,0,15,5,2,27,0,0,0,3,3,1,1,1
1,2,0,0,0,2,0,0,0,0,0,0,0,6,1,1,1
1,5,3,28,3,5,0,0,0,0,0,0,0,2,1,1,1
1,1,1,1,1,2,0,0,0,0,0,0,0,2,2,2,3
1,1,1,1,1,3,28,3,5,12,0,0,5,9,0,0,3
1,1,1,1,1,1,1,1,2,5,2,2,0,0,0,0,6
1,1,1,1,1,1,1,1,2,0,0,0,0,0,0,0,2
1,1,1,1,1,1,1,1,21,0,0,0,0,0,0,5,3
1,1,1,1,1,1,1,1,2,23,0,0,0,3,28,5,1
1,1,1,1,1,1,1,1,2,12,0,0,2,1,1,1,1
1,1,1,1,1,1,1,1,3,5,5,5,5,1,1,1,1
endlayer

layer
1,1,3,0,2,3,1,1,1,1,1,1,1,1,1,1,1
1,1,3,0,0,5,0,5,3,1,1,1,1,1,1,1,1
1,1,29,0,0,0,0,0,0,1,1,1,1,1,1,1,1
1,1,2,0,0,0,0,0,2,1,1,1,1,1,1,1,1
1,1,5,2,0,0,0,2,3,1,1,1,1,1,1,1,1
1,1,1,2,23,0,0,29,1,1,1,1,1,1,1,1,1
1,1,1,0,0,0,0,2,1,1,1,1,1,1,1,1,1
1,1,1,5,5,2,5,5,5,5,5,3,1,1,1,1,1
1,1,1,1,1,5,0,0,0,0,0,5,1,1,1,1,1
1,1,1,1,1,30,0,0,0,0,0,30,1,1,1,1,1
1,1,1,1,1,5,0,0,0,12,0,3,1,1,1,1,1
3,5,29,5,5,3,0,0,3,2,2,3,3,1,1,1,1
5,0,0,0,2,2,2,3,20,25,0,0,2,1,1,1,1
0,0,0,0,0,0,0,2,20,0,0,0,30,1,1,1,1
5,0,0,0,0,0,0,2,20,0,0,0,5,1,1,1,1
1,2,0,0,0,0,5,2,3,0,0,0,3,3,1,1,1
1,0,0,0,0,2,0,0,0,0,0,0,0,0,1,1,1
1,5,3,30,3,5,0,0,0,0,0,0,0,2,1,1,1
1,1,1,1,1,2,0,0,0,0,0,0,0,2,2,2,3
1,1,1,1,1,3,29,3,5,0,0,0,5,0,0,0,3
1,1,1,1,1,1,1,1,2,5,2,2,0,0,0,0,0
1,1,1,1,1,1,1,1,2,0,0,0,0,0,0,0,2
1,1,1,1,1,1,1,1,29,0,0,0,0,0,0,5,3
1,1,1,1,1,1,1,1,2,23,0,0,0,3,29,2,1
1,1,1,1,1,1,1,1,2,0,0,0,2,1,1,1,1
1,1,1,1,1,1,1,1,3,3,0,3,5,1,1,1,1
endlayer

layer
1,1,3,2,2,3,1,1,1,1,1,1,1,1,1,1,1
1,1,5,0,0,5,5,5,5,1,1,1,1,1,1,1,1
1,1,5,0,0,0,0,0,2,1,1,1,1,1,1,1,1
1,1,5,0,0,0,0,0,2,1,1,1,1,1,1,1,1
1,1,5,2,0,0,0,2,2,1,1,1,1,1,1,1,1
1,1,1,2,0,0,0,2,1,1,1,1,1,1,1,1,1
1,1,1,2,18,18,18,2,1,1,1,1,1,1,1,1,1
1,1,1,5,5,5,5,5,5,5,5,5,1,1,1,1,1
1,1,1,1,20,5,0,0,0,0,31,3,1,1,1,1,1
1,1,1,1,20,5,0,0,0,0,31,3,1,1,1,1,1
1,1,1,1,20,5,0,0,0,0,31,3,1,1,1,1,1
5,5,5,5,5,3,0,0,3,2,2,5,2,1,1,1,1
5,0,0,0,2,2,2,3,32,0,0,0,2,1,1,1,1
5,0,0,0,0,0,31,2,33,0,0,0,5,1,1,1,1
5,0,0,0,0,0,31,2,33,0,0,0,5,1,1,1,1
1,2,0,0,0,0,5,2,3,0,0,0,5,2,1,1,1
1,2,0,0,0,2,0,0,0,0,0,0,0,2,1,1,1
1,5,5,3,5,5,0,0,0,0,0,0,0,2,1,1,1
1,1,1,1,1,2,0,0,0,0,0,0,0,2,3,3,2
1,1,1,1,1,2,5,5,5,0,0,0,5,19,0,0,3
1,1,1,1,1,1,1,1,2,2,2,2,0,0,0,0,2
1,1,1,1,1,1,1,1,2,0,0,0,0,0,0,0,2
1,1,1,1,1,1,1,1,2,0,0,0,0,0,0,5,2
1,1,1,1,1,1,1,1,2,0,0,0,0,3,3,5,1
1,1,1,1,1,1,1,1,2,34,34,34,2,1,1,1,1
1,1,1,1,1,1,1,1,2,5,5,5,5,1,1,1,1
endlayer

layer
1,1,4,4,4,7,1,1,1,1,1,1,1,1,1,1,1
1,1,6,35,35,3,5,5,3,1,1,1,1,1,1,1,1
1,1,6,35,9,36,0,0,2,1,1,1,1,1,1,1,1
1,1,6,35,35,36,0,0,2,1,1,1,1,1,1,1,1
1,1,8,2,37,37,37,2,3,1,1,1,1,1,1,1,1
1,1,1,2,0,0,0,2,34,1,1,1,1,1,1,1,1
1,1,1,2,0,0,0,2,34,1,1,1,1,1,1,1,1
1,1,1,3,5,5,5,5,5,5,5,3,1,1,1,1,1
1,1,1,1,1,5,0,0,27,0,0,5,1,1,1,1,1
1,1,1,1,1,5,0,0,27,0,0,5,1,1,1,1,1
1,1,1,1,1,5,0,0,27,0,0,5,1,1,1,1,1
3,5,5,3,5,2,0,0,3,2,2,5,3,1,1,1,1
5,0,0,0,2,2,2,3,0,0,0,0,2,1,1,1,1
5,0,0,0,36,38,38,3,0,0,0,0,3,1,1,1,1
3,39,39,39,39,38,38,3,0,0,0,0,2,1,1,1,1
1,3,0,0,36,2,5,2,2,37,37,37,2,3,1,1,1
1,2,0,0,36,2,35,35,35,27,0,0,0,2,1,1,1
1,3,5,5,5,5,35,10,35,27,0,0,0,2,1,1,1
1,1,1,1,1,6,35,35,35,27,0,0,0,2,4,4,3
1,1,1,1,1,6,8,8,6,27,0,0,3,35,35,35,7
1,1,1,1,1,1,1,1,3,2,2,2,3,35,9,35,7
1,1,1,1,1,1,1,1,2,0,0,0,2,35,35,35,7
1,1,1,1,1,1,1,1,2,0,0,0,2,35,35,3,3
1,1,1,1,1,1,1,1,2,0,0,0,2,3,8,2,1
1,1,1,1,1,1,1,1,2,0,0,0,2,1,1,1,1
1,1,1,1,1,1,1,1,3,3,5,5,3,1,1,1,1
endlayer

layer
1,1,1,1,1,1,1,1,1,1,1,1,1,1,1,1,1
1,1,1,1,1,40,40,40,40,1,1,1,1,1,1,1,1
1,1,1,1,0,43,42,42,41,1,1,1,1,1,1,1,1
1,1,1,1,1,43,42,42,41,1,1,1,1,1,1,1,1
1,1,1,45,45,45,44,44,41,1,1,1,1,1,1,1,1
1,1,1,45,45,19,45,45,1,1,1,1,1,1,1,1,1
1,1,1,45,45,45,45,45,1,1,1,1,1,1,1,1,1
1,1,1,45,45,3,4,4,3,4,4,7,1,1,1,1,1
1,1,1,1,1,6,35,35,7,45,45,7,1,1,1,1,1
1,1,1,1,1,3,35,35,4,17,45,7,1,1,1,1,1
1,1,1,1,1,3,35,26,3,45,45,7,1,1,1,1,1
6,4,4,4,7,6,35,35,3,8,8,8,1,1,1,1,1
6,34,34,34,4,3,3,3,8,45,45,45,45,1,1,1,1
6,34,18,34,3,42,42,42,7,45,19,45,45,1,1,1,1
6,8,8,8,6,42,42,42,7,45,45,45,45,1,1,1,1
1,1,45,19,45,8,8,8,45,45,45,45,45,1,1,1,1
1,1,45,45,45,1,1,1,1,45,34,34,34,45,1,1,1
1,1,1,1,1,1,1,0,1,45,34,19,34,45,1,1,1
1,1,1,1,1,1,1,1,1,45,34,34,34,45,1,1,1
1,1,1,1,1,1,1,1,1,45,34,34,34,45,1,1,1
1,1,1,1,1,1,1,1,45,3,4,3,45,1,0,1,1
1,1,1,1,1,1,1,1,3,35,35,35,3,1,1,1,1
1,1,1,1,1,1,1,1,6,35,26,35,7,1,1,1,1
1,1,1,1,1,1,1,1,6,35,35,35,7,1,1,1,1
1,1,1,1,1,1,1,1,3,35,35,35,3,1,1,1,1
1,1,1,1,1,1,1,1,45,3,8,3,45,1,1,1,1
endlayer

layer
1,1,1,1,1,1,1,1,1,1,1,1,1,1,1,1,1
1,1,1,1,1,1,1,1,1,1,1,1,1,1,1,1,1
1,1,1,1,0,1,1,1,1,1,1,1,1,1,1,1,1
1,1,1,1,1,1,1,1,1,1,1,1,1,1,1,1,1
1,1,1,1,1,1,1,1,1,1,1,1,1,1,1,1,1
1,1,1,1,1,0,1,1,1,1,1,1,1,1,1,1,1
1,1,1,1,1,1,1,1,1,1,1,1,1,1,1,1,1
1,1,1,1,1,1,1,1,1,1,1,1,1,1,1,1,1
1,1,1,1,1,1,45,45,1,1,1,1,1,1,1,1,1
1,1,1,1,1,1,45,45,1,0,1,1,1,1,1,1,1
1,1,1,1,1,1,45,0,45,1,1,1,1,1,1,1,1
1,1,1,1,1,1,45,45,45,1,1,1,1,1,1,1,1
1,1,1,1,1,1,1,1,1,1,1,1,1,1,1,1,1
1,1,0,1,1,1,1,1,1,1,0,1,1,1,1,1,1
1,1,1,1,1,1,1,1,1,1,1,1,1,1,1,1,1
1,1,1,0,1,1,1,1,1,1,1,1,1,1,1,1,1
1,1,1,1,1,1,1,1,1,1,1,1,1,1,1,1,1
1,1,1,1,1,1,1,0,1,1,1,0,1,1,1,1,1
1,1,1,1,1,1,1,1,1,1,1,1,1,1,1,1,1
1,1,1,1,1,1,1,1,1,1,1,1,1,1,1,1,1
1,1,1,1,1,1,1,1,1,1,1,1,1,1,0,1,1
1,1,1,1,1,1,1,1,1,45,45,45,1,1,1,1,1
1,1,1,1,1,1,1,1,1,45,0,45,1,1,1,1,1
1,1,1,1,1,1,1,1,1,45,1,45,1,1,1,1,1
1,1,1,1,1,1,1,1,1,45,45,45,1,1,1,1,1
1,1,1,1,1,1,1,1,1,1,1,1,1,1,1,1,1
endlayer

