
# Created by Ruins mod version 16.5 Ingame Parser
# authoring Player: lafuller

weight=1
embed_into_distance=5
acceptable_target_blocks=
unacceptable_target_blocks=flowing_water,water,flowing_lava,lava,ice,bedrock,netherrack,nether_brick,nether_brick_fence,soul_sand,quartz_ore,end_stone,obsidian,iron_bars,cloud,flesh,ash_block,slime_grass,slime_congealed,slime_dirt
dimensions=12,20,23
allowable_overhang=0
max_leveling=7
leveling_buffer=-1
preserve_water=0
preserve_lava=0

rule1=0,100,preserveBlock
rule2=0,100,minecraft:sandstone-2
rule3=0,100,minecraft:sandstone-0
rule4=0,100,minecraft:double_stone_slab-9
rule5=0,100,minecraft:sandstone_stairs-0
rule6=0,100,minecraft:sandstone_stairs-2
rule7=0,100,minecraft:sandstone_stairs-1
rule8=0,100,minecraft:sandstone_stairs-3
rule9=0,100,minecraft:wooden_slab-9
rule10=0,100,minecraft:ladder-3
rule11=0,100,bookshelf,pumpkin,melon_block,hay_block,ChestGenHook:chests/spawn_bonus_chest:5-4
rule12=0,100,bookshelf,pumpkin,melon_block,hay_block,ChestGenHook:chests/village_blacksmith:5-5
rule13=0,100,minecraft:spruce_stairs-7
rule14=0,100,minecraft:spruce_stairs-6
rule15=0,100,bookshelf,pumpkin,melon_block,hay_block,ChestGenHook:chests/stronghold_corridor:5-3
rule16=0,100,minecraft:spruce_stairs-5
rule17=0,100,minecraft:stone_slab-1
rule18=0,100,minecraft:spruce_stairs-4
rule19=0,100,minecraft:carpet-8
rule20=0,100,minecraft:carpet-7
rule21=0,100,minecraft:dirt-0
rule22=0,100,minecraft:trapdoor-3
rule23=0,100,minecraft:sandstone_stairs-7
rule24=0,100,minecraft:sandstone_stairs-4
rule25=0,100,minecraft:sandstone_stairs-6
rule26=0,100,minecraft:sandstone_stairs-5
rule27=0,100,minecraft:jungle_door-1
rule28=0,100,minecraft:jungle_door-3
rule29=0,100,minecraft:jungle_door-2
rule30=0,100,minecraft:jungle_door-0
rule31=0,100,minecraft:ladder-2
rule32=0,100,minecraft:jungle_door-9
rule33=0,100,minecraft:jungle_door-8
rule34=0,100,minecraft:wooden_slab-1
rule35=0,100,minecraft:stone_slab-9
rule36=0,100,minecraft:trapdoor-10
rule37=0,100,minecraft:trapdoor-11
rule38=0,100,minecraft:trapdoor-8
rule39=0,100,minecraft:trapdoor-1
rule40=0,100,minecraft:hay_block-0
rule41=0,100,minecraft:trapdoor-2

layer
1,1,3,3,3,3,3,2,1,1,1,1,1,1,1,1,1,1,1,1,1,1,1
1,1,4,4,4,4,4,4,1,1,1,1,1,1,1,1,1,1,1,1,1,1,1
1,1,2,3,3,3,4,3,1,1,1,1,1,1,1,1,1,1,1,1,1,1,1
1,1,2,3,3,3,4,3,1,1,1,1,1,1,1,1,1,1,1,1,1,1,1
4,2,2,3,3,3,4,3,4,1,1,1,1,1,1,1,1,1,1,1,1,1,1
4,3,3,3,3,2,4,3,2,2,2,3,3,3,2,2,3,4,1,1,1,1,1
4,3,3,3,3,2,4,4,4,4,2,2,2,2,3,3,3,3,1,1,1,1,1
4,4,4,4,4,4,4,4,4,4,4,4,2,2,3,4,4,3,3,3,3,3,1
2,4,4,4,4,3,3,3,3,3,4,4,2,2,3,4,4,4,4,4,3,4,1
3,3,2,3,4,3,3,3,3,3,4,4,3,3,3,3,4,3,3,3,3,3,1
3,3,2,3,4,3,3,3,3,3,4,4,4,4,4,4,4,3,3,3,3,3,4
1,3,3,3,4,3,3,3,3,3,4,3,3,3,3,3,4,3,3,3,3,3,4
1,3,4,4,4,3,3,3,3,3,4,3,3,3,3,3,4,3,3,3,3,3,4
1,4,4,4,4,4,4,4,4,4,4,3,3,3,3,3,4,3,3,3,3,3,4
1,1,4,4,4,4,3,3,3,3,3,4,3,3,3,3,4,4,4,4,4,4,4
1,1,4,2,4,4,3,3,3,3,3,4,3,3,3,3,4,3,3,3,3,3,3
1,1,4,2,3,4,3,3,3,3,3,4,4,4,4,4,4,3,3,3,3,3,3
1,1,1,2,3,4,3,3,3,3,3,4,3,3,3,3,3,3,2,2,1,1,1
1,1,1,2,3,4,2,2,2,3,3,4,3,3,3,3,3,3,3,4,1,1,1
1,1,1,2,4,4,4,4,4,4,4,4,3,3,3,3,3,4,1,1,1,1,1
endlayer

layer
1,1,3,3,3,3,3,2,1,1,1,1,1,1,1,1,1,1,1,1,1,1,1
1,1,4,4,4,4,4,4,1,1,1,1,1,1,1,1,1,1,1,1,1,1,1
1,1,2,3,3,3,4,3,1,1,1,1,1,1,1,1,1,1,1,1,1,1,1
1,1,2,3,3,3,4,3,1,1,1,1,1,1,1,1,1,1,1,1,1,1,1
4,2,2,3,3,3,4,3,5,1,1,1,1,1,1,1,1,1,1,1,1,1,1
4,3,3,3,3,2,4,3,2,2,2,3,3,3,2,2,3,6,1,1,1,1,1
4,3,3,3,3,2,4,4,4,4,2,2,2,2,3,3,3,3,1,1,1,1,1
4,4,4,4,4,4,4,4,4,4,4,4,2,2,3,4,4,3,3,3,3,3,1
2,4,4,4,4,3,3,3,3,3,4,4,2,2,3,4,4,4,4,4,3,4,1
3,3,2,3,4,3,3,3,3,3,4,4,3,3,3,3,4,3,3,3,3,3,1
3,3,2,3,4,3,3,3,3,3,4,4,4,4,4,4,4,3,3,3,3,3,4
1,3,3,3,4,3,3,3,3,3,4,3,3,3,3,3,4,3,3,3,3,3,4
1,3,4,4,4,3,3,3,3,3,4,3,3,3,3,3,4,3,3,3,3,3,4
1,7,4,4,4,4,4,4,4,4,4,3,3,3,3,3,4,3,3,3,3,3,4
1,1,4,4,4,4,3,3,3,3,3,4,3,3,3,3,4,4,4,4,4,4,4
1,1,8,2,4,4,3,3,3,3,3,4,3,3,3,3,4,3,3,3,3,3,3
1,1,7,2,3,4,3,3,3,3,3,4,4,4,4,4,4,3,3,3,3,3,3
1,1,1,2,3,4,3,3,3,3,3,4,3,3,3,3,3,3,2,2,1,1,1
1,1,1,2,3,4,2,2,2,3,3,4,3,3,3,3,3,3,3,7,1,1,1
1,1,1,2,4,4,4,4,4,4,4,4,3,3,3,3,3,6,1,1,1,1,1
endlayer

layer
1,1,3,3,3,3,3,2,1,1,1,1,1,1,1,1,1,1,1,1,1,1,1
1,1,4,4,4,4,4,4,1,1,1,1,1,1,1,1,1,1,1,1,1,1,1
1,1,2,9,9,9,4,3,1,1,1,1,1,1,1,1,1,1,1,1,1,1,1
1,1,2,0,0,0,4,3,1,1,1,1,1,1,1,1,1,1,1,1,1,1,1
4,2,0,0,0,10,4,3,1,1,1,1,1,1,1,1,1,1,1,1,1,1,1
4,0,0,0,0,2,4,3,1,8,3,3,3,3,2,3,6,1,1,1,1,1,1
4,0,0,0,11,2,4,4,4,4,2,2,2,2,3,3,3,3,1,1,1,1,1
4,4,4,4,4,4,4,4,4,4,4,4,2,2,3,4,4,3,3,3,3,3,1
2,4,4,4,4,2,2,6,0,0,4,4,2,2,3,4,4,4,4,4,3,4,1
3,3,2,3,4,0,0,0,0,0,4,4,3,3,3,3,3,14,9,13,12,3,1
2,3,2,3,4,0,0,0,0,0,4,4,4,4,4,4,3,0,0,0,0,3,4
1,3,3,3,4,0,0,0,0,0,4,3,0,0,0,15,4,0,0,0,0,10,4
1,7,4,4,4,11,0,0,0,0,4,3,0,0,0,0,4,0,0,0,0,0,4
1,1,4,4,4,4,4,4,4,4,4,3,17,0,0,16,4,0,0,0,0,0,4
1,1,4,4,4,4,0,0,0,0,10,4,0,0,0,9,4,4,4,4,4,4,4
1,1,1,1,4,4,0,0,0,0,0,4,0,0,0,18,4,3,3,3,3,3,3
1,1,1,1,3,4,0,0,0,0,0,4,4,4,4,4,4,3,3,2,3,3,3
1,1,1,5,3,4,0,0,0,0,0,4,3,3,3,3,3,3,2,7,1,1,1
1,1,1,2,3,4,2,2,2,11,0,4,3,3,3,3,3,3,3,1,1,1,1
1,1,1,2,4,4,6,1,4,4,4,4,3,3,3,3,6,1,1,1,1,1,1
endlayer

layer
1,1,3,3,3,3,3,2,1,1,1,1,1,1,1,1,1,1,1,1,1,1,1
1,1,4,4,4,4,4,4,1,1,1,1,1,1,1,1,1,1,1,1,1,1,1
1,1,2,20,20,19,4,4,1,1,1,1,1,1,1,1,1,1,1,1,1,1,1
1,1,2,0,0,0,4,3,1,1,1,1,1,1,1,1,1,1,1,1,1,1,1
4,2,0,0,0,10,4,3,1,1,1,1,1,1,1,1,1,1,1,1,1,1,1
4,0,0,0,0,2,4,3,1,1,8,2,3,3,3,6,1,1,1,1,1,1,1
4,0,0,0,0,2,4,4,4,2,2,2,21,2,3,3,3,3,1,1,1,1,1
4,4,4,4,4,4,4,4,4,4,4,2,21,2,3,3,4,4,3,3,3,4,1
2,2,4,4,4,2,6,0,0,0,4,4,2,2,3,4,4,4,4,4,3,4,1
2,3,2,3,4,0,0,0,0,0,4,4,3,3,3,3,3,19,20,20,0,3,1
2,3,2,3,4,0,0,0,0,0,4,4,0,0,0,4,3,0,0,0,0,3,4
1,7,3,3,4,0,0,0,0,0,4,3,0,0,0,0,4,0,0,0,0,10,4
1,1,3,4,4,0,0,0,0,0,4,7,0,0,0,0,4,0,0,0,0,0,4
1,1,3,4,4,4,4,4,4,4,4,0,0,0,0,20,4,0,0,0,0,0,4
1,1,3,4,4,4,0,0,0,0,10,4,0,0,0,20,4,2,4,4,4,4,4
1,1,1,1,4,4,0,0,0,0,0,4,0,0,0,19,4,3,3,3,3,3,3
1,1,1,1,3,4,0,0,0,0,0,4,4,4,4,4,4,3,3,1,8,3,3
1,1,1,1,3,4,0,0,0,0,0,4,2,2,2,2,2,2,2,1,1,1,1
1,1,1,5,4,4,2,2,2,0,0,4,2,21,21,2,2,2,3,1,1,1,1
1,1,1,2,2,6,1,1,4,4,4,4,2,2,2,6,1,1,1,1,1,1,1
endlayer

layer
1,1,3,3,3,3,3,2,1,1,1,1,1,1,1,1,1,1,1,1,1,1,1
1,1,4,20,20,19,4,2,1,1,1,1,1,1,1,1,1,1,1,1,1,1,1
1,1,2,0,0,0,4,4,1,1,1,1,1,1,1,1,1,1,1,1,1,1,1
1,1,2,0,0,0,4,4,1,1,1,1,1,1,1,1,1,1,1,1,1,1,1
4,2,0,0,0,10,4,4,1,1,1,1,1,1,1,1,1,1,1,1,1,1,1
4,0,0,0,0,2,21,4,1,1,1,1,8,2,6,1,1,1,1,1,1,1,1
4,0,0,0,0,2,21,4,6,1,1,1,1,2,3,3,3,3,1,1,1,1,1
4,4,4,4,4,4,4,4,4,4,4,5,1,2,3,3,3,4,4,4,4,4,1
2,2,2,4,4,6,0,0,0,0,4,2,2,2,3,3,0,0,0,0,0,4,1
2,21,2,4,0,0,0,0,0,0,4,4,4,4,4,3,0,0,0,0,0,3,1
2,7,2,4,0,0,0,0,0,0,4,2,22,22,22,4,0,0,0,0,0,3,4
1,1,3,4,0,0,0,0,0,0,4,7,0,0,0,0,4,0,0,0,0,10,4
1,1,3,4,0,0,0,0,0,0,4,0,0,0,0,0,4,0,0,0,0,0,4
1,1,3,3,4,4,4,4,4,4,3,0,0,0,0,0,4,0,0,0,0,0,4
1,1,3,3,4,4,0,0,0,0,10,4,0,0,0,0,4,2,4,4,4,4,4
1,1,1,1,4,4,0,0,0,0,0,4,0,0,0,0,4,2,3,3,3,3,2
1,1,1,1,4,4,0,0,0,0,0,4,4,4,4,4,4,3,3,1,1,8,2
1,1,1,1,4,4,0,0,0,0,0,4,2,2,2,2,2,2,2,1,1,1,1
1,1,1,1,7,4,2,2,2,0,0,4,2,1,1,1,1,8,2,1,1,1,1
1,1,1,1,1,1,1,1,4,4,4,4,6,1,1,1,1,1,1,1,1,1,1
endlayer

layer
1,1,3,3,3,3,3,1,1,1,1,1,1,1,1,1,1,1,1,1,1,1,1
1,1,4,9,9,9,2,5,1,1,1,1,1,1,1,1,1,1,1,1,1,1,1
1,1,4,9,9,9,4,2,1,1,1,1,1,1,1,1,1,1,1,1,1,1,1
1,1,4,9,9,9,4,4,1,1,1,1,1,1,1,1,1,1,1,1,1,1,1
2,4,9,9,9,10,4,7,1,1,1,1,1,1,1,1,1,1,1,1,1,1,1
4,16,16,16,16,4,1,1,1,1,1,1,1,1,1,1,1,1,1,1,1,1,1
4,9,9,9,9,4,1,1,1,1,1,1,1,5,3,3,3,3,1,1,1,1,1
2,4,4,4,4,4,4,4,4,4,6,1,1,2,3,3,3,3,4,4,4,3,1
7,8,2,3,6,0,0,0,23,4,4,5,2,2,3,9,9,9,9,9,9,4,1
1,1,7,4,9,9,9,9,9,9,4,3,4,4,4,9,9,9,9,9,9,4,1
1,1,8,4,16,16,16,16,16,16,4,7,9,14,9,4,9,9,9,9,9,4,4
1,1,3,4,9,9,9,24,24,24,4,0,9,14,9,9,4,24,9,9,9,10,2
1,1,3,9,9,9,23,4,4,4,4,0,9,14,9,9,9,2,25,9,9,9,4
1,1,3,9,9,9,4,16,16,14,4,0,9,14,9,9,9,2,25,9,9,9,4
1,1,3,3,3,4,26,14,9,14,10,4,9,14,9,9,9,2,4,2,4,4,2
1,1,1,1,4,4,9,14,9,14,9,4,24,25,24,9,9,2,3,3,3,6,1
1,1,1,1,4,4,9,14,9,14,9,4,21,21,21,4,2,3,3,1,1,1,1
1,1,1,1,7,4,9,14,9,14,9,4,3,3,3,3,3,6,1,1,1,1,1
1,1,1,1,1,4,4,4,4,4,4,4,7,1,1,1,1,1,1,1,1,1,1
1,1,1,1,1,1,1,1,2,4,4,2,1,1,1,1,1,1,1,1,1,1,1
endlayer

layer
1,1,2,3,3,3,2,1,1,1,1,1,1,1,1,1,1,1,1,1,1,1,1
1,1,4,0,0,0,4,1,1,1,1,1,1,1,1,1,1,1,1,1,1,1,1
1,1,3,0,0,0,27,1,1,1,1,1,1,1,1,1,1,1,1,1,1,1,1
1,1,3,0,0,0,2,1,1,1,1,1,1,1,1,1,1,1,1,1,1,1,1
4,2,0,0,0,10,3,1,1,1,1,1,1,1,1,1,1,1,1,1,1,1,1
4,0,0,0,0,3,1,1,1,1,1,1,1,1,1,1,1,1,1,1,1,1,1
4,0,0,0,0,3,1,1,1,1,1,1,1,1,2,3,3,2,1,1,1,1,1
4,29,4,4,4,4,4,4,1,1,1,1,1,1,28,0,0,0,3,3,3,2,1
1,1,1,3,0,0,0,0,3,30,4,1,1,1,3,0,0,0,0,0,0,3,1
1,1,1,28,0,0,0,0,0,0,4,3,30,3,3,0,0,0,0,0,0,3,1
1,1,1,3,0,0,0,0,0,0,4,0,0,0,0,4,0,0,0,0,0,3,4
1,1,2,3,0,0,0,3,3,3,4,0,0,0,0,0,3,3,0,0,0,10,4
1,1,3,0,0,10,3,9,9,9,4,0,0,0,0,0,0,0,3,31,0,0,4
1,1,3,0,0,0,3,0,0,0,4,0,0,0,0,0,0,0,3,0,0,0,4
1,1,2,3,3,4,3,0,0,0,10,4,0,0,0,0,0,0,4,4,29,4,4
1,1,1,1,1,2,0,0,0,0,0,4,3,3,3,0,0,0,3,1,1,1,1
1,1,1,1,1,28,0,0,0,0,0,4,1,1,1,4,29,3,2,1,1,1,1
1,1,1,1,1,2,0,0,0,0,0,27,1,1,1,1,1,1,1,1,1,1,1
1,1,1,1,1,4,3,3,0,0,0,4,1,1,1,1,1,1,1,1,1,1,1
1,1,1,1,1,1,1,1,4,4,4,4,1,1,1,1,1,1,1,1,1,1,1
endlayer

layer
1,1,2,3,0,3,2,1,1,1,1,1,1,1,1,1,1,1,1,1,1,1,1
1,1,3,0,0,0,2,1,1,1,1,1,1,1,1,1,1,1,1,1,1,1,1
1,1,0,0,0,0,32,1,1,1,1,1,1,1,1,1,1,1,1,1,1,1,1
1,1,3,0,0,0,2,1,1,1,1,1,1,1,1,1,1,1,1,1,1,1,1
4,2,0,0,0,0,3,1,1,1,1,1,1,1,1,1,1,1,1,1,1,1,1
0,0,0,0,0,3,1,1,1,1,1,1,1,1,1,1,1,1,1,1,1,1,1
4,0,0,0,0,3,1,1,1,1,1,1,1,1,2,3,0,2,1,1,1,1,1
2,33,2,4,4,4,4,4,1,1,1,1,1,1,32,0,0,0,3,0,3,2,1
1,1,1,3,0,0,0,0,3,33,4,1,1,1,3,0,0,0,0,0,0,0,1
1,1,1,33,0,0,0,0,0,0,4,3,33,3,3,0,0,0,0,0,0,3,1
1,1,1,3,0,0,0,0,0,0,4,0,0,0,0,4,0,0,0,0,0,3,3
1,1,2,3,0,0,0,3,3,3,4,0,0,0,0,0,3,3,0,0,0,0,4
1,1,0,0,0,10,3,20,20,19,4,0,0,0,0,0,0,0,3,31,0,0,0
1,1,2,9,9,9,3,0,0,0,4,0,0,0,0,0,0,0,3,0,0,0,4
1,1,2,3,3,4,3,0,0,0,0,4,0,0,0,0,0,0,3,4,33,4,2
1,1,1,1,1,2,0,0,0,0,0,4,3,0,3,0,0,0,3,1,1,1,1
1,1,1,1,1,33,0,0,0,0,0,4,1,1,1,4,33,3,2,1,1,1,1
1,1,1,1,1,2,0,0,0,0,0,32,1,1,1,1,1,1,1,1,1,1,1
1,1,1,1,1,4,0,3,0,0,0,4,1,1,1,1,1,1,1,1,1,1,1
1,1,1,1,1,1,1,1,4,0,4,2,1,1,1,1,1,1,1,1,1,1,1
endlayer

layer
1,1,3,3,3,3,3,1,1,1,1,1,1,1,1,1,1,1,1,1,1,1,1
1,1,4,0,0,0,4,1,1,1,1,1,1,1,1,1,1,1,1,1,1,1,1
1,1,3,0,0,0,4,1,1,1,1,1,1,1,1,1,1,1,1,1,1,1,1
1,1,3,0,0,0,4,1,1,1,1,1,1,1,1,1,1,1,1,1,1,1,1
4,2,0,0,0,0,2,1,1,1,1,1,1,1,1,1,1,1,1,1,1,1,1
4,0,0,0,0,3,1,1,1,1,1,1,1,1,1,1,1,1,1,1,1,1,1
4,0,0,0,0,3,1,1,1,1,1,1,1,1,3,3,3,3,1,1,1,1,1
4,4,4,4,4,4,4,4,9,9,9,9,9,9,2,0,0,0,3,3,3,3,1
1,1,9,3,0,0,0,0,2,2,4,9,9,9,3,0,0,0,0,0,0,3,1
1,1,9,3,0,0,0,0,0,0,4,3,2,2,3,0,0,0,0,0,0,3,1
1,1,9,3,0,0,0,0,0,0,4,0,0,0,0,4,0,0,0,0,0,3,4
1,1,3,3,0,0,0,3,3,3,4,0,0,0,0,0,3,3,0,0,0,0,4
1,1,2,0,0,0,3,0,0,0,4,0,0,0,0,0,0,0,3,0,0,0,4
1,1,3,19,20,20,3,0,0,0,4,0,0,0,0,0,0,0,3,34,34,34,4
1,1,3,3,3,4,3,0,0,0,0,4,0,0,0,0,0,0,4,4,4,4,4
1,1,1,1,1,4,0,0,0,0,0,4,3,3,3,0,0,0,3,1,1,1,1
1,1,1,1,1,2,0,0,0,0,0,4,1,1,1,4,4,3,3,1,1,1,1
1,1,1,1,1,4,0,0,0,0,0,4,1,1,1,1,1,1,1,1,1,1,1
1,1,1,1,1,4,3,3,0,0,0,4,1,1,1,1,1,1,1,1,1,1,1
1,1,1,1,1,1,1,1,4,4,4,4,1,1,1,1,1,1,1,1,1,1,1
endlayer

layer
1,1,2,3,3,3,2,1,1,1,1,1,1,1,1,1,1,1,1,1,1,1,1
1,1,4,0,0,0,2,1,1,1,1,1,1,1,1,1,1,1,1,1,1,1,1
1,1,3,0,0,0,4,1,1,1,1,1,1,1,1,1,1,1,1,1,1,1,1
1,1,3,0,0,0,4,1,1,1,1,1,1,1,1,1,1,1,1,1,1,1,1
5,5,26,26,26,26,4,1,1,1,1,1,1,1,1,1,1,1,1,1,1,1,1
8,35,35,36,35,3,1,1,1,1,1,1,1,1,1,1,1,1,1,1,1,1,1
8,35,35,35,35,3,1,1,1,1,1,1,1,1,2,3,3,2,1,1,1,1,1
7,7,7,4,4,4,4,4,1,1,1,1,1,1,3,0,0,25,3,3,3,2,1
1,1,1,3,0,0,0,23,3,3,2,1,1,1,3,0,0,25,35,35,35,3,1
1,1,1,3,0,0,0,23,9,9,4,5,5,5,3,0,0,25,35,36,35,3,1
1,1,1,3,0,0,0,23,9,9,4,35,37,35,35,3,24,25,24,24,24,3,4
1,1,2,3,24,24,24,3,3,3,4,35,35,35,35,25,3,3,25,0,0,0,2
1,1,3,0,0,0,3,0,0,0,4,26,26,26,26,25,35,35,3,0,0,0,4
1,1,3,0,0,0,3,0,0,0,4,0,0,0,0,25,38,35,3,0,0,0,4
1,1,2,3,3,3,3,26,25,26,26,4,0,0,0,25,35,35,4,2,4,4,2
1,1,1,1,1,8,35,35,25,0,0,4,3,3,2,25,35,35,6,1,1,1,1
1,1,1,1,1,8,36,35,25,0,0,4,1,1,1,8,7,7,7,1,1,1,1
1,1,1,1,1,8,35,35,25,0,0,4,1,1,1,1,1,1,1,1,1,1,1
1,1,1,1,1,8,7,7,25,0,0,4,1,1,1,1,1,1,1,1,1,1,1
1,1,1,1,1,1,1,1,2,2,4,2,1,1,1,1,1,1,1,1,1,1,1
endlayer

layer
1,1,17,2,5,2,17,1,1,1,1,1,1,1,1,1,1,1,1,1,1,1,1
1,1,2,9,9,9,2,1,1,1,1,1,1,1,1,1,1,1,1,1,1,1,1
1,1,8,9,37,9,6,1,1,1,1,1,1,1,1,1,1,1,1,1,1,1,1
1,1,2,9,9,9,2,1,1,1,1,1,1,1,1,1,1,1,1,1,1,1,1
1,1,17,2,7,2,17,1,1,1,1,1,1,1,1,1,1,1,1,1,1,1,1
1,1,1,0,1,1,1,1,1,1,1,1,1,1,1,1,1,1,1,1,1,1,1
1,1,1,1,1,1,1,1,1,1,1,1,1,1,17,17,17,17,1,1,1,1,1
1,1,1,17,5,2,5,17,1,1,1,1,1,1,17,17,17,17,1,1,1,1,1
1,1,1,8,0,0,0,6,1,1,1,1,1,1,17,17,39,17,1,1,1,1,1
1,1,1,2,0,0,0,2,1,1,1,1,1,1,17,17,17,17,1,0,1,1,1
1,1,1,8,0,0,0,6,1,1,1,1,0,1,1,17,17,17,2,5,5,5,2
1,1,1,5,2,2,7,17,17,17,17,1,1,1,1,17,1,1,8,40,40,40,6
1,1,8,2,36,2,6,17,17,17,17,5,5,5,5,5,1,1,8,40,37,40,6
1,1,8,2,2,2,6,17,39,17,17,8,34,22,34,6,0,1,8,40,40,40,6
1,1,1,7,7,7,17,17,17,17,17,8,34,34,34,6,1,1,2,7,7,7,2
1,1,1,1,1,1,1,1,17,5,5,8,7,7,7,7,1,1,1,1,1,1,1
1,1,1,1,1,1,0,1,2,35,35,2,1,1,1,1,1,1,1,1,1,1,1
1,1,1,1,1,1,1,1,2,38,35,2,1,1,1,1,1,1,1,1,1,1,1
1,1,1,1,1,1,1,1,2,35,35,2,1,1,1,1,1,1,1,1,1,1,1
1,1,1,1,1,1,1,1,17,7,7,17,1,1,1,1,1,1,1,1,1,1,1
endlayer

layer
1,1,1,1,1,1,1,1,1,1,1,1,1,1,1,1,1,1,1,1,1,1,1
1,1,1,1,1,1,1,1,1,1,1,1,1,1,1,1,1,1,1,1,1,1,1
1,1,1,1,0,1,1,1,1,1,1,1,1,1,1,1,1,1,1,1,1,1,1
1,1,1,1,1,1,1,1,1,1,1,1,1,1,1,1,1,1,1,1,1,1,1
1,1,1,1,1,1,1,1,1,1,1,1,1,1,1,1,1,1,1,1,1,1,1
1,1,1,0,1,1,1,1,1,1,1,1,1,1,1,1,1,1,1,1,1,1,1
1,1,1,1,1,1,1,1,1,1,1,1,1,1,1,1,1,1,1,1,1,1,1
1,1,1,1,1,17,1,1,1,1,1,1,1,1,1,1,1,1,1,1,1,1,1
1,1,1,1,17,17,17,1,1,1,1,1,1,1,1,1,0,1,1,1,1,1,1
1,1,1,17,17,41,17,17,1,1,1,1,1,1,1,1,1,1,1,0,1,1,1
1,1,1,1,17,17,17,1,1,1,1,1,0,1,1,1,1,1,1,1,1,1,1
1,1,1,1,1,17,1,1,1,1,1,1,1,1,1,1,1,1,1,1,1,1,1
1,1,1,1,0,1,1,1,1,1,1,1,1,1,1,1,1,1,1,1,0,1,1
1,1,1,1,1,1,1,1,0,1,1,1,1,0,1,1,0,1,1,1,1,1,1
1,1,1,1,1,1,1,1,1,1,1,1,1,1,1,1,1,1,1,1,1,1,1
1,1,1,1,1,1,1,1,1,1,1,1,1,1,1,1,1,1,1,1,1,1,1
1,1,1,1,1,1,0,1,1,1,1,1,1,1,1,1,1,1,1,1,1,1,1
1,1,1,1,1,1,1,1,1,0,1,1,1,1,1,1,1,1,1,1,1,1,1
1,1,1,1,1,1,1,1,1,1,1,1,1,1,1,1,1,1,1,1,1,1,1
1,1,1,1,1,1,1,1,1,1,1,1,1,1,1,1,1,1,1,1,1,1,1
endlayer

