
# Created by Ruins mod version 16.7 Ingame Parser
# authoring Player: lafuller

weight=1
embed_into_distance=0
random_height_offset=50,100
acceptable_target_blocks=grass,sand,dirt,stone,water,flowing_water
unacceptable_target_blocks=flowing_lava,lava,gravel,bedrock,netherrack,nether_brick,nether_brick_fence,soul_sand,quartz_ore,end_stone,obsidian,iron_bars,cloud,flesh,ash_block,slime_grass,slime_congealed,slime_dirt
dimensions=20,19,19
allowable_overhang=0
max_leveling=20
leveling_buffer=-1
preserve_water=0
preserve_lava=0

rule1=0,100,preserveBlock
rule2=0,100,minecraft:wool-0
rule3=0,100,minecraft:wooden_slab-9
rule4=0,100,minecraft:spruce_stairs-6
rule5=0,100,minecraft:planks-1
rule6=0,100,minecraft:spruce_stairs-4
rule7=0,100,minecraft:wooden_slab-1
rule8=0,100,minecraft:spruce_stairs-3
rule9=0,100,minecraft:spruce_stairs-1
rule10=0,100,minecraft:spruce_stairs-7
rule11=0,100,minecraft:spruce_stairs-5
rule12=0,100,minecraft:dark_oak_stairs-2
rule13=0,100,minecraft:wooden_slab-13
rule14=0,100,minecraft:dark_oak_stairs-7
rule15=0,100,minecraft:dark_oak_stairs-0
rule16=0,100,minecraft:dark_oak_stairs-5
rule17=0,100,minecraft:spruce_stairs-2
rule18=0,100,minecraft:spruce_stairs-0
rule19=0,100,minecraft:dark_oak_stairs-6
rule20=0,100,minecraft:dark_oak_stairs-1
rule21=0,100,minecraft:dark_oak_fence-0
rule22=0,100,minecraft:trapdoor-2

layer
1,1,1,1,1,1,1,1,1,1,1,1,1,1,1,1,1,1,1
1,1,1,1,1,1,1,1,1,1,1,1,1,1,1,1,1,1,1
1,1,1,1,1,1,1,1,1,1,1,1,1,1,1,1,1,1,1
1,1,1,1,1,1,1,1,1,1,1,1,1,1,1,1,1,1,1
1,1,1,1,1,1,1,1,1,1,1,1,1,1,1,1,1,1,1
1,1,2,2,1,1,1,1,1,1,1,1,1,1,1,1,1,1,1
1,1,1,2,2,1,1,1,1,1,1,1,1,1,1,1,1,1,1
1,1,1,5,4,3,1,1,1,1,1,1,1,1,1,1,1,1,1
1,1,1,1,1,1,1,1,1,1,1,1,1,1,1,1,1,1,1
1,1,1,1,1,1,1,1,1,1,1,1,1,1,1,1,1,1,1
1,1,1,1,1,1,1,1,1,1,1,1,1,1,1,1,1,1,1
1,1,1,1,1,1,1,1,1,1,1,1,1,1,1,1,1,1,1
1,1,1,1,1,1,1,1,1,1,1,1,1,1,1,1,1,1,1
1,1,1,1,1,1,1,1,1,1,1,3,1,1,1,1,1,1,1
1,1,1,1,1,1,1,1,1,1,1,6,2,1,1,1,1,1,1
1,1,1,1,1,1,1,1,1,1,1,5,2,2,1,1,1,1,1
1,1,1,1,1,1,1,1,1,1,1,1,1,2,1,1,1,1,1
1,1,1,1,1,1,1,1,1,1,1,1,1,1,1,1,1,1,1
1,1,1,1,1,1,1,1,1,1,1,1,1,1,1,1,1,1,1
endlayer

layer
1,1,1,1,1,1,1,1,1,1,1,1,1,1,1,1,1,1,1
1,1,1,1,1,1,1,1,1,1,1,1,1,1,1,1,1,1,1
1,1,1,1,1,1,1,1,1,1,1,1,1,1,1,1,1,1,1
1,2,2,2,1,1,1,1,1,1,1,1,1,1,1,1,1,1,1
1,1,2,2,2,2,1,1,1,1,1,1,1,1,1,1,1,1,1
1,1,1,1,2,2,2,1,1,1,1,1,1,1,1,1,1,1,1
1,1,1,1,1,2,5,3,1,1,1,1,1,1,1,1,1,1,1
1,1,1,1,1,1,1,1,1,1,1,1,1,1,1,1,1,1,1
1,1,1,1,1,1,1,1,1,1,1,1,1,1,1,1,1,1,1
1,1,1,1,1,1,1,1,1,1,1,1,1,1,1,1,1,1,1
1,1,1,1,1,1,1,1,1,1,1,1,1,1,1,1,1,1,1
1,1,1,1,1,1,1,1,1,1,1,1,3,2,1,1,1,1,1
1,1,1,1,1,1,1,1,1,1,1,1,5,2,2,1,1,1,1
1,1,1,1,1,1,1,1,1,1,1,1,2,2,2,2,1,1,1
1,1,1,1,1,1,1,1,1,1,1,1,1,2,2,2,1,1,1
1,1,1,1,1,1,1,1,1,1,1,1,1,1,2,2,1,1,1
1,1,1,1,1,1,1,1,1,1,1,1,1,1,2,2,1,1,1
1,1,1,1,1,1,1,1,1,1,1,1,1,1,1,2,1,1,1
1,1,1,1,1,1,1,1,1,1,1,1,1,1,1,1,1,1,1
endlayer

layer
1,1,1,1,1,1,1,1,1,1,1,1,1,1,1,1,1,1,1
1,1,1,1,1,1,1,1,1,1,1,1,1,1,1,1,1,1,1
1,1,2,2,1,1,1,1,1,1,1,1,1,1,1,1,1,1,1
1,1,1,1,2,2,1,1,1,1,1,1,1,1,1,1,1,1,1
1,1,1,1,1,1,2,2,1,1,1,1,1,1,1,1,1,1,1
1,1,1,1,1,1,2,2,5,3,1,1,1,1,1,1,1,1,1
1,1,1,1,1,1,1,1,1,1,1,1,1,1,1,1,1,1,1
1,1,1,1,1,1,1,1,1,1,1,1,1,1,1,1,1,1,1
1,1,1,1,1,1,1,1,1,1,1,1,1,1,1,1,1,1,1
1,1,1,1,1,1,1,1,1,1,1,1,1,3,1,1,1,1,1
1,1,1,1,1,1,1,1,1,1,1,1,1,5,2,1,1,1,1
1,1,1,1,1,1,1,1,1,1,1,1,1,2,2,2,1,1,1
1,1,1,1,1,1,1,1,1,1,1,1,1,1,2,2,1,1,1
1,1,1,1,1,1,1,1,1,1,1,1,1,1,1,2,2,1,1
1,1,1,1,1,1,1,1,1,1,1,1,1,1,1,1,2,1,1
1,1,1,1,1,1,1,1,1,1,1,1,1,1,1,1,2,1,1
1,1,1,1,1,1,1,1,1,1,1,1,1,1,1,1,2,1,1
1,1,1,1,1,1,1,1,1,1,1,1,1,1,1,1,1,1,1
1,1,1,1,1,1,1,1,1,1,1,1,1,1,1,1,1,1,1
endlayer

layer
1,1,1,1,1,1,1,1,1,1,1,1,1,1,1,1,1,1,1
1,2,2,2,1,1,1,1,1,1,1,1,1,1,1,1,1,1,1
1,1,1,1,2,2,1,1,1,1,1,1,1,1,1,1,1,1,1
1,1,1,1,1,1,2,2,2,1,1,1,1,1,1,1,1,1,1
1,1,1,1,1,1,1,1,2,2,5,1,1,1,1,1,1,1,1
1,1,1,1,1,1,1,1,1,1,1,1,1,1,1,1,1,1,1
1,1,1,1,1,1,1,1,1,1,1,1,1,1,1,1,1,1,1
1,1,1,1,1,1,1,1,1,1,1,1,1,1,1,1,1,1,1
1,1,1,1,1,1,1,1,1,1,1,1,1,1,5,1,1,1,1
1,1,1,1,1,1,1,1,1,1,1,1,1,1,2,2,1,1,1
1,1,1,1,1,1,1,1,1,1,1,1,1,1,1,2,1,1,1
1,1,1,1,1,1,1,1,1,1,1,1,1,1,1,1,2,1,1
1,1,1,1,1,1,1,1,1,1,1,1,1,1,1,1,2,2,1
1,1,1,1,1,1,1,1,1,1,1,1,1,1,1,1,1,2,1
1,1,1,1,1,1,1,1,1,1,1,1,1,1,1,1,1,2,1
1,1,1,1,1,1,1,1,1,1,1,1,1,1,1,1,1,2,1
1,1,1,1,1,1,1,1,1,1,1,1,1,1,1,1,1,2,1
1,1,1,1,1,1,1,1,1,1,1,1,1,1,1,1,1,2,1
1,1,1,1,1,1,1,1,1,1,1,1,1,1,1,1,1,1,1
endlayer

layer
1,1,2,1,1,1,1,1,1,1,1,1,1,1,1,1,1,1,1
1,1,1,2,2,1,1,1,1,1,1,1,1,1,1,1,1,1,1
1,1,1,1,1,2,2,2,1,1,1,1,1,1,1,1,1,1,1
1,1,1,1,1,1,1,1,2,2,1,1,1,1,1,1,1,1,1
1,1,1,1,1,1,1,1,1,1,2,5,1,1,1,1,1,1,1
1,1,1,1,1,1,1,1,1,1,1,1,1,1,1,1,1,1,1
1,1,1,1,1,1,1,1,1,1,1,1,1,1,1,1,1,1,1
1,1,1,1,1,1,1,1,1,1,1,1,1,1,5,1,1,1,1
1,1,1,1,1,1,1,1,1,1,1,1,1,1,1,2,1,1,1
1,1,1,1,1,1,1,1,1,1,1,1,1,1,1,2,1,1,1
1,1,1,1,1,1,1,1,1,1,1,1,1,1,1,1,2,1,1
1,1,1,1,1,1,1,1,1,1,1,1,1,1,1,1,1,2,1
1,1,1,1,1,1,1,1,1,1,1,1,1,1,1,1,1,1,2
1,1,1,1,1,1,1,1,1,1,1,1,1,1,1,1,1,1,2
1,1,1,1,1,1,1,1,1,1,1,1,1,1,1,1,1,1,2
1,1,1,1,1,1,1,1,1,1,1,1,1,1,1,1,1,1,2
1,1,1,1,1,1,1,1,1,1,1,1,1,1,1,1,1,1,2
1,1,1,1,1,1,1,1,1,1,1,1,1,1,1,1,1,1,1
1,1,1,1,1,1,1,1,1,1,1,1,1,1,1,1,1,1,1
endlayer

layer
1,2,2,2,1,1,1,1,1,1,1,1,1,1,1,1,1,1,1
1,1,1,1,2,2,1,1,1,1,1,1,1,1,1,1,1,1,1
1,1,1,1,1,1,2,2,2,1,1,1,1,1,1,1,1,1,1
1,1,1,1,1,1,1,1,1,2,2,2,5,1,1,1,1,1,1
1,1,1,1,1,1,1,1,1,1,1,1,1,1,1,1,1,1,1
1,1,1,1,1,1,1,1,1,1,1,1,1,1,1,1,1,1,1
1,1,1,1,1,1,1,1,1,1,1,1,1,1,1,5,1,1,1
1,1,1,1,1,1,1,1,1,1,1,1,1,1,1,2,1,1,1
1,1,1,1,1,1,1,1,1,1,1,1,1,1,1,2,1,1,1
1,1,1,1,1,1,1,1,1,1,1,1,1,1,1,1,2,1,1
1,1,1,1,1,1,1,1,1,1,1,1,1,1,1,1,1,2,1
1,1,1,1,1,1,1,1,1,1,1,1,1,1,1,1,1,1,2
1,1,1,1,1,1,1,1,1,1,1,1,1,1,1,1,1,1,2
1,1,1,1,1,1,1,1,1,1,1,1,1,1,1,1,1,1,2
1,1,1,1,1,1,1,1,1,1,1,1,1,1,1,1,1,1,2
1,1,1,1,1,1,1,1,1,1,1,1,1,1,1,1,1,1,2
1,1,1,1,1,1,1,1,1,1,1,1,1,1,1,1,1,1,2
1,3,1,1,1,1,1,1,1,1,1,1,1,1,1,1,1,1,2
5,1,1,1,1,1,1,1,1,1,1,1,1,1,1,1,1,1,1
endlayer

layer
1,7,7,5,5,1,1,1,1,1,1,1,1,1,1,1,1,1,1
1,1,1,1,1,2,2,1,1,1,1,1,1,1,1,1,1,1,1
1,1,1,1,1,1,1,2,2,2,2,1,1,1,1,1,1,1,1
1,1,1,1,1,1,1,1,1,1,2,2,5,1,1,1,1,1,1
1,1,1,1,1,1,1,1,1,1,1,1,1,1,1,1,1,1,1
1,1,1,1,1,1,1,1,1,1,1,1,1,1,1,1,1,1,1
1,1,1,1,1,1,1,1,1,1,1,1,1,1,1,5,1,1,1
1,1,1,1,1,1,1,1,1,1,1,1,1,1,1,2,1,1,1
1,1,1,1,1,1,1,1,1,1,1,1,1,1,1,1,2,1,1
1,1,1,1,1,1,1,1,1,1,1,1,1,1,1,1,2,1,1
1,1,1,1,1,1,1,1,1,1,1,1,1,1,1,1,1,2,1
1,1,1,1,1,1,1,1,1,1,1,1,1,1,1,1,1,2,1
1,1,1,1,1,1,1,1,1,1,1,1,1,1,1,1,1,1,2
1,1,1,1,1,1,1,1,1,1,1,1,1,1,1,1,1,1,2
1,1,1,1,1,1,1,1,1,1,1,1,1,1,1,1,1,1,5
1,1,1,3,1,1,1,1,1,1,1,1,1,1,1,1,1,1,5
1,1,5,1,1,1,1,1,1,1,1,1,1,1,1,1,1,1,7
1,2,1,1,1,1,1,1,1,1,1,1,1,1,1,1,1,1,7
2,1,1,1,1,1,1,1,1,1,1,1,1,1,1,1,1,1,1
endlayer

layer
1,1,1,1,1,1,1,1,1,1,1,1,1,1,1,1,1,1,1
1,1,1,1,1,7,8,5,1,1,1,1,1,1,1,1,1,1,1
1,1,1,1,1,1,1,1,2,2,2,2,1,1,1,1,1,1,1
1,1,1,1,1,1,1,1,1,1,1,2,2,5,1,1,1,1,1
1,1,1,1,1,1,1,1,1,1,1,1,5,1,1,1,1,1,1
1,1,1,1,1,1,1,1,1,1,1,3,1,1,1,5,1,1,1
1,1,1,1,1,1,1,1,1,1,3,1,1,1,5,2,1,1,1
1,1,1,1,1,1,1,1,1,1,1,1,1,3,1,1,2,1,1
1,1,1,1,1,1,1,1,1,1,1,1,3,1,1,1,2,1,1
1,1,1,1,1,1,1,1,1,1,1,1,1,1,1,1,2,1,1
1,1,1,1,1,1,1,1,1,1,1,1,1,1,1,1,2,1,1
1,1,1,1,1,1,1,1,1,1,1,1,1,1,1,1,1,5,1
1,1,1,1,1,1,1,1,1,1,1,1,1,1,1,1,1,9,1
1,1,1,1,1,1,1,1,1,1,1,1,1,1,1,1,1,7,1
1,1,1,1,5,1,1,1,1,1,1,1,1,1,1,1,1,1,1
1,1,1,2,1,1,1,1,1,1,1,1,1,1,1,1,1,1,1
1,2,2,1,1,1,1,1,1,1,1,1,1,1,1,1,1,1,1
1,2,1,1,1,1,1,1,1,1,1,1,1,1,1,1,1,1,1
1,1,1,1,1,1,1,1,1,1,1,1,1,1,1,1,1,1,1
endlayer

layer
1,1,1,1,1,1,1,1,1,1,1,1,1,1,1,1,1,1,1
1,1,1,1,1,1,1,1,1,1,1,1,1,1,1,1,1,1,1
1,1,1,1,1,1,1,1,7,8,5,2,2,1,1,1,1,1,1
1,1,1,1,1,1,1,1,1,1,1,1,2,5,5,1,1,1,1
1,1,1,1,1,1,1,1,1,1,1,10,5,1,1,5,1,1,1
1,1,1,1,1,1,1,1,1,1,10,5,1,1,1,5,1,1,1
1,1,1,1,1,1,1,1,1,1,5,1,1,1,5,5,2,1,1
1,1,1,1,1,1,1,1,1,5,1,1,1,5,11,1,2,1,1
1,1,1,1,1,1,1,1,5,1,1,1,5,11,1,1,5,1,1
1,1,1,1,1,1,1,10,1,1,1,5,1,1,1,1,9,1,1
1,1,1,1,1,1,1,3,1,1,5,1,1,1,1,1,7,1,1
1,1,1,1,1,1,1,1,3,11,1,1,1,1,1,1,1,1,1
1,1,1,1,1,1,1,1,1,1,1,1,1,1,1,1,1,1,1
1,1,1,1,1,5,1,1,1,1,1,1,1,1,1,1,1,1,1
1,1,1,1,2,1,1,1,1,1,1,1,1,1,1,1,1,1,1
1,1,2,2,1,1,1,1,1,1,1,1,1,1,1,1,1,1,1
1,1,2,1,1,1,1,1,1,1,1,1,1,1,1,1,1,1,1
1,1,2,1,1,1,1,1,1,1,1,1,1,1,1,1,1,1,1
1,1,1,1,1,1,1,1,1,1,1,1,1,1,1,1,1,1,1
endlayer

layer
1,1,1,1,1,1,1,1,1,1,1,1,1,1,1,1,1,1,1
1,1,1,1,1,1,1,1,1,1,1,1,1,1,1,1,1,1,1
1,1,1,1,1,1,1,1,1,1,1,8,5,5,5,1,1,1,1
1,1,1,1,1,1,1,1,1,1,1,1,5,5,5,5,1,1,1
1,1,1,1,1,1,1,1,1,1,1,5,5,5,5,5,5,1,1
1,1,1,1,1,1,1,1,1,1,5,5,5,5,5,5,5,1,1
1,1,1,1,1,1,1,1,1,10,5,5,5,5,5,5,5,1,1
1,1,1,1,1,1,1,1,10,5,5,5,5,5,5,1,9,1,1
1,1,1,1,1,1,1,10,5,5,5,5,5,5,1,1,1,1,1
1,1,1,1,1,1,1,5,5,5,5,5,11,1,1,1,1,1,1
1,1,1,1,1,1,10,5,5,5,5,11,1,1,1,1,1,1,1
1,1,1,1,1,1,5,5,5,5,11,1,1,1,1,1,1,1,1
1,1,1,1,1,5,5,5,11,1,1,1,1,1,1,1,1,1,1
1,1,1,1,1,2,5,1,1,1,1,1,1,1,1,1,1,1,1
1,1,1,2,2,1,1,1,1,1,1,1,1,1,1,1,1,1,1
1,1,1,2,2,1,1,1,1,1,1,1,1,1,1,1,1,1,1
1,1,2,2,1,1,1,1,1,1,1,1,1,1,1,1,1,1,1
1,1,1,1,1,1,1,1,1,1,1,1,1,1,1,1,1,1,1
1,1,1,1,1,1,1,1,1,1,1,1,1,1,1,1,1,1,1
endlayer

layer
1,1,1,1,1,1,1,1,1,1,1,1,1,1,1,1,1,1,1
1,1,1,1,1,1,1,1,1,1,1,1,1,1,1,1,1,1,1
1,1,1,1,1,1,1,1,1,1,1,1,5,0,0,1,1,1,1
1,1,1,1,1,1,1,1,1,1,1,13,12,0,5,5,1,1,1
1,1,1,1,1,1,1,1,1,1,13,0,0,0,0,5,0,1,1
1,1,1,1,1,1,1,1,1,14,0,0,0,0,0,0,0,1,1
1,1,1,1,1,1,1,1,13,0,0,0,0,0,0,15,5,1,1
1,1,1,1,1,1,1,14,0,0,0,0,0,0,0,13,1,1,1
1,1,1,1,1,1,1,0,0,0,0,0,0,0,13,1,1,1,1
1,1,1,1,1,1,10,18,17,0,0,0,0,16,1,1,1,1,1
1,1,1,1,1,1,5,5,5,5,0,0,13,1,1,1,1,1,1
1,1,1,1,1,1,5,5,5,5,19,13,1,1,1,1,1,1,1
1,1,1,1,1,1,5,5,5,11,1,1,1,1,1,1,1,1,1
1,1,1,1,2,2,1,1,1,1,1,1,1,1,1,1,1,1,1
1,1,1,1,2,2,1,1,1,1,1,1,1,1,1,1,1,1,1
1,1,1,2,1,1,1,1,1,1,1,1,1,1,1,1,1,1,1
1,2,2,1,1,1,1,1,1,1,1,1,1,1,1,1,1,1,1
1,1,1,1,1,1,1,1,1,1,1,1,1,1,1,1,1,1,1
1,1,1,1,1,1,1,1,1,1,1,1,1,1,1,1,1,1,1
endlayer

layer
1,1,1,1,1,1,1,1,1,1,1,1,1,1,1,1,1,1,1
1,1,1,1,1,1,1,1,1,1,1,1,1,1,1,1,1,1,1
1,1,1,1,1,1,1,1,1,1,1,5,0,0,0,1,1,1,1
1,1,1,1,1,1,1,1,1,1,1,0,5,5,5,0,1,1,1
1,1,1,1,1,1,1,1,1,1,0,0,0,0,0,5,0,1,1
1,1,1,1,1,1,1,1,1,0,0,0,0,0,0,5,0,1,1
1,1,1,1,1,1,1,1,0,0,0,0,0,0,0,5,0,1,1
1,1,1,1,1,1,1,0,0,0,0,0,0,0,0,0,5,1,1
1,1,1,1,1,1,15,0,0,0,0,0,0,0,0,1,1,1,1
1,1,1,1,1,1,20,0,0,0,0,0,0,0,1,1,1,1,1
1,1,1,1,1,1,18,18,8,5,0,0,0,1,1,1,1,1,1
1,1,1,1,1,1,5,5,5,5,0,0,1,1,1,1,1,1,1
1,1,1,1,1,2,5,5,5,5,1,1,1,1,1,1,1,1,1
1,1,1,1,1,2,1,1,1,1,1,1,1,1,1,1,1,1,1
1,1,1,1,2,2,1,1,1,1,1,1,1,1,1,1,1,1,1
1,1,2,2,2,1,1,1,1,1,1,1,1,1,1,1,1,1,1
1,1,2,1,1,1,1,1,1,1,1,1,1,1,1,1,1,1,1
1,1,1,1,1,1,1,1,1,1,1,1,1,1,1,1,1,1,1
1,1,1,1,1,1,1,1,1,1,1,1,1,1,1,1,1,1,1
endlayer

layer
1,1,1,1,1,1,1,1,1,1,1,1,1,1,1,1,1,1,1
1,1,1,1,1,1,1,1,1,1,1,1,1,1,1,1,1,1,1
1,1,1,1,1,1,1,1,1,5,5,5,0,0,1,1,1,1,1
1,1,1,1,1,1,1,1,1,1,1,0,0,0,0,0,1,1,1
1,1,1,1,1,1,1,1,1,1,0,0,0,0,5,0,1,1,1
1,1,1,1,1,1,1,1,1,0,0,0,0,0,0,0,0,1,1
1,1,1,1,1,1,1,1,0,0,0,0,0,0,0,0,0,1,1
1,1,1,1,1,1,1,0,0,0,0,0,0,0,0,0,5,1,1
1,1,1,1,1,1,1,0,0,0,0,0,0,0,0,1,5,1,1
1,1,1,1,1,1,16,0,0,0,0,0,0,0,1,1,5,1,1
1,1,1,1,1,1,13,0,0,21,0,0,0,1,1,1,1,1,1
1,1,1,1,1,1,13,0,0,0,0,0,1,1,1,1,1,1,1
1,1,1,1,1,1,5,13,13,14,1,1,1,1,1,1,1,1,1
1,1,1,1,2,2,1,1,1,1,1,1,1,1,1,1,1,1,1
1,1,1,2,2,1,1,1,1,1,1,1,1,1,1,1,1,1,1
1,1,1,2,2,1,1,1,1,1,1,1,1,1,1,1,1,1,1
1,1,2,1,1,1,1,1,1,1,1,1,1,1,1,1,1,1,1
1,1,2,1,1,1,1,1,1,1,1,1,1,1,1,1,1,1,1
1,1,1,1,1,1,1,1,1,1,1,1,1,1,1,1,1,1,1
endlayer

layer
1,1,1,1,1,1,1,1,1,1,1,1,1,1,1,1,1,1,1
1,1,1,1,1,3,3,5,5,1,1,1,1,1,1,1,1,1,1
1,1,1,1,1,1,1,1,1,2,5,1,1,1,1,1,1,1,1
1,1,1,1,1,1,1,1,1,1,1,0,0,0,0,1,1,1,1
1,1,1,1,1,1,1,1,1,1,0,0,0,0,5,0,1,1,1
1,1,1,1,1,1,1,1,1,0,0,0,0,0,0,0,1,1,1
1,1,1,1,1,1,1,1,0,0,0,0,0,0,0,0,1,1,1
1,1,1,1,1,1,1,0,0,0,0,0,0,0,0,0,1,1,1
1,1,1,1,1,1,1,0,0,0,0,0,0,0,0,1,5,1,1
1,1,1,1,1,1,0,0,0,0,0,0,0,0,1,1,2,1,1
1,1,1,1,1,1,0,0,0,22,0,0,0,1,1,1,1,5,1
1,1,1,1,1,1,0,0,0,0,0,0,1,1,1,1,1,5,1
1,1,1,1,1,1,0,0,0,0,1,1,1,1,1,1,1,3,1
1,1,1,1,1,5,1,1,1,1,1,1,1,1,1,1,1,3,1
1,1,1,1,2,1,1,1,1,1,1,1,1,1,1,1,1,1,1
1,1,2,2,1,1,1,1,1,1,1,1,1,1,1,1,1,1,1
1,1,2,2,1,1,1,1,1,1,1,1,1,1,1,1,1,1,1
1,2,1,1,1,1,1,1,1,1,1,1,1,1,1,1,1,1,1
1,1,1,1,1,1,1,1,1,1,1,1,1,1,1,1,1,1,1
endlayer

layer
3,3,3,5,5,1,1,1,1,1,1,1,1,1,1,1,1,1,1
1,1,1,1,2,2,2,1,1,1,1,1,1,1,1,1,1,1,1
1,1,1,1,1,1,1,2,2,2,5,1,1,1,1,1,1,1,1
1,1,1,1,1,1,1,1,1,1,1,1,1,1,1,1,1,1,1
1,1,1,1,1,1,1,1,1,1,1,0,0,0,0,1,1,1,1
1,1,1,1,1,1,1,1,1,1,0,0,0,5,0,1,1,1,1
1,1,1,1,1,1,1,1,1,0,0,0,0,0,0,1,1,1,1
1,1,1,1,1,1,1,1,0,0,0,0,0,0,0,1,1,1,1
1,1,1,1,1,1,1,0,0,0,0,0,0,0,1,1,5,1,1
1,1,1,1,1,1,0,0,0,0,0,0,0,1,1,1,2,1,1
1,1,1,1,1,1,0,0,0,0,0,0,1,1,1,1,1,2,1
1,1,1,1,1,1,0,0,0,0,0,1,1,1,1,1,1,2,1
1,1,1,1,1,1,0,0,0,0,1,1,1,1,1,1,1,2,1
1,1,1,1,1,1,1,1,1,1,1,1,1,1,1,1,1,2,1
1,1,1,1,5,1,1,1,1,1,1,1,1,1,1,1,1,1,5
1,1,1,2,1,1,1,1,1,1,1,1,1,1,1,1,1,1,5
1,2,2,1,1,1,1,1,1,1,1,1,1,1,1,1,1,1,3
2,2,2,1,1,1,1,1,1,1,1,1,1,1,1,1,1,1,3
1,1,1,1,1,1,1,1,1,1,1,1,1,1,1,1,1,1,3
endlayer

layer
2,2,2,2,1,1,1,1,1,1,1,1,1,1,1,1,1,1,1
1,1,1,1,2,1,1,1,1,1,1,1,1,1,1,1,1,1,1
1,1,1,1,1,2,2,2,2,1,1,1,1,1,1,1,1,1,1
1,1,1,1,1,1,1,1,1,5,1,1,1,1,1,1,1,1,1
1,1,1,1,1,1,1,1,1,1,1,1,1,1,1,1,1,1,1
1,1,1,1,1,1,1,1,1,1,1,0,0,5,1,1,1,1,1
1,1,1,1,1,1,1,1,1,1,0,0,0,0,1,1,1,1,1
1,1,1,1,1,1,1,1,1,0,0,0,0,0,1,1,1,1,1
1,1,1,1,1,1,1,1,0,0,0,0,0,1,1,1,1,1,1
1,1,1,1,1,1,1,0,0,0,0,0,1,1,1,5,1,1,1
1,1,1,1,1,1,1,0,0,0,0,1,1,1,1,2,2,1,1
1,1,1,1,1,1,1,0,0,0,1,1,1,1,1,1,2,2,1
1,1,1,1,1,1,1,1,1,1,1,1,1,1,1,1,1,2,1
1,1,1,1,1,1,1,1,1,1,1,1,1,1,1,1,1,2,1
1,1,1,1,1,1,1,1,1,1,1,1,1,1,1,1,1,2,1
1,1,1,7,1,1,1,1,1,1,1,1,1,1,1,1,1,2,2
1,1,5,1,1,1,1,1,1,1,1,1,1,1,1,1,1,1,2
1,2,1,1,1,1,1,1,1,1,1,1,1,1,1,1,1,1,2
2,1,1,1,1,1,1,1,1,1,1,1,1,1,1,1,1,1,2
endlayer

layer
1,1,1,1,1,1,1,1,1,1,1,1,1,1,1,1,1,1,1
1,2,2,2,2,1,1,1,1,1,1,1,1,1,1,1,1,1,1
1,1,2,2,2,1,1,1,1,1,1,1,1,1,1,1,1,1,1
1,1,1,1,1,2,2,2,5,1,1,1,1,1,1,1,1,1,1
1,1,1,1,1,1,1,1,1,1,1,1,1,1,1,1,1,1,1
1,1,1,1,1,1,1,1,1,1,1,1,1,1,1,1,1,1,1
1,1,1,1,1,1,1,1,1,1,1,0,5,1,1,1,1,1,1
1,1,1,1,1,1,1,1,1,1,0,0,0,1,1,1,1,1,1
1,1,1,1,1,1,1,1,1,0,0,0,1,1,1,1,1,1,1
1,1,1,1,1,1,1,1,0,0,0,1,1,1,1,1,1,1,1
1,1,1,1,1,1,1,1,0,0,1,1,1,1,1,5,1,1,1
1,1,1,1,1,1,1,1,1,1,1,1,1,1,1,2,2,1,1
1,1,1,1,1,1,1,1,1,1,1,1,1,1,1,1,2,2,1
1,1,1,1,1,1,1,1,1,1,1,1,1,1,1,1,1,2,1
1,1,1,1,1,1,1,1,1,1,1,1,1,1,1,1,1,2,1
1,1,1,1,1,1,1,1,1,1,1,1,1,1,1,1,1,2,1
1,1,1,1,1,1,1,1,1,1,1,1,1,1,1,1,1,2,1
1,7,1,1,1,1,1,1,1,1,1,1,1,1,1,1,1,2,1
5,1,1,1,1,1,1,1,1,1,1,1,1,1,1,1,1,1,1
endlayer

layer
1,1,1,1,1,1,1,1,1,1,1,1,1,1,1,1,1,1,1
1,1,1,1,1,1,1,1,1,1,1,1,1,1,1,1,1,1,1
1,1,1,1,1,1,1,1,1,1,1,1,1,1,1,1,1,1,1
1,2,2,2,2,1,1,1,1,1,1,1,1,1,1,1,1,1,1
1,1,1,1,2,2,2,5,1,1,1,1,1,1,1,1,1,1,1
1,1,1,1,1,1,1,1,1,1,1,1,1,1,1,1,1,1,1
1,1,1,1,1,1,1,1,1,1,1,1,5,1,1,1,1,1,1
1,1,1,1,1,1,1,1,1,1,1,1,1,1,1,1,1,1,1
1,1,1,1,1,1,1,1,1,1,1,1,1,1,1,1,1,1,1
1,1,1,1,1,1,1,1,1,1,1,1,1,1,1,1,1,1,1
1,1,1,1,1,1,1,1,1,1,1,1,1,1,1,1,1,1,1
1,1,1,1,1,1,1,1,1,1,1,1,1,1,5,1,1,1,1
1,1,1,1,1,1,1,1,1,1,1,1,1,1,2,2,1,1,1
1,1,1,1,1,1,1,1,1,1,1,1,1,1,2,2,2,1,1
1,1,1,1,1,1,1,1,1,1,1,1,1,1,1,2,2,1,1
1,1,1,1,1,1,1,1,1,1,1,1,1,1,1,2,2,1,1
1,1,1,1,1,1,1,1,1,1,1,1,1,1,1,2,2,1,1
1,1,1,1,1,1,1,1,1,1,1,1,1,1,1,2,1,1,1
1,1,1,1,1,1,1,1,1,1,1,1,1,1,1,1,1,1,1
endlayer

layer
1,1,1,1,1,1,1,1,1,1,1,1,1,1,1,1,1,1,1
1,1,1,1,1,1,1,1,1,1,1,1,1,1,1,1,1,1,1
1,1,1,1,1,1,1,1,1,1,1,1,1,1,1,1,1,1,1
1,1,1,1,1,1,1,1,1,1,1,1,1,1,1,1,1,1,1
1,1,2,2,1,1,1,1,1,1,1,1,1,1,1,1,1,1,1
1,2,2,2,2,2,7,1,1,1,1,1,1,1,1,1,1,1,1
1,1,1,1,2,5,1,1,1,1,1,1,1,1,1,1,1,1,1
1,1,1,1,1,1,1,1,1,1,1,5,1,1,1,1,1,1,1
1,1,1,1,1,1,1,1,1,1,1,1,1,1,1,1,1,1,1
1,1,1,1,1,1,1,1,1,1,1,1,1,1,1,1,1,1,1
1,1,1,1,1,1,1,1,1,1,1,1,1,1,1,1,1,1,1
1,1,1,1,1,1,1,1,1,1,1,1,1,1,1,1,1,1,1
1,1,1,1,1,1,1,1,1,1,1,1,1,7,1,1,1,1,1
1,1,1,1,1,1,1,1,1,1,1,1,5,2,1,1,1,1,1
1,1,1,1,1,1,1,1,1,1,1,1,2,2,2,1,1,1,1
1,1,1,1,1,1,1,1,1,1,1,1,1,2,2,1,1,1,1
1,1,1,1,1,1,1,1,1,1,1,1,1,2,2,1,1,1,1
1,1,1,1,1,1,1,1,1,1,1,1,1,2,1,1,1,1,1
1,1,1,1,1,1,1,1,1,1,1,1,1,1,1,1,1,1,1
endlayer

layer
1,1,1,1,1,1,1,1,1,1,1,1,1,1,1,1,1,1,1
1,1,1,1,1,1,1,1,1,1,1,1,1,1,1,1,1,1,1
1,1,1,1,1,1,1,1,1,1,1,1,1,1,1,1,1,1,1
1,1,1,1,1,1,1,1,1,1,1,1,1,1,1,1,1,1,1
1,1,1,1,1,1,1,1,1,1,1,1,1,1,1,1,1,1,1
1,1,1,1,1,1,1,1,1,1,1,1,1,1,1,1,1,1,1
1,1,2,2,1,1,1,1,1,1,1,1,1,1,1,1,1,1,1
1,1,1,2,7,1,1,1,1,1,1,1,1,1,1,1,1,1,1
1,1,1,5,1,1,1,1,1,1,5,1,1,1,1,1,1,1,1
1,1,1,1,1,1,1,1,1,1,1,1,1,1,1,1,1,1,1
1,1,1,1,1,1,1,1,1,1,1,1,1,1,1,1,1,1,1
1,1,1,1,1,1,1,1,1,1,1,1,1,1,1,1,1,1,1
1,1,1,1,1,1,1,1,1,1,1,1,1,1,1,1,1,1,1
1,1,1,1,1,1,1,1,1,1,1,1,1,1,1,1,1,1,1
1,1,1,1,1,1,1,1,1,1,1,7,1,1,1,1,1,1,1
1,1,1,1,1,1,1,1,1,1,5,2,2,1,1,1,1,1,1
1,1,1,1,1,1,1,1,1,1,1,1,2,1,1,1,1,1,1
1,1,1,1,1,1,1,1,1,1,1,1,1,1,1,1,1,1,1
1,1,1,1,1,1,1,1,1,1,1,1,1,1,1,1,1,1,1
endlayer

