
# Created by Ruins mod version 16.5 Ingame Parser
# authoring Player: lafuller

weight=1
embed_into_distance=5
acceptable_target_blocks=
unacceptable_target_blocks=flowing_water,water,flowing_lava,lava,ice,bedrock,netherrack,nether_brick,nether_brick_fence,soul_sand,quartz_ore,end_stone,obsidian,iron_bars,cloud,flesh,ash_block,slime_grass,slime_congealed,slime_dirt
dimensions=12,17,23
allowable_overhang=0
max_leveling=7
leveling_buffer=-1
preserve_water=0
preserve_lava=0

rule1=0,100,preserveBlock
rule2=0,100,minecraft:sandstone-2
rule3=0,100,minecraft:sandstone-0
rule4=0,100,minecraft:double_stone_slab-9
rule5=0,100,minecraft:sandstone_stairs-2
rule6=0,100,minecraft:sandstone_stairs-0
rule7=0,100,minecraft:sandstone_stairs-1
rule8=0,100,minecraft:trapdoor-11
rule9=0,100,bookshelf,pumpkin,melon_block,hay_block,ChestGenHook:chests/spawn_bonus_chest:5-5
rule10=0,100,minecraft:stone_slab-1
rule11=0,100,minecraft:trapdoor-8
rule12=0,100,bookshelf,pumpkin,melon_block,hay_block,ChestGenHook:chests/stronghold_library:5-2
rule13=0,100,minecraft:trapdoor-10
rule14=0,100,minecraft:wooden_slab-9
rule15=0,100,minecraft:sandstone_stairs-3
rule16=0,100,minecraft:carpet-8
rule17=0,100,minecraft:carpet-7
rule18=0,100,minecraft:spruce_stairs-6
rule19=0,100,minecraft:trapdoor-3
rule20=0,100,minecraft:sandstone_stairs-4
rule21=0,100,minecraft:trapdoor-2
rule22=0,100,minecraft:spruce_stairs-3
rule23=0,100,minecraft:stone_slab-9
rule24=0,100,minecraft:jungle_door-1
rule25=0,100,minecraft:ladder-4
rule26=0,100,minecraft:sandstone_stairs-7
rule27=0,100,minecraft:jungle_door-0
rule28=0,100,minecraft:jungle_door-2
rule29=0,100,minecraft:ladder-3
rule30=0,100,minecraft:jungle_door-3
rule31=0,100,minecraft:jungle_door-9
rule32=0,100,minecraft:jungle_door-8
rule33=0,100,minecraft:hay_block-0
rule34=0,100,minecraft:sandstone_stairs-6
rule35=0,100,minecraft:wooden_slab-1
rule36=0,100,minecraft:trapdoor-1
rule37=0,100,minecraft:trapdoor-9

layer
1,1,1,1,1,1,1,1,1,1,1,1,1,4,4,4,3,3,2,2,1,1,1
1,1,1,1,1,1,1,1,3,4,3,3,3,3,3,3,3,3,2,4,1,1,1
1,1,1,3,2,2,4,1,3,4,3,3,3,3,3,3,3,3,2,2,4,2,4
1,1,1,4,3,3,3,3,3,4,3,3,3,3,3,3,3,4,2,2,2,2,2
1,1,4,3,4,4,4,4,4,4,3,3,3,3,3,4,2,2,3,2,2,2,2
1,1,3,3,3,3,3,3,3,4,3,3,3,3,3,4,3,3,3,3,3,4,4
1,1,4,3,3,3,3,3,3,4,4,4,4,4,4,4,3,3,3,3,3,4,4
1,1,3,3,3,3,3,3,3,4,4,4,4,4,4,4,3,3,3,3,3,4,4
1,1,3,4,3,3,3,3,3,4,4,4,4,4,4,4,3,3,3,3,3,4,4
1,1,3,4,3,3,3,3,3,4,4,2,3,4,4,4,4,4,4,4,4,4,4
3,3,3,4,3,3,3,3,4,4,4,4,4,1,1,1,1,3,3,3,3,4,4
4,3,4,3,3,3,3,3,3,4,4,1,1,1,1,1,1,3,3,3,3,4,1
4,3,3,2,2,2,2,2,2,4,4,1,1,1,1,1,1,1,1,1,1,1,1
4,3,3,3,3,3,3,3,3,4,4,1,1,1,1,1,1,1,1,1,1,1,1
4,3,3,3,3,3,3,3,3,3,3,1,1,1,1,1,1,1,1,1,1,1,1
4,3,3,3,3,3,3,3,3,3,3,1,1,1,1,1,1,1,1,1,1,1,1
1,1,1,1,4,4,4,4,4,4,3,1,1,1,1,1,1,1,1,1,1,1,1
endlayer

layer
1,1,1,1,1,1,1,1,1,1,1,1,1,4,4,4,3,3,2,2,1,1,1
1,1,1,1,1,1,1,1,3,4,3,3,3,3,3,3,3,3,2,4,1,1,1
1,1,1,3,2,2,5,1,3,4,3,3,3,3,3,3,3,3,2,2,4,2,5
1,1,1,4,3,3,3,3,3,4,3,3,3,3,3,3,3,4,2,2,2,2,2
1,1,6,3,4,4,4,4,4,4,3,3,3,3,3,4,2,2,3,2,2,2,2
1,1,3,3,3,3,3,3,3,4,3,3,3,3,3,4,3,3,3,3,3,4,4
1,1,4,3,3,3,3,3,3,4,4,4,4,4,4,4,3,3,3,3,3,4,4
1,1,3,3,3,3,3,3,3,4,4,4,4,4,4,4,3,3,3,3,3,4,4
1,1,3,4,3,3,3,3,3,4,4,4,4,4,4,4,3,3,3,3,3,4,4
1,1,3,4,3,3,3,3,3,4,4,2,3,4,4,4,4,4,4,4,4,4,4
3,3,3,4,3,3,3,3,4,4,4,7,7,1,1,1,1,3,3,3,3,4,4
4,3,4,3,3,3,3,3,3,4,4,1,1,1,1,1,1,3,3,3,3,5,1
4,3,3,2,2,2,2,2,2,4,4,1,1,1,1,1,1,1,1,1,1,1,1
4,3,3,3,3,3,3,3,3,4,4,1,1,1,1,1,1,1,1,1,1,1,1
4,3,3,3,3,3,3,3,3,3,3,1,1,1,1,1,1,1,1,1,1,1,1
4,3,3,3,3,3,3,3,3,3,3,1,1,1,1,1,1,1,1,1,1,1,1
1,1,1,1,4,4,4,4,4,4,3,1,1,1,1,1,1,1,1,1,1,1,1
endlayer

layer
1,1,1,1,1,1,1,1,1,1,1,1,1,4,4,4,3,3,2,2,1,1,1
1,1,1,1,1,1,1,1,3,4,3,3,3,3,9,8,8,3,2,4,1,1,1
1,1,1,3,3,5,1,1,3,2,2,2,2,0,0,0,0,3,2,2,4,5,1
1,1,1,3,3,3,3,3,3,4,10,0,0,0,0,0,0,4,2,2,2,2,2
1,1,1,3,4,3,3,3,3,4,0,0,0,0,0,0,2,2,3,2,2,2,2
1,1,6,3,3,11,0,0,10,4,0,0,0,0,0,4,8,8,9,3,3,4,4
1,1,4,3,3,0,0,0,0,4,4,4,4,4,4,4,0,0,0,0,0,3,4
1,1,4,2,12,0,0,0,0,4,4,4,4,4,4,4,0,0,0,0,0,3,4
1,1,3,4,0,0,0,0,3,4,3,3,3,4,4,4,0,0,0,0,0,3,4
1,1,3,4,0,0,0,0,3,4,3,7,7,3,4,4,4,4,0,0,10,3,4
3,3,3,4,0,0,0,13,4,4,4,1,1,1,1,1,1,2,3,3,3,4,2
3,3,4,3,3,3,3,3,3,4,4,1,1,1,1,1,1,2,3,3,5,1,1
4,11,0,0,0,0,0,0,14,4,4,1,1,1,1,1,1,1,1,1,1,1,1
4,11,0,0,0,0,0,0,14,4,4,1,1,1,1,1,1,1,1,1,1,1,1
2,12,0,0,0,0,0,0,14,3,3,1,1,1,1,1,1,1,1,1,1,1,1
4,3,4,3,3,6,3,3,3,3,3,1,1,1,1,1,1,1,1,1,1,1,1
1,1,1,1,4,4,4,4,4,4,3,1,1,1,1,1,1,1,1,1,1,1,1
endlayer

layer
1,1,1,1,1,1,1,1,1,1,1,1,1,4,4,4,3,3,2,4,1,1,1
1,1,1,1,1,1,1,1,3,4,3,3,3,3,8,8,8,3,2,4,1,1,1
1,1,1,2,5,1,1,1,3,2,0,15,2,0,0,0,0,3,2,2,5,1,1
1,1,1,2,3,3,3,3,3,4,0,0,0,0,0,0,0,4,2,2,2,2,2
1,1,1,3,4,3,3,5,0,4,0,0,0,0,0,0,2,2,3,2,2,2,2
1,1,1,4,3,0,0,0,0,4,0,0,0,0,0,4,0,0,0,3,3,4,4
1,1,6,3,3,0,0,0,0,4,4,4,4,4,4,4,0,0,0,0,0,3,4
1,1,2,2,0,0,0,0,0,4,3,3,3,4,4,4,0,0,0,0,0,3,4
1,1,3,4,0,0,0,0,3,5,7,7,7,15,4,4,0,0,0,0,0,7,4
1,1,4,4,0,0,0,0,3,5,1,1,1,15,4,4,4,4,0,0,0,0,4
3,4,3,3,0,0,0,0,4,4,1,1,1,1,1,1,1,2,3,3,4,4,2
4,3,4,3,3,3,3,3,3,4,6,1,1,1,1,1,1,2,3,5,1,1,1
4,0,0,0,0,0,0,0,16,4,4,1,1,1,1,1,1,1,1,1,1,1,1
4,0,0,0,0,0,0,0,17,4,3,1,1,1,1,1,1,1,1,1,1,1,1
4,0,0,0,0,0,0,0,17,3,3,1,1,1,1,1,1,1,1,1,1,1,1
4,3,4,4,3,0,15,2,2,4,3,1,1,1,1,1,1,1,1,1,1,1,1
1,1,1,1,4,4,4,4,4,4,3,1,1,1,1,1,1,1,1,1,1,1,1
endlayer

layer
1,1,1,1,1,1,1,1,1,1,1,1,1,4,4,4,3,4,2,3,1,1,1
1,1,1,1,1,1,1,1,3,4,3,3,3,3,0,0,0,3,2,7,1,1,1
1,1,1,1,1,1,1,1,3,4,0,0,15,18,0,0,0,3,4,1,1,1,1
1,1,1,6,3,3,3,3,3,4,0,0,0,0,0,0,0,4,4,1,1,15,3
1,1,1,4,4,3,5,0,0,4,0,0,0,0,0,0,2,2,3,2,2,2,2
1,1,1,4,3,19,0,0,0,4,0,0,0,0,0,4,19,19,19,3,3,4,2
1,1,1,2,3,0,0,0,0,3,4,4,4,4,4,4,0,0,0,0,0,3,4
1,1,1,15,0,0,0,0,20,7,1,1,1,7,4,4,0,0,0,0,0,7,2
1,1,6,4,0,0,0,0,3,1,1,1,1,1,4,4,0,0,0,0,0,0,2
1,1,4,4,0,0,0,0,3,1,1,1,1,1,15,4,4,4,0,0,0,0,2
3,3,3,4,0,0,0,21,4,6,1,1,1,1,1,1,1,3,4,4,4,4,4
3,3,4,3,3,3,3,3,3,4,1,1,1,1,1,1,1,3,5,1,1,1,1
3,0,0,0,0,0,0,0,0,4,6,1,1,1,1,1,1,1,1,1,1,1,1
4,0,0,0,0,0,0,0,0,4,3,1,1,1,1,1,1,1,1,1,1,1,1
4,0,0,0,0,0,0,0,0,4,3,1,1,1,1,1,1,1,1,1,1,1,1
4,4,3,3,3,0,0,15,2,4,3,1,1,1,1,1,1,1,1,1,1,1,1
1,1,1,1,4,4,4,4,4,3,7,1,1,1,1,1,1,1,1,1,1,1,1
endlayer

layer
1,1,1,1,1,1,1,1,1,1,1,1,1,4,4,3,4,3,1,1,1,1,1
1,1,1,1,1,1,1,1,3,4,4,2,4,4,14,14,14,3,6,1,1,1,1
1,1,1,1,1,1,1,1,3,2,0,0,0,22,14,14,14,3,4,1,1,1,1
1,1,1,1,3,3,3,3,3,2,14,14,14,14,14,14,14,4,4,1,1,1,1
1,1,1,6,2,10,0,0,0,4,14,14,14,14,14,4,4,4,4,3,3,5,1
1,1,1,2,4,14,14,14,23,4,4,4,4,4,4,4,14,14,4,4,4,4,3
1,1,1,7,4,14,14,14,20,7,2,4,3,7,4,4,14,14,14,14,14,10,3
1,1,1,1,4,14,14,14,4,1,1,1,1,1,4,4,14,14,14,14,14,0,4
1,1,1,4,4,14,14,4,4,1,1,1,1,1,3,4,4,4,14,14,14,0,4
1,1,6,4,14,14,14,4,4,1,1,1,1,1,1,15,4,4,4,14,14,0,4
15,2,2,4,14,14,14,4,4,1,1,1,1,1,1,1,1,7,4,4,4,4,4
3,3,4,4,14,14,14,4,4,6,1,1,1,1,1,1,1,1,1,1,1,1,1
4,14,14,14,4,4,4,4,4,4,1,1,1,1,1,1,1,1,1,1,1,1,1
4,14,14,14,14,14,14,14,14,4,6,1,1,1,1,1,1,1,1,1,1,1,1
4,14,14,14,14,14,14,14,14,4,3,1,1,1,1,1,1,1,1,1,1,1,1
4,3,3,3,4,0,0,0,10,3,7,1,1,1,1,1,1,1,1,1,1,1,1
1,1,1,1,4,2,4,4,2,3,1,1,1,1,1,1,1,1,1,1,1,1,1
endlayer

layer
1,1,1,1,1,1,1,1,1,1,1,1,1,2,4,3,4,2,1,1,1,1,1
1,1,1,1,1,1,1,1,2,4,3,3,3,3,0,0,0,3,1,1,1,1,1
1,1,1,1,1,1,1,1,3,11,0,0,0,0,0,0,0,24,1,1,1,1,1
1,1,1,1,2,3,3,3,3,11,0,0,0,0,0,0,0,4,1,1,1,1,1
1,1,1,1,4,0,0,0,26,11,25,0,0,0,0,4,3,3,2,1,1,1,1
1,1,1,1,30,0,0,29,3,4,3,28,3,3,3,14,0,0,2,3,27,4,2
1,1,1,1,3,0,0,0,3,1,1,1,1,1,4,14,0,0,0,0,0,0,3
1,1,1,1,3,0,0,0,3,1,1,1,1,1,3,14,0,0,0,0,0,0,3
1,1,1,2,3,0,0,3,2,1,1,1,1,1,2,4,28,3,0,0,0,0,4
1,1,1,4,0,0,0,3,1,1,1,1,1,1,1,1,1,1,3,0,0,0,4
1,1,1,4,0,0,0,24,1,1,1,1,1,1,1,1,1,1,2,3,3,4,2
2,27,3,3,0,0,0,3,1,1,1,1,1,1,1,1,1,1,1,1,1,1,1
4,0,0,0,3,3,3,3,2,2,1,1,1,1,1,1,1,1,1,1,1,1,1
4,0,0,0,0,0,0,0,0,3,1,1,1,1,1,1,1,1,1,1,1,1,1
3,0,0,0,0,0,0,0,0,24,1,1,1,1,1,1,1,1,1,1,1,1,1
2,4,3,3,3,0,0,0,0,3,1,1,1,1,1,1,1,1,1,1,1,1,1
1,1,1,1,2,4,4,4,4,2,1,1,1,1,1,1,1,1,1,1,1,1,1
endlayer

layer
1,1,1,1,1,1,1,1,1,1,1,1,1,2,4,0,3,2,1,1,1,1,1
1,1,1,1,1,1,1,1,2,4,0,3,3,3,0,0,0,4,1,1,1,1,1
1,1,1,1,1,1,1,1,3,0,0,0,0,0,0,0,0,31,1,1,1,1,1
1,1,1,1,2,3,0,3,3,0,0,0,0,0,0,0,0,3,1,1,1,1,1
1,1,1,1,4,0,0,0,4,0,25,0,0,0,0,4,3,3,2,1,1,1,1
1,1,1,1,32,0,0,29,3,4,3,32,3,3,3,16,0,0,2,3,32,3,2
1,1,1,1,3,0,0,0,0,1,1,1,1,1,4,17,0,0,0,0,0,0,3
1,1,1,1,3,0,0,0,3,1,1,1,1,1,3,17,0,0,0,0,0,0,0
1,1,1,2,3,0,0,3,2,1,1,1,1,1,2,4,31,3,0,0,0,0,3
1,1,1,4,0,0,0,3,1,1,1,1,1,1,1,1,1,1,3,0,0,0,4
1,1,1,0,0,0,0,32,1,1,1,1,1,1,1,1,1,1,2,3,0,4,2
2,32,3,3,0,0,0,3,1,1,1,1,1,1,1,1,1,1,1,1,1,1,1
3,0,0,0,3,3,3,3,2,2,1,1,1,1,1,1,1,1,1,1,1,1,1
0,0,0,0,0,0,0,0,0,3,1,1,1,1,1,1,1,1,1,1,1,1,1
3,0,0,0,0,0,0,0,0,32,1,1,1,1,1,1,1,1,1,1,1,1,1
2,3,0,3,3,0,0,0,0,3,1,1,1,1,1,1,1,1,1,1,1,1,1
1,1,1,1,2,4,0,4,2,2,1,1,1,1,1,1,1,1,1,1,1,1,1
endlayer

layer
1,1,1,1,1,1,1,1,1,1,1,1,1,4,4,2,3,3,1,1,1,1,1
1,1,1,1,1,1,1,1,3,4,2,3,3,3,0,0,0,4,1,1,1,1,1
1,1,1,1,1,1,1,1,3,14,0,0,0,0,0,0,0,4,1,1,1,1,1
1,1,1,1,3,2,2,2,3,14,0,0,0,0,0,0,0,4,1,1,1,1,1
1,1,1,1,4,19,19,19,4,14,25,0,0,0,0,4,3,3,3,1,1,1,1
1,1,1,1,3,0,0,0,3,4,2,2,2,3,3,0,0,0,2,4,3,4,3
1,1,1,1,3,0,0,0,3,1,1,1,1,1,4,0,0,0,0,0,0,0,3
1,1,1,1,3,0,0,0,3,1,1,1,1,1,3,0,0,0,0,0,0,0,3
1,1,1,4,3,0,0,3,3,1,1,1,1,1,3,4,3,3,0,0,0,0,3
1,1,1,4,0,0,0,3,1,1,1,1,1,1,1,1,1,1,2,0,0,0,4
1,1,1,2,0,0,0,4,1,1,1,1,1,1,1,1,1,1,3,4,4,4,3
3,3,3,3,0,0,0,3,1,1,1,1,1,1,1,1,1,1,1,1,1,1,1
2,0,0,0,3,3,3,3,4,3,1,1,1,1,1,1,1,1,1,1,1,1,1
2,0,0,0,0,0,0,0,0,3,1,1,1,1,1,1,1,1,1,1,1,1,1
2,0,0,0,0,0,0,0,0,2,1,1,1,1,1,1,1,1,1,1,1,1,1
3,2,2,2,3,0,0,0,0,3,1,1,1,1,1,1,1,1,1,1,1,1,1
1,1,1,1,4,4,4,4,4,3,1,1,1,1,1,1,1,1,1,1,1,1,1
endlayer

layer
1,1,1,1,1,1,1,1,1,1,1,1,1,15,6,6,6,6,1,1,1,1,1
1,1,1,1,1,1,1,1,2,4,3,3,3,3,23,23,23,5,1,1,1,1,1
1,1,1,1,1,1,1,1,3,17,0,0,0,26,23,0,23,5,1,1,1,1,1
1,1,1,1,2,3,3,3,3,17,0,0,0,26,23,23,23,5,1,1,1,1,1
1,1,1,1,4,0,0,0,4,16,0,0,0,26,3,3,3,3,2,1,1,1,1
1,1,1,1,3,0,0,0,3,3,3,3,3,3,3,33,33,33,2,4,3,3,2
1,1,1,1,3,0,0,0,3,1,1,1,1,1,3,33,11,33,34,0,0,0,3
1,1,1,1,3,0,0,0,3,1,1,1,1,1,3,33,33,33,34,0,0,0,3
1,1,1,2,3,20,20,3,2,1,1,1,1,1,2,3,3,3,34,0,0,0,4
1,1,1,3,23,23,23,3,35,1,1,1,1,1,1,1,1,1,3,0,0,0,3
1,1,1,3,23,13,23,3,35,1,1,1,1,1,1,1,1,1,2,3,3,4,2
2,6,6,3,23,23,23,3,35,1,1,1,1,1,1,1,1,1,1,1,1,1,1
15,14,14,14,3,3,3,3,3,2,1,1,1,1,1,1,1,1,1,1,1,1,1
15,14,11,14,34,0,0,0,0,3,1,1,1,1,1,1,1,1,1,1,1,1,1
15,14,14,14,34,0,0,0,0,3,1,1,1,1,1,1,1,1,1,1,1,1,1
2,7,7,7,3,0,0,0,0,3,1,1,1,1,1,1,1,1,1,1,1,1,1
1,1,1,1,2,2,4,4,2,2,1,1,1,1,1,1,1,1,1,1,1,1,1
endlayer

layer
1,1,1,1,1,1,1,1,1,1,1,1,1,1,1,1,1,1,1,1,1,1,1
1,1,1,1,1,1,1,1,2,6,2,2,6,2,10,10,10,1,1,1,1,1,1
1,1,1,1,1,1,1,1,15,0,0,0,0,5,10,21,10,1,1,1,1,1,1
1,1,1,1,1,10,10,10,2,0,0,0,0,2,10,10,10,1,1,1,1,1,1
1,1,1,1,10,35,35,35,15,0,0,0,0,5,1,10,10,10,1,1,1,1,1
1,1,1,1,10,35,19,35,2,7,2,2,7,2,10,1,1,1,10,6,6,6,1
1,1,1,1,10,35,35,35,10,1,1,1,1,1,10,1,0,1,15,35,35,35,5
1,1,1,1,10,35,35,35,10,1,1,1,1,1,10,1,1,1,15,35,36,35,5
1,1,1,1,1,10,10,10,1,1,1,1,1,1,1,10,10,10,15,35,35,35,5
1,1,1,1,1,1,1,1,1,1,1,1,1,1,1,1,1,1,15,35,35,35,5
1,1,1,1,1,0,1,1,1,1,1,1,1,1,1,1,1,1,1,7,7,7,1
1,1,1,1,1,1,1,1,1,1,1,1,1,1,1,1,1,1,1,1,1,1,1
1,1,1,1,6,2,6,6,2,6,1,1,1,1,1,1,1,1,1,1,1,1,1
1,1,0,1,2,23,23,23,23,2,1,1,1,1,1,1,1,1,1,1,1,1,1
1,1,1,1,15,23,37,23,23,5,1,1,1,1,1,1,1,1,1,1,1,1,1
1,1,1,1,2,23,23,23,23,2,1,1,1,1,1,1,1,1,1,1,1,1,1
1,1,1,1,7,2,7,7,2,7,1,1,1,1,1,1,1,1,1,1,1,1,1
endlayer

layer
1,1,1,1,1,1,1,1,1,1,1,1,1,1,1,1,1,1,1,1,1,1,1
1,1,1,1,1,1,1,1,1,1,1,1,1,1,1,1,1,1,1,1,1,1,1
1,1,1,1,1,1,1,1,1,10,10,10,10,1,1,0,1,1,1,1,1,1,1
1,1,1,1,1,1,1,1,1,10,10,36,10,1,1,1,1,1,1,1,1,1,1
1,1,1,1,1,1,1,1,1,10,10,10,10,1,1,1,1,1,1,1,1,1,1
1,1,1,1,1,1,0,1,1,1,1,1,1,1,1,1,1,1,1,1,1,1,1
1,1,1,1,1,1,1,1,1,1,1,1,1,1,1,1,0,1,1,1,1,1,1
1,1,1,1,1,1,1,1,1,1,1,1,1,1,1,1,1,1,1,1,0,1,1
1,1,1,1,1,1,1,1,1,1,1,1,1,1,1,1,1,1,1,1,1,1,1
1,1,1,1,1,1,1,1,1,1,1,1,1,1,1,1,1,1,1,1,1,1,1
1,1,1,1,1,0,1,1,1,1,1,1,1,1,1,1,1,1,1,1,1,1,1
1,1,1,1,1,1,1,1,1,1,1,1,1,1,1,1,1,1,1,1,1,1,1
1,1,1,1,1,1,1,1,1,1,1,1,1,1,1,1,1,1,1,1,1,1,1
1,1,0,1,1,10,10,10,10,1,1,1,1,1,1,1,1,1,1,1,1,1,1
1,1,1,1,1,10,0,1,10,1,1,1,1,1,1,1,1,1,1,1,1,1,1
1,1,1,1,1,10,10,10,10,1,1,1,1,1,1,1,1,1,1,1,1,1,1
1,1,1,1,1,1,1,1,1,1,1,1,1,1,1,1,1,1,1,1,1,1,1
endlayer

