
# Created by Ruins mod version 16.7 Ingame Parser
# authoring Player: lafuller

weight=1
embed_into_distance=4
acceptable_target_blocks=
unacceptable_target_blocks=flowing_water,water,flowing_lava,lava,ice,bedrock,netherrack,nether_brick,nether_brick_fence,soul_sand,quartz_ore,end_stone,obsidian,iron_bars,cloud,flesh,ash_block,slime_grass,slime_congealed,slime_dirt
dimensions=21,19,17
allowable_overhang=0
max_leveling=4
leveling_buffer=-1
preserve_water=0
preserve_lava=0

rule1=0,100,preserveBlock
rule2=0,100,stonebrick,stonebrick,stonebrick,stonebrick-1,stonebrick-2,stonebrick-2,stone-5,stone-6,cobblestone
rule3=0,100,minecraft:stone-6
rule4=0,100,minecraft:dirt-0
rule5=0,100,minecraft:stone_brick_stairs-0
rule6=0,100,minecraft:stone_brick_stairs-1
rule7=0,100,stonebrick,stonebrick,stonebrick,stonebrick-1,stonebrick-2,stonebrick-2,stone-5,stone-6,cobblestone,gravel
rule8=0,100,minecraft:stone-5
rule9=0,100,minecraft:cobblestone_wall-0
rule10=0,100,minecraft:double_stone_slab-8
rule11=0,100,minecraft:stained_hardened_clay-9
rule12=0,100,minecraft:nether_brick-0
rule13=0,100,minecraft:log-0
rule14=0,100,minecraft:trapdoor-9
rule15=0,100,minecraft:trapdoor-8
rule16=0,100,minecraft:acacia_door-5
rule17=0,100,minecraft:spruce_fence_gate-6
rule18=0,100,minecraft:spruce_fence_gate-7
rule19=0,100,minecraft:nether_brick_stairs-5
rule20=0,100,minecraft:nether_brick_stairs-6
rule21=0,100,minecraft:stone_slab-14
rule22=0,100,minecraft:wooden_slab-2
rule23=0,100,minecraft:planks-2
rule24=0,100,minecraft:furnace-3
rule25=0,100,minecraft:cake-0
rule26=0,100,minecraft:acacia_door-9
rule27=0,100,minecraft:carpet-7
rule28=0,100,minecraft:acacia_door-8
rule29=0,100,minecraft:stone_brick_stairs-2
rule30=1,100,minecraft:torch-5
rule31=0,100,minecraft:stone_stairs-7
rule32=0,100,minecraft:stone_stairs-6
rule33=0,100,minecraft:spruce_fence_gate-0
rule34=0,100,minecraft:wooden_slab-9
rule35=0,100,minecraft:spruce_fence_gate-2
rule36=0,100,minecraft:spruce_fence_gate-3
rule37=0,100,minecraft:stone_brick_stairs-3
rule38=0,100,minecraft:stone_stairs-5
rule39=0,100,minecraft:spruce_fence-0
rule40=0,100,minecraft:birch_stairs-7
rule41=0,100,minecraft:birch_stairs-4
rule42=0,100,minecraft:dark_oak_stairs-2
rule43=0,100,minecraft:dark_oak_stairs-0
rule44=0,100,minecraft:wooden_slab-5
rule45=0,100,minecraft:spruce_stairs-5
rule46=0,100,minecraft:dark_oak_stairs-5
rule47=0,100,minecraft:wooden_slab-13
rule48=0,100,minecraft:dark_oak_stairs-6
rule49=0,100,minecraft:dark_oak_stairs-4
rule50=0,100,minecraft:planks-1
rule51=0,100,minecraft:birch_stairs-5
rule52=0,100,minecraft:dark_oak_stairs-7
rule53=0,100,minecraft:spruce_stairs-4
rule54=0,100,minecraft:spruce_stairs-7
rule55=0,100,minecraft:spruce_stairs-6
rule56=0,100,minecraft:planks-5
rule57=0,100,minecraft:dark_oak_stairs-1
rule58=0,100,minecraft:dark_oak_stairs-3
rule59=0,100,minecraft:double_wooden_slab-5
rule60=0,100,minecraft:double_wooden_slab-1
rule61=0,100,minecraft:dark_oak_fence-0
rule62=0,100,minecraft:iron_bars-0
rule63=0,100,stonebrick,stone_slab-0,stone_slab-3,stone_slab-5,stone_brick_stairs-0,stone_brick_stairs-1,stone_brick_stairs-2,stone_brick_stairs-3,air,air,air,air
rule64=0,100,IInventory;furnace;coal#2#1#1-3

layer
1,1,1,1,2,2,2,2,2,2,2,2,1,1,1,1,1
1,1,1,2,2,2,2,2,2,2,2,2,2,1,1,1,1
1,1,1,2,2,2,2,2,2,2,2,2,2,1,1,1,1
1,1,1,2,2,2,2,2,2,2,2,2,2,1,1,1,1
1,1,3,2,2,2,2,2,2,2,2,2,2,1,1,1,1
5,5,2,4,4,4,4,4,4,4,4,4,2,3,1,1,1
2,2,2,4,4,4,4,4,4,4,4,4,4,2,2,1,1
2,2,2,4,4,4,4,4,4,4,4,4,4,4,2,1,1
2,3,2,4,4,4,4,4,4,4,4,4,4,4,2,1,1
2,2,2,4,4,4,4,4,4,4,4,4,4,4,3,1,1
2,2,2,4,4,4,4,4,4,4,4,4,4,4,2,2,1
2,2,2,4,4,4,4,4,4,4,4,4,4,4,4,2,1
2,2,2,4,4,4,4,4,4,4,4,4,4,4,4,2,1
2,2,2,4,4,4,4,4,4,4,4,4,4,4,4,2,1
2,3,2,4,4,4,4,4,4,4,4,4,4,4,2,3,1
2,2,2,2,2,2,2,2,2,4,4,4,4,4,2,1,1
2,2,2,3,1,1,1,1,3,2,4,4,4,4,2,1,1
6,6,6,1,1,1,1,1,1,2,2,2,2,2,3,1,1
1,1,1,1,1,1,1,1,1,1,1,1,1,1,1,1,1
endlayer

layer
1,1,1,1,7,7,7,7,7,7,7,7,1,1,1,1,1
1,1,1,7,7,7,7,7,7,7,7,7,7,1,1,1,1
1,1,1,7,7,7,7,7,7,7,7,7,7,1,1,1,1
1,1,1,7,7,7,7,7,7,7,7,7,7,1,1,1,1
1,1,8,7,7,7,7,7,7,7,7,7,7,1,1,1,1
1,1,9,4,4,4,4,4,4,4,4,4,7,8,1,1,1
5,5,7,4,4,4,4,4,4,4,4,4,4,7,7,1,1
7,7,7,4,4,4,4,4,4,4,4,4,4,4,9,1,1
7,8,7,4,4,4,4,4,4,4,4,4,4,4,7,1,1
7,7,7,4,4,4,4,4,4,4,4,4,4,4,8,1,1
7,7,7,4,4,4,4,4,4,4,4,4,4,4,7,7,1
7,7,7,4,4,4,4,4,4,4,4,4,4,4,4,9,1
7,7,7,4,4,4,4,4,4,4,4,4,4,4,4,7,1
7,7,7,4,4,4,4,4,4,4,4,4,4,4,4,9,1
7,8,7,4,4,4,4,4,4,4,4,4,4,4,7,8,1
7,7,7,7,9,7,7,9,7,4,4,4,4,4,7,1,1
6,6,6,8,1,1,1,1,8,7,4,4,4,4,9,1,1
1,1,1,1,1,1,1,1,1,7,9,7,7,9,8,1,1
1,1,1,1,1,1,1,1,1,1,1,1,1,1,1,1,1
endlayer

layer
1,1,1,1,7,7,7,7,7,7,7,7,1,1,1,1,1
1,1,1,7,7,7,7,7,7,7,7,7,7,1,1,1,1
1,1,1,7,7,7,7,7,7,7,7,7,7,1,1,1,1
1,1,1,7,7,7,7,7,7,7,7,7,7,1,1,1,1
1,1,3,7,7,7,7,7,7,7,7,7,7,1,1,1,1
1,1,9,4,4,4,4,4,4,4,4,4,7,3,1,1,1
1,1,7,4,4,4,4,4,4,4,4,4,4,7,7,1,1
5,5,7,4,4,4,4,4,4,4,4,4,4,4,9,1,1
7,3,7,4,4,4,4,4,4,4,4,4,4,4,7,1,1
7,7,7,4,4,4,4,4,4,4,4,4,4,4,3,1,1
7,7,7,4,4,4,4,4,4,4,4,4,4,4,7,7,1
7,7,7,4,4,4,4,4,4,4,4,4,4,4,4,9,1
7,7,7,4,4,4,4,4,4,4,4,4,4,4,4,7,1
7,7,7,4,4,4,4,4,4,4,4,4,4,4,4,9,1
7,3,7,4,4,4,4,4,4,4,4,4,4,4,7,3,1
6,6,7,7,9,7,7,9,7,4,4,4,4,4,7,1,1
1,1,1,3,1,1,1,1,3,7,4,4,4,4,9,1,1
1,1,1,1,1,1,1,1,1,7,9,7,7,9,3,1,1
1,1,1,1,1,1,1,1,1,1,1,1,1,1,1,1,1
endlayer

layer
1,1,1,1,7,7,7,7,7,7,7,7,1,1,1,1,1
1,1,1,7,7,7,7,7,7,7,7,7,7,1,1,1,1
1,1,1,7,7,7,7,7,7,7,7,7,7,1,1,1,1
1,1,1,7,7,7,7,7,7,7,7,7,7,1,1,1,1
1,1,8,7,7,7,7,7,7,7,7,7,7,1,1,1,1
1,1,9,4,4,4,4,4,4,4,4,4,7,8,1,1,1
1,1,7,4,4,4,4,4,4,4,4,4,4,7,7,1,1
1,1,9,4,4,4,4,4,4,4,4,4,4,4,9,1,1
5,8,7,4,4,4,4,4,4,4,4,4,4,4,7,1,1
7,7,7,4,4,4,4,4,4,4,4,4,4,4,8,1,1
7,7,7,4,4,4,4,4,4,4,4,4,4,4,7,7,1
7,7,7,4,4,4,4,4,4,4,4,4,4,4,4,9,1
7,7,7,4,4,4,4,4,4,4,4,4,4,4,4,7,1
7,7,7,4,4,4,4,4,4,4,4,4,4,4,4,9,1
6,8,7,4,4,4,4,4,4,4,4,4,4,4,7,8,1
1,1,7,7,9,7,7,9,7,4,4,4,4,4,7,1,1
1,1,1,8,1,1,1,1,8,7,4,4,4,4,9,1,1
1,1,1,1,1,1,1,1,1,7,9,7,7,9,8,1,1
1,1,1,1,1,1,1,1,1,1,1,1,1,1,1,1,1
endlayer

layer
1,1,1,1,7,7,7,7,7,7,7,7,1,1,1,1,1
1,1,1,7,7,7,7,7,7,7,7,7,7,1,1,1,1
1,1,1,7,7,7,7,7,7,7,7,7,7,1,1,1,1
1,1,1,7,7,7,7,7,7,7,7,7,7,1,1,1,1
1,1,3,3,3,3,3,3,3,3,3,3,7,1,1,1,1
1,1,7,10,10,3,10,10,3,10,10,3,10,3,1,1,1
1,1,7,10,10,3,10,10,3,10,10,3,10,10,7,1,1
1,1,7,3,3,3,3,3,3,3,3,3,3,3,7,1,1
1,3,7,10,10,3,10,10,3,10,10,3,10,10,7,1,1
5,2,7,11,11,3,11,11,3,10,10,3,10,10,3,1,1
2,2,7,3,3,10,3,3,10,3,3,10,3,3,10,7,1
2,2,3,11,11,3,11,11,3,11,11,3,11,11,3,7,1
2,2,3,11,11,3,11,11,3,11,11,3,11,11,3,7,1
6,2,7,3,3,10,3,3,10,3,3,10,3,3,10,7,1
1,3,7,11,11,3,11,11,3,11,11,3,11,11,3,3,1
1,1,7,7,7,7,7,7,7,11,11,3,11,11,7,1,1
1,1,1,3,1,1,1,1,3,3,3,10,3,3,7,1,1
1,1,1,1,1,1,1,1,1,7,7,7,7,7,3,1,1
1,1,1,1,1,1,1,1,1,1,1,1,1,1,1,1,1
endlayer

layer
1,1,1,1,7,7,7,7,7,7,7,7,1,1,1,1,1
1,1,1,7,12,12,12,12,12,12,12,7,7,1,1,1,1
1,1,1,7,10,10,10,10,10,10,10,7,7,1,1,1,1
1,1,0,7,3,10,3,10,3,10,3,7,7,1,1,1,1
1,1,13,7,0,0,0,0,0,0,0,7,7,0,1,1,1
1,0,3,0,0,0,0,0,0,0,0,0,0,13,0,1,1
1,0,3,0,0,0,0,0,0,0,0,0,0,3,3,0,1
0,0,3,0,0,0,0,0,0,0,0,0,0,3,3,0,1
0,13,3,14,10,10,10,10,10,0,0,0,0,3,3,0,0
0,0,3,0,0,0,0,0,10,0,0,0,0,3,13,0,0
0,0,3,0,0,0,0,0,10,10,10,10,15,10,10,3,0
0,0,16,0,0,0,0,0,0,0,0,0,0,0,0,3,0
0,0,16,0,0,0,0,0,0,0,0,0,0,0,17,3,1
0,0,3,0,0,0,0,0,0,0,0,0,0,0,17,3,1
1,13,3,18,18,18,18,18,0,0,0,0,0,0,17,13,1
1,1,3,3,3,3,3,3,3,0,0,0,0,0,3,1,1
1,1,0,13,0,0,0,0,13,18,18,18,18,18,3,1,1
1,1,1,1,1,0,0,0,0,3,3,3,3,3,13,1,1
1,1,1,1,1,1,1,0,0,0,1,1,1,1,1,1,1
endlayer

layer
1,1,1,1,7,7,7,7,7,7,7,7,1,1,1,1,1
1,1,1,7,12,12,12,12,12,12,12,7,7,1,1,1,1
1,1,0,7,20,19,19,19,19,19,19,7,7,0,1,1,1
1,0,0,7,12,21,12,21,12,21,12,7,7,0,0,1,1
1,0,13,7,0,0,0,0,0,0,0,7,7,0,0,0,1
0,0,22,0,0,0,0,0,0,0,0,0,0,13,0,0,1
0,0,22,0,0,0,0,0,0,0,0,0,0,24,23,0,0
0,0,22,0,0,0,0,0,0,0,0,0,0,64,23,0,0
0,13,23,0,0,0,0,0,0,0,0,0,0,24,23,0,0
0,0,23,0,0,0,0,0,25,0,0,0,0,0,13,0,0
0,0,23,0,0,0,0,0,0,0,0,0,0,0,0,23,0
0,0,26,0,0,0,0,0,0,0,0,0,0,0,0,22,0
0,0,28,0,0,0,0,0,0,0,0,0,0,0,27,22,0
0,0,23,0,0,0,0,0,0,0,0,0,0,0,27,23,0
0,13,23,27,27,27,27,27,0,0,0,0,0,0,27,13,1
1,0,23,23,22,22,22,23,23,0,0,0,0,0,23,0,1
1,1,0,13,0,0,0,0,13,27,27,27,27,27,23,1,1
1,1,1,1,0,0,0,0,0,23,22,22,22,23,13,1,1
1,1,1,1,1,0,0,0,0,0,0,0,0,1,1,1,1
endlayer

layer
1,1,1,0,5,5,5,5,5,5,5,29,0,1,1,1,1
1,1,0,5,7,7,7,7,7,7,7,7,7,0,1,1,1
1,0,0,7,0,30,0,30,0,30,0,0,7,0,0,1,1
0,0,0,7,12,12,12,12,12,12,12,7,7,0,0,0,1
0,0,13,7,32,0,0,0,0,0,31,7,7,0,0,0,0
0,0,33,0,0,0,0,0,0,0,0,0,0,13,0,0,0
0,0,33,0,0,0,0,0,0,0,0,0,0,0,23,0,0
0,0,33,0,0,0,0,0,0,0,0,0,0,9,23,0,0
0,13,23,34,34,34,34,34,34,0,0,0,0,0,23,0,0
0,0,23,0,0,0,0,0,34,0,0,0,0,0,13,0,0
0,0,23,0,0,0,0,0,34,34,34,34,34,34,34,23,0
0,0,33,0,0,0,0,0,0,0,0,0,0,0,0,35,0
0,0,33,0,0,0,0,0,0,0,0,0,0,0,0,35,0
0,0,23,0,0,0,0,0,0,0,0,0,0,0,0,23,0
0,13,23,0,0,0,0,0,0,0,0,0,0,0,0,13,0
0,0,23,23,36,36,36,23,23,0,0,0,0,0,23,0,0
1,0,0,13,0,0,0,0,13,0,0,0,0,0,23,0,1
1,1,0,0,0,0,0,0,0,23,36,36,36,23,13,1,1
1,1,1,0,0,0,0,0,0,0,0,0,0,0,1,1,1
endlayer

layer
1,1,0,0,0,0,0,0,0,0,0,0,0,0,0,1,1
1,0,0,0,5,5,5,5,5,5,7,7,7,0,0,0,1
0,0,0,37,8,3,8,3,8,3,32,0,7,0,0,0,0
0,0,0,0,7,7,7,7,7,7,7,7,7,0,0,0,0
0,0,13,7,7,38,38,38,38,38,7,7,7,0,0,0,0
0,0,23,0,0,0,0,0,0,0,0,0,0,13,0,0,0
0,0,23,0,0,0,0,0,0,0,0,0,0,0,23,0,0
0,0,23,0,0,0,0,0,0,0,0,0,0,9,23,0,0
0,13,23,0,39,0,0,39,0,0,0,0,0,0,23,0,0
0,0,23,0,0,0,0,0,0,0,0,0,0,0,13,0,0
0,0,23,0,0,0,0,0,39,0,0,0,39,0,0,23,0
0,0,23,0,0,0,0,0,0,0,0,0,0,0,0,40,0
0,0,23,0,0,0,0,0,0,0,0,0,0,0,0,40,0
0,0,23,0,0,0,0,0,0,0,0,0,0,0,0,23,0
0,13,23,0,0,0,0,0,0,0,0,0,0,0,41,13,0
0,0,23,23,41,41,41,23,23,0,0,0,0,0,23,0,0
0,0,0,13,0,0,0,0,13,0,0,0,0,0,23,0,0
1,0,0,0,0,0,0,0,0,23,41,41,41,23,13,0,1
1,1,0,0,0,0,0,0,0,0,0,0,0,0,0,1,1
endlayer

layer
1,0,0,0,0,0,0,0,0,0,0,0,0,0,0,0,1
0,0,0,0,0,0,0,0,0,0,7,7,7,0,0,0,0
0,0,0,0,0,0,0,0,0,37,7,0,7,0,0,0,0
0,0,0,0,0,0,0,0,0,0,7,7,7,0,0,0,0
0,44,43,43,43,43,43,43,43,43,43,43,43,43,42,0,0
47,46,23,45,45,45,45,45,45,45,45,45,45,13,42,43,0
47,47,23,0,0,0,0,0,0,0,0,0,0,0,23,42,0
0,47,23,0,0,0,0,0,0,0,0,0,0,9,23,42,0
0,13,23,0,39,0,0,39,0,0,0,0,0,0,23,48,0
0,47,23,0,0,0,0,0,0,0,0,0,0,0,13,49,0
0,47,23,0,0,0,0,0,39,0,0,0,39,0,51,50,48
0,47,23,0,0,0,0,0,0,0,0,0,0,0,40,50,42
0,47,23,0,0,0,0,0,0,0,0,0,0,0,40,50,42
52,49,23,0,0,0,0,0,0,0,0,0,0,0,41,50,42
52,13,23,53,53,53,53,53,53,53,0,0,0,53,23,13,42
0,46,56,56,56,56,56,56,56,55,0,0,0,54,23,48,0
0,0,58,57,57,57,57,57,56,55,0,0,0,54,23,42,0
0,0,0,0,0,0,0,44,58,23,23,23,23,23,13,57,0
1,0,0,0,0,0,0,0,57,48,0,0,0,52,57,0,1
endlayer

layer
0,0,0,0,0,0,0,0,0,0,0,0,0,0,0,0,0
0,0,0,0,0,0,0,0,0,0,7,7,29,0,0,0,0
0,0,0,0,0,0,0,0,0,0,7,0,7,0,0,0,0
0,0,0,0,0,0,0,0,0,0,7,7,7,0,0,0,0
0,0,0,0,0,0,0,0,0,0,0,0,0,0,0,0,0
0,58,43,43,43,43,43,43,43,43,43,43,43,43,42,0,0
0,56,23,45,45,45,45,45,45,45,45,45,45,50,56,43,0
44,56,23,34,34,34,34,34,34,34,34,34,34,50,23,42,0
44,56,23,34,39,0,0,39,0,0,0,0,0,54,23,42,0
52,56,23,34,0,0,0,0,0,0,0,0,0,54,13,42,0
52,56,23,34,0,0,0,0,39,0,0,0,39,54,23,42,0
58,56,23,34,0,0,0,0,0,0,0,0,0,54,23,42,0
58,56,23,34,0,0,0,0,0,0,0,0,0,54,23,42,0
58,56,23,53,53,53,53,53,53,53,55,34,54,53,23,42,0
58,57,56,56,56,56,56,56,56,56,55,34,54,56,56,44,0
0,0,57,57,57,57,57,57,57,56,55,34,54,56,56,0,0
0,0,0,0,0,0,0,0,58,56,55,34,54,56,59,0,0
0,0,0,0,0,0,0,0,58,56,23,23,23,56,44,0,0
0,0,0,0,0,0,0,0,58,57,57,57,57,57,42,0,0
endlayer

layer
0,0,0,0,0,0,0,0,0,0,0,0,0,0,0,0,0
0,0,0,0,0,0,0,0,0,0,5,7,0,0,0,0,0
0,0,0,0,0,0,0,0,0,0,7,0,7,0,0,0,0
0,0,0,0,0,0,0,0,0,0,7,7,7,0,0,0,0
0,0,0,0,0,0,0,0,0,0,0,0,0,0,0,0,0
0,0,0,0,0,0,0,0,0,0,0,0,0,0,0,0,0
0,0,58,43,43,43,43,43,43,43,43,43,43,42,0,0,0
0,43,43,56,56,56,56,56,56,56,56,56,56,42,43,0,0
0,58,56,56,50,50,50,50,50,50,50,50,50,56,56,0,0
0,58,56,56,34,34,34,34,50,34,34,34,60,56,56,0,0
0,58,56,56,34,15,14,34,50,34,15,34,50,56,56,0,0
0,58,56,56,34,34,34,34,50,34,34,34,60,56,56,0,0
0,57,58,47,50,50,50,50,50,50,50,50,50,56,56,0,0
0,0,57,56,56,56,56,56,56,56,56,56,56,57,57,0,0
0,0,0,58,57,57,57,57,57,57,58,56,42,44,44,0,0
0,0,0,0,0,0,0,0,0,44,58,56,42,44,0,0,0
0,0,0,0,0,0,0,0,0,44,58,56,42,44,0,0,0
0,0,0,0,0,0,0,0,0,0,58,57,42,0,0,0,0
0,0,0,0,0,0,0,0,0,0,0,0,0,0,0,0,0
endlayer

layer
0,0,0,0,0,0,0,0,0,0,0,0,0,0,0,0,0
0,0,0,0,0,0,0,0,0,0,0,7,0,0,0,0,0
0,0,0,0,0,0,0,0,0,0,7,0,7,0,0,0,0
0,0,0,0,0,0,0,0,0,0,7,7,29,0,0,0,0
0,0,0,0,0,0,0,0,0,0,0,0,0,0,0,0,0
0,0,0,0,0,0,0,0,0,0,0,0,0,0,0,0,0
0,0,0,0,0,0,0,0,0,0,0,0,0,0,0,0,0
0,0,0,61,61,61,61,61,61,61,61,61,61,9,0,0,0
0,0,61,61,44,44,44,44,44,44,44,44,44,61,61,0,0
0,0,61,44,44,44,44,44,44,44,44,44,44,44,61,0,0
0,0,61,44,44,0,0,44,44,44,0,44,44,44,61,0,0
0,0,61,44,44,44,44,44,44,44,44,44,44,44,61,0,0
0,0,61,61,44,44,44,44,44,44,44,44,44,61,61,0,0
0,0,0,61,61,61,61,61,61,61,61,61,61,61,0,0,0
0,0,0,0,0,0,0,0,0,0,0,0,0,0,0,0,0
0,0,0,0,0,0,0,0,0,0,0,0,0,0,0,0,0
0,0,0,0,0,0,0,0,0,0,0,0,0,0,0,0,0
0,0,0,0,0,0,0,0,0,0,0,0,0,0,0,0,0
0,0,0,0,0,0,0,0,0,0,0,0,0,0,0,0,0
endlayer

layer
0,0,0,0,0,0,0,0,0,0,0,0,0,0,0,0,0
0,0,0,0,0,0,0,0,0,0,0,7,0,0,0,0,0
0,0,0,0,0,0,0,0,0,0,7,0,7,0,0,0,0
0,0,0,0,0,0,0,0,0,0,37,7,0,0,0,0,0
0,0,0,0,0,0,0,0,0,0,0,0,0,0,0,0,0
0,0,0,0,0,0,0,0,0,0,0,0,0,0,0,0,0
0,0,0,0,0,0,0,0,0,0,0,0,0,0,0,0,0
0,0,0,0,0,0,0,0,0,0,0,0,0,9,0,0,0
0,0,0,0,0,0,0,0,0,0,0,0,0,0,0,0,0
0,0,0,0,0,0,0,0,0,0,0,0,0,0,0,0,0
0,0,0,0,0,0,0,0,0,0,0,0,0,0,0,0,0
0,0,0,0,0,0,0,0,0,0,0,0,0,0,0,0,0
0,0,0,0,0,0,0,0,0,0,0,0,0,0,0,0,0
0,0,0,0,0,0,0,0,0,0,0,0,0,0,0,0,0
0,0,0,0,0,0,0,0,0,0,0,0,0,0,0,0,0
0,0,0,0,0,0,0,0,0,0,0,0,0,0,0,0,0
0,0,0,0,0,0,0,0,0,0,0,0,0,0,0,0,0
0,0,0,0,0,0,0,0,0,0,0,0,0,0,0,0,0
0,0,0,0,0,0,0,0,0,0,0,0,0,0,0,0,0
endlayer

layer
0,0,0,0,0,0,0,0,0,0,0,0,0,0,0,0,0
0,0,0,0,0,0,0,0,0,0,0,7,0,0,0,0,0
0,0,0,0,0,0,0,0,0,0,7,0,7,0,0,0,0
0,0,0,0,0,0,0,0,0,0,0,7,0,0,0,0,0
0,0,0,0,0,0,0,0,0,0,0,0,0,0,0,0,0
0,0,0,0,0,0,0,0,0,0,0,0,0,0,0,0,0
0,0,0,0,0,0,0,0,0,0,0,0,0,0,0,0,0
0,0,0,0,0,0,0,0,0,0,0,0,0,0,0,0,0
0,0,0,0,0,0,0,0,0,0,0,0,0,0,0,0,0
0,0,0,0,0,0,0,0,0,0,0,0,0,0,0,0,0
0,0,0,0,0,0,0,0,0,0,0,0,0,0,0,0,0
0,0,0,0,0,0,0,0,0,0,0,0,0,0,0,0,0
0,0,0,0,0,0,0,0,0,0,0,0,0,0,0,0,0
0,0,0,0,0,0,0,0,0,0,0,0,0,0,0,0,0
0,0,0,0,0,0,0,0,0,0,0,0,0,0,0,0,0
0,0,0,0,0,0,0,0,0,0,0,0,0,0,0,0,0
0,0,0,0,0,0,0,0,0,0,0,0,0,0,0,0,0
0,0,0,0,0,0,0,0,0,0,0,0,0,0,0,0,0
0,0,0,0,0,0,0,0,0,0,0,0,0,0,0,0,0
endlayer

layer
0,0,0,0,0,0,0,0,0,0,0,0,0,0,0,0,0
0,0,0,0,0,0,0,0,0,0,0,7,0,0,0,0,0
0,0,0,0,0,0,0,0,0,0,7,0,7,0,0,0,0
0,0,0,0,0,0,0,0,0,0,0,7,0,0,0,0,0
0,0,0,0,0,0,0,0,0,0,0,0,0,0,0,0,0
0,0,0,0,0,0,0,0,0,0,0,0,0,0,0,0,0
0,0,0,0,0,0,0,0,0,0,0,0,0,0,0,0,0
0,0,0,0,0,0,0,0,0,0,0,0,0,0,0,0,0
0,0,0,0,0,0,0,0,0,0,0,0,0,0,0,0,0
0,0,0,0,0,0,0,0,0,0,0,0,0,0,0,0,0
0,0,0,0,0,0,0,0,0,0,0,0,0,0,0,0,0
0,0,0,0,0,0,0,0,0,0,0,0,0,0,0,0,0
0,0,0,0,0,0,0,0,0,0,0,0,0,0,0,0,0
0,0,0,0,0,0,0,0,0,0,0,0,0,0,0,0,0
0,0,0,0,0,0,0,0,0,0,0,0,0,0,0,0,0
0,0,0,0,0,0,0,0,0,0,0,0,0,0,0,0,0
0,0,0,0,0,0,0,0,0,0,0,0,0,0,0,0,0
0,0,0,0,0,0,0,0,0,0,0,0,0,0,0,0,0
0,0,0,0,0,0,0,0,0,0,0,0,0,0,0,0,0
endlayer

layer
0,0,0,0,0,0,0,0,0,0,0,0,0,0,0,0,0
0,0,0,0,0,0,0,0,0,0,0,7,0,0,0,0,0
0,0,0,0,0,0,0,0,0,0,7,0,7,0,0,0,0
0,0,0,0,0,0,0,0,0,0,0,7,0,0,0,0,0
0,0,0,0,0,0,0,0,0,0,0,0,0,0,0,0,0
0,0,0,0,0,0,0,0,0,0,0,0,0,0,0,0,0
0,0,0,0,0,0,0,0,0,0,0,0,0,0,0,0,0
0,0,0,0,0,0,0,0,0,0,0,0,0,0,0,0,0
0,0,0,0,0,0,0,0,0,0,0,0,0,0,0,0,0
0,0,0,0,0,0,0,0,0,0,0,0,0,0,0,0,0
0,0,0,0,0,0,0,0,0,0,0,0,0,0,0,0,0
0,0,0,0,0,0,0,0,0,0,0,0,0,0,0,0,0
0,0,0,0,0,0,0,0,0,0,0,0,0,0,0,0,0
0,0,0,0,0,0,0,0,0,0,0,0,0,0,0,0,0
0,0,0,0,0,0,0,0,0,0,0,0,0,0,0,0,0
0,0,0,0,0,0,0,0,0,0,0,0,0,0,0,0,0
0,0,0,0,0,0,0,0,0,0,0,0,0,0,0,0,0
0,0,0,0,0,0,0,0,0,0,0,0,0,0,0,0,0
0,0,0,0,0,0,0,0,0,0,0,0,0,0,0,0,0
endlayer

layer
0,0,0,0,0,0,0,0,0,0,0,0,0,0,0,0,0
0,0,0,0,0,0,0,0,0,0,0,7,0,0,0,0,0
0,0,0,0,0,0,0,0,0,0,7,62,7,0,0,0,0
0,0,0,0,0,0,0,0,0,0,0,7,0,0,0,0,0
0,0,0,0,0,0,0,0,0,0,0,0,0,0,0,0,0
0,0,0,0,0,0,0,0,0,0,0,0,0,0,0,0,0
0,0,0,0,0,0,0,0,0,0,0,0,0,0,0,0,0
0,0,0,0,0,0,0,0,0,0,0,0,0,0,0,0,0
0,0,0,0,0,0,0,0,0,0,0,0,0,0,0,0,0
0,0,0,0,0,0,0,0,0,0,0,0,0,0,0,0,0
0,0,0,0,0,0,0,0,0,0,0,0,0,0,0,0,0
0,0,0,0,0,0,0,0,0,0,0,0,0,0,0,0,0
0,0,0,0,0,0,0,0,0,0,0,0,0,0,0,0,0
0,0,0,0,0,0,0,0,0,0,0,0,0,0,0,0,0
0,0,0,0,0,0,0,0,0,0,0,0,0,0,0,0,0
0,0,0,0,0,0,0,0,0,0,0,0,0,0,0,0,0
0,0,0,0,0,0,0,0,0,0,0,0,0,0,0,0,0
0,0,0,0,0,0,0,0,0,0,0,0,0,0,0,0,0
0,0,0,0,0,0,0,0,0,0,0,0,0,0,0,0,0
endlayer

layer
0,0,0,0,0,0,0,0,0,0,0,0,0,0,0,0,0
0,0,0,0,0,0,0,0,0,0,0,63,0,0,0,0,0
0,0,0,0,0,0,0,0,0,0,7,0,7,0,0,0,0
0,0,0,0,0,0,0,0,0,0,0,7,0,0,0,0,0
0,0,0,0,0,0,0,0,0,0,0,0,0,0,0,0,0
0,0,0,0,0,0,0,0,0,0,0,0,0,0,0,0,0
0,0,0,0,0,0,0,0,0,0,0,0,0,0,0,0,0
0,0,0,0,0,0,0,0,0,0,0,0,0,0,0,0,0
0,0,0,0,0,0,0,0,0,0,0,0,0,0,0,0,0
0,0,0,0,0,0,0,0,0,0,0,0,0,0,0,0,0
0,0,0,0,0,0,0,0,0,0,0,0,0,0,0,0,0
0,0,0,0,0,0,0,0,0,0,0,0,0,0,0,0,0
0,0,0,0,0,0,0,0,0,0,0,0,0,0,0,0,0
0,0,0,0,0,0,0,0,0,0,0,0,0,0,0,0,0
0,0,0,0,0,0,0,0,0,0,0,0,0,0,0,0,0
0,0,0,0,0,0,0,0,0,0,0,0,0,0,0,0,0
0,0,0,0,0,0,0,0,0,0,0,0,0,0,0,0,0
0,0,0,0,0,0,0,0,0,0,0,0,0,0,0,0,0
0,0,0,0,0,0,0,0,0,0,0,0,0,0,0,0,0
endlayer

layer
0,0,0,0,0,0,0,0,0,0,0,0,0,0,0,0,0
0,0,0,0,0,0,0,0,0,0,0,0,0,0,0,0,0
0,0,0,0,0,0,0,0,0,0,63,0,7,0,0,0,0
0,0,0,0,0,0,0,0,0,0,0,7,0,0,0,0,0
0,0,0,0,0,0,0,0,0,0,0,0,0,0,0,0,0
0,0,0,0,0,0,0,0,0,0,0,0,0,0,0,0,0
0,0,0,0,0,0,0,0,0,0,0,0,0,0,0,0,0
0,0,0,0,0,0,0,0,0,0,0,0,0,0,0,0,0
0,0,0,0,0,0,0,0,0,0,0,0,0,0,0,0,0
0,0,0,0,0,0,0,0,0,0,0,0,0,0,0,0,0
0,0,0,0,0,0,0,0,0,0,0,0,0,0,0,0,0
0,0,0,0,0,0,0,0,0,0,0,0,0,0,0,0,0
0,0,0,0,0,0,0,0,0,0,0,0,0,0,0,0,0
0,0,0,0,0,0,0,0,0,0,0,0,0,0,0,0,0
0,0,0,0,0,0,0,0,0,0,0,0,0,0,0,0,0
0,0,0,0,0,0,0,0,0,0,0,0,0,0,0,0,0
0,0,0,0,0,0,0,0,0,0,0,0,0,0,0,0,0
0,0,0,0,0,0,0,0,0,0,0,0,0,0,0,0,0
0,0,0,0,0,0,0,0,0,0,0,0,0,0,0,0,0
endlayer

layer
0,0,0,0,0,0,0,0,0,0,0,0,0,0,0,0,0
0,0,0,0,0,0,0,0,0,0,0,0,0,0,0,0,0
0,0,0,0,0,0,0,0,0,0,0,0,63,0,0,0,0
0,0,0,0,0,0,0,0,0,0,0,63,0,0,0,0,0
0,0,0,0,0,0,0,0,0,0,0,0,0,0,0,0,0
0,0,0,0,0,0,0,0,0,0,0,0,0,0,0,0,0
0,0,0,0,0,0,0,0,0,0,0,0,0,0,0,0,0
0,0,0,0,0,0,0,0,0,0,0,0,0,0,0,0,0
0,0,0,0,0,0,0,0,0,0,0,0,0,0,0,0,0
0,0,0,0,0,0,0,0,0,0,0,0,0,0,0,0,0
0,0,0,0,0,0,0,0,0,0,0,0,0,0,0,0,0
0,0,0,0,0,0,0,0,0,0,0,0,0,0,0,0,0
0,0,0,0,0,0,0,0,0,0,0,0,0,0,0,0,0
0,0,0,0,0,0,0,0,0,0,0,0,0,0,0,0,0
0,0,0,0,0,0,0,0,0,0,0,0,0,0,0,0,0
0,0,0,0,0,0,0,0,0,0,0,0,0,0,0,0,0
0,0,0,0,0,0,0,0,0,0,0,0,0,0,0,0,0
0,0,0,0,0,0,0,0,0,0,0,0,0,0,0,0,0
0,0,0,0,0,0,0,0,0,0,0,0,0,0,0,0,0
endlayer

