
# Created by Ruins mod version 16.5 Ingame Parser
# authoring Player: lafuller

weight=1
embed_into_distance=9
acceptable_target_blocks=
unacceptable_target_blocks=flowing_lava,lava,ice,bedrock,netherrack,nether_brick,nether_brick_fence,soul_sand,quartz_ore,end_stone,obsidian,iron_bars,cloud,flesh,ash_block,slime_grass,slime_congealed,slime_dirt
biomesToSpawnIn=swampland,wetland,marsh,lush swamp
dimensions=18,7,9
allowable_overhang=0
max_leveling=4
leveling_buffer=-1
preserve_water=0
preserve_lava=0

rule1=0,100,preserveBlock
rule2=0,100,minecraft:log2-1
rule3=0,100,minecraft:spruce_stairs-3
rule4=0,100,minecraft:trapdoor-1
rule5=0,100,minecraft:planks-1
rule6=0,100,minecraft:trapdoor-3
rule7=0,100,minecraft:spruce_fence-0
rule8=0,100,minecraft:spruce_stairs-4
rule9=0,100,minecraft:ladder-3
rule10=0,100,minecraft:ladder-5
rule11=0,100,minecraft:spruce_stairs-5
rule12=0,100,minecraft:spruce_stairs-6
rule13=0,100,minecraft:wooden_slab-9
rule14=0,100,minecraft:spruce_stairs-1
rule15=0,100,minecraft:spruce_stairs-0
rule16=0,100,minecraft:crafting_table-0
rule17=0,100,minecraft:sticky_piston-1
rule18=0,100,minecraft:cauldron-0
rule19=0,100,minecraft:jungle_door-3

rule20=0,100,IInventory;hopper;redstone#5#0#0-3,IInventory;hopper;book#1#0#0+torch#5#0#1-3,IInventory;hopper;feather#7#0#0,IInventory;hopper;milk_bucket#1#0#0-3,IInventory;hopper;glowstone_dust#3#0#0-3,IInventory;hopper;bucket#1#0#0+leather#2#0#1-3

rule21=0,100,IInventory;dropper;stick#1#0#2+stick#3#0#5+stick#7#0#6-1,IInventory;dropper;log#3#0#3-1,IInventory;dropper;log#4#1#1-1,IInventory;dropper;carrot#4#0#4-1,IInventory;dropper;cooked_beef#2#0#0-1,IInventory;dropper;cooked_fish#3#0#8-1

rule22=0,100,minecraft:planks-5
rule23=0,100,minecraft:bookshelf-0
rule24=0,100,minecraft:brewing_stand-0,air,air
rule25=0,100,minecraft:furnace-5
rule26=0,100,minecraft:spruce_stairs-7
rule27=0,100,minecraft:dark_oak_stairs-1
rule28=0,100,minecraft:trapdoor-9
rule29=0,100,minecraft:dark_oak_stairs-2
rule30=0,100,minecraft:jungle_door-9
rule31=0,100,minecraft:dark_oak_stairs-6
rule32=0,100,minecraft:carpet-7
rule33=0,100,minecraft:dark_oak_stairs-0
rule34=0,100,minecraft:dark_oak_stairs-4
rule35=0,100,minecraft:dark_oak_fence_gate-1
rule36=0,100,minecraft:dark_oak_stairs-3
rule37=0,100,minecraft:dark_oak_stairs-7
rule38=0,100,minecraft:jungle_fence_gate-2
rule39=0,100,minecraft:spruce_fence_gate-3
rule40=0,100,minecraft:wooden_slab-13
rule41=0,100,minecraft:dark_oak_fence_gate-5
rule42=0,100,minecraft:dark_oak_stairs-5
rule43=0,100,minecraft:wooden_slab-5
rule44=0,100,minecraft:double_wooden_slab-5

layer
1,1,1,1,1,1,2,1,1
1,1,2,1,1,1,1,1,1
1,1,1,1,1,1,1,1,1
1,1,1,1,1,1,1,1,1
1,1,1,1,1,1,1,1,1
1,1,2,1,1,1,1,2,1
1,1,1,1,1,1,1,1,1
endlayer

layer
1,1,1,1,1,1,2,1,1
1,1,2,1,1,1,1,1,1
1,1,1,1,1,1,1,1,1
1,1,1,1,1,1,1,1,1
1,1,1,1,1,1,1,1,1
1,1,2,1,1,1,1,2,1
1,1,1,1,1,1,1,1,1
endlayer

layer
1,1,1,1,1,1,2,1,1
1,1,2,1,1,1,1,1,1
1,1,1,1,1,1,1,1,1
1,1,1,1,1,1,1,1,1
1,1,1,1,1,1,1,1,1
1,1,2,1,1,1,1,2,1
1,1,1,1,1,1,1,1,1
endlayer

layer
1,1,1,1,1,1,2,1,1
1,1,2,1,1,1,1,1,1
1,1,1,1,1,1,1,1,1
1,1,1,1,1,1,1,1,1
1,1,1,1,1,1,1,1,1
1,1,2,1,1,1,1,2,1
1,1,1,1,1,1,1,1,1
endlayer

layer
1,1,1,1,1,1,2,1,1
1,1,2,1,1,1,1,1,1
1,1,1,1,1,1,1,1,1
1,1,1,1,1,1,1,1,1
1,1,1,1,1,1,1,1,1
1,1,2,1,1,1,1,2,1
1,1,1,1,1,1,1,1,1
endlayer

layer
1,1,1,1,1,1,2,1,1
1,1,2,1,1,1,1,1,1
1,1,1,1,1,1,1,1,1
1,1,1,1,1,1,1,1,1
1,1,1,1,1,1,1,1,1
1,1,2,1,1,1,1,2,1
1,1,1,1,1,1,1,1,1
endlayer

layer
1,1,1,1,1,1,2,1,1
1,1,2,1,1,1,1,1,1
1,1,1,1,1,1,1,1,1
1,1,1,1,1,1,1,1,1
1,1,1,1,1,1,1,1,1
1,1,2,1,1,1,1,2,1
1,1,1,1,1,1,1,1,1
endlayer

layer
1,1,1,1,1,1,2,1,1
1,1,2,1,1,1,1,1,1
1,1,1,1,1,1,1,1,1
1,1,1,1,1,1,1,1,1
1,1,1,1,1,1,1,1,1
1,1,2,1,1,1,1,2,1
1,1,1,1,1,1,1,1,1
endlayer

layer
1,1,1,1,1,1,2,1,1
1,1,2,1,1,1,1,1,1
1,1,1,1,1,1,1,1,1
1,1,1,1,1,1,1,1,1
1,1,1,1,1,1,1,1,1
1,1,2,1,1,1,1,2,1
1,1,1,1,1,1,1,1,1
endlayer

layer
1,1,1,1,1,1,2,1,1
1,1,2,1,1,1,1,1,1
1,1,1,1,1,1,1,1,1
4,3,1,1,1,1,1,1,1
4,5,1,1,1,1,1,1,1
1,6,2,1,1,1,1,2,1
1,1,1,1,1,1,1,1,1
endlayer

layer
1,1,1,1,1,1,2,1,1
1,1,2,7,7,7,7,1,1
1,8,7,7,1,1,1,1,1
9,5,7,1,1,1,1,1,1
9,5,7,7,1,1,1,1,1
1,10,2,7,7,7,7,2,1
1,1,1,1,1,1,1,1,1
endlayer

layer
1,1,1,7,7,7,2,1,1
1,1,2,11,11,11,7,7,1
1,14,5,12,13,13,12,7,1
0,3,5,12,13,13,12,7,1
0,14,5,8,8,8,12,7,7
1,0,2,7,11,11,11,2,1
1,1,1,1,0,0,0,1,1
endlayer

layer
1,1,7,8,15,15,2,7,1
1,0,5,18,17,5,16,12,0
0,7,5,0,0,10,0,3,12
0,0,19,0,0,0,0,3,12
0,0,5,21,20,0,0,3,7
1,0,2,11,14,5,11,2,0
1,1,0,0,0,0,0,7,1
endlayer

layer
1,0,5,8,14,8,2,7,0
0,0,26,25,24,5,23,22,7
0,7,3,0,0,10,28,28,27
0,0,30,0,0,0,28,28,29
0,0,26,32,0,0,28,28,31
0,0,22,5,15,15,11,2,7
1,0,0,0,0,0,0,7,0
endlayer

layer
0,0,36,33,35,34,33,7,0
0,0,29,0,0,3,23,22,33
0,37,5,0,0,0,32,32,22
0,0,38,0,0,0,32,32,29
0,0,5,0,0,0,32,32,33
0,37,22,5,39,39,5,2,27
0,0,0,41,0,0,40,31,0
endlayer

layer
0,0,0,33,42,29,33,29,0
0,0,36,0,0,0,0,33,0
0,0,33,0,0,0,0,0,29
0,43,31,0,0,0,0,0,36
0,43,22,0,0,0,0,0,29
0,0,36,22,34,34,22,36,0
0,0,43,44,27,29,27,29,0
endlayer

layer
0,0,0,0,0,0,0,0,0
0,0,0,36,33,33,29,0,0
0,0,36,40,13,13,40,29,0
0,0,36,13,13,13,13,29,0
0,0,27,40,40,13,13,29,0
0,0,0,43,36,27,27,29,0
0,0,0,0,0,0,0,0,0
endlayer

layer
0,0,0,0,0,0,0,0,0
0,0,0,0,0,0,0,0,0
0,0,0,0,43,43,0,0,0
0,0,0,43,43,43,43,0,0
0,0,0,0,43,43,43,0,0
0,0,0,0,0,0,0,0,0
0,0,0,0,0,0,0,0,0
endlayer

