
# Created by Ruins mod version 16.7 Ingame Parser
# authoring Player: lafuller

weight=1
embed_into_distance=9
acceptable_target_blocks=flowing_water,water
unacceptable_target_blocks=
biomesToSpawnIn=swampland,wetland,marsh,lush swamp
dimensions=13,9,7
allowable_overhang=0
max_leveling=4
leveling_buffer=-1
preserve_water=0
preserve_lava=0

rule1=0,100,preserveBlock
rule2=0,100,minecraft:log2-1
rule3=0,100,minecraft:wooden_slab-9
rule4=0,100,minecraft:ladder-4
rule5=0,100,minecraft:planks-1
rule6=0,100,minecraft:dark_oak_fence-0
rule7=0,100,minecraft:spruce_fence-0
rule8=0,100,minecraft:dark_oak_fence_gate-3
rule9=0,100,minecraft:dark_oak_fence_gate-2
rule10=0,100,minecraft:dark_oak_fence_gate-0
rule11=0,100,minecraft:dark_oak_fence_gate-1
rule12=0,100,minecraft:spruce_stairs-4
rule13=0,100,minecraft:spruce_stairs-6
rule14=0,100,minecraft:log2-9
rule15=0,100,minecraft:spruce_stairs-5
rule16=0,100,minecraft:spruce_stairs-7
rule17=0,100,minecraft:trapdoor-15

layer
2,1,1,1,1,1,1
1,1,1,1,1,1,2
1,1,1,1,1,1,1
1,1,1,1,1,1,1
1,1,1,1,1,1,1
1,1,1,1,1,1,1
1,1,1,1,1,1,1
1,1,1,1,1,2,1
1,2,1,1,1,1,1
endlayer

layer
2,1,1,1,1,1,1
1,1,1,1,1,1,2
1,1,1,1,1,1,1
1,1,1,1,1,1,1
1,1,1,1,1,1,1
1,1,1,1,1,1,1
1,1,1,1,1,1,1
1,1,1,1,1,2,1
1,2,1,1,1,1,1
endlayer

layer
2,1,1,1,1,1,1
1,1,1,1,1,1,2
1,1,1,1,1,1,1
1,1,1,1,1,1,1
1,1,1,1,1,1,1
1,1,1,1,1,1,1
1,1,1,1,1,1,1
1,1,1,1,1,2,1
1,2,1,1,1,1,1
endlayer

layer
2,1,1,1,1,1,1
1,1,1,1,1,1,2
1,1,1,1,1,1,1
1,1,1,1,1,1,1
1,1,1,1,1,1,1
1,1,1,1,1,1,1
1,1,1,1,1,1,1
1,1,1,1,1,2,1
1,2,1,1,1,1,1
endlayer

layer
2,1,1,1,1,1,1
1,1,1,1,1,1,2
1,1,1,1,1,1,1
1,1,1,1,1,1,1
1,1,1,1,1,1,1
1,1,1,1,1,1,1
1,1,1,1,1,1,1
1,1,1,1,1,2,1
1,2,1,1,1,1,1
endlayer

layer
2,1,1,1,1,1,1
1,1,1,1,1,1,2
1,1,1,1,1,1,1
1,1,1,1,1,1,1
1,1,1,1,1,1,1
1,1,1,1,1,1,1
1,1,1,1,1,1,1
1,1,1,1,1,2,1
1,2,1,1,1,1,1
endlayer

layer
2,1,1,1,1,1,1
1,1,1,1,1,1,2
1,1,1,1,1,1,1
1,1,1,1,1,1,1
1,1,1,1,1,1,1
1,1,1,1,1,1,1
1,1,1,1,1,1,1
1,1,1,1,1,2,1
1,2,1,1,1,1,1
endlayer

layer
2,1,1,1,1,1,1
1,1,1,1,1,1,2
1,1,1,1,1,1,1
1,1,1,1,1,1,1
1,1,1,1,1,1,1
1,1,1,1,1,1,1
1,1,1,1,1,1,1
1,1,1,1,1,2,1
1,2,1,1,1,1,1
endlayer

layer
2,1,1,1,1,1,1
1,1,1,1,1,1,2
1,1,1,1,1,1,1
1,1,1,1,1,1,1
1,1,1,1,1,1,1
1,1,1,1,1,1,1
1,1,3,3,3,1,1
1,1,3,3,3,2,1
1,2,1,1,1,1,1
endlayer

layer
2,1,1,1,1,1,1
1,1,1,1,1,1,2
1,1,1,1,1,1,1
1,1,1,1,1,1,1
1,1,1,1,1,1,1
1,1,1,1,1,1,1
1,1,4,4,4,1,1
1,6,5,5,5,2,1
1,2,6,7,7,1,1
endlayer

layer
2,6,1,1,1,1,1
6,6,8,8,8,6,2
1,9,1,1,1,6,6
1,9,1,1,1,10,1
1,9,1,1,1,10,1
1,9,1,1,1,10,1
1,9,1,4,1,10,1
1,6,11,5,6,2,7
7,2,6,6,7,7,1
endlayer

layer
2,13,12,3,3,3,7
16,15,15,15,15,15,14
16,13,3,3,3,16,13
3,13,3,3,3,16,3
3,13,3,3,3,16,3
3,13,3,17,3,16,3
3,13,3,4,3,16,13
7,13,12,5,12,2,13
7,2,15,15,6,7,1
endlayer

layer
6,8,8,6,8,6,6
9,1,1,1,1,1,6
9,1,1,1,1,1,10
6,1,1,1,1,1,10
9,1,1,1,1,1,6
9,1,1,1,1,1,10
6,1,1,1,1,1,6
6,6,1,1,1,6,6
1,6,1,1,6,6,1
endlayer

