
# Created by Ruins mod version 16.5 Ingame Parser
# authoring Player: lafuller

weight=1
embed_into_distance=5
acceptable_target_blocks=
unacceptable_target_blocks=flowing_water,water,flowing_lava,lava,ice,bedrock,netherrack,nether_brick,nether_brick_fence,soul_sand,quartz_ore,end_stone,obsidian,iron_bars,cloud,flesh,ash_block,slime_grass,slime_congealed,slime_dirt
dimensions=12,24,23
allowable_overhang=0
max_leveling=7
leveling_buffer=-1
preserve_water=0
preserve_lava=0

rule1=0,100,preserveBlock
rule2=0,100,minecraft:double_stone_slab-9
rule3=0,100,minecraft:sandstone-0
rule4=0,100,minecraft:sandstone-2
rule5=0,100,minecraft:sandstone_stairs-2
rule6=0,100,minecraft:sandstone_stairs-0
rule7=0,100,minecraft:sandstone_stairs-3
rule8=0,100,bookshelf,pumpkin,melon_block,hay_block,ChestGenHook:chests/village_blacksmith:5-3
rule9=0,100,minecraft:spruce_stairs-5
rule10=0,100,minecraft:ladder-3
rule11=0,100,minecraft:wooden_slab-9
rule12=0,100,minecraft:spruce_stairs-4
rule13=0,100,bookshelf,pumpkin,melon_block,hay_block,ChestGenHook:chests/spawn_bonus_chest:5-4
rule14=0,100,minecraft:dirt-0
rule15=0,100,minecraft:trapdoor-11
rule16=0,100,bookshelf,pumpkin,melon_block,hay_block,ChestGenHook:chests/stronghold_library:5-5
rule17=0,100,minecraft:sandstone_stairs-1
rule18=0,100,minecraft:ladder-2
rule19=0,100,minecraft:carpet-7
rule20=0,100,minecraft:carpet-8
rule21=0,100,minecraft:trapdoor-3
rule22=0,100,minecraft:spruce_stairs-6
rule23=0,100,minecraft:sandstone_stairs-6
rule24=0,100,minecraft:sandstone_stairs-4
rule25=0,100,minecraft:stone_slab-1
rule26=0,100,minecraft:spruce_stairs-7
rule27=0,100,minecraft:ladder-5
rule28=0,100,minecraft:jungle_door-1
rule29=0,100,minecraft:jungle_door-0
rule30=0,100,minecraft:jungle_door-2
rule31=0,100,minecraft:spruce_fence-0
rule32=0,100,minecraft:jungle_door-3
rule33=0,100,minecraft:jungle_door-9
rule34=0,100,minecraft:jungle_door-8
rule35=0,100,minecraft:trapdoor-1
rule36=0,100,minecraft:wooden_slab-1
rule37=0,100,minecraft:spruce_stairs-1
rule38=0,100,minecraft:trapdoor-2
rule39=0,100,minecraft:stone_slab-9
rule40=0,100,minecraft:sandstone_stairs-5
rule41=0,100,minecraft:trapdoor-8
rule42=0,100,minecraft:sandstone_stairs-7
rule43=0,100,minecraft:trapdoor-9
rule44=0,100,minecraft:trapdoor-0
rule45=0,100,minecraft:hay_block-0
rule46=0,100,minecraft:trapdoor-10

layer
1,1,3,2,2,2,2,1,1,1,1,1,1,1,2,2,2,2,1,1,1,1,1
1,1,3,2,3,3,3,4,4,2,3,3,3,4,3,3,4,3,4,4,3,3,4
1,1,3,2,3,3,3,3,3,2,3,3,3,3,3,2,2,2,2,2,2,2,3
1,1,3,2,3,3,3,3,3,2,3,3,3,3,3,2,3,3,3,3,3,3,3
1,1,3,2,3,3,3,3,3,2,3,3,3,3,3,2,3,3,3,3,3,3,3
1,1,3,2,3,3,3,3,3,2,2,2,2,2,2,2,3,3,3,3,3,2,3
1,1,3,2,2,2,2,2,2,2,3,3,3,3,3,2,3,3,3,3,3,2,3
1,1,2,2,2,2,2,2,2,2,3,3,3,3,3,2,3,3,3,3,3,2,3
2,2,3,3,3,2,2,2,2,2,3,3,3,3,3,2,2,2,2,2,2,2,3
3,3,3,3,3,2,2,2,2,2,3,3,3,3,3,2,2,3,3,3,3,2,3
3,3,3,3,3,2,2,2,2,2,3,3,3,3,3,2,2,3,3,3,2,1,1
3,3,3,3,3,2,2,2,2,2,2,2,2,2,2,2,2,3,3,1,1,1,1
2,3,3,3,3,2,2,3,3,3,3,3,2,2,2,4,4,3,2,1,1,1,1
2,2,2,2,2,2,2,3,3,3,3,3,2,2,4,3,3,3,2,1,1,1,1
2,3,3,3,3,3,2,3,3,3,3,3,2,2,3,3,3,3,2,1,1,1,1
2,3,3,3,3,3,2,3,3,3,3,3,2,2,2,2,2,2,2,1,1,1,1
2,4,3,3,3,3,2,3,3,3,3,3,2,3,3,3,3,4,2,1,1,1,1
1,1,4,3,3,3,2,2,2,2,2,2,2,3,3,3,3,4,2,1,1,1,1
1,1,4,3,3,3,2,2,3,3,3,2,2,3,3,3,3,3,2,4,1,1,1
1,1,2,2,2,2,2,2,3,3,3,2,2,3,3,3,3,3,2,3,1,1,1
1,1,1,1,1,1,2,3,3,3,3,2,2,3,3,3,3,3,2,3,1,1,1
1,1,1,1,1,1,1,1,1,1,3,3,2,2,2,2,2,2,2,3,1,1,1
1,1,1,1,1,1,1,1,1,1,3,3,3,3,3,3,3,3,3,3,1,1,1
1,1,1,1,1,1,1,1,1,1,3,3,3,3,3,3,1,1,1,1,1,1,1
endlayer

layer
1,1,3,2,2,2,2,1,1,1,1,1,1,1,7,6,6,5,1,1,1,1,1
1,1,3,2,3,3,3,4,4,2,3,3,3,4,3,3,4,3,4,4,3,3,4
1,1,3,2,3,3,3,3,3,2,3,3,3,3,3,2,2,2,2,2,2,2,3
1,1,3,2,3,3,3,3,3,2,3,3,3,3,3,2,3,3,3,3,3,3,3
1,1,3,2,3,3,3,3,3,2,3,3,3,3,3,2,3,3,3,3,3,3,3
1,1,3,2,3,3,3,3,3,2,2,2,2,2,2,2,3,3,3,3,3,2,3
1,1,3,2,2,2,2,2,2,2,3,3,3,3,3,2,3,3,3,3,3,2,3
1,1,2,2,2,2,2,2,2,2,3,3,3,3,3,2,3,3,3,3,3,2,3
6,6,3,3,3,2,2,2,2,2,3,3,3,3,3,2,2,2,2,2,2,2,3
3,3,3,3,3,2,2,2,2,2,3,3,3,3,3,2,2,3,3,3,3,2,3
3,3,3,3,3,2,2,2,2,2,3,3,3,3,3,2,2,3,3,3,5,1,1
3,3,3,3,3,2,2,2,2,2,2,2,2,2,2,2,2,3,3,1,1,1,1
2,3,3,3,3,2,2,3,3,3,3,3,2,2,2,4,4,3,5,1,1,1,1
2,2,2,2,2,2,2,3,3,3,3,3,2,2,4,3,3,3,5,1,1,1,1
2,3,3,3,3,3,2,3,3,3,3,3,2,2,3,3,3,3,2,1,1,1,1
2,3,3,3,3,3,2,3,3,3,3,3,2,2,2,2,2,2,2,1,1,1,1
2,4,3,3,3,3,2,3,3,3,3,3,2,3,3,3,3,4,2,1,1,1,1
1,1,4,3,3,3,2,2,2,2,2,2,2,3,3,3,3,4,2,1,1,1,1
1,1,4,3,3,3,2,2,3,3,3,2,2,3,3,3,3,3,2,4,1,1,1
1,1,2,2,2,2,2,2,3,3,3,2,2,3,3,3,3,3,2,3,1,1,1
1,1,1,1,1,1,7,3,3,3,3,2,2,3,3,3,3,3,2,3,1,1,1
1,1,1,1,1,1,1,1,1,1,3,3,2,2,2,2,2,2,2,3,1,1,1
1,1,1,1,1,1,1,1,1,1,3,3,3,3,3,3,3,3,3,3,1,1,1
1,1,1,1,1,1,1,1,1,1,3,3,3,3,3,3,1,1,1,1,1,1,1
endlayer

layer
1,1,3,2,2,2,2,1,1,1,1,1,1,1,1,1,1,1,1,1,1,1,1
1,1,3,5,0,0,0,4,4,2,4,3,3,3,5,1,1,3,3,3,3,3,3
1,1,3,3,0,0,0,0,8,2,3,3,3,3,3,2,2,2,2,2,2,2,3
1,1,3,3,0,0,0,0,9,2,3,3,3,3,3,2,0,0,0,0,0,0,3
1,1,3,3,0,0,0,0,11,2,3,3,3,3,3,2,0,0,0,0,0,10,4
1,1,3,2,0,0,0,0,12,2,2,2,2,2,2,2,0,0,0,0,0,2,4
1,1,3,2,2,2,2,2,2,2,0,0,0,0,8,2,0,0,0,0,0,2,3
1,1,3,2,2,2,2,2,2,2,0,0,0,0,0,2,0,0,0,0,13,2,3
1,1,4,3,3,2,2,2,2,2,0,0,0,0,0,2,2,2,2,2,2,2,3
6,6,3,3,3,2,2,2,2,2,0,0,0,0,0,2,2,3,3,3,3,2,4
3,14,14,14,4,2,2,2,2,2,0,7,3,3,3,2,2,3,3,5,1,1,1
3,3,3,3,3,2,2,2,2,2,2,2,2,2,2,2,2,3,4,1,1,1,1
2,3,3,3,3,2,3,16,0,0,0,15,2,2,2,4,4,5,1,1,1,1,1
2,2,2,2,2,2,3,0,0,0,0,0,2,2,4,3,3,5,1,1,1,1,1
2,0,0,0,0,3,3,0,0,0,0,0,2,2,3,3,3,3,2,1,1,1,1
2,18,0,0,0,3,17,0,0,0,0,0,2,2,2,2,2,2,2,1,1,1,1
2,4,0,0,0,3,0,0,0,0,0,0,2,3,3,3,3,4,2,1,1,1,1
1,1,4,0,0,0,2,2,2,2,2,2,2,3,0,0,0,4,2,1,1,1,1
1,1,4,13,0,0,2,2,3,3,3,2,2,18,0,0,0,0,2,4,1,1,1
1,1,2,2,2,2,2,2,3,3,3,2,2,0,0,0,0,0,8,4,1,1,1
1,1,1,1,1,1,1,7,3,3,3,2,2,0,0,0,0,0,0,3,1,1,1
1,1,1,1,1,1,1,1,1,1,3,3,2,2,2,2,11,11,11,3,1,1,1
1,1,1,1,1,1,1,1,1,1,3,3,3,3,3,3,3,3,3,3,1,1,1
1,1,1,1,1,1,1,1,1,1,3,4,3,3,3,4,1,1,1,1,1,1,1
endlayer

layer
1,1,3,2,2,2,2,1,1,1,1,1,1,1,1,1,1,1,1,1,1,1,1
1,1,3,0,0,0,0,4,4,2,4,4,4,5,1,1,1,4,3,4,4,4,4
1,1,3,6,0,0,0,0,0,2,3,3,3,3,4,2,2,2,2,2,2,2,3
1,1,3,3,0,0,0,0,19,2,3,3,3,3,3,2,0,0,0,0,0,0,3
1,1,3,3,0,0,0,0,19,2,3,3,3,3,3,2,0,0,0,0,0,10,3
1,1,3,2,0,0,0,0,20,2,2,19,19,20,2,2,0,0,0,0,0,2,4
1,1,4,2,2,2,2,2,2,2,0,0,0,0,0,2,0,0,0,0,0,2,1
1,1,4,14,14,2,2,2,2,2,0,0,0,0,0,2,0,0,0,0,0,2,1
1,1,17,7,4,3,2,2,2,2,0,0,0,0,0,2,2,2,2,2,2,2,6
1,1,1,1,1,7,2,2,2,2,0,0,0,0,0,2,2,3,3,3,2,2,4
1,1,1,1,3,4,2,2,2,2,0,0,7,3,3,2,2,3,5,1,1,1,1
6,3,3,3,4,2,2,2,2,2,2,2,2,2,2,2,3,3,4,1,1,1,1
2,2,3,3,3,2,3,0,0,0,0,0,2,2,4,4,5,1,1,1,1,1,1
2,2,2,2,2,2,3,0,0,0,0,0,2,2,14,14,5,1,1,1,1,1,1
2,0,0,0,0,3,17,0,0,0,0,0,2,2,3,3,3,6,2,1,1,1,1
2,18,0,0,0,3,0,0,0,0,0,0,2,2,2,2,2,2,2,1,1,1,1
2,4,0,0,0,3,0,0,0,0,0,0,2,3,3,3,3,4,2,1,1,1,1
1,1,4,0,0,0,2,2,2,2,2,2,2,3,0,0,0,4,2,1,1,1,1
1,1,4,0,0,0,2,2,3,3,3,2,2,18,0,0,0,0,2,3,1,1,1
1,1,2,2,2,2,2,2,4,4,4,2,2,0,0,0,0,0,0,3,1,1,1
1,1,1,1,1,1,1,1,7,4,3,3,2,0,0,0,0,0,0,3,1,1,1
1,1,1,1,1,1,1,1,1,1,3,3,2,0,0,2,19,19,20,3,1,1,1
1,1,1,1,1,1,1,1,1,1,4,3,3,3,3,3,4,4,3,4,1,1,1
1,1,1,1,1,1,1,1,1,1,3,3,3,3,3,4,1,1,1,1,1,1,1
endlayer

layer
1,1,3,2,2,2,2,1,1,1,1,1,1,1,1,1,1,1,1,1,1,1,1
1,1,3,0,0,0,0,4,4,2,3,3,5,1,1,1,1,4,3,3,3,3,3
1,1,3,0,0,0,0,0,0,0,3,3,3,3,3,2,2,2,0,0,0,0,4
1,1,3,6,0,0,0,0,0,0,3,3,3,3,3,2,0,0,0,0,0,0,4
1,1,3,3,0,0,0,0,0,0,3,3,3,3,3,2,0,0,0,0,0,10,3
1,1,3,2,0,0,0,0,0,2,2,0,0,0,2,2,0,0,0,0,0,2,4
1,1,17,2,2,2,2,2,2,2,0,0,0,0,0,2,0,0,0,0,0,2,1
1,1,1,1,1,2,2,14,14,2,0,0,0,0,0,2,0,0,0,0,0,2,1
1,1,1,1,1,1,7,14,14,2,0,0,0,0,0,2,2,2,2,2,2,2,1
1,1,1,1,1,1,7,4,4,2,0,0,0,0,0,2,2,2,2,2,2,5,1
1,1,1,1,4,4,4,2,2,2,0,0,0,7,3,2,4,5,1,1,1,1,1
1,7,3,3,4,3,2,2,2,2,2,2,2,2,2,2,1,1,1,1,1,1,1
3,2,2,2,2,2,3,0,0,0,0,21,2,3,5,1,1,1,1,1,1,1,1
2,0,0,0,0,2,17,0,0,0,0,0,2,2,1,1,1,1,1,1,1,1,1
2,0,0,0,0,3,0,0,0,0,0,0,2,2,2,2,2,1,1,1,1,1,1
2,18,0,0,0,3,0,0,0,0,0,0,2,2,2,2,2,6,1,1,1,1,1
2,4,0,0,0,3,0,0,0,0,0,0,2,3,3,3,3,4,1,1,1,1,1
1,1,4,0,0,0,2,2,2,2,2,2,2,3,0,0,0,4,1,1,1,1,1
1,1,4,0,0,0,2,2,17,2,2,2,2,18,0,0,0,0,2,3,1,1,1
1,1,2,2,2,2,2,1,1,1,7,3,0,0,0,0,0,0,0,3,1,1,1
1,1,1,1,1,1,1,1,1,1,3,3,0,0,0,0,0,0,0,3,1,1,1
1,1,1,1,1,1,1,1,1,1,3,3,0,0,0,2,0,0,0,3,1,1,1
1,1,1,1,1,1,1,1,1,1,4,3,3,3,3,3,3,3,3,4,1,1,1
1,1,1,1,1,1,1,1,1,1,17,4,3,3,3,3,1,1,1,1,1,1,1
endlayer

layer
1,1,3,4,2,2,4,1,1,1,1,1,1,1,1,1,1,1,1,1,1,1,1
1,1,3,0,11,22,2,2,2,2,3,5,1,1,1,1,1,3,4,4,3,3,4
1,1,3,0,11,22,11,11,11,11,3,4,1,1,7,4,2,2,22,11,11,11,3
1,1,3,0,11,22,11,11,11,11,3,4,4,6,3,2,23,11,22,11,11,11,3
1,1,3,6,11,22,11,11,11,11,3,3,3,3,3,11,11,11,22,11,11,10,3
1,1,3,2,2,2,11,11,11,2,2,11,11,11,2,11,11,11,22,11,11,4,3
1,1,1,7,2,17,2,2,2,2,11,11,11,11,2,11,11,11,22,11,11,2,1
1,1,1,1,1,1,1,1,1,2,11,11,11,11,2,2,24,23,22,11,11,2,1
1,1,1,1,1,1,1,1,1,2,9,9,9,9,9,2,2,17,2,2,2,4,1
1,1,1,1,1,1,1,1,1,1,23,11,11,11,11,2,4,1,7,2,5,1,1
1,1,1,1,1,1,1,4,2,6,23,0,0,0,7,2,4,1,1,1,1,1,1
1,1,7,3,6,3,4,2,2,2,2,2,2,2,2,4,1,1,1,1,1,1,1
3,3,2,2,2,3,25,11,11,22,11,11,2,5,1,1,1,1,1,1,1,1,1
4,11,11,11,11,2,0,11,11,22,11,11,2,3,1,1,1,1,1,1,1,1,1
2,11,11,11,11,2,0,11,11,22,11,11,4,2,2,2,4,1,1,1,1,1,1
2,18,11,11,11,2,0,11,11,22,11,11,2,2,2,2,5,1,1,1,1,1,1
4,2,9,9,9,9,24,24,23,22,11,11,2,2,2,2,2,2,1,1,1,1,1
1,1,2,11,11,11,2,2,17,2,2,2,2,2,11,26,11,2,1,1,1,1,1
1,1,2,11,11,11,2,4,1,2,2,3,4,18,11,26,11,11,4,3,1,1,1
1,1,2,4,2,2,4,1,1,1,1,3,11,11,11,26,11,11,11,3,1,1,1
1,1,1,1,1,1,1,1,1,1,6,3,11,11,11,26,11,11,11,3,1,1,1
1,1,1,1,1,1,1,1,1,1,4,3,11,11,11,4,11,11,11,3,1,1,1
1,1,1,1,1,1,1,1,1,1,17,3,3,3,3,3,3,3,3,3,1,1,1
1,1,1,1,1,1,1,1,1,1,1,3,3,4,4,4,1,1,1,1,1,1,1
endlayer

layer
1,1,4,2,2,2,2,1,1,1,1,1,1,1,1,1,1,1,1,1,1,1,1
1,1,3,0,0,0,3,3,3,2,4,1,1,1,1,1,1,4,3,3,3,3,4
1,1,3,0,0,0,0,0,0,0,28,1,1,1,1,1,1,2,0,0,27,0,3
1,1,3,0,0,0,0,0,0,0,3,1,1,1,4,29,3,0,0,0,0,0,3
1,1,3,0,0,0,0,0,0,0,3,3,29,3,3,0,0,0,0,0,0,0,3
1,1,4,2,30,3,0,0,0,2,2,0,0,0,3,0,0,0,0,0,0,2,4
1,1,1,1,1,1,3,4,2,2,0,0,0,10,3,0,0,0,0,0,0,2,1
1,1,1,1,1,1,1,1,1,2,0,0,0,0,3,2,3,3,0,0,0,2,1
1,1,1,1,1,1,1,1,1,4,0,0,0,0,0,2,1,1,4,30,3,2,1
1,1,1,1,1,1,1,1,1,1,3,0,0,0,0,28,1,1,1,1,1,1,1
1,1,1,1,1,1,1,31,1,1,3,0,0,0,0,2,31,1,1,1,1,1,1
1,1,1,1,1,4,2,4,29,2,2,2,2,2,2,2,1,1,1,1,1,1,1
4,3,4,29,3,3,0,0,0,0,0,0,2,1,1,1,1,1,1,1,1,1,1
2,0,27,0,0,2,0,0,0,0,0,0,28,1,1,1,1,1,1,1,1,1,1
2,0,0,0,0,3,0,0,0,0,0,0,2,1,1,1,1,1,1,1,1,1,1
2,18,0,0,0,3,0,0,0,0,0,0,11,2,1,1,1,1,1,1,1,1,1
2,3,0,0,0,0,2,3,3,0,0,0,11,3,3,29,3,4,1,1,1,1,1
1,1,3,0,0,10,2,1,1,4,0,0,11,3,0,0,0,3,1,1,1,1,1
1,1,3,0,0,0,28,1,1,3,3,3,2,18,0,0,0,0,2,4,1,1,1
1,1,2,2,2,2,2,1,1,1,1,3,0,0,0,0,0,0,0,3,1,1,1
1,1,1,1,1,1,1,1,1,1,1,3,0,0,0,0,0,0,0,3,1,1,1
1,1,1,1,1,1,1,1,1,1,1,32,0,0,10,2,0,0,0,3,1,1,1
1,1,1,1,1,1,1,1,1,1,1,3,0,0,0,3,3,3,3,4,1,1,1
1,1,1,1,1,1,1,1,1,1,1,4,3,3,3,4,1,1,1,1,1,1,1
endlayer

layer
1,1,4,4,2,0,2,1,1,1,1,1,1,1,1,1,1,1,1,1,1,1,1
1,1,3,0,0,0,3,3,0,2,4,1,1,1,1,1,1,4,3,0,4,3,4
1,1,4,0,0,0,0,0,0,0,33,1,1,1,1,1,1,3,0,0,27,0,3
1,1,0,0,0,0,0,0,0,0,3,1,1,1,4,34,3,0,0,0,0,0,0
1,1,3,0,0,0,0,0,0,0,3,3,33,3,3,0,0,0,0,0,0,0,3
1,1,4,2,34,3,0,0,0,2,2,0,0,0,3,0,0,0,0,0,0,2,4
1,1,1,1,1,1,3,0,2,2,0,0,0,10,3,0,0,0,0,0,0,0,1
1,1,1,1,1,1,1,1,1,2,0,0,0,0,3,2,3,3,0,0,0,2,1
1,1,1,1,1,1,1,1,1,4,0,0,0,0,0,2,1,1,4,34,3,4,1
1,1,1,1,1,1,1,1,1,1,3,0,0,0,0,34,1,1,1,1,1,1,1
1,1,1,1,1,1,1,31,1,1,3,0,0,0,0,2,31,1,1,1,1,1,1
1,1,1,1,1,4,4,4,34,2,2,2,2,2,0,4,1,1,1,1,1,1,1
4,3,4,33,3,3,0,0,0,0,0,0,2,1,1,1,1,1,1,1,1,1,1
4,0,27,0,0,2,0,0,0,0,0,0,34,1,1,1,1,1,1,1,1,1,1
0,0,0,0,0,3,0,0,0,0,0,0,2,1,1,1,1,1,1,1,1,1,1
3,0,0,0,0,3,0,0,0,0,0,0,19,2,1,1,1,1,1,1,1,1,1
2,3,0,0,0,0,2,3,4,0,0,0,19,3,3,33,3,4,1,1,1,1,1
1,1,3,0,0,10,2,1,1,4,0,0,20,3,0,0,0,3,1,1,1,1,1
1,1,0,0,0,0,33,1,1,3,3,3,2,0,0,0,0,0,2,4,1,1,1
1,1,3,2,0,2,4,1,1,1,1,3,0,0,0,0,0,0,0,3,1,1,1
1,1,1,1,1,1,1,1,1,1,1,3,0,0,0,0,0,0,0,0,1,1,1
1,1,1,1,1,1,1,1,1,1,1,33,0,0,10,2,0,0,0,3,1,1,1
1,1,1,1,1,1,1,1,1,1,1,3,11,11,11,3,3,0,3,4,1,1,1
1,1,1,1,1,1,1,1,1,1,1,4,3,3,3,4,1,1,1,1,1,1,1
endlayer

layer
1,1,3,2,2,2,2,1,1,1,1,1,1,1,1,1,1,1,1,1,1,1,1
1,1,3,0,0,0,3,3,3,2,3,1,1,1,1,1,1,3,3,3,3,3,3
1,1,4,0,0,0,0,0,0,0,4,1,1,1,1,1,1,2,0,0,0,35,3
1,1,4,0,0,0,0,0,0,0,3,11,11,11,3,2,3,0,0,0,0,35,3
1,1,4,0,0,0,0,0,0,0,3,4,4,4,3,0,0,0,0,0,0,35,3
1,1,3,2,3,3,0,0,0,2,2,36,36,36,3,0,0,0,0,0,0,2,3
1,1,1,1,1,1,4,2,2,2,0,0,0,0,3,0,0,0,0,0,0,2,1
1,1,1,1,1,1,1,1,1,2,0,0,0,0,3,2,3,3,0,0,0,2,1
1,1,1,1,1,1,1,1,1,2,0,0,0,0,0,2,11,11,4,3,3,2,1
1,1,1,1,1,1,1,1,1,11,3,0,0,0,0,2,11,1,1,1,1,1,1
1,1,1,1,1,1,1,31,1,11,3,0,0,0,0,2,37,1,1,1,1,1,1
1,1,1,1,1,3,2,2,2,2,2,2,2,2,2,2,1,1,1,1,1,1,1
3,3,3,4,3,3,0,0,0,0,0,0,2,11,1,1,1,1,1,1,1,1,1
2,11,0,0,0,2,0,0,0,0,0,0,2,11,1,1,1,1,1,1,1,1,1
2,11,0,0,0,3,0,0,0,0,0,0,2,11,1,1,1,1,1,1,1,1,1
2,11,0,0,0,3,0,0,0,0,0,0,0,2,1,1,1,1,1,1,1,1,1
2,3,0,0,0,0,2,3,3,0,0,0,0,3,3,3,3,3,1,1,1,1,1
1,1,3,0,0,0,2,1,1,4,0,0,0,3,0,0,0,3,1,1,1,1,1
1,1,3,38,38,35,2,1,1,3,3,3,2,0,0,0,0,0,2,3,1,1,1
1,1,2,2,2,2,2,1,1,1,1,3,0,0,0,0,0,0,0,3,1,1,1
1,1,1,1,1,1,1,1,1,1,1,3,0,0,0,0,0,0,0,3,1,1,1
1,1,1,1,1,1,1,1,1,1,1,3,0,0,0,2,0,0,0,3,1,1,1
1,1,1,1,1,1,1,1,1,1,1,3,20,19,19,3,3,3,3,3,1,1,1
1,1,1,1,1,1,1,1,1,1,1,3,3,3,3,3,1,1,1,1,1,1,1
endlayer

layer
1,1,4,4,2,2,4,1,1,1,1,1,1,1,1,1,1,1,1,1,1,1,1
1,1,3,0,0,0,3,6,6,6,6,1,1,1,1,1,1,4,3,3,3,3,4
1,1,3,0,0,0,23,39,39,39,5,1,1,1,1,1,1,3,23,0,0,0,3
1,1,3,0,0,0,23,39,41,39,5,1,1,1,4,3,3,40,23,0,0,0,3
1,1,3,0,0,0,23,39,39,39,3,3,3,3,3,0,0,0,23,0,0,0,3
1,1,4,2,3,3,23,39,39,2,2,0,0,0,3,0,0,0,40,40,40,4,4
1,1,1,1,1,1,7,17,17,2,0,0,0,0,3,0,0,0,23,0,0,2,1
1,1,1,1,1,1,1,1,1,2,0,0,0,0,3,3,3,3,23,0,0,2,1
1,1,1,1,1,1,1,1,1,2,40,40,40,40,40,5,1,1,2,3,3,4,1
1,1,1,1,1,1,1,1,1,1,7,39,39,15,39,5,1,1,1,1,1,1,1
1,1,1,1,1,1,1,36,36,36,7,39,39,39,39,5,1,1,1,1,1,1,1
1,1,1,1,1,4,4,2,2,2,2,2,5,17,17,17,1,1,1,1,1,1,1
4,3,3,3,3,3,0,0,0,3,0,0,2,1,1,1,1,1,1,1,1,1,1
4,20,0,0,0,2,0,0,0,3,0,0,2,1,1,1,1,1,1,1,1,1,1
2,19,0,0,0,3,0,0,0,3,0,0,4,1,1,1,1,1,1,1,1,1,1
2,19,0,0,0,3,0,0,0,3,3,3,3,2,1,1,1,1,1,1,1,1,1
4,3,40,40,40,40,2,3,3,3,0,0,0,3,6,3,6,4,1,1,1,1,1
1,1,7,0,0,0,5,36,36,2,0,0,0,3,0,0,0,5,1,1,1,1,1
1,1,7,0,0,0,5,36,36,3,3,3,4,23,0,0,0,3,6,4,1,1,1
1,1,17,17,17,17,5,1,1,1,1,4,40,40,40,42,40,40,40,5,1,1,1
1,1,1,1,1,1,1,1,1,1,1,42,0,0,0,42,39,43,39,5,1,1,1
1,1,1,1,1,1,1,1,1,1,1,42,0,0,0,4,39,39,39,5,1,1,1
1,1,1,1,1,1,1,1,1,1,1,42,0,0,0,3,17,17,17,4,1,1,1
1,1,1,1,1,1,1,1,1,1,1,4,40,40,40,4,1,1,1,1,1,1,1
endlayer

layer
1,1,4,4,24,4,4,1,1,1,1,1,1,1,1,1,1,1,1,1,1,1,1
1,1,4,0,0,0,4,1,1,1,1,1,1,1,1,1,1,25,4,4,4,4,25
1,1,42,0,0,0,23,1,1,1,1,1,1,1,1,1,1,4,25,25,25,25,4
1,1,42,0,0,0,23,1,0,1,1,1,1,1,1,1,1,4,25,35,25,25,4
1,1,4,0,0,0,4,1,1,1,6,6,6,6,6,25,25,4,25,25,25,25,4
1,1,4,4,40,4,4,1,1,6,7,36,36,36,5,25,44,25,4,4,4,4,25
1,1,1,1,1,1,1,1,1,7,36,36,21,36,5,25,25,25,25,44,25,25,1
1,1,1,1,1,1,1,1,1,7,36,36,36,36,5,1,1,1,25,25,25,25,1
1,1,1,1,1,1,1,1,1,7,17,17,17,17,5,1,1,1,1,25,25,1,1
1,1,1,1,1,1,1,1,1,1,1,1,1,0,1,1,1,1,1,1,1,1,1
1,1,1,1,1,1,1,1,1,1,1,1,1,1,1,1,1,1,1,1,1,1,1
1,1,1,1,1,7,6,6,6,6,6,6,1,1,1,1,1,1,1,1,1,1,1
4,4,4,4,4,4,25,25,25,4,39,39,5,1,1,1,1,1,1,1,1,1,1
4,0,0,0,0,4,25,25,25,4,41,39,5,1,1,1,1,1,1,1,1,1,1
4,0,0,0,0,4,25,44,25,4,39,39,5,1,1,1,1,1,1,1,1,1,1
4,0,0,0,0,4,25,25,25,5,17,17,25,1,1,1,1,1,1,1,1,1,1
4,4,4,4,4,4,17,17,17,17,25,21,25,1,1,1,1,1,1,1,1,1,1
1,1,1,25,21,25,1,1,1,1,25,25,25,1,25,25,25,1,1,1,1,1,1
1,1,1,25,25,25,1,1,1,1,1,1,1,1,25,38,25,1,1,1,1,1,1
1,1,1,1,1,1,1,1,1,1,1,4,4,4,4,4,25,1,1,1,1,1,1
1,1,1,1,1,1,1,1,1,1,1,4,45,45,45,4,1,0,1,1,1,1,1
1,1,1,1,1,1,1,1,1,1,1,4,45,46,45,4,1,1,1,1,1,1,1
1,1,1,1,1,1,1,1,1,1,1,4,45,45,45,4,1,1,1,1,1,1,1
1,1,1,1,1,1,1,1,1,1,1,4,4,4,4,4,1,1,1,1,1,1,1
endlayer

layer
1,1,1,25,1,25,1,1,1,1,1,1,1,1,1,1,1,1,1,1,1,1,1
1,1,25,25,25,25,25,1,1,1,1,1,1,1,1,1,1,1,1,1,1,1,1
1,1,1,25,25,25,1,1,1,1,1,1,1,1,1,1,1,1,1,1,1,1,1
1,1,1,25,21,25,1,1,0,1,1,1,1,1,1,1,1,1,1,0,1,1,1
1,1,25,25,25,25,25,1,1,1,1,1,1,1,1,1,1,1,1,1,1,1,1
1,1,1,25,1,25,1,1,1,1,1,1,1,1,1,1,0,1,1,1,1,1,1
1,1,1,1,1,1,1,1,1,1,1,1,0,1,1,1,1,1,1,0,1,1,1
1,1,1,1,1,1,1,1,1,1,1,1,1,1,1,1,1,1,1,1,1,1,1
1,1,1,1,1,1,1,1,1,1,1,1,1,1,1,1,1,1,1,1,1,1,1
1,1,1,1,1,1,1,1,1,1,1,1,1,0,1,1,1,1,1,1,1,1,1
1,1,1,1,1,1,1,1,1,1,1,1,1,1,1,1,1,1,1,1,1,1,1
1,1,1,1,1,1,1,1,1,1,1,1,1,1,1,1,1,1,1,1,1,1,1
25,4,6,6,4,25,1,1,1,1,1,1,1,1,1,1,1,1,1,1,1,1,1
4,36,36,36,36,4,1,1,1,1,0,1,1,1,1,1,1,1,1,1,1,1,1
7,36,36,44,36,5,1,0,1,1,1,1,1,1,1,1,1,1,1,1,1,1,1
4,36,36,36,36,4,1,1,1,1,1,1,1,1,1,1,1,1,1,1,1,1,1
25,4,17,17,4,25,1,1,1,1,1,0,1,1,1,1,1,1,1,1,1,1,1
1,1,1,1,0,1,1,1,1,1,1,1,1,1,1,1,1,1,1,1,1,1,1
1,1,1,1,1,1,1,1,1,1,1,1,1,1,1,0,1,1,1,1,1,1,1
1,1,1,1,1,1,1,1,1,1,1,1,1,1,1,1,1,1,1,1,1,1,1
1,1,1,1,1,1,1,1,1,1,1,1,1,1,1,1,1,0,1,1,1,1,1
1,1,1,1,1,1,1,1,1,1,1,1,1,0,1,1,1,1,1,1,1,1,1
1,1,1,1,1,1,1,1,1,1,1,1,1,1,1,1,1,1,1,1,1,1,1
1,1,1,1,1,1,1,1,1,1,1,1,1,1,1,1,1,1,1,1,1,1,1
endlayer

