
# Created by Ruins mod version 16.7 Ingame Parser
# authoring Player: lafuller

weight=1
embed_into_distance=2
acceptable_target_blocks=water
unacceptable_target_blocks=
biomesToSpawnIn=ocean,deep ocean,ocean oil field,kelp forest
dimensions=19,21,21
allowable_overhang=0
max_leveling=0
leveling_buffer=-1
preserve_water=0
preserve_lava=0

rule1=0,100,preserveBlock
rule2=0,100,minecraft:planks-5
rule3=0,100,minecraft:dark_oak_stairs-3
rule4=0,100,minecraft:dark_oak_stairs-1
rule5=0,100,minecraft:dark_oak_stairs-2
rule6=0,100,minecraft:spruce_stairs-4
rule7=0,100,minecraft:spruce_stairs-6
rule8=0,100,minecraft:planks-1
rule9=0,100,minecraft:spruce_stairs-1
rule10=0,100,ChestGenHook:chests/stronghold_library:5-3
rule11=0,100,minecraft:spruce_stairs-3
rule12=0,100,minecraft:spruce_stairs-0
rule13=0,100,minecraft:spruce_stairs-7
rule14=0,100,minecraft:spruce_stairs-2
rule15=0,100,minecraft:spruce_stairs-5
rule16=0,100,minecraft:spruce_door-2
rule17=0,100,minecraft:trapdoor-14
rule18=0,100,minecraft:dark_oak_stairs-4
rule19=0,100,minecraft:wooden_slab-9
rule20=0,100,minecraft:trapdoor-12
rule21=0,100,minecraft:trapdoor-8
rule22=0,100,minecraft:dark_oak_stairs-6
rule23=0,100,minecraft:trapdoor-13
rule24=0,100,minecraft:trapdoor-10
rule25=0,100,minecraft:wooden_slab-1
rule26=0,100,minecraft:trapdoor-9
rule27=0,100,minecraft:trapdoor-15
rule28=0,100,minecraft:spruce_door-8
rule29=0,100,minecraft:carpet-7
rule30=0,100,minecraft:carpet-8
rule31=0,100,minecraft:spruce_fence-0
rule32=0,100,minecraft:dark_oak_fence-0
rule33=0,100,minecraft:log-0
rule34=0,100,minecraft:ladder-5
rule35=0,100,minecraft:ladder-2
rule36=0,100,minecraft:wooden_slab-13
rule37=0,100,minecraft:wooden_slab-5
rule38=0,100,minecraft:wool-0
rule39=0,100,minecraft:spruce_fence_gate-2
rule40=0,100,minecraft:fence-0
rule41=0,100,minecraft:log-12
rule42=0,100,minecraft:log-8
rule43=0,100,minecraft:log-4
rule44=0,100,minecraft:trapdoor-0

layer
1,1,1,1,1,1,1,1,1,1,1,1,1,1,1,1,1,1,1,1,1
1,1,1,1,1,1,1,1,1,1,1,1,1,1,1,1,1,1,1,1,1
1,1,1,1,1,1,1,1,1,1,1,1,1,1,1,1,1,1,1,1,1
1,1,1,1,1,1,1,1,1,1,1,1,1,1,1,1,1,1,1,1,1
1,1,1,1,1,1,1,1,1,1,1,1,1,1,1,1,1,1,1,1,1
1,1,1,1,1,1,1,1,1,1,1,1,1,1,1,1,1,1,1,1,1
1,1,1,1,1,1,1,1,1,1,1,1,1,2,2,1,1,1,1,1,1
1,1,1,1,1,1,1,1,1,1,1,1,2,2,2,1,1,1,1,1,1
1,1,1,1,1,1,1,1,1,1,2,2,2,2,1,1,1,1,1,1,1
1,1,1,1,1,1,1,1,1,2,2,2,2,1,1,1,1,1,1,1,1
1,1,1,1,1,1,1,1,2,2,2,2,2,1,1,1,1,1,1,1,1
1,1,1,1,1,1,1,2,2,2,2,2,1,1,1,1,1,1,1,1,1
1,1,1,1,1,1,2,2,2,2,2,1,1,1,1,1,1,1,1,1,1
1,1,1,1,1,2,2,2,2,2,1,1,1,1,1,1,1,1,1,1,1
1,1,1,1,1,2,2,2,2,1,1,1,1,1,1,1,1,1,1,1,1
1,1,1,1,2,2,2,2,1,1,1,1,1,1,1,1,1,1,1,1,1
1,1,1,1,2,2,1,1,1,1,1,1,1,1,1,1,1,1,1,1,1
1,1,1,1,1,1,1,1,1,1,1,1,1,1,1,1,1,1,1,1,1
1,1,1,1,1,1,1,1,1,1,1,1,1,1,1,1,1,1,1,1,1
1,1,1,1,1,1,1,1,1,1,1,1,1,1,1,1,1,1,1,1,1
1,1,1,1,1,1,1,1,1,1,1,1,1,1,1,1,1,1,1,1,1
endlayer

layer
1,1,1,1,1,1,1,1,1,1,1,1,1,1,1,1,1,1,1,1,1
1,1,1,1,1,1,1,1,1,1,1,1,1,1,1,1,1,1,1,1,1
1,1,1,1,1,1,1,1,1,1,1,1,1,1,1,1,1,1,1,1,1
1,1,1,1,1,1,1,1,1,1,1,1,1,1,1,1,1,1,1,1,1
1,1,1,1,1,1,1,1,1,1,1,1,1,1,1,1,1,1,1,1,1
1,1,1,1,1,1,1,1,1,1,1,1,1,1,2,2,1,1,1,1,1
1,1,1,1,1,1,1,1,1,1,1,1,2,2,2,2,1,1,1,1,1
1,1,1,1,1,1,1,1,1,1,2,5,4,3,2,1,1,1,1,1,1
1,1,1,1,1,1,1,1,1,2,0,0,0,3,2,1,1,1,1,1,1
1,1,1,1,1,1,1,1,2,0,0,0,0,2,1,1,1,1,1,1,1
1,1,1,1,1,1,1,2,0,0,0,0,0,2,1,1,1,1,1,1,1
1,1,1,1,1,1,2,0,0,0,0,0,2,1,1,1,1,1,1,1,1
1,1,1,1,1,2,2,0,0,0,0,2,1,1,1,1,1,1,1,1,1
1,1,1,1,2,2,5,0,0,0,2,1,1,1,1,1,1,1,1,1,1
1,1,1,2,2,2,2,2,2,2,1,1,1,1,1,1,1,1,1,1,1
1,1,1,2,2,2,2,2,2,1,1,1,1,1,1,1,1,1,1,1,1
1,1,2,2,2,2,2,2,1,1,1,1,1,1,1,1,1,1,1,1,1
1,1,2,2,2,2,2,1,1,1,1,1,1,1,1,1,1,1,1,1,1
1,1,1,2,2,1,1,1,1,1,1,1,1,1,1,1,1,1,1,1,1
1,1,1,1,1,1,1,1,1,1,1,1,1,1,1,1,1,1,1,1,1
1,1,1,1,1,1,1,1,1,1,1,1,1,1,1,1,1,1,1,1,1
endlayer

layer
1,1,1,1,1,1,1,1,1,1,1,1,1,1,1,1,1,1,1,1,1
1,1,1,1,1,1,1,1,1,1,1,1,1,1,1,1,1,1,1,1,1
1,1,1,1,1,1,1,1,1,1,1,1,1,1,1,1,1,1,1,1,1
1,1,1,1,1,1,1,1,1,1,1,1,1,1,1,1,1,1,1,1,1
1,1,1,1,1,1,1,1,1,1,1,1,1,1,1,6,1,1,1,1,1
1,1,1,1,1,1,1,1,1,1,1,1,1,6,8,8,7,1,1,1,1
1,1,1,1,1,1,1,1,1,1,1,6,9,0,0,8,1,1,1,1,1
1,1,1,1,1,1,1,1,1,6,8,0,0,0,10,7,1,1,1,1,1
1,1,1,1,1,1,1,1,6,8,0,0,0,0,11,1,1,1,1,1,1
1,1,1,1,1,1,1,6,8,0,0,0,0,12,8,1,1,1,1,1,1
1,1,1,1,1,1,13,8,0,0,0,0,0,8,1,1,1,1,1,1,1
1,1,1,1,1,13,8,0,0,0,0,0,8,7,1,1,1,1,1,1,1
1,1,1,1,13,8,8,0,0,0,0,8,7,1,1,1,1,1,1,1,1
1,1,1,13,8,14,0,0,0,0,8,7,1,1,1,1,1,1,1,1,1
1,1,1,8,8,8,8,8,8,8,15,1,1,1,1,1,1,1,1,1,1
1,1,6,8,8,8,8,8,8,15,1,1,1,1,1,1,1,1,1,1,1
1,13,8,8,8,8,8,8,15,1,1,1,1,1,1,1,1,1,1,1,1
1,13,8,8,8,8,8,15,1,1,1,1,1,1,1,1,1,1,1,1,1
1,13,8,8,8,7,1,1,1,1,1,1,1,1,1,1,1,1,1,1,1
1,1,15,15,15,1,1,1,1,1,1,1,1,1,1,1,1,1,1,1,1
1,1,1,1,1,1,1,1,1,1,1,1,1,1,1,1,1,1,1,1,1
endlayer

layer
1,1,1,1,1,1,1,1,1,1,1,1,1,1,1,1,1,1,1,1,1
1,1,1,1,1,1,1,1,1,1,1,1,1,1,1,1,1,1,1,1,1
1,1,1,1,1,1,1,1,1,1,1,1,1,1,1,1,1,1,1,1,1
1,1,1,1,1,1,1,1,1,1,1,1,1,1,1,1,6,1,1,1,1
1,1,1,1,1,1,1,1,1,1,1,1,1,1,6,8,8,7,1,1,1
1,1,1,1,1,1,1,1,1,1,1,1,6,8,8,8,8,1,1,1,1
1,1,1,1,1,1,1,1,1,1,6,8,0,0,0,8,7,1,1,1,1
1,1,1,1,1,1,1,1,1,8,0,0,0,0,0,8,1,1,1,1,1
1,1,1,1,1,1,1,1,8,0,0,0,0,0,0,7,1,1,1,1,1
1,1,1,1,1,1,1,8,0,0,0,0,0,0,8,1,1,1,1,1,1
1,1,1,1,1,1,8,0,0,0,0,0,0,12,7,1,1,1,1,1,1
1,1,1,1,1,8,8,0,0,0,0,0,8,8,1,1,1,1,1,1,1
1,1,1,1,8,9,8,0,0,0,0,0,8,1,1,1,1,1,1,1,1
1,1,1,8,8,0,0,0,0,0,0,8,1,1,1,1,1,1,1,1,1
1,1,13,8,8,16,8,8,8,8,8,1,1,1,1,1,1,1,1,1,1
1,13,8,0,0,0,8,8,8,8,1,1,1,1,1,1,1,1,1,1,1
1,8,8,0,0,0,8,8,8,1,1,1,1,1,1,1,1,1,1,1,1
1,8,8,0,0,0,8,8,1,1,1,1,1,1,1,1,1,1,1,1,1
1,8,8,0,0,12,15,1,1,1,1,1,1,1,1,1,1,1,1,1,1
1,8,8,8,8,15,1,1,1,1,1,1,1,1,1,1,1,1,1,1,1
1,1,1,1,1,1,1,1,1,1,1,1,1,1,1,1,1,1,1,1,1
endlayer

layer
1,1,1,1,1,1,1,1,1,1,1,1,1,1,1,1,1,1,1,1,1
1,1,1,1,1,1,1,1,1,1,1,1,1,1,1,1,1,1,1,1,1
1,1,1,1,1,1,1,1,1,1,1,1,1,1,1,1,1,6,1,1,1
1,1,1,1,1,1,1,1,1,1,1,1,1,1,1,6,8,8,7,1,1
1,1,1,1,1,1,1,1,1,1,1,1,17,6,8,8,8,8,1,1,1
1,1,1,1,1,1,1,1,1,1,17,18,2,8,8,8,8,7,1,1,1
1,1,1,1,1,1,1,1,1,17,2,8,19,19,19,8,8,1,1,1,1
1,1,1,1,1,1,1,1,17,2,19,19,19,19,19,8,7,1,1,1,1
1,1,1,1,1,1,1,17,2,19,19,19,19,21,19,2,20,1,1,1,1
1,1,1,1,1,1,23,2,19,19,19,19,19,21,8,22,1,1,1,1,1
1,1,1,1,1,23,2,19,19,19,19,19,25,24,2,20,1,1,1,1,1
1,1,1,1,23,2,8,19,19,19,19,19,8,2,20,1,1,1,1,1,1
1,1,1,23,2,21,11,19,19,19,19,19,2,20,1,1,1,1,1,1,1
1,1,1,8,8,21,26,19,19,19,19,2,20,1,1,1,1,1,1,1,1
1,1,8,8,8,28,8,8,8,8,2,27,1,1,1,1,1,1,1,1,1
1,8,0,0,0,0,8,8,8,2,27,1,1,1,1,1,1,1,1,1,1
13,29,29,0,0,0,8,8,2,27,1,1,1,1,1,1,1,1,1,1,1
8,29,29,0,0,0,8,8,27,1,1,1,1,1,1,1,1,1,1,1,1
13,30,30,0,0,0,8,1,1,1,1,1,1,1,1,1,1,1,1,1,1
1,8,0,0,0,8,1,1,1,1,1,1,1,1,1,1,1,1,1,1,1
1,1,15,8,15,1,1,1,1,1,1,1,1,1,1,1,1,1,1,1,1
endlayer

layer
1,1,1,1,1,1,1,1,1,1,1,1,1,1,1,1,1,1,1,1,1
1,1,1,1,1,1,1,1,1,1,1,1,1,1,1,1,1,1,6,1,1
1,1,1,1,1,1,1,1,1,1,1,1,1,1,1,31,18,8,8,7,1
1,1,1,1,1,1,1,1,1,1,1,1,1,1,31,2,8,8,8,1,1
1,1,1,1,1,1,1,1,1,1,1,1,31,2,2,8,8,8,22,1,1
1,1,1,1,1,1,1,1,1,1,31,31,31,9,9,9,8,2,31,1,1
1,1,1,1,1,1,1,1,1,1,31,0,0,0,32,11,2,31,1,1,1
1,1,1,1,1,1,1,1,1,31,0,0,0,0,0,11,2,1,1,1,1
1,1,1,1,1,1,1,1,31,0,0,0,0,0,0,31,31,1,1,1,1
1,1,1,1,1,1,1,31,0,0,0,0,0,0,0,31,1,1,1,1,1
1,1,1,1,1,31,31,0,0,0,33,0,0,0,31,31,1,1,1,1,1
1,1,1,1,31,31,0,0,0,0,34,0,0,31,1,1,1,1,1,1,1
1,1,1,31,31,0,0,0,0,0,0,0,31,1,1,1,1,1,1,1,1
1,1,32,8,8,0,0,0,0,0,0,31,1,1,1,1,1,1,1,1,1
1,1,8,8,8,6,8,0,0,0,31,1,1,1,1,1,1,1,1,1,1
31,8,0,0,0,0,8,35,0,31,31,1,1,1,1,1,1,1,1,1,1
15,0,0,0,0,0,8,8,31,31,1,1,1,1,1,1,1,1,1,1,1
8,0,0,0,0,0,8,8,31,1,1,1,1,1,1,1,1,1,1,1,1
6,0,0,0,0,0,8,32,1,1,1,1,1,1,1,1,1,1,1,1,1
31,8,0,0,0,8,1,1,1,1,1,1,1,1,1,1,1,1,1,1,1
1,31,7,8,13,31,1,1,1,1,1,1,1,1,1,1,1,1,1,1,1
endlayer

layer
1,1,1,1,1,1,1,1,1,1,1,1,1,1,1,1,1,1,1,18,36
1,1,1,1,1,1,1,1,1,1,1,1,1,1,1,1,1,1,3,8,22
1,1,1,1,1,1,1,1,1,1,1,1,1,1,1,31,31,37,2,4,1
1,1,1,1,1,1,1,1,1,1,1,1,1,31,31,31,0,25,37,1,1
1,1,1,1,1,1,1,1,1,1,1,1,31,31,0,0,0,0,31,1,1
1,1,1,1,1,1,1,1,1,1,1,0,0,0,0,0,0,31,31,1,1
1,1,1,1,1,1,1,1,1,1,0,0,0,0,32,0,0,31,1,1,1
1,1,1,1,1,1,1,1,1,0,0,0,0,0,0,0,31,31,1,1,1
1,1,1,1,1,1,1,1,0,0,0,0,0,0,0,0,31,1,1,1,1
1,1,1,1,1,1,1,0,0,0,0,0,0,0,0,0,1,1,1,1,1
1,1,1,1,1,1,0,0,0,0,33,0,0,0,0,1,1,1,1,1,1
1,1,1,1,1,0,0,0,0,0,34,0,0,0,1,1,1,1,1,1,1
1,1,1,1,0,0,0,0,0,0,0,0,0,1,1,1,1,1,1,1,1
1,1,1,12,12,0,0,0,0,0,0,0,1,1,1,1,1,1,1,1,1
1,32,8,8,8,8,8,0,0,0,0,1,1,1,1,1,1,1,1,1,1
32,8,8,8,8,8,8,35,0,0,1,1,1,1,1,1,1,1,1,1,1
8,8,8,8,8,8,8,14,0,1,1,1,1,1,1,1,1,1,1,1,1
8,8,8,8,8,8,8,14,1,1,1,1,1,1,1,1,1,1,1,1,1
8,8,8,8,8,8,8,1,1,1,1,1,1,1,1,1,1,1,1,1,1
32,8,8,8,8,8,32,1,1,1,1,1,1,1,1,1,1,1,1,1,1
1,32,8,8,8,32,1,1,1,1,1,1,1,1,1,1,1,1,1,1,1
endlayer

layer
1,1,1,1,1,1,1,1,1,1,1,1,1,1,1,1,1,1,1,0,37
1,1,1,1,1,1,1,1,1,1,1,1,1,1,1,1,1,1,0,37,0
1,1,1,1,1,1,1,1,1,1,1,1,1,1,1,1,0,0,0,0,1
1,1,1,1,1,1,1,1,1,1,1,1,1,1,0,0,0,0,0,1,1
1,1,1,1,1,1,1,1,1,1,1,1,1,0,0,0,0,0,0,1,1
1,1,1,1,1,1,1,1,1,1,1,0,0,0,0,0,0,0,1,1,1
1,1,1,1,1,1,1,1,1,1,0,0,0,0,32,0,0,0,1,1,1
1,1,1,1,1,1,1,1,1,38,38,0,0,0,0,0,0,1,1,1,1
1,1,1,1,1,1,1,1,0,0,31,38,38,0,0,0,1,1,1,1,1
1,1,1,1,1,1,1,0,0,0,0,0,38,38,0,0,1,1,1,1,1
1,1,1,1,1,1,0,0,0,0,33,0,31,38,0,1,1,1,1,1,1
1,1,1,1,1,0,0,0,0,0,34,0,0,31,38,1,1,1,1,1,1
1,1,1,1,0,0,0,0,0,0,0,0,0,1,1,1,1,1,1,1,1
1,1,1,0,0,0,0,0,0,0,0,0,1,1,1,1,1,1,1,1,1
1,1,25,25,25,25,0,0,0,0,0,1,1,1,1,1,1,1,1,1,1
1,12,25,25,25,8,25,0,0,0,1,1,1,1,1,1,1,1,1,1,1
11,14,25,25,25,25,25,0,0,1,1,1,1,1,1,1,1,1,1,1,1
11,14,25,2,25,25,25,0,1,1,1,1,1,1,1,1,1,1,1,1,1
9,12,25,25,25,25,25,1,1,1,1,1,1,1,1,1,1,1,1,1,1
32,8,14,12,12,14,1,1,1,1,1,1,1,1,1,1,1,1,1,1,1
1,32,11,9,9,1,1,1,1,1,1,1,1,1,1,1,1,1,1,1,1
endlayer

layer
1,1,1,1,1,1,1,1,1,1,1,1,1,1,39,1,1,1,1,0,0
1,1,1,1,1,1,1,1,1,1,1,1,1,1,39,1,1,1,0,0,0
1,1,1,1,1,1,1,1,1,1,1,1,1,1,39,1,0,0,0,0,1
1,1,1,1,1,1,1,1,1,1,1,1,1,1,39,0,0,0,0,1,1
1,1,1,1,1,1,1,1,1,1,1,1,1,0,39,0,0,0,0,1,1
1,1,1,1,1,1,1,1,38,1,1,0,0,0,39,0,0,0,1,1,1
1,1,1,1,1,1,1,1,1,38,38,0,0,0,32,0,0,0,1,1,1
1,1,1,1,1,1,1,1,1,0,38,38,38,0,32,0,0,1,1,1,1
1,1,1,1,1,1,1,1,0,0,0,0,38,38,0,0,1,1,1,1,1
1,1,1,1,1,1,1,0,0,0,0,0,0,38,0,0,1,1,1,1,1
1,1,1,1,1,1,0,0,0,0,33,0,0,0,38,1,1,1,1,1,1
1,1,1,1,1,0,0,0,0,0,34,0,0,0,1,38,1,1,1,1,1
1,1,1,1,0,0,0,0,0,0,0,0,0,1,1,1,1,1,1,1,1
1,1,1,0,0,0,0,0,0,0,0,0,1,1,1,1,1,1,1,1,1
1,1,0,0,0,0,0,0,0,0,0,1,1,1,1,1,1,1,1,1,1
1,0,0,0,0,44,0,0,0,0,1,1,1,1,1,1,1,1,1,1,1
0,32,0,0,0,0,0,0,0,1,1,1,1,1,1,1,1,1,1,1,1
0,32,0,32,0,0,0,0,1,1,1,1,1,1,1,1,1,1,1,1,1
0,32,0,0,0,0,0,1,1,1,1,1,1,1,1,1,1,1,1,1,1
1,0,32,32,32,0,1,1,1,1,1,1,1,1,1,1,1,1,1,1,1
1,1,0,0,0,1,1,1,1,1,1,1,1,1,1,1,1,1,1,1,1
endlayer

layer
1,1,1,1,1,1,1,1,1,1,1,1,1,1,38,1,1,1,1,0,0
1,1,1,1,1,1,1,1,1,1,1,1,1,1,1,38,1,1,0,0,0
1,1,1,1,1,1,1,1,1,1,1,1,1,1,1,38,0,0,0,0,1
1,1,1,1,1,1,1,1,1,1,1,1,1,1,0,38,0,0,0,1,1
1,1,1,1,1,1,1,1,1,1,1,1,1,0,0,38,0,0,0,1,1
1,1,1,1,1,1,1,1,38,38,1,0,0,0,0,38,0,0,1,1,1
1,1,1,1,1,1,1,1,1,38,38,38,0,0,32,0,0,0,1,1,1
1,1,1,1,1,1,1,1,1,0,0,0,38,38,32,0,0,1,1,1,1
1,1,1,1,1,1,1,1,0,0,0,0,0,38,0,0,1,1,1,1,1
1,1,1,1,1,1,1,0,0,0,0,0,0,0,38,0,1,1,1,1,1
1,1,1,1,1,1,0,0,0,0,33,0,0,0,38,38,1,1,1,1,1
1,1,1,1,1,0,0,0,0,0,34,0,0,0,1,38,1,1,1,1,1
1,1,1,39,0,0,0,0,0,0,0,0,0,1,1,1,38,1,1,1,1
1,1,1,39,0,0,0,0,0,0,0,0,1,1,1,1,1,1,1,1,1
1,1,0,39,0,0,0,0,0,0,0,1,1,1,1,1,1,1,1,1,1
1,0,0,39,0,0,0,0,0,0,1,1,1,1,1,1,1,1,1,1,1
0,0,0,39,0,0,0,0,0,1,1,1,1,1,1,1,1,1,1,1,1
0,0,0,32,0,0,0,0,1,1,1,1,1,1,1,1,1,1,1,1,1
0,0,0,32,0,0,0,1,1,1,1,1,1,1,1,1,1,1,1,1,1
1,0,0,0,0,0,1,1,1,1,1,1,1,1,1,1,1,1,1,1,1
1,1,0,0,0,1,1,1,1,1,1,1,1,1,1,1,1,1,1,1,1
endlayer

layer
1,1,1,1,1,1,1,1,1,1,1,1,1,1,1,38,1,1,1,1,1
1,1,1,1,1,1,1,1,1,1,1,1,1,1,1,38,1,1,0,0,1
1,1,1,1,1,1,1,1,1,1,1,1,1,1,1,38,38,0,0,0,1
1,1,1,1,1,1,1,1,1,1,1,1,1,1,0,38,38,0,0,1,1
1,1,1,1,1,1,1,1,38,1,1,1,1,0,0,38,38,0,1,1,1
1,1,1,1,1,1,1,1,38,38,38,1,0,0,0,38,0,0,1,1,1
1,1,1,1,1,1,1,1,1,38,38,38,0,0,32,38,0,1,1,1,1
1,1,1,1,1,1,1,1,1,0,0,0,38,38,0,0,1,1,1,1,1
1,1,1,1,1,1,1,1,0,0,0,0,0,38,38,0,1,1,1,1,1
1,1,1,1,1,1,1,0,0,0,0,0,0,0,38,1,1,1,1,1,1
1,1,1,1,1,1,0,0,0,0,33,0,0,0,38,1,1,1,1,1,1
1,1,1,38,1,0,0,0,0,0,34,0,0,0,1,38,1,1,1,1,1
1,1,1,1,38,0,0,0,0,0,0,0,0,1,1,1,38,1,1,1,1
1,1,1,0,0,38,0,0,0,0,0,0,1,1,1,1,1,1,1,1,1
1,1,0,0,0,38,0,0,0,0,0,1,1,1,1,1,1,1,1,1,1
1,0,0,0,38,38,0,0,0,0,1,1,1,1,1,1,1,1,1,1,1
0,0,0,38,38,0,0,0,0,1,1,1,1,1,1,1,1,1,1,1,1
0,0,0,32,38,0,0,0,1,1,1,1,1,1,1,1,1,1,1,1,1
0,0,0,32,0,0,0,1,1,1,1,1,1,1,1,1,1,1,1,1,1
1,0,0,0,0,0,1,1,1,1,1,1,1,1,1,1,1,1,1,1,1
1,1,0,0,0,1,1,1,1,1,1,1,1,1,1,1,1,1,1,1,1
endlayer

layer
1,1,1,1,1,1,1,1,1,1,1,1,1,1,1,1,38,1,1,1,1
1,1,1,1,1,1,1,1,1,1,1,1,1,1,1,1,38,1,1,1,1
1,1,1,1,1,1,1,1,1,1,1,1,1,1,1,1,38,0,0,1,1
1,1,1,1,1,1,1,1,1,1,1,1,1,1,1,0,38,38,0,1,1
1,1,1,1,1,1,1,38,38,1,1,1,1,1,0,0,38,0,1,1,1
1,1,1,1,1,1,1,1,1,38,1,1,1,0,0,38,38,1,1,1,1
1,1,1,1,1,1,1,1,1,1,38,38,38,0,32,38,0,1,1,1,1
1,1,1,1,1,1,1,1,1,1,0,0,0,38,0,0,1,1,1,1,1
1,1,1,1,1,1,1,1,1,0,0,0,0,38,38,1,1,1,1,1,1
1,1,1,1,1,1,1,1,0,0,0,0,0,0,38,1,1,1,1,1,1
1,1,1,1,1,1,1,0,0,0,33,0,0,0,1,38,1,1,1,1,1
1,1,1,1,38,1,0,0,0,0,34,0,0,1,1,38,1,1,1,1,1
1,1,1,38,38,0,0,0,0,0,0,0,1,1,1,1,38,1,1,1,1
1,1,1,0,38,38,0,0,0,0,0,1,1,1,1,1,38,1,1,1,1
1,1,1,0,38,38,38,0,0,0,1,1,1,1,1,1,1,1,1,1,1
1,1,0,0,38,38,38,0,0,1,1,1,1,1,1,1,1,1,1,1,1
1,0,0,0,38,38,0,0,1,1,1,1,1,1,1,1,1,1,1,1,1
0,0,0,32,0,0,0,1,1,1,1,1,1,1,1,1,1,1,1,1,1
1,0,0,0,0,0,1,1,1,1,1,1,1,1,1,1,1,1,1,1,1
1,1,0,0,0,1,1,1,1,1,1,1,1,1,1,1,1,1,1,1,1
1,1,1,0,1,1,1,1,1,1,1,1,1,1,1,1,1,1,1,1,1
endlayer

layer
1,1,1,1,1,1,1,1,1,1,1,1,1,1,1,1,1,1,1,1,1
1,1,1,1,1,1,1,1,1,1,1,1,1,1,1,1,38,1,1,1,1
1,1,1,1,1,1,1,1,1,1,1,1,1,1,1,1,38,38,1,1,1
1,1,1,1,1,1,1,1,1,1,1,1,1,1,1,1,38,38,1,1,1
1,1,1,1,1,1,1,38,38,1,1,1,1,1,1,0,38,38,1,1,1
1,1,1,1,1,1,1,38,1,38,38,1,1,1,1,0,38,1,1,1,1
1,1,1,1,1,1,1,1,1,1,1,38,38,0,31,38,1,1,1,1,1
1,1,1,1,1,1,1,1,1,1,1,0,38,38,0,1,1,1,1,1,1
1,1,1,1,1,1,1,1,1,1,0,0,0,38,38,1,1,1,1,1,1
1,1,1,1,1,1,1,1,1,0,0,0,0,0,38,1,1,1,1,1,1
1,1,1,1,1,1,1,1,0,0,33,0,0,0,1,38,1,1,1,1,1
1,1,1,1,1,1,1,0,0,0,34,0,0,1,1,38,1,1,1,1,1
1,1,1,1,1,38,0,0,0,0,0,1,1,1,1,1,38,1,1,1,1
1,1,1,1,38,38,38,0,0,0,1,1,1,1,1,1,38,1,1,1,1
1,1,1,1,0,38,38,0,0,1,1,1,1,1,1,1,1,1,1,1,1
1,1,1,0,0,38,0,0,1,1,1,1,1,1,1,1,1,1,1,1,1
1,1,0,0,38,0,1,1,1,1,1,1,1,1,1,1,1,1,1,1,1
1,0,0,31,38,1,1,1,1,1,1,1,1,1,1,1,1,1,1,1,1
1,1,0,0,0,1,1,1,1,1,1,1,1,1,1,1,1,1,1,1,1
1,1,1,0,1,1,1,1,1,1,1,1,1,1,1,1,1,1,1,1,1
1,1,1,1,1,1,1,1,1,1,1,1,1,1,1,1,1,1,1,1,1
endlayer

layer
1,1,1,1,1,1,1,1,1,1,1,1,1,1,1,1,1,1,1,1,1
1,1,1,1,1,1,1,1,1,1,1,1,1,1,1,1,1,1,1,1,1
1,1,1,1,1,1,1,1,1,1,1,1,1,1,1,38,1,1,1,1,1
1,1,1,1,1,1,1,1,1,1,1,1,1,1,1,38,38,1,1,1,1
1,1,1,1,1,1,1,38,1,1,1,1,1,1,1,38,38,38,1,1,1
1,1,1,1,1,1,1,38,38,38,1,1,1,1,1,38,38,1,1,1,1
1,1,1,1,1,1,1,1,1,1,38,38,1,1,31,38,1,1,1,1,1
1,1,1,1,1,1,1,1,1,1,1,1,38,1,1,1,1,1,1,1,1
1,1,1,1,1,1,1,1,1,1,1,0,0,38,1,1,1,1,1,1,1
1,1,1,1,1,1,1,1,1,1,0,0,0,0,38,1,1,1,1,1,1
1,1,1,1,1,1,1,1,1,0,33,0,0,1,38,1,1,1,1,1,1
1,1,1,1,1,1,1,1,0,0,34,1,1,1,1,38,1,1,1,1,1
1,1,1,1,38,1,1,0,0,0,1,1,1,1,1,38,1,1,1,1,1
1,1,1,1,38,1,0,0,0,1,1,1,1,1,1,1,38,1,1,1,1
1,1,1,1,38,38,0,0,1,1,1,1,1,1,1,1,1,1,1,1,1
1,1,1,1,38,38,38,1,1,1,1,1,1,1,1,1,1,1,1,1,1
1,1,1,0,38,38,1,1,1,1,1,1,1,1,1,1,1,1,1,1,1
1,1,0,31,38,1,1,1,1,1,1,1,1,1,1,1,1,1,1,1,1
1,1,1,0,1,1,1,1,1,1,1,1,1,1,1,1,1,1,1,1,1
1,1,1,1,1,1,1,1,1,1,1,1,1,1,1,1,1,1,1,1,1
1,1,1,1,1,1,1,1,1,1,1,1,1,1,1,1,1,1,1,1,1
endlayer

layer
1,1,1,1,1,1,1,1,1,1,1,1,1,1,1,1,1,1,1,1,1
1,1,1,1,1,1,1,1,1,1,1,1,1,1,1,1,1,1,1,1,1
1,1,1,1,1,1,1,1,1,1,1,1,1,1,1,1,38,1,1,1,1
1,1,1,1,1,1,1,1,1,1,1,1,1,1,1,1,38,1,1,1,1
1,1,1,1,1,1,1,1,1,1,1,1,1,1,1,38,38,1,1,1,1
1,1,1,1,1,1,1,38,38,1,1,1,1,1,1,38,38,1,1,1,1
1,1,1,1,1,1,1,1,1,38,1,1,1,1,31,38,1,1,1,1,1
1,1,1,1,1,1,1,1,1,1,38,38,1,1,1,1,1,1,1,1,1
1,1,1,1,1,1,1,1,1,1,1,0,38,1,1,1,1,1,1,1,1
1,1,1,1,1,1,1,1,1,1,1,0,0,38,1,1,1,1,1,1,1
1,1,1,1,1,1,1,1,1,1,33,1,1,38,1,1,1,1,1,1,1
1,1,1,1,1,1,1,1,1,0,34,1,1,1,38,1,1,1,1,1,1
1,1,1,1,1,1,1,1,0,1,1,1,1,1,1,38,1,1,1,1,1
1,1,1,1,38,1,1,0,1,1,1,1,1,1,1,38,1,1,1,1,1
1,1,1,38,38,38,0,1,1,1,1,1,1,1,1,1,1,1,1,1,1
1,1,1,38,38,38,1,1,1,1,1,1,1,1,1,1,1,1,1,1,1
1,1,1,38,38,38,1,1,1,1,1,1,1,1,1,1,1,1,1,1,1
1,1,1,31,1,1,1,1,1,1,1,1,1,1,1,1,1,1,1,1,1
1,1,1,1,1,1,1,1,1,1,1,1,1,1,1,1,1,1,1,1,1
1,1,1,1,1,1,1,1,1,1,1,1,1,1,1,1,1,1,1,1,1
1,1,1,1,1,1,1,1,1,1,1,1,1,1,1,1,1,1,1,1,1
endlayer

layer
1,1,1,1,1,1,1,1,1,1,1,1,1,1,1,1,1,1,1,1,1
1,1,1,1,1,1,1,1,1,1,1,1,1,1,1,1,1,1,1,1,1
1,1,1,1,1,1,1,1,1,1,1,1,1,1,1,1,1,1,1,1,1
1,1,1,1,1,1,1,1,1,1,1,1,1,1,1,38,1,1,1,1,1
1,1,1,1,1,1,1,1,1,1,1,1,1,1,38,38,38,1,1,1,1
1,1,1,1,1,1,38,38,1,1,1,1,1,1,38,38,1,1,1,1,1
1,1,1,1,1,1,1,1,38,1,1,1,1,1,31,1,1,1,1,1,1
1,1,1,1,1,1,1,1,1,38,1,1,1,1,1,1,1,1,1,1,1
1,1,1,1,1,1,1,1,1,1,38,38,1,1,1,1,1,1,1,1,1
1,1,1,1,1,1,1,1,1,1,1,38,38,1,1,1,1,1,1,1,1
1,1,1,1,1,1,1,1,1,1,33,1,38,1,1,1,1,1,1,1,1
1,1,1,1,1,1,1,1,1,1,34,1,1,38,1,1,1,1,1,1,1
1,1,1,1,1,1,1,1,1,1,1,1,1,1,38,1,1,1,1,1,1
1,1,1,1,1,1,1,1,1,1,1,1,1,1,1,38,1,1,1,1,1
1,1,1,1,38,1,1,1,1,1,1,1,1,1,1,38,1,1,1,1,1
1,1,1,1,38,38,1,1,1,1,1,1,1,1,1,1,1,1,1,1,1
1,1,1,38,38,1,1,1,1,1,1,1,1,1,1,1,1,1,1,1,1
1,1,1,31,1,1,1,1,1,1,1,1,1,1,1,1,1,1,1,1,1
1,1,1,1,1,1,1,1,1,1,1,1,1,1,1,1,1,1,1,1,1
1,1,1,1,1,1,1,1,1,1,1,1,1,1,1,1,1,1,1,1,1
1,1,1,1,1,1,1,1,1,1,1,1,1,1,1,1,1,1,1,1,1
endlayer

layer
1,1,1,1,1,1,1,1,1,1,1,1,1,1,1,1,1,1,1,1,1
1,1,1,1,1,1,1,1,1,1,1,1,1,1,1,1,1,1,1,1,1
1,1,1,1,1,1,1,1,1,1,1,1,1,1,1,1,1,1,1,1,1
1,1,1,1,1,1,1,1,1,1,1,1,1,1,1,1,1,1,1,1,1
1,1,1,1,1,1,1,1,1,1,1,1,1,1,1,1,1,1,1,1,1
1,1,1,1,1,1,1,40,1,1,1,1,1,1,38,1,1,1,1,1,1
1,1,1,1,1,1,42,41,40,1,1,1,1,1,31,1,1,1,1,1,1
1,1,1,1,1,1,1,41,41,40,1,1,1,1,1,1,1,1,1,1,1
1,1,1,1,1,1,1,1,41,41,31,1,1,1,1,1,1,1,1,1,1
1,1,1,1,1,1,1,1,31,41,41,31,1,1,1,1,1,1,1,1,1
1,1,1,1,1,1,1,1,31,25,33,41,31,1,1,1,1,1,1,1,1
1,1,1,1,1,1,1,1,1,25,34,41,41,40,1,1,1,1,1,1,1
1,1,1,1,1,1,1,1,1,1,31,31,41,41,40,1,1,1,1,1,1
1,1,1,1,1,1,1,1,1,1,1,1,1,41,41,40,1,1,1,1,1
1,1,1,1,1,1,1,1,1,1,1,1,1,1,43,1,1,1,1,1,1
1,1,1,38,1,1,1,1,1,1,1,1,1,1,1,1,1,1,1,1,1
1,1,1,38,38,1,1,1,1,1,1,1,1,1,1,1,1,1,1,1,1
1,1,1,31,1,1,1,1,1,1,1,1,1,1,1,1,1,1,1,1,1
1,1,1,1,1,1,1,1,1,1,1,1,1,1,1,1,1,1,1,1,1
1,1,1,1,1,1,1,1,1,1,1,1,1,1,1,1,1,1,1,1,1
1,1,1,1,1,1,1,1,1,1,1,1,1,1,1,1,1,1,1,1,1
endlayer

layer
1,1,1,1,1,1,1,1,1,1,1,1,1,1,1,1,1,1,1,1,1
1,1,1,1,1,1,1,1,1,1,1,1,1,1,1,1,1,1,1,1,1
1,1,1,1,1,1,1,1,1,1,1,1,1,1,1,1,1,1,1,1,1
1,1,1,1,1,1,1,1,1,1,1,1,1,1,1,1,1,1,1,1,1
1,1,1,1,1,1,1,1,1,1,1,1,1,1,1,1,1,1,1,1,1
1,1,1,1,1,1,1,1,1,1,1,1,1,1,1,1,1,1,1,1,1
1,1,1,1,1,1,1,1,1,1,1,1,1,1,1,1,1,1,1,1,1
1,1,1,1,1,1,1,1,1,1,1,1,1,1,1,1,1,1,1,1,1
1,1,1,1,1,1,1,1,1,31,31,1,1,1,1,1,1,1,1,1,1
1,1,1,1,1,1,1,1,31,0,0,0,1,1,1,1,1,1,1,1,1
1,1,1,1,1,1,1,1,31,0,33,0,31,1,1,1,1,1,1,1,1
1,1,1,1,1,1,1,1,31,0,0,0,31,1,1,1,1,1,1,1,1
1,1,1,1,1,1,1,1,1,31,31,31,1,1,1,1,1,1,1,1,1
1,1,1,1,1,1,1,1,1,1,1,1,1,1,1,1,1,1,1,1,1
1,1,1,1,1,1,1,1,1,1,1,1,1,1,1,1,1,1,1,1,1
1,1,1,1,1,1,1,1,1,1,1,1,1,1,1,1,1,1,1,1,1
1,1,1,38,1,1,1,1,1,1,1,1,1,1,1,1,1,1,1,1,1
1,1,1,31,1,1,1,1,1,1,1,1,1,1,1,1,1,1,1,1,1
1,1,1,1,1,1,1,1,1,1,1,1,1,1,1,1,1,1,1,1,1
1,1,1,1,1,1,1,1,1,1,1,1,1,1,1,1,1,1,1,1,1
1,1,1,1,1,1,1,1,1,1,1,1,1,1,1,1,1,1,1,1,1
endlayer

layer
1,1,1,1,1,1,1,1,1,1,1,1,1,1,1,1,1,1,1,1,1
1,1,1,1,1,1,1,1,1,1,1,1,1,1,1,1,1,1,1,1,1
1,1,1,1,1,1,1,1,1,1,1,1,1,1,1,1,1,1,1,1,1
1,1,1,1,1,1,1,1,1,1,1,1,1,1,1,1,1,1,1,1,1
1,1,1,1,1,1,1,1,1,1,1,1,1,1,1,1,1,1,1,1,1
1,1,1,1,1,1,1,1,1,1,1,1,1,1,1,1,1,1,1,1,1
1,1,1,1,1,1,1,1,1,1,1,1,1,1,1,1,1,1,1,1,1
1,1,1,1,1,1,1,1,1,1,1,1,1,1,1,1,1,1,1,1,1
1,1,1,1,1,1,1,1,1,1,1,1,1,1,1,1,1,1,1,1,1
1,1,1,1,1,1,1,1,1,0,0,0,1,1,1,1,1,1,1,1,1
1,1,1,1,1,1,1,1,1,0,33,0,1,1,1,1,1,1,1,1,1
1,1,1,1,1,1,1,1,1,0,0,0,1,1,1,1,1,1,1,1,1
1,1,1,1,1,1,1,1,1,1,1,1,1,1,1,1,1,1,1,1,1
1,1,1,1,1,1,1,1,1,1,1,1,1,1,1,1,1,1,1,1,1
1,1,1,1,1,1,1,1,1,1,1,1,1,1,1,1,1,1,1,1,1
1,1,1,1,1,1,1,1,1,1,1,1,1,1,1,1,1,1,1,1,1
1,1,1,1,1,1,1,1,1,1,1,1,1,1,1,1,1,1,1,1,1
1,1,1,1,1,1,1,1,1,1,1,1,1,1,1,1,1,1,1,1,1
1,1,1,1,1,1,1,1,1,1,1,1,1,1,1,1,1,1,1,1,1
1,1,1,1,1,1,1,1,1,1,1,1,1,1,1,1,1,1,1,1,1
1,1,1,1,1,1,1,1,1,1,1,1,1,1,1,1,1,1,1,1,1
endlayer

