
# Created by Ruins mod version 16.5 Ingame Parser
# authoring Player: lafuller

weight=1
embed_into_distance=9
acceptable_target_blocks=
unacceptable_target_blocks=dirt,stone,flowing_lava,lava,ice,bedrock,netherrack,nether_brick,nether_brick_fence,soul_sand,quartz_ore,gravel,end_stone,obsidian,iron_bars,cloud,flesh,ash_block,slime_grass,slime_congealed,slime_dirt
biomesToSpawnIn=swampland,wetland,marsh,lush swamp
dimensions=21,11,10
allowable_overhang=0
max_leveling=4
leveling_buffer=-1
preserve_water=0
preserve_lava=0

rule1=0,100,preserveBlock
rule2=0,100,minecraft:log2-1
rule3=0,100,minecraft:trapdoor-2
rule4=0,100,minecraft:spruce_stairs-0
rule5=0,100,minecraft:planks-1
rule6=0,100,minecraft:trapdoor-1
rule7=0,100,minecraft:spruce_fence-0
rule8=0,100,minecraft:spruce_stairs-6
rule9=0,100,minecraft:spruce_stairs-4
rule10=0,100,minecraft:ladder-3
rule11=0,100,minecraft:spruce_stairs-3
rule12=0,100,minecraft:wooden_slab-9
rule13=0,100,minecraft:spruce_stairs-7
rule14=0,100,minecraft:spruce_stairs-5
rule15=0,100,minecraft:wooden_slab-8
rule16=0,100,minecraft:spruce_door-2
rule17=0,100,minecraft:double_wooden_slab-1
rule18=0,100,minecraft:planks-5
rule19=0,100,minecraft:ladder-5
rule20=0,100,minecraft:trapdoor-8
rule21=0,100,minecraft:dark_oak_stairs-7
rule22=0,100,minecraft:cauldron-0
rule23=0,100,minecraft:dark_oak_stairs-6
rule24=0,100,minecraft:spruce_stairs-2
rule25=0,100,minecraft:crafting_table-0

rule26=0,100,IInventory;hopper;brown_mushroom#2#0#0-3,IInventory;hopper;glass_bottle#3#0#0-3,IInventory;hopper;redstone#2#0#0-3,IInventory;hopper;rabbit_stew#1#0#0-3,IInventory;hopper;glowstone_dust#2#0#0-3,IInventory;hopper;gunpowder#2#0#0-3

rule27=0,100,IInventory;dropper;feather#3#0#2-1,IInventory;dropper;coal#1#0#7-1,IInventory;dropper;bucket#1#0#8-1,IInventory;dropper;glass_bottle#5#0#1-1,IInventory;dropper;speckled_melon#1#0#1-1,IInventory;dropper;spruce_boat#1#0#4-1

rule28=0,100,minecraft:spruce_door-8
rule29=0,100,minecraft:dark_oak_stairs-5
rule30=0,100,minecraft:dark_oak_stairs-4
rule31=0,100,minecraft:dark_oak_stairs-0
rule32=0,100,IInventory;furnace;coal#1#0#1-3
rule33=0,100,minecraft:wooden_slab-5
rule34=0,100,minecraft:dark_oak_stairs-3
rule35=0,100,minecraft:double_wooden_slab-5
rule36=0,100,minecraft:brewing_stand-0,air,air
rule37=0,100,minecraft:carpet-7
rule38=0,100,minecraft:spruce_fence_gate-3
rule39=0,100,minecraft:spruce_fence_gate-7
rule40=0,100,minecraft:cobblestone_wall-0
rule41=0,100,minecraft:dark_oak_stairs-1
rule42=0,100,minecraft:wooden_slab-13
rule43=0,100,minecraft:dark_oak_stairs-2
rule44=0,100,minecraft:spruce_fence_gate-5

layer
1,1,1,1,1,1,1,1,1,1
1,1,1,1,1,1,1,1,1,1
1,1,1,1,1,1,1,1,1,1
1,1,2,1,1,1,1,1,2,1
1,1,1,1,1,1,1,1,1,1
1,1,1,1,1,1,1,1,1,1
1,1,1,1,1,1,1,1,1,1
1,1,1,1,1,1,1,1,1,1
1,1,2,1,1,1,1,1,1,1
1,1,1,1,1,1,1,2,1,1
1,1,1,1,1,1,1,1,1,1
endlayer

layer
1,1,1,1,1,1,1,1,1,1
1,1,1,1,1,1,1,1,1,1
1,1,1,1,1,1,1,1,1,1
1,1,2,1,1,1,1,1,2,1
1,1,1,1,1,1,1,1,1,1
1,1,1,1,1,1,1,1,1,1
1,1,1,1,1,1,1,1,1,1
1,1,1,1,1,1,1,1,1,1
1,1,2,1,1,1,1,1,1,1
1,1,1,1,1,1,1,2,1,1
1,1,1,1,1,1,1,1,1,1
endlayer

layer
1,1,1,1,1,1,1,1,1,1
1,1,1,1,1,1,1,1,1,1
1,1,1,1,1,1,1,1,1,1
1,1,2,1,1,1,1,1,2,1
1,1,1,1,1,1,1,1,1,1
1,1,1,1,1,1,1,1,1,1
1,1,1,1,1,1,1,1,1,1
1,1,1,1,1,1,1,1,1,1
1,1,2,1,1,1,1,1,1,1
1,1,1,1,1,1,1,2,1,1
1,1,1,1,1,1,1,1,1,1
endlayer

layer
1,1,1,1,1,1,1,1,1,1
1,1,1,1,1,1,1,1,1,1
1,1,1,1,1,1,1,1,1,1
1,1,2,1,1,1,1,1,2,1
1,1,1,1,1,1,1,1,1,1
1,1,1,1,1,1,1,1,1,1
1,1,1,1,1,1,1,1,1,1
1,1,1,1,1,1,1,1,1,1
1,1,2,1,1,1,1,1,1,1
1,1,1,1,1,1,1,2,1,1
1,1,1,1,1,1,1,1,1,1
endlayer

layer
1,1,1,1,1,1,1,1,1,1
1,1,1,1,1,1,1,1,1,1
1,1,1,1,1,1,1,1,1,1
1,1,2,1,1,1,1,1,2,1
1,1,1,1,1,1,1,1,1,1
1,1,1,1,1,1,1,1,1,1
1,1,1,1,1,1,1,1,1,1
1,1,1,1,1,1,1,1,1,1
1,1,2,1,1,1,1,1,1,1
1,1,1,1,1,1,1,2,1,1
1,1,1,1,1,1,1,1,1,1
endlayer

layer
1,1,1,1,1,1,1,1,1,1
1,1,1,1,1,1,1,1,1,1
1,1,1,1,1,1,1,1,1,1
1,1,2,1,1,1,1,1,2,1
1,1,1,1,1,1,1,1,1,1
1,1,1,1,1,1,1,1,1,1
1,1,1,1,1,1,1,1,1,1
1,1,1,1,1,1,1,1,1,1
1,1,2,1,1,1,1,1,1,1
1,1,1,1,1,1,1,2,1,1
1,1,1,1,1,1,1,1,1,1
endlayer

layer
1,1,1,1,1,1,1,1,1,1
1,1,1,1,1,1,1,1,1,1
1,1,1,1,1,1,1,1,1,1
1,1,2,1,1,1,1,1,2,1
1,1,1,1,1,1,1,1,1,1
1,1,1,1,1,1,1,1,1,1
1,1,1,1,1,1,1,1,1,1
1,1,1,1,1,1,1,1,1,1
1,1,2,1,1,1,1,1,1,1
1,1,1,1,1,1,1,2,1,1
1,1,1,1,1,1,1,1,1,1
endlayer

layer
1,1,1,1,1,1,1,1,1,1
1,1,1,1,1,1,1,1,1,1
1,1,1,1,1,1,1,1,1,1
1,1,2,1,1,1,1,1,2,1
1,1,1,1,1,1,1,1,1,1
1,1,1,1,1,1,1,1,1,1
1,1,1,1,1,1,1,1,1,1
1,1,1,1,1,1,1,1,1,1
1,1,2,1,1,1,1,1,1,1
1,1,1,1,1,1,1,2,1,1
1,1,1,1,1,1,1,1,1,1
endlayer

layer
1,1,1,1,1,1,1,1,1,1
1,1,1,1,1,1,1,1,1,1
1,1,1,1,1,1,1,1,1,1
1,1,2,1,1,1,1,1,2,1
1,1,1,1,1,1,1,1,1,1
1,1,1,1,1,1,1,1,1,1
1,1,1,1,1,1,1,1,1,1
1,1,1,1,1,1,1,1,1,1
1,1,2,1,1,1,1,1,1,1
1,1,1,1,1,1,1,2,1,1
1,1,1,1,1,1,1,1,1,1
endlayer

layer
1,1,1,0,3,3,1,1,1,1
1,1,1,6,5,4,1,1,1,1
1,1,1,1,7,7,1,1,1,1
1,1,2,1,1,1,1,1,2,1
1,1,1,1,1,1,1,1,1,1
1,1,1,1,1,1,1,1,1,1
1,1,1,1,1,1,1,1,1,1
1,1,1,1,1,1,1,1,1,1
1,1,2,1,1,1,1,1,1,1
1,1,1,1,1,1,1,2,1,1
1,1,1,1,1,1,1,1,1,1
endlayer

layer
1,1,1,0,0,0,1,1,1,1
1,1,1,10,5,9,8,1,1,1
1,1,1,1,7,7,7,1,1,1
1,1,2,7,7,7,7,7,2,1
1,1,7,7,7,7,7,7,7,1
1,1,7,1,1,1,1,1,7,1
1,1,7,1,1,1,1,1,7,1
1,1,7,1,1,1,1,1,7,1
1,1,2,7,7,7,7,7,7,1
1,1,1,1,1,1,1,2,1,1
1,1,1,1,1,1,1,1,1,1
endlayer

layer
1,1,1,0,0,0,0,1,1,1
1,1,0,0,11,9,9,9,1,1
1,1,12,12,13,12,12,8,12,1
1,12,2,14,14,14,14,14,2,12
1,12,8,15,15,15,15,15,8,12
0,12,8,15,15,15,15,15,8,12
0,12,8,15,15,15,15,15,8,12
1,12,8,15,15,15,15,15,8,12
1,12,2,9,9,9,9,9,8,0
1,1,12,14,14,14,14,2,1,1
1,1,1,1,1,1,1,1,1,1
endlayer

layer
1,1,0,0,0,0,0,0,1,1
1,0,0,0,0,0,0,0,0,1
0,0,13,9,4,9,16,9,7,0
0,9,18,17,0,0,0,0,2,7
13,21,20,19,0,0,0,0,0,8
14,23,20,0,0,0,0,0,22,8
9,23,20,0,0,0,0,0,6,8
13,23,14,0,0,0,0,0,17,8
0,13,12,0,0,0,0,0,24,7
1,12,17,27,26,25,0,2,7,0
1,1,7,14,17,14,14,7,0,1
endlayer

layer
1,0,0,0,0,0,0,0,0,1
0,0,0,0,0,0,0,0,0,0
0,0,9,4,9,17,28,9,9,0
0,30,29,17,0,0,0,0,18,8
31,29,0,19,0,0,0,0,0,8
21,23,0,0,0,0,0,0,32,23
34,30,0,0,0,0,0,0,0,33
34,30,14,0,0,0,0,0,36,35
29,21,12,0,0,0,0,0,35,8
0,13,17,37,0,0,0,4,14,0
1,0,14,4,24,11,4,7,0,0
endlayer

layer
0,0,0,0,0,0,0,0,0,0
0,0,0,0,0,0,0,0,0,0
0,0,7,30,30,29,38,30,7,0
39,18,18,17,0,0,0,0,18,7
30,21,20,19,0,0,0,0,0,18
34,23,20,0,0,0,0,0,40,35
21,23,20,0,0,0,0,0,0,7
41,21,14,0,0,0,0,0,0,18
7,35,12,0,0,0,0,0,23,29
0,7,17,0,0,0,0,21,30,0
0,0,29,30,23,21,30,33,0,0
endlayer

layer
0,0,0,0,0,0,0,0,0,0
0,0,0,0,0,0,0,0,0,0
0,42,30,30,30,29,30,30,30,0
30,41,41,17,0,0,0,0,21,7
43,37,37,0,0,0,0,0,0,43
43,37,37,0,0,0,0,0,40,29
43,37,37,0,0,0,0,0,0,23
34,18,14,0,0,0,0,0,0,23
33,21,12,0,0,0,0,0,35,29
0,34,9,0,0,0,0,35,35,0
0,0,41,41,29,29,29,35,0,0
endlayer

layer
0,0,0,0,0,0,0,0,0,0
0,0,0,0,0,0,0,0,0,0
0,0,34,35,31,31,30,31,43,0
33,31,29,17,23,0,0,29,35,33
29,0,0,0,0,0,0,0,29,35
44,0,0,0,0,0,0,0,40,23
39,0,0,0,0,0,0,0,0,23
21,21,23,0,0,0,0,0,30,23
0,34,42,0,0,0,0,21,35,33
0,0,33,30,30,30,21,41,33,0
0,0,0,0,41,35,41,0,0,0
endlayer

layer
0,0,0,0,0,0,0,0,0,0
0,0,0,0,0,0,0,0,0,0
0,0,0,0,33,31,31,0,0,0
0,0,31,35,18,18,35,43,0,0
0,33,21,14,14,14,14,21,31,0
33,21,21,8,0,0,0,13,18,43
33,30,35,8,0,0,0,13,35,33
0,34,35,8,0,0,0,13,43,0
0,0,33,23,30,30,30,41,0,0
0,0,0,0,33,41,43,0,0,0
0,0,0,0,0,0,0,0,0,0
endlayer

layer
0,0,0,0,0,0,0,0,0,0
0,0,0,0,0,0,0,0,0,0
0,0,0,0,0,0,0,0,0,0
0,0,0,0,33,33,33,0,0,0
0,0,0,34,31,35,31,31,0,0
0,0,31,31,14,14,14,35,18,0
0,0,41,41,8,12,13,18,43,0
0,0,0,34,9,9,9,43,0,0
0,0,0,0,41,41,41,0,0,0
0,0,0,0,0,0,0,0,0,0
0,0,0,0,0,0,0,0,0,0
endlayer

layer
0,0,0,0,0,0,0,0,0,0
0,0,0,0,0,0,0,0,0,0
0,0,0,0,0,0,0,0,0,0
0,0,0,0,0,0,0,0,0,0
0,0,0,0,0,0,0,0,0,0
0,0,0,33,31,31,31,31,40,0
0,0,0,0,34,18,18,41,0,0
0,0,0,0,33,33,41,0,0,0
0,0,0,0,0,0,0,0,0,0
0,0,0,0,0,0,0,0,0,0
0,0,0,0,0,0,0,0,0,0
endlayer

layer
0,0,0,0,0,0,0,0,0,0
0,0,0,0,0,0,0,0,0,0
0,0,0,0,0,0,0,0,0,0
0,0,0,0,0,0,0,0,0,0
0,0,0,0,0,0,0,0,0,0
0,0,0,0,0,0,0,0,40,0
0,0,0,0,0,0,0,0,0,0
0,0,0,0,0,0,0,0,0,0
0,0,0,0,0,0,0,0,0,0
0,0,0,0,0,0,0,0,0,0
0,0,0,0,0,0,0,0,0,0
endlayer

