
# Created by Ruins mod version 16.7 Ingame Parser
# authoring Player: lafuller

weight=1
embed_into_distance=7
acceptable_target_blocks=
unacceptable_target_blocks=flowing_water,water,flowing_lava,lava,ice,bedrock,netherrack,nether_brick,nether_brick_fence,soul_sand,quartz_ore,gravel,end_stone,obsidian,iron_bars,cloud,flesh,ash_block,slime_grass,slime_congealed,slime_dirt
biomesToSpawnIn=desert,lush desert
dimensions=98,11,11
allowable_overhang=0
max_leveling=7
leveling_buffer=-1
preserve_water=0
preserve_lava=0

rule1=0,100,minecraft:double_stone_slab-9
rule2=0,100,minecraft:planks-2
rule3=0,100,minecraft:sandstone-1
rule4=0,100,minecraft:sandstone_stairs-2
rule5=0,100,minecraft:sandstone_stairs-0
rule6=0,100,minecraft:sandstone_stairs-3
rule7=0,100,minecraft:sandstone-2
rule8=0,100,minecraft:sandstone_stairs-1
rule9=0,100,minecraft:sandstone_stairs-6
rule10=0,100,minecraft:sandstone_stairs-4
rule11=0,100,minecraft:sandstone_stairs-7
rule12=0,100,minecraft:sandstone-0
rule13=0,100,minecraft:sandstone_stairs-5
rule14=0,100,minecraft:stone_slab-1
rule15=0,100,minecraft:stone_slab-9
rule16=0,100,minecraft:double_stone_slab-1

layer
1,1,1,1,1,1,1,1,1,1,1
1,1,2,1,2,1,1,2,2,1,1
1,1,2,1,1,2,1,2,2,1,1
1,1,2,1,1,1,1,1,1,1,1
1,2,2,1,2,2,1,1,2,1,1
1,1,1,1,2,1,1,1,2,1,1
1,1,2,1,2,2,1,1,2,1,1
1,1,2,1,2,1,1,1,2,1,1
1,2,2,1,2,2,1,2,1,1,1
1,1,1,1,1,2,1,1,2,1,1
1,1,1,1,1,1,1,1,1,1,1
endlayer

layer
1,1,1,1,1,1,1,1,1,1,1
1,1,1,1,1,1,1,1,1,1,1
1,1,1,1,1,1,1,1,1,1,1
1,1,1,1,1,1,1,1,1,1,1
1,1,1,1,1,1,1,1,1,1,1
1,1,1,1,1,1,1,1,1,1,1
1,1,1,1,1,1,1,1,1,1,1
1,1,1,1,1,1,1,1,1,1,1
1,1,1,1,1,1,1,1,1,1,1
1,1,1,1,1,1,1,1,1,1,1
1,1,1,1,1,1,1,1,1,1,1
endlayer

layer
1,1,1,1,1,1,1,1,1,1,1
1,1,1,1,1,1,1,1,1,1,1
1,1,1,1,1,1,1,1,1,1,1
1,1,1,1,1,1,1,1,1,1,1
1,1,1,1,1,1,1,1,1,1,1
1,1,1,1,1,1,1,1,1,1,1
1,1,1,1,1,1,1,1,1,1,1
1,1,1,1,1,1,1,1,1,1,1
1,1,1,1,1,1,1,1,1,1,1
1,1,1,1,1,1,1,1,1,1,1
1,1,1,1,1,1,1,1,1,1,1
endlayer

layer
1,1,1,1,1,1,1,1,1,1,1
1,1,1,1,1,1,1,1,1,1,1
1,1,1,1,1,1,1,1,1,1,1
1,1,1,1,1,1,1,1,1,1,1
1,1,1,1,1,1,1,1,1,1,1
1,1,1,1,1,1,1,1,1,1,1
1,1,1,1,1,1,1,1,1,1,1
1,1,1,1,1,1,1,1,1,1,1
1,1,1,1,1,1,1,1,1,1,1
1,1,1,1,1,1,1,1,1,1,1
1,1,1,1,1,1,1,1,1,1,1
endlayer

layer
1,1,1,1,1,1,1,1,1,1,1
1,1,1,1,1,1,1,1,1,1,1
1,1,1,1,1,1,1,1,1,1,1
1,1,1,1,1,1,1,1,1,1,1
1,1,1,1,1,1,1,1,1,1,1
1,1,1,1,1,1,1,1,1,1,1
1,1,1,1,1,1,1,1,1,1,1
1,1,1,1,1,1,1,1,1,1,1
1,1,1,1,1,1,1,1,1,1,1
1,1,1,1,1,1,1,1,1,1,1
1,1,1,1,1,1,1,1,1,1,1
endlayer

layer
1,1,1,1,1,1,1,1,1,1,1
1,1,1,1,1,1,1,1,1,1,1
1,1,1,1,1,1,1,1,1,1,1
1,1,1,1,1,1,1,1,1,1,1
1,1,1,1,1,1,1,1,1,1,1
1,1,1,1,1,1,1,1,1,1,1
1,1,1,1,1,1,1,1,1,1,1
1,1,1,1,1,1,1,1,1,1,1
1,1,1,1,1,1,1,1,1,1,1
1,1,1,1,1,1,1,1,1,1,1
1,1,1,1,1,1,1,1,1,1,1
endlayer

layer
1,1,1,1,1,1,1,1,1,1,1
1,1,1,1,1,1,1,1,1,1,1
1,1,1,1,1,1,1,1,1,1,1
1,1,1,1,1,1,1,1,1,1,1
1,1,1,1,1,1,1,1,1,1,1
1,1,1,1,1,1,1,1,1,1,1
1,1,1,1,1,1,1,1,1,1,1
1,1,1,1,1,1,1,1,1,1,1
1,1,1,1,1,1,1,1,1,1,1
1,1,1,1,1,1,1,1,1,1,1
1,1,1,1,1,1,1,1,1,1,1
endlayer

layer
1,1,1,1,1,3,1,1,1,1,1
1,1,1,1,1,1,1,1,1,1,1
1,1,1,1,1,1,1,1,1,1,1
1,1,1,1,1,1,1,1,1,1,1
1,1,1,1,1,1,1,1,1,1,1
3,1,1,1,1,1,1,1,1,1,3
1,1,1,1,1,1,1,1,1,1,1
1,1,1,1,1,1,1,1,1,1,1
1,1,1,1,1,1,1,1,1,1,1
1,1,1,1,1,1,1,1,1,1,1
1,1,1,1,1,3,1,1,1,1,1
endlayer

layer
5,5,1,1,1,1,1,1,1,5,4
6,1,1,1,1,1,1,1,1,1,4
7,1,1,1,1,1,1,1,1,1,1
7,1,1,1,1,1,1,1,1,1,1
1,1,1,1,1,1,1,1,1,1,1
1,1,1,1,1,1,1,1,1,1,1
1,1,1,1,1,1,1,1,1,1,1
7,1,1,1,1,1,1,1,1,1,1
7,1,1,1,1,1,1,1,1,1,1
6,1,1,1,1,1,1,1,1,1,4
8,8,7,7,1,1,1,7,7,8,4
endlayer

layer
0,0,11,10,5,5,5,10,9,0,0
0,3,1,1,1,1,1,1,1,3,0
10,1,12,12,12,12,12,12,12,1,10
11,1,12,12,12,12,12,12,12,1,9
6,1,12,12,12,12,12,12,12,1,4
6,1,12,12,12,1,12,12,12,1,4
6,1,12,12,12,12,12,12,12,1,4
11,1,12,12,12,12,12,12,12,1,9
13,1,12,12,12,12,12,12,12,1,13
0,3,1,1,1,1,1,1,1,3,0
0,0,11,13,8,8,8,13,9,0,0
endlayer

layer
0,10,12,12,12,12,12,12,12,10,0
11,1,1,1,1,1,1,1,1,1,9
12,1,12,12,12,12,12,12,12,1,12
12,1,12,12,12,12,12,12,12,1,12
12,1,12,12,12,12,12,12,12,1,12
12,1,12,12,12,1,12,12,12,1,12
12,1,12,12,12,12,12,12,12,1,12
12,1,12,12,12,12,12,12,12,1,12
12,1,12,12,12,12,12,12,12,1,12
11,1,1,1,1,1,1,1,1,1,9
0,13,12,12,12,12,12,12,12,13,0
endlayer

layer
12,12,12,12,3,12,3,12,3,12,3
3,1,1,1,1,1,1,1,1,1,3
12,1,12,12,12,12,12,12,12,1,12
12,1,12,12,12,12,12,12,12,1,3
12,1,12,12,12,12,12,12,12,1,12
12,1,12,12,12,1,12,12,12,1,3
12,1,12,12,12,12,12,12,12,1,12
3,1,12,12,12,12,12,12,12,1,12
3,1,12,12,12,12,12,12,12,1,12
12,1,1,1,1,1,1,1,1,1,12
12,3,12,3,12,12,12,3,12,12,12
endlayer

layer
12,3,3,3,3,3,12,12,12,12,3
3,1,1,1,1,1,1,1,1,1,12
12,1,12,12,12,12,12,12,12,1,12
12,1,12,12,12,12,12,12,12,1,3
12,1,12,12,12,12,12,12,12,1,12
3,1,12,12,12,1,12,12,12,1,3
12,1,12,12,12,12,12,12,12,1,12
12,1,12,12,12,12,12,12,12,1,3
12,1,12,12,12,12,12,12,12,1,3
12,1,1,1,1,1,1,1,1,1,3
12,3,12,3,12,12,3,3,3,12,12
endlayer

layer
12,12,3,3,12,12,3,3,3,12,3
3,1,1,1,1,1,1,1,1,1,3
12,1,12,12,12,12,12,12,12,1,12
3,1,12,12,12,12,12,12,12,1,3
12,1,12,12,12,12,12,12,12,1,12
3,1,12,12,12,1,12,12,12,1,3
3,1,12,12,12,12,12,12,12,1,3
3,1,12,12,12,12,12,12,12,1,12
12,1,12,12,12,12,12,12,12,1,3
12,1,1,1,1,1,1,1,1,1,3
12,3,12,3,12,3,12,3,12,12,12
endlayer

layer
0,12,12,12,12,12,12,12,12,12,0
12,1,1,1,1,1,1,1,1,1,12
12,1,12,12,12,12,12,12,12,1,12
12,1,12,12,12,12,12,12,12,1,12
12,1,12,12,12,12,12,12,12,1,12
12,1,12,12,12,1,12,12,12,1,12
12,1,12,12,12,12,12,12,12,1,12
12,1,12,12,12,12,12,12,12,1,12
12,1,12,12,12,12,12,12,12,1,12
12,1,1,1,1,1,1,1,1,1,12
0,12,12,12,12,12,12,12,12,12,0
endlayer

layer
0,12,12,4,14,0,14,6,12,12,0
12,1,1,1,1,1,1,1,1,1,12
12,1,12,12,12,12,12,12,12,1,12
8,1,12,12,12,12,12,12,12,1,8
14,1,12,12,12,12,12,12,12,1,14
0,1,12,12,12,1,12,12,12,1,0
14,1,12,12,12,12,12,12,12,1,14
5,1,12,12,12,12,12,12,12,1,5
12,1,12,12,12,12,12,12,12,1,12
12,1,1,1,1,1,1,1,1,1,12
0,12,12,4,14,0,14,6,12,12,0
endlayer

layer
0,12,4,0,0,0,0,0,6,12,0
12,1,1,1,1,1,1,1,1,1,12
8,1,12,12,12,12,12,12,12,1,8
0,1,12,12,12,12,12,12,12,1,0
0,1,12,12,12,12,12,12,12,1,0
0,1,12,12,12,12,12,12,12,1,0
0,1,12,12,12,12,12,12,12,1,0
0,1,12,12,12,12,12,12,12,1,0
5,1,12,12,12,12,12,12,12,1,5
12,1,1,1,1,1,1,1,1,1,12
0,12,4,0,0,0,0,0,6,12,0
endlayer

layer
0,12,0,0,0,0,0,0,0,12,0
12,1,1,1,4,0,11,1,1,1,12
0,1,2,2,2,2,2,2,2,1,0
0,1,2,12,12,12,12,12,2,13,0
0,1,2,12,12,12,12,12,2,14,0
0,0,2,12,12,12,12,12,2,0,0
0,0,2,12,12,12,12,12,2,14,0
0,1,2,12,12,12,12,12,2,1,0
0,1,2,2,2,2,2,2,2,1,0
12,1,1,0,15,1,14,0,1,1,12
0,12,0,0,0,0,0,0,0,12,0
endlayer

layer
0,12,0,0,0,0,0,0,0,12,0
12,1,1,15,0,0,6,1,1,1,12
0,1,2,2,2,2,2,2,2,1,0
0,1,2,12,12,12,12,12,2,1,0
0,0,2,12,12,12,12,12,2,15,0
0,0,2,12,12,12,12,12,2,15,0
0,1,2,12,12,12,12,12,2,0,0
0,1,2,12,12,12,12,12,2,14,0
0,1,2,2,2,2,2,2,2,5,0
12,1,1,15,15,15,14,14,1,1,12
0,12,0,0,0,0,0,0,0,12,0
endlayer

layer
0,12,0,0,0,0,0,0,0,12,0
12,1,1,1,4,0,0,14,1,1,12
0,1,2,2,2,2,2,2,2,1,0
0,0,2,12,12,12,12,12,2,15,0
0,1,2,12,12,12,12,12,2,0,0
0,1,2,12,12,12,12,12,2,0,0
0,0,2,12,12,12,12,12,2,0,0
0,1,2,12,12,12,12,12,2,15,0
0,1,2,2,2,2,2,2,2,1,0
12,1,1,15,0,14,0,14,1,1,12
0,12,0,0,0,0,0,0,0,12,0
endlayer

layer
0,12,0,0,0,0,0,0,0,12,0
12,1,1,1,1,0,0,0,1,1,12
0,1,2,2,2,2,2,2,2,1,0
0,0,2,12,12,12,12,12,2,8,0
0,0,2,12,12,12,12,12,2,0,0
0,0,2,12,12,12,12,12,2,1,0
0,0,2,12,12,12,12,12,2,14,0
0,1,2,12,12,12,12,12,2,14,0
0,1,2,2,2,2,2,2,2,1,0
12,1,1,0,0,14,14,16,1,1,12
0,12,0,0,0,0,0,0,0,12,0
endlayer

layer
0,12,0,0,0,0,0,0,0,12,0
12,1,1,14,0,0,0,11,1,1,12
0,1,2,2,2,2,2,2,2,1,0
0,1,2,12,12,12,12,12,2,1,0
0,0,2,12,12,12,12,12,2,15,0
0,1,2,12,12,12,12,12,2,0,0
0,1,2,12,12,12,12,12,2,0,0
0,0,2,12,12,12,12,12,2,10,0
0,1,2,2,2,2,2,2,2,1,0
12,1,1,14,0,15,15,15,1,1,12
0,12,0,0,0,0,0,0,0,12,0
endlayer

layer
0,12,0,0,0,0,0,0,0,12,0
12,1,1,1,1,4,0,6,1,1,12
0,1,2,2,2,2,2,2,2,8,0
0,1,2,12,12,12,12,12,2,0,0
0,1,2,12,12,12,12,12,2,0,0
0,0,2,12,12,12,12,12,2,10,0
0,0,2,12,12,12,12,12,2,15,0
0,1,2,12,12,12,12,12,2,14,0
0,1,2,2,2,2,2,2,2,1,0
12,1,1,14,14,0,15,0,1,1,12
0,12,0,0,0,0,0,0,0,12,0
endlayer

layer
0,12,0,0,0,0,0,0,0,12,0
12,1,1,4,0,0,15,15,1,1,12
0,1,2,2,2,2,2,2,2,1,0
0,1,2,12,12,12,12,12,2,0,0
0,0,2,12,12,12,12,12,2,5,0
0,1,2,12,12,12,12,12,2,8,0
0,0,2,12,12,12,12,12,2,0,0
0,0,2,12,12,12,12,12,2,15,0
0,1,2,2,2,2,2,2,2,1,0
12,1,1,0,15,15,0,14,1,1,12
0,12,0,0,0,0,0,0,0,12,0
endlayer

layer
0,12,0,0,0,0,0,0,0,12,0
12,1,1,1,15,0,0,6,1,1,12
0,1,2,2,2,2,2,2,2,1,0
0,0,2,12,12,12,12,12,2,8,0
0,0,2,12,12,12,12,12,2,0,0
0,1,2,12,12,12,12,12,2,15,0
0,1,2,12,12,12,12,12,2,13,0
0,0,2,12,12,12,12,12,2,0,0
0,1,2,2,2,2,2,2,2,5,0
12,1,1,15,0,15,15,1,1,1,12
0,12,0,0,0,0,0,0,0,12,0
endlayer

layer
0,12,0,0,0,0,0,0,0,12,0
12,1,9,0,0,15,1,11,1,1,12
0,1,2,2,2,2,2,2,2,1,0
0,1,2,12,12,12,12,12,2,15,0
0,0,2,12,12,12,12,12,2,0,0
0,0,2,12,12,12,12,12,2,15,0
0,1,2,12,12,12,12,12,2,14,0
0,1,2,12,12,12,12,12,2,1,0
0,1,2,2,2,2,2,2,2,1,0
12,1,1,0,15,0,14,14,1,1,12
0,12,0,0,0,0,0,0,0,12,0
endlayer

layer
0,12,0,0,0,0,0,0,0,12,0
12,1,1,1,1,1,1,1,1,1,12
0,1,2,2,2,2,2,2,2,1,0
0,1,2,12,12,12,12,12,2,1,0
0,1,2,12,12,12,12,12,2,1,0
0,1,2,12,12,12,12,12,2,1,0
0,1,2,12,12,12,12,12,2,15,0
0,1,2,12,12,12,12,12,2,10,0
0,1,2,2,2,2,2,2,2,1,0
12,1,1,1,1,1,1,1,1,1,12
0,12,0,0,0,0,0,0,0,12,0
endlayer

layer
0,12,0,0,0,0,0,0,0,12,0
12,1,1,4,14,0,14,1,1,1,12
0,1,2,2,2,2,2,2,2,1,0
0,1,2,12,12,12,12,12,2,13,0
0,1,2,12,12,12,12,12,2,0,0
0,1,2,12,12,12,12,12,2,0,0
0,0,2,12,12,12,12,12,2,14,0
0,1,2,12,12,12,12,12,2,1,0
0,1,2,2,2,2,2,2,2,1,0
12,1,1,14,14,0,0,14,1,1,12
0,12,0,0,0,0,0,0,0,12,0
endlayer

layer
0,12,0,0,0,0,0,0,0,12,0
12,1,1,0,0,14,1,1,1,1,12
0,1,2,2,2,2,2,2,2,1,0
0,1,2,12,12,12,12,12,2,8,0
0,0,2,12,12,12,12,12,2,5,0
0,0,2,12,12,12,12,12,2,15,0
0,1,2,12,12,12,12,12,2,0,0
0,0,2,12,12,12,12,12,2,0,0
0,1,2,2,2,2,2,2,2,1,0
12,1,1,15,0,15,4,14,1,1,12
0,12,0,0,0,0,0,0,0,12,0
endlayer

layer
0,12,0,0,0,0,0,0,0,12,0
12,1,1,1,4,0,1,14,1,1,12
0,1,2,2,2,2,2,2,2,1,0
0,1,2,12,12,12,12,12,2,1,0
0,1,2,12,12,12,12,12,2,14,0
0,0,2,12,12,12,12,12,2,0,0
0,1,2,12,12,12,12,12,2,15,0
0,1,2,12,12,12,12,12,2,13,0
0,1,2,2,2,2,2,2,2,10,0
12,1,1,0,0,15,15,15,1,1,12
0,12,0,0,0,0,0,0,0,12,0
endlayer

layer
0,12,0,0,0,0,0,0,0,12,0
12,1,1,14,0,0,0,11,1,1,12
0,1,2,2,2,2,2,2,2,1,0
0,0,2,12,12,12,12,12,2,15,0
0,0,2,12,12,12,12,12,2,0,0
0,1,2,12,12,12,12,12,2,14,0
0,0,2,12,12,12,12,12,2,1,0
0,0,2,12,12,12,12,12,2,1,0
0,1,2,2,2,2,2,2,2,1,0
12,1,1,1,14,0,14,14,1,1,12
0,12,0,0,0,0,0,0,0,12,0
endlayer

layer
0,12,0,0,0,0,0,0,0,12,0
12,1,1,1,0,0,0,1,1,1,12
0,1,2,2,2,2,2,2,2,1,0
0,1,2,12,12,12,12,12,2,8,0
0,0,2,12,12,12,12,12,2,0,0
0,0,2,12,12,12,12,12,2,15,0
0,0,2,12,12,12,12,12,2,0,0
0,1,2,12,12,12,12,12,2,5,0
0,1,2,2,2,2,2,2,2,1,0
12,1,1,1,14,14,0,14,1,1,12
0,12,0,0,0,0,0,0,0,12,0
endlayer

layer
0,12,0,0,0,0,0,0,0,12,0
12,1,1,4,15,9,0,0,1,1,12
0,1,2,2,2,2,2,2,2,8,0
0,0,2,12,12,12,12,12,2,1,0
0,1,2,12,12,12,12,12,2,15,0
0,1,2,12,12,12,12,12,2,0,0
0,1,2,12,12,12,12,12,2,13,0
0,0,2,12,12,12,12,12,2,0,0
0,1,2,2,2,2,2,2,2,10,0
12,1,1,14,0,15,15,1,1,1,12
0,12,0,0,0,0,0,0,0,12,0
endlayer

layer
0,12,0,0,0,0,0,0,0,12,0
12,1,1,0,11,1,0,14,1,1,12
0,1,2,2,2,2,2,2,2,1,0
0,0,2,12,12,12,12,12,2,0,0
0,0,2,12,12,12,12,12,2,0,0
0,1,2,12,12,12,12,12,2,0,0
0,0,2,12,12,12,12,12,2,15,0
0,0,2,12,12,12,12,12,2,0,0
0,1,2,2,2,2,2,2,2,5,0
12,1,1,1,15,0,0,15,1,1,12
0,12,0,0,0,0,0,0,0,12,0
endlayer

layer
0,12,0,0,0,0,0,0,0,12,0
12,1,1,0,0,11,9,0,1,1,12
0,1,2,2,2,2,2,2,2,1,0
0,0,2,12,12,12,12,12,2,13,0
0,1,2,12,12,12,12,12,2,0,0
0,1,2,12,12,12,12,12,2,14,0
0,0,2,12,12,12,12,12,2,14,0
0,1,2,12,12,12,12,12,2,1,0
0,1,2,2,2,2,2,2,2,10,0
12,1,1,15,15,0,14,6,1,1,12
0,12,0,0,0,0,0,0,0,12,0
endlayer

layer
0,12,0,0,0,0,0,0,0,12,0
12,1,1,0,1,1,0,15,1,1,12
0,1,2,2,2,2,2,2,2,1,0
0,1,2,12,12,12,12,12,2,14,0
0,1,2,12,12,12,12,12,2,0,0
0,0,2,12,12,12,12,12,2,15,0
0,0,2,12,12,12,12,12,2,0,0
0,1,2,12,12,12,12,12,2,10,0
0,1,2,2,2,2,2,2,2,1,0
12,1,1,15,0,0,15,15,1,1,12
0,12,0,0,0,0,0,0,0,12,0
endlayer

layer
0,12,0,0,0,0,0,0,0,12,0
12,1,1,1,1,1,1,1,1,1,12
0,1,2,2,2,2,2,2,2,1,0
0,1,2,12,12,12,12,12,2,1,0
0,1,2,12,12,12,12,12,2,10,0
0,1,2,12,12,12,12,12,2,1,0
0,1,2,12,12,12,12,12,2,1,0
0,1,2,12,12,12,12,12,2,1,0
0,1,2,2,2,2,2,2,2,1,0
12,1,1,1,1,1,1,1,1,1,12
0,12,0,0,0,0,0,0,0,12,0
endlayer

layer
0,12,0,0,0,0,0,0,0,12,0
12,1,1,14,1,0,14,6,1,1,12
0,1,2,2,2,2,2,2,2,1,0
0,1,2,12,12,12,12,12,2,5,0
0,1,2,12,12,12,12,12,2,1,0
0,0,2,12,12,12,12,12,2,14,0
0,0,2,12,12,12,12,12,2,0,0
0,1,2,12,12,12,12,12,2,5,0
0,1,2,2,2,2,2,2,2,1,0
12,1,1,0,14,0,15,15,1,1,12
0,12,0,0,0,0,0,0,0,12,0
endlayer

layer
0,12,0,0,0,0,0,0,0,12,0
12,1,1,9,0,9,15,0,6,1,12
0,1,2,2,2,2,2,2,2,1,0
0,1,2,12,12,12,12,12,2,0,0
0,0,2,12,12,12,12,12,2,8,0
0,0,2,12,12,12,12,12,2,0,0
0,1,2,12,12,12,12,12,2,13,0
0,1,2,12,12,12,12,12,2,0,0
0,1,2,2,2,2,2,2,2,1,0
12,1,1,14,14,14,0,11,1,1,12
0,12,0,0,0,0,0,0,0,12,0
endlayer

layer
0,12,0,0,0,0,0,0,0,12,0
12,1,1,4,0,14,4,0,11,1,12
0,1,2,2,2,2,2,2,2,1,0
0,0,2,12,12,12,12,12,2,13,0
0,0,2,12,12,12,12,12,2,15,0
0,1,2,12,12,12,12,12,2,14,0
0,1,2,12,12,12,12,12,2,0,0
0,1,2,12,12,12,12,12,2,10,0
0,1,2,2,2,2,2,2,2,1,0
12,1,1,15,15,14,0,14,1,1,12
0,12,0,0,0,0,0,0,0,12,0
endlayer

layer
0,12,0,0,0,0,0,0,0,12,0
12,1,4,0,0,15,0,15,1,1,12
0,1,2,2,2,2,2,2,2,1,0
0,0,2,12,12,12,12,12,2,14,0
0,0,2,12,12,12,12,12,2,0,0
0,0,2,12,12,12,12,12,2,15,0
0,0,2,12,12,12,12,12,2,1,0
0,0,2,12,12,12,12,12,2,1,0
0,1,2,2,2,2,2,2,2,1,0
12,1,1,0,0,11,1,1,1,1,12
0,12,0,0,0,0,0,0,0,12,0
endlayer

layer
0,12,0,0,0,0,0,0,0,12,0
12,1,9,9,0,0,14,1,1,1,12
0,1,2,2,2,2,2,2,2,1,0
0,1,2,12,12,12,12,12,2,8,0
0,0,2,12,12,12,12,12,2,0,0
0,0,2,12,12,12,12,12,2,0,0
0,0,2,12,12,12,12,12,2,0,0
0,1,2,12,12,12,12,12,2,5,0
0,1,2,2,2,2,2,2,2,1,0
12,1,1,14,14,14,14,0,1,1,12
0,12,0,0,0,0,0,0,0,12,0
endlayer

layer
0,12,0,0,0,0,0,0,0,12,0
12,1,1,1,9,15,0,6,1,1,12
0,1,2,2,2,2,2,2,2,1,0
0,1,2,12,12,12,12,12,2,14,0
0,1,2,12,12,12,12,12,2,15,0
0,1,2,12,12,12,12,12,2,1,0
0,1,2,12,12,12,12,12,2,13,0
0,0,2,12,12,12,12,12,2,0,0
0,1,2,2,2,2,2,2,2,10,0
12,1,1,4,0,14,14,1,1,1,12
0,12,0,0,0,0,0,0,0,12,0
endlayer

layer
0,12,0,0,0,0,0,0,0,12,0
12,1,1,1,1,1,15,0,1,1,12
0,1,2,2,2,2,2,2,2,1,0
0,0,2,12,12,12,12,12,2,1,0
0,0,2,12,12,12,12,12,2,8,0
0,1,2,12,12,12,12,12,2,14,0
0,0,2,12,12,12,12,12,2,0,0
0,0,2,12,12,12,12,12,2,0,0
0,1,2,2,2,2,2,2,2,10,0
12,1,1,15,15,0,11,1,1,1,12
0,12,0,0,0,0,0,0,0,12,0
endlayer

layer
0,12,0,0,0,0,0,0,0,12,0
12,1,4,0,0,14,0,0,1,1,12
0,1,2,2,2,2,2,2,2,1,0
0,0,2,12,12,12,12,12,2,14,0
0,1,2,12,12,12,12,12,2,0,0
0,1,2,12,12,12,12,12,2,15,0
0,0,2,12,12,12,12,12,2,0,0
0,1,2,12,12,12,12,12,2,5,0
0,1,2,2,2,2,2,2,2,1,0
12,1,1,1,0,0,15,15,1,1,12
0,12,0,0,0,0,0,0,0,12,0
endlayer

layer
0,12,0,0,0,0,0,0,0,12,0
12,1,1,1,15,15,0,11,1,1,12
0,1,2,2,2,2,2,2,2,13,0
0,1,2,12,12,12,12,12,2,0,0
0,1,2,12,12,12,12,12,2,13,0
0,0,2,12,12,12,12,12,2,8,0
0,0,2,12,12,12,12,12,2,0,0
0,1,2,12,12,12,12,12,2,10,0
0,1,2,2,2,2,2,2,2,1,0
12,1,1,15,15,0,0,14,1,1,12
0,12,0,0,0,0,0,0,0,12,0
endlayer

layer
0,12,0,0,0,0,0,0,0,12,0
12,1,1,1,1,1,1,1,1,1,12
0,1,2,2,2,2,2,2,2,1,0
0,1,2,12,12,12,12,12,2,1,0
0,1,2,12,12,12,12,12,2,1,0
0,1,2,12,12,12,12,12,2,1,0
0,1,2,12,12,12,12,12,2,1,0
0,1,2,12,12,12,12,12,2,1,0
0,1,2,2,2,2,2,2,2,1,0
12,1,1,1,1,1,1,1,1,1,12
0,12,0,0,0,0,0,0,0,12,0
endlayer

layer
0,12,0,0,0,0,0,0,0,12,0
12,1,1,1,1,0,1,0,6,1,12
0,1,2,2,2,2,2,2,2,1,0
0,1,2,12,12,12,12,12,2,1,0
0,0,2,12,12,12,12,12,2,14,0
0,1,2,12,12,12,12,12,2,0,0
0,1,2,12,12,12,12,12,2,15,0
0,1,2,12,12,12,12,12,2,10,0
0,1,2,2,2,2,2,2,2,1,0
12,1,1,0,1,14,14,14,1,1,12
0,12,0,0,0,0,0,0,0,12,0
endlayer

layer
0,12,0,0,0,0,0,0,0,12,0
12,1,1,4,1,9,0,0,1,1,12
0,1,2,2,2,2,2,2,2,13,0
0,0,2,12,12,12,12,12,2,0,0
0,0,2,12,12,12,12,12,2,0,0
0,1,2,12,12,12,12,12,2,5,0
0,0,2,12,12,12,12,12,2,14,0
0,1,2,12,12,12,12,12,2,5,0
0,1,2,2,2,2,2,2,2,1,0
12,1,1,14,14,0,15,11,1,1,12
0,12,0,0,0,0,0,0,0,12,0
endlayer

layer
0,12,0,0,0,0,0,0,0,12,0
12,1,1,9,0,4,0,11,1,1,12
0,1,2,2,2,2,2,2,2,1,0
0,1,2,12,12,12,12,12,2,1,0
0,1,2,12,12,12,12,12,2,13,0
0,0,2,12,12,12,12,12,2,0,0
0,0,2,12,12,12,12,12,2,0,0
0,0,2,12,12,12,12,12,2,14,0
0,1,2,2,2,2,2,2,2,1,0
12,1,1,0,15,15,0,0,1,1,12
0,12,0,0,0,0,0,0,0,12,0
endlayer

layer
0,12,0,0,0,0,0,0,0,12,0
12,1,1,4,0,0,11,1,1,1,12
0,1,2,2,2,2,2,2,2,1,0
0,0,2,12,12,12,12,12,2,14,0
0,0,2,12,12,12,12,12,2,0,0
0,0,2,12,12,12,12,12,2,0,0
0,1,2,12,12,12,12,12,2,15,0
0,1,2,12,12,12,12,12,2,1,0
0,1,2,2,2,2,2,2,2,1,0
12,1,1,1,0,15,15,1,1,1,12
0,12,0,0,0,0,0,0,0,12,0
endlayer

layer
0,12,0,0,0,0,0,0,0,12,0
12,1,4,0,0,0,0,6,1,1,12
0,1,2,2,2,2,2,2,2,1,0
0,1,2,12,12,12,12,12,2,1,0
0,0,2,12,12,12,12,12,2,0,0
0,0,2,12,12,12,12,12,2,0,0
0,0,2,12,12,12,12,12,2,0,0
0,1,2,12,12,12,12,12,2,5,0
0,1,2,2,2,2,2,2,2,1,0
12,1,1,15,0,0,0,1,1,1,12
0,12,0,0,0,0,0,0,0,12,0
endlayer

layer
0,12,0,0,0,0,0,0,0,12,0
12,1,9,0,15,11,1,0,1,1,12
0,1,2,2,2,2,2,2,2,1,0
0,0,2,12,12,12,12,12,2,8,0
0,0,2,12,12,12,12,12,2,14,0
0,1,2,12,12,12,12,12,2,0,0
0,1,2,12,12,12,12,12,2,0,0
0,1,2,12,12,12,12,12,2,10,0
0,1,2,2,2,2,2,2,2,1,0
12,1,1,1,1,15,15,0,1,1,12
0,12,0,0,0,0,0,0,0,12,0
endlayer

layer
0,12,0,0,0,0,0,0,0,12,0
12,1,1,0,6,1,4,0,1,1,12
0,1,2,2,2,2,2,2,2,1,0
0,0,2,12,12,12,12,12,2,1,0
0,0,2,12,12,12,12,12,2,13,0
0,0,2,12,12,12,12,12,2,0,0
0,1,2,12,12,12,12,12,2,14,0
0,0,2,12,12,12,12,12,2,14,0
0,1,2,2,2,2,2,2,2,10,0
12,1,1,0,0,15,15,0,1,1,12
0,12,0,0,0,0,0,0,0,12,0
endlayer

layer
0,12,0,0,0,0,0,0,0,12,0
12,1,1,9,0,1,0,0,1,1,12
0,1,2,2,2,2,2,2,2,1,0
0,0,2,12,12,12,12,12,2,15,0
0,1,2,12,12,12,12,12,2,0,0
0,0,2,12,12,12,12,12,2,0,0
0,0,2,12,12,12,12,12,2,1,0
0,0,2,12,12,12,12,12,2,1,0
0,1,2,2,2,2,2,2,2,1,0
12,1,1,14,14,1,0,1,1,1,12
0,12,0,0,0,0,0,0,0,12,0
endlayer

layer
0,12,0,0,0,0,0,0,0,12,0
12,1,1,0,1,9,0,11,1,1,12
0,1,2,2,2,2,2,2,2,1,0
0,1,2,12,12,12,12,12,2,1,0
0,1,2,12,12,12,12,12,2,13,0
0,0,2,12,12,12,12,12,2,15,0
0,1,2,12,12,12,12,12,2,0,0
0,1,2,12,12,12,12,12,2,14,0
0,1,2,2,2,2,2,2,2,1,0
12,1,1,1,15,0,14,14,1,1,12
0,12,0,0,0,0,0,0,0,12,0
endlayer

layer
0,12,0,0,0,0,0,0,0,12,0
12,1,1,1,1,1,1,1,1,1,12
0,1,2,2,2,2,2,2,2,1,0
0,1,2,12,12,12,12,12,2,1,0
0,1,2,12,12,12,12,12,2,1,0
0,1,2,12,12,12,12,12,2,1,0
0,1,2,12,12,12,12,12,2,1,0
0,1,2,12,12,12,12,12,2,1,0
0,1,2,2,2,2,2,2,2,1,0
12,1,1,1,1,1,1,1,1,1,12
0,12,0,0,0,0,0,0,0,12,0
endlayer

layer
0,12,0,0,0,0,0,0,0,12,0
12,1,1,1,1,0,6,0,6,1,12
0,1,2,2,2,2,2,2,2,1,0
0,0,2,12,12,12,12,12,2,1,0
0,1,2,12,12,12,12,12,2,14,0
0,1,2,12,12,12,12,12,2,0,0
0,0,2,12,12,12,12,12,2,14,0
0,1,2,12,12,12,12,12,2,1,0
0,1,2,2,2,2,2,2,2,1,0
12,1,1,14,0,15,15,1,1,1,12
0,12,0,0,0,0,0,0,0,12,0
endlayer

layer
0,12,0,0,0,0,0,0,0,12,0
12,1,1,14,1,9,0,0,1,1,12
0,1,2,2,2,2,2,2,2,1,0
0,0,2,12,12,12,12,12,2,8,0
0,0,2,12,12,12,12,12,2,0,0
0,0,2,12,12,12,12,12,2,0,0
0,0,2,12,12,12,12,12,2,10,0
0,1,2,12,12,12,12,12,2,15,0
0,1,2,2,2,2,2,2,2,1,0
12,1,1,14,6,0,0,15,1,1,12
0,12,0,0,0,0,0,0,0,12,0
endlayer

layer
0,12,0,0,0,0,0,0,0,12,0
12,1,9,0,0,6,0,11,1,1,12
0,1,2,2,2,2,2,2,2,13,0
0,1,2,12,12,12,12,12,2,0,0
0,1,2,12,12,12,12,12,2,5,0
0,0,2,12,12,12,12,12,2,15,0
0,0,2,12,12,12,12,12,2,0,0
0,0,2,12,12,12,12,12,2,15,0
0,1,2,2,2,2,2,2,2,1,0
12,1,1,0,15,15,0,0,1,1,12
0,12,0,0,0,0,0,0,0,12,0
endlayer

layer
0,12,0,0,0,0,0,0,0,12,0
12,1,1,4,0,0,11,1,1,1,12
0,1,2,2,2,2,2,2,2,1,0
0,0,2,12,12,12,12,12,2,15,0
0,0,2,12,12,12,12,12,2,0,0
0,0,2,12,12,12,12,12,2,5,0
0,1,2,12,12,12,12,12,2,15,0
0,1,2,12,12,12,12,12,2,5,0
0,1,2,2,2,2,2,2,2,1,0
12,1,1,1,0,15,15,1,1,1,12
0,12,0,0,0,0,0,0,0,12,0
endlayer

layer
0,12,0,0,0,0,0,0,0,12,0
12,1,1,15,0,0,0,6,1,1,12
0,1,2,2,2,2,2,2,2,1,0
0,1,2,12,12,12,12,12,2,14,0
0,0,2,12,12,12,12,12,2,15,0
0,0,2,12,12,12,12,12,2,0,0
0,0,2,12,12,12,12,12,2,0,0
0,1,2,12,12,12,12,12,2,5,0
0,1,2,2,2,2,2,2,2,1,0
12,1,1,14,0,0,14,1,1,1,12
0,12,0,0,0,0,0,0,0,12,0
endlayer

layer
0,12,0,0,0,0,0,0,0,12,0
12,1,1,1,9,0,15,0,1,1,12
0,1,2,2,2,2,2,2,2,1,0
0,1,2,12,12,12,12,12,2,13,0
0,0,2,12,12,12,12,12,2,10,0
0,1,2,12,12,12,12,12,2,8,0
0,0,2,12,12,12,12,12,2,0,0
0,0,2,12,12,12,12,12,2,0,0
0,1,2,2,2,2,2,2,2,10,0
12,1,1,1,0,14,14,1,1,1,12
0,12,0,0,0,0,0,0,0,12,0
endlayer

layer
0,12,0,0,0,0,0,0,0,12,0
12,1,1,4,0,0,6,1,1,1,12
0,1,2,2,2,2,2,2,2,8,0
0,0,2,12,12,12,12,12,2,0,0
0,0,2,12,12,12,12,12,2,14,0
0,0,2,12,12,12,12,12,2,1,0
0,1,2,12,12,12,12,12,2,13,0
0,1,2,12,12,12,12,12,2,0,0
0,1,2,2,2,2,2,2,2,10,0
12,1,1,0,14,0,14,1,1,1,12
0,12,0,0,0,0,0,0,0,12,0
endlayer

layer
0,12,0,0,0,0,0,0,0,12,0
12,1,1,0,1,9,0,1,1,1,12
0,1,2,2,2,2,2,2,2,1,0
0,1,2,12,12,12,12,12,2,1,0
0,1,2,12,12,12,12,12,2,15,0
0,0,2,12,12,12,12,12,2,0,0
0,0,2,12,12,12,12,12,2,14,0
0,0,2,12,12,12,12,12,2,15,0
0,1,2,2,2,2,2,2,2,1,0
12,1,1,14,14,0,1,0,1,1,12
0,12,0,0,0,0,0,0,0,12,0
endlayer

layer
0,12,0,0,0,0,0,0,0,12,0
12,1,1,1,14,0,0,15,1,1,12
0,1,2,2,2,2,2,2,2,1,0
0,1,2,12,12,12,12,12,2,0,0
0,0,2,12,12,12,12,12,2,15,0
0,0,2,12,12,12,12,12,2,15,0
0,1,2,12,12,12,12,12,2,0,0
0,1,2,12,12,12,12,12,2,5,0
0,1,2,2,2,2,2,2,2,1,0
12,1,1,15,1,15,0,1,1,1,12
0,12,0,0,0,0,0,0,0,12,0
endlayer

layer
0,12,0,0,0,0,0,0,0,12,0
12,1,1,1,1,1,1,1,1,1,12
0,1,2,2,2,2,2,2,2,1,0
0,1,2,12,12,12,12,12,2,1,0
0,1,2,12,12,12,12,12,2,1,0
0,1,2,12,12,12,12,12,2,1,0
0,1,2,12,12,12,12,12,2,1,0
0,1,2,12,12,12,12,12,2,1,0
0,1,2,2,2,2,2,2,2,1,0
12,1,1,1,1,1,1,1,1,1,12
0,12,0,0,0,0,0,0,0,12,0
endlayer

layer
0,12,0,0,0,0,0,0,0,12,0
12,1,4,14,1,14,0,14,1,1,12
0,1,2,2,2,2,2,2,2,1,0
0,1,2,12,12,12,12,12,2,1,0
0,1,2,12,12,12,12,12,2,15,0
0,1,2,12,12,12,12,12,2,0,0
0,0,2,12,12,12,12,12,2,14,0
0,1,2,12,12,12,12,12,2,1,0
0,1,2,2,2,2,2,2,2,1,0
12,1,1,15,15,14,0,15,1,1,12
0,12,0,0,0,0,0,0,0,12,0
endlayer

layer
0,12,0,0,0,0,0,0,0,12,0
12,1,1,0,0,4,0,0,1,1,12
0,1,2,2,2,2,2,2,2,1,0
0,1,2,12,12,12,12,12,2,14,0
0,0,2,12,12,12,12,12,2,0,0
0,1,2,12,12,12,12,12,2,15,0
0,0,2,12,12,12,12,12,2,15,0
0,1,2,12,12,12,12,12,2,5,0
0,1,2,2,2,2,2,2,2,1,0
12,1,1,0,14,1,15,0,1,1,12
0,12,0,0,0,0,0,0,0,12,0
endlayer

layer
0,12,0,0,0,0,0,0,0,12,0
12,1,1,1,0,11,1,15,1,1,12
0,1,2,2,2,2,2,2,2,8,0
0,0,2,12,12,12,12,12,2,14,0
0,1,2,12,12,12,12,12,2,0,0
0,0,2,12,12,12,12,12,2,10,0
0,1,2,12,12,12,12,12,2,0,0
0,0,2,12,12,12,12,12,2,0,0
0,1,2,2,2,2,2,2,2,1,0
12,1,1,0,14,14,0,1,1,1,12
0,12,0,0,0,0,0,0,0,12,0
endlayer

layer
0,12,0,0,0,0,0,0,0,12,0
12,1,1,9,0,0,11,1,1,1,12
0,1,2,2,2,2,2,2,2,13,0
0,1,2,12,12,12,12,12,2,0,0
0,0,2,12,12,12,12,12,2,5,0
0,0,2,12,12,12,12,12,2,14,0
0,1,2,12,12,12,12,12,2,8,0
0,1,2,12,12,12,12,12,2,15,0
0,1,2,2,2,2,2,2,2,10,0
12,1,1,1,0,14,0,0,1,1,12
0,12,0,0,0,0,0,0,0,12,0
endlayer

layer
0,12,0,0,0,0,0,0,0,12,0
12,1,1,4,0,0,0,15,1,1,12
0,1,2,2,2,2,2,2,2,13,0
0,1,2,12,12,12,12,12,2,14,0
0,0,2,12,12,12,12,12,2,15,0
0,0,2,12,12,12,12,12,2,0,0
0,0,2,12,12,12,12,12,2,0,0
0,1,2,12,12,12,12,12,2,15,0
0,1,2,2,2,2,2,2,2,1,0
12,1,1,15,0,0,0,14,1,1,12
0,12,0,0,0,0,0,0,0,12,0
endlayer

layer
0,12,0,0,0,0,0,0,0,12,0
12,1,1,0,15,1,1,1,1,1,12
0,1,2,2,2,2,2,2,2,1,0
0,0,2,12,12,12,12,12,2,14,0
0,0,2,12,12,12,12,12,2,0,0
0,1,2,12,12,12,12,12,2,10,0
0,1,2,12,12,12,12,12,2,14,0
0,1,2,12,12,12,12,12,2,5,0
0,1,2,2,2,2,2,2,2,1,0
12,1,1,14,14,0,15,1,1,1,12
0,12,0,0,0,0,0,0,0,12,0
endlayer

layer
0,12,0,0,0,0,0,0,0,12,0
12,1,4,0,1,1,14,0,11,1,12
0,1,2,2,2,2,2,2,2,1,0
0,1,2,12,12,12,12,12,2,8,0
0,1,2,12,12,12,12,12,2,0,0
0,0,2,12,12,12,12,12,2,5,0
0,0,2,12,12,12,12,12,2,8,0
0,0,2,12,12,12,12,12,2,0,0
0,1,2,2,2,2,2,2,2,1,0
12,1,1,1,1,14,0,0,1,1,12
0,12,0,0,0,0,0,0,0,12,0
endlayer

layer
0,12,0,0,0,0,0,0,0,12,0
12,1,1,9,0,1,4,0,11,1,12
0,1,2,2,2,2,2,2,2,1,0
0,1,2,12,12,12,12,12,2,0,0
0,0,2,12,12,12,12,12,2,0,0
0,0,2,12,12,12,12,12,2,0,0
0,1,2,12,12,12,12,12,2,0,0
0,1,2,12,12,12,12,12,2,0,0
0,1,2,2,2,2,2,2,2,10,0
12,1,1,0,0,15,4,14,1,1,12
0,12,0,0,0,0,0,0,0,12,0
endlayer

layer
0,12,0,0,0,0,0,0,0,12,0
12,1,1,4,0,0,11,1,1,1,12
0,1,2,2,2,2,2,2,2,1,0
0,1,2,12,12,12,12,12,2,8,0
0,1,2,12,12,12,12,12,2,15,0
0,0,2,12,12,12,12,12,2,0,0
0,0,2,12,12,12,12,12,2,10,0
0,1,2,12,12,12,12,12,2,13,0
0,1,2,2,2,2,2,2,2,1,0
12,1,1,1,0,0,14,1,1,1,12
0,12,0,0,0,0,0,0,0,12,0
endlayer

layer
0,12,0,0,0,0,0,0,0,12,0
12,1,1,1,1,1,1,1,1,1,12
0,1,2,2,2,2,2,2,2,1,0
0,1,2,12,12,12,12,12,2,1,0
0,1,2,12,12,12,12,12,2,1,0
0,1,2,12,12,12,12,12,2,1,0
0,1,2,12,12,12,12,12,2,1,0
0,1,2,12,12,12,12,12,2,1,0
0,1,2,2,2,2,2,2,2,1,0
12,1,1,1,1,1,1,1,1,1,12
0,12,0,0,0,0,0,0,0,12,0
endlayer

layer
0,12,0,0,0,0,0,0,0,12,0
12,1,1,1,4,0,14,6,1,1,12
0,1,2,2,2,2,2,2,2,1,0
0,0,2,12,12,12,12,12,2,1,0
0,0,2,12,12,12,12,12,2,8,0
0,1,2,12,12,12,12,12,2,0,0
0,1,2,12,12,12,12,12,2,14,0
0,0,2,12,12,12,12,12,2,1,0
0,1,2,2,2,2,2,2,2,1,0
12,1,1,15,15,1,14,0,1,1,12
0,12,0,0,0,0,0,0,0,12,0
endlayer

layer
0,12,0,0,0,0,0,0,0,12,0
12,1,1,4,14,0,0,14,1,1,12
0,1,2,2,2,2,2,2,2,1,0
0,1,2,12,12,12,12,12,2,1,0
0,0,2,12,12,12,12,12,2,15,0
0,1,2,12,12,12,12,12,2,0,0
0,1,2,12,12,12,12,12,2,14,0
0,0,2,12,12,12,12,12,2,5,0
0,1,2,2,2,2,2,2,2,1,0
12,1,1,0,14,14,15,15,1,1,12
0,12,0,0,0,0,0,0,0,12,0
endlayer

layer
0,12,0,0,0,0,0,0,0,12,0
12,1,1,1,9,0,15,1,1,1,12
0,1,2,2,2,2,2,2,2,1,0
0,0,2,12,12,12,12,12,2,8,0
0,1,2,12,12,12,12,12,2,0,0
0,0,2,12,12,12,12,12,2,10,0
0,0,2,12,12,12,12,12,2,14,0
0,1,2,12,12,12,12,12,2,0,0
0,1,2,2,2,2,2,2,2,5,0
12,1,1,14,1,0,0,15,1,1,12
0,12,0,0,0,0,0,0,0,12,0
endlayer

layer
0,12,0,0,0,0,0,0,0,12,0
12,1,1,1,4,0,6,1,1,1,12
0,1,2,2,2,2,2,2,2,1,0
0,1,2,12,12,12,12,12,2,0,0
0,0,2,12,12,12,12,12,2,14,0
0,0,2,12,12,12,12,12,2,1,0
0,1,2,12,12,12,12,12,2,13,0
0,1,2,12,12,12,12,12,2,0,0
0,1,2,2,2,2,2,2,2,1,0
12,1,1,1,0,1,14,14,1,1,12
0,12,0,0,0,0,0,0,0,12,0
endlayer

layer
0,12,0,0,0,0,0,0,0,12,0
12,1,1,15,0,0,0,14,1,1,12
0,1,2,2,2,2,2,2,2,13,0
0,0,2,12,12,12,12,12,2,10,0
0,0,2,12,12,12,12,12,2,14,0
0,0,2,12,12,12,12,12,2,0,0
0,0,2,12,12,12,12,12,2,0,0
0,1,2,12,12,12,12,12,2,15,0
0,1,2,2,2,2,2,2,2,5,0
12,1,1,14,14,0,0,14,1,1,12
0,12,0,0,0,0,0,0,0,12,0
endlayer

layer
0,12,0,0,0,0,0,0,0,12,0
12,1,1,1,1,4,0,1,1,1,12
0,1,2,2,2,2,2,2,2,1,0
0,1,2,12,12,12,12,12,2,8,0
0,1,2,12,12,12,12,12,2,0,0
0,0,2,12,12,12,12,12,2,15,0
0,0,2,12,12,12,12,12,2,5,0
0,1,2,12,12,12,12,12,2,5,0
0,1,2,2,2,2,2,2,2,1,0
12,1,1,1,1,15,0,1,1,1,12
0,12,0,0,0,0,0,0,0,12,0
endlayer

layer
0,12,0,0,0,0,0,0,0,12,0
12,1,1,1,14,0,11,14,1,1,12
0,1,2,2,2,2,2,2,2,1,0
0,0,2,12,12,12,12,12,2,0,0
0,1,2,12,12,12,12,12,2,13,0
0,1,2,12,12,12,12,12,2,0,0
0,0,2,12,12,12,12,12,2,0,0
0,0,2,12,12,12,12,12,2,5,0
0,1,2,2,2,2,2,2,2,1,0
12,1,1,1,15,0,15,15,1,1,12
0,12,0,0,0,0,0,0,0,12,0
endlayer

layer
0,12,0,0,0,0,0,0,0,12,0
12,1,1,1,9,0,0,0,1,1,12
0,1,2,2,2,2,2,2,2,1,0
0,0,2,12,12,12,12,12,2,8,0
0,0,2,12,12,12,12,12,2,0,0
0,1,2,12,12,12,12,12,2,15,0
0,0,2,12,12,12,12,12,2,13,0
0,1,2,12,12,12,12,12,2,15,0
0,1,2,2,2,2,2,2,2,1,0
12,1,1,0,15,15,0,0,1,1,12
0,12,0,0,0,0,0,0,0,12,0
endlayer

layer
0,12,0,0,0,0,0,0,0,12,0
12,1,1,15,0,0,15,1,1,1,12
0,1,2,2,2,2,2,2,2,1,0
0,1,2,12,12,12,12,12,2,15,0
0,0,2,12,12,12,12,12,2,0,0
0,1,2,12,12,12,12,12,2,14,0
0,0,2,12,12,12,12,12,2,0,0
0,0,2,12,12,12,12,12,2,14,0
0,1,2,2,2,2,2,2,2,1,0
12,1,1,0,15,0,14,1,1,1,12
0,12,0,0,0,0,0,0,0,12,0
endlayer

layer
0,12,0,0,0,0,0,0,0,12,0
12,1,1,1,1,1,1,1,1,1,12
0,1,2,2,2,2,2,2,2,1,0
0,1,2,12,12,12,12,12,2,13,0
0,1,2,12,12,12,12,12,2,1,0
0,1,2,12,12,12,12,12,2,13,0
0,1,2,12,12,12,12,12,2,10,0
0,1,2,12,12,12,12,12,2,1,0
0,1,2,2,2,2,2,2,2,1,0
12,1,1,1,1,1,1,1,1,1,12
0,12,0,0,0,0,0,0,0,12,0
endlayer

layer
0,12,9,0,0,0,0,0,11,12,0
12,1,1,1,1,1,1,1,1,1,12
13,1,12,12,12,12,12,12,12,1,13
0,1,12,12,12,12,12,12,12,1,0
0,1,12,12,12,12,12,12,12,1,0
0,1,12,12,12,12,12,12,12,1,0
0,1,12,12,12,12,12,12,12,1,0
0,1,12,12,12,12,12,12,12,1,0
10,1,12,12,12,12,12,12,12,1,10
12,1,1,1,1,1,1,1,1,1,12
0,12,9,0,0,0,0,0,11,12,0
endlayer

layer
0,12,12,9,15,0,15,11,12,12,0
12,1,1,1,1,1,1,1,1,1,12
12,1,12,12,12,12,12,12,12,1,12
13,1,12,12,12,12,12,12,12,1,13
15,1,12,12,12,12,12,12,12,1,15
0,1,12,12,12,12,12,12,12,1,0
15,1,12,12,12,12,12,12,12,1,15
10,1,12,12,12,12,12,12,12,1,10
12,1,12,12,12,12,12,12,12,1,12
12,1,1,1,1,1,1,1,1,1,12
0,12,12,9,15,0,15,11,12,12,0
endlayer

layer
0,14,14,12,12,12,12,12,14,14,0
14,1,1,1,1,1,1,1,1,1,14
14,1,12,12,12,12,12,12,12,1,14
12,1,12,12,12,12,12,12,12,1,12
12,1,12,12,12,12,12,12,12,1,12
12,1,12,12,12,12,12,12,12,1,12
12,1,12,12,12,12,12,12,12,1,12
12,1,12,12,12,12,12,12,12,1,12
14,1,12,12,12,12,12,12,12,1,14
14,1,1,1,1,1,1,1,1,1,14
0,14,14,12,12,12,12,12,14,14,0
endlayer

layer
12,12,12,12,12,12,12,12,12,12,12
12,1,1,1,1,1,1,1,1,1,12
12,1,12,12,12,12,12,12,12,1,12
12,1,12,12,12,12,12,12,12,1,12
12,1,12,12,12,12,12,12,12,1,12
12,1,12,12,12,12,12,12,12,1,12
12,1,12,12,12,12,12,12,12,1,12
12,1,12,12,12,12,12,12,12,1,12
12,1,12,12,12,12,12,12,12,1,12
12,1,1,1,1,1,1,1,1,1,12
12,12,12,12,12,12,12,12,12,12,12
endlayer

layer
15,15,15,15,12,12,12,15,15,15,15
15,1,1,1,1,1,1,1,1,1,15
15,1,12,12,12,12,12,12,12,1,15
15,1,12,12,12,12,12,12,12,1,15
12,1,12,12,12,12,12,12,12,1,12
12,1,12,12,12,12,12,12,12,1,12
12,1,12,12,12,12,12,12,12,1,12
15,1,12,12,12,12,12,12,12,1,15
15,1,12,12,12,12,12,12,12,1,15
15,1,1,1,1,1,1,1,1,1,15
15,15,15,15,12,12,12,15,15,15,15
endlayer

layer
14,14,14,14,12,12,12,14,14,14,14
14,1,1,1,1,1,1,1,1,1,14
14,1,12,12,12,12,12,12,12,1,14
14,1,12,12,12,12,12,12,12,1,14
12,1,12,12,12,12,12,12,12,1,12
12,1,12,12,12,12,12,12,12,1,12
12,1,12,12,12,12,12,12,12,1,12
14,1,12,12,12,12,12,12,12,1,14
14,1,12,12,12,12,12,12,12,1,14
14,1,1,1,1,1,1,1,1,1,14
14,14,14,14,12,12,12,14,14,14,14
endlayer

layer
12,12,12,12,12,12,12,12,12,12,12
12,1,1,1,1,1,1,1,1,1,12
12,1,12,12,12,12,12,12,12,1,12
12,1,12,12,12,12,12,12,12,1,12
12,1,12,12,12,12,12,12,12,1,12
12,1,12,12,12,12,12,12,12,1,12
12,1,12,12,12,12,12,12,12,1,12
12,1,12,12,12,12,12,12,12,1,12
12,1,12,12,12,12,12,12,12,1,12
12,1,1,1,1,1,1,1,1,1,12
12,12,12,12,12,12,12,12,12,12,12
endlayer

layer
15,15,15,12,12,12,12,12,15,15,15
15,1,1,1,1,1,1,1,1,1,15
15,1,12,12,12,12,12,12,12,1,15
12,1,12,12,12,12,12,12,12,1,12
12,1,12,12,12,12,12,12,12,1,12
12,1,12,12,12,12,12,12,12,1,12
12,1,12,12,12,12,12,12,12,1,12
12,1,12,12,12,12,12,12,12,1,12
15,1,12,12,12,12,12,12,12,1,15
15,1,1,1,1,1,1,1,1,1,15
15,15,15,12,12,12,12,12,15,15,15
endlayer

layer
14,14,12,12,12,12,12,12,12,14,14
14,1,1,1,1,1,1,1,1,1,14
12,1,12,12,12,12,12,12,12,1,12
12,1,12,12,12,12,12,12,12,1,12
12,1,12,12,12,12,12,12,12,1,12
12,1,12,12,12,12,12,12,12,1,12
12,1,12,12,12,12,12,12,12,1,12
12,1,12,12,12,12,12,12,12,1,12
12,1,12,12,12,12,12,12,12,1,12
14,1,1,1,1,1,1,1,1,1,14
14,14,12,12,12,12,12,12,12,14,14
endlayer

layer
12,12,12,12,14,14,14,12,12,12,12
12,1,1,1,1,1,1,1,1,1,12
12,1,12,12,12,12,12,12,12,1,12
12,1,12,12,12,12,12,12,12,1,12
14,1,12,12,12,12,12,12,12,1,14
14,1,12,12,12,12,12,12,12,1,14
14,1,12,12,12,12,12,12,12,1,14
12,1,12,12,12,12,12,12,12,1,12
12,1,12,12,12,12,12,12,12,1,12
12,1,1,1,1,1,1,1,1,1,12
12,12,12,12,14,14,14,12,12,12,12
endlayer

layer
0,14,0,0,0,0,0,0,0,14,0
14,7,14,0,0,0,0,0,14,7,14
0,14,14,0,0,0,0,0,14,14,0
0,0,0,0,0,0,0,0,0,0,0
0,0,0,0,0,0,0,0,0,0,0
0,0,0,0,0,0,0,0,0,0,0
0,0,0,0,0,0,0,0,0,0,0
0,0,0,0,0,0,0,0,0,0,0
0,14,14,0,0,0,0,0,14,14,0
14,7,14,0,0,0,0,0,14,7,14
0,14,0,0,0,0,0,0,0,14,0
endlayer

