
# Created by Ruins mod version 16.5 Ingame Parser
# authoring Player: lafuller

weight=1
embed_into_distance=5
acceptable_target_blocks=
unacceptable_target_blocks=flowing_water,water,flowing_lava,lava,ice,bedrock,netherrack,nether_brick,nether_brick_fence,soul_sand,quartz_ore,end_stone,obsidian,iron_bars,cloud,flesh,ash_block,slime_grass,slime_congealed,slime_dirt
dimensions=12,22,21
allowable_overhang=0
max_leveling=7
leveling_buffer=-1
preserve_water=0
preserve_lava=0

rule1=0,100,preserveBlock
rule2=0,100,minecraft:sandstone-2
rule3=0,100,minecraft:sandstone-0
rule4=0,100,minecraft:double_stone_slab-9
rule5=0,100,minecraft:sandstone_stairs-2
rule6=0,100,minecraft:sandstone_stairs-0
rule7=0,100,minecraft:sandstone_stairs-1
rule8=0,100,minecraft:sandstone_stairs-3
rule9=0,100,minecraft:trapdoor-8
rule10=0,100,bookshelf,pumpkin,melon_block,hay_block,ChestGenHook:chests/spawn_bonus_chest:5-5
rule11=0,100,minecraft:trapdoor-11
rule12=0,100,bookshelf,pumpkin,melon_block,hay_block,ChestGenHook:chests/stronghold_library:5-2
rule13=0,100,minecraft:trapdoor-10
rule14=0,100,minecraft:wooden_slab-9
rule15=0,100,minecraft:trapdoor-9
rule16=0,100,minecraft:sandstone_stairs-5
rule17=0,100,minecraft:trapdoor-0
rule18=0,100,minecraft:trapdoor-3
rule19=0,100,minecraft:trapdoor-2
rule20=0,100,minecraft:sandstone_stairs-4
rule21=0,100,minecraft:trapdoor-1
rule22=0,100,minecraft:stone_slab-9
rule23=0,100,minecraft:sandstone_stairs-6
rule24=0,100,minecraft:jungle_door-3
rule25=0,100,minecraft:jungle_door-0
rule26=0,100,minecraft:ladder-5
rule27=0,100,minecraft:jungle_door-2
rule28=0,100,minecraft:ladder-3
rule29=0,100,minecraft:jungle_door-1
rule30=0,100,bookshelf,pumpkin,melon_block,hay_block,ChestGenHook:chests/stronghold_crossing:5-3
rule31=0,100,minecraft:ladder-2
rule32=0,100,minecraft:jungle_door-8
rule33=0,100,minecraft:carpet-7
rule34=0,100,minecraft:carpet-8
rule35=0,100,minecraft:jungle_door-9
rule36=0,100,minecraft:wooden_slab-1
rule37=0,100,minecraft:stone_slab-1
rule38=0,100,minecraft:spruce_stairs-0
rule39=0,100,minecraft:spruce_stairs-2
rule40=0,100,minecraft:hay_block-0
rule41=0,100,minecraft:spruce_stairs-3
rule42=0,100,minecraft:spruce_stairs-1
rule43=0,100,minecraft:trapdoor-4

layer
2,2,2,3,3,3,3,3,2,1,1,1,1,1,1,1,1,1,1,1,1
4,4,4,4,4,4,4,4,3,1,1,1,1,1,1,1,1,1,1,1,1
4,2,2,3,3,3,4,4,3,3,3,3,4,4,2,4,1,1,1,1,1
4,2,2,3,3,3,4,4,4,4,4,4,4,4,3,3,3,3,4,1,1
4,3,3,3,3,3,4,3,3,3,3,3,4,4,4,4,4,4,4,1,1
4,3,3,3,3,3,4,3,3,3,3,3,4,3,3,3,3,3,4,1,1
4,3,3,3,3,3,4,3,3,3,3,3,4,3,3,3,3,3,4,4,1
4,4,4,4,4,4,4,3,3,3,3,3,4,3,3,3,3,3,4,3,1
4,2,2,4,4,4,4,3,3,3,3,3,4,3,3,3,3,3,4,3,1
2,2,2,4,4,4,4,4,4,4,4,4,4,3,3,3,3,3,4,3,1
1,1,1,1,4,4,4,4,3,3,3,3,3,4,4,4,4,4,4,4,1
1,1,1,1,4,4,4,4,3,3,3,3,3,4,3,3,3,3,3,4,1
1,1,1,1,4,4,4,4,3,3,3,3,3,4,3,3,3,3,3,2,2
1,1,1,1,4,4,4,4,3,3,3,3,3,4,3,3,3,3,3,4,3
1,1,1,2,4,4,4,4,3,3,3,3,3,4,3,3,3,3,3,4,3
1,1,1,2,4,4,4,4,4,4,4,4,4,4,3,3,3,3,3,4,3
1,1,1,2,4,3,3,3,3,3,4,4,4,4,4,4,4,4,4,4,2
1,1,1,2,4,3,3,3,3,3,4,4,4,4,3,3,3,3,3,4,3
1,1,1,2,4,3,3,3,3,3,4,4,4,4,3,3,3,3,3,3,3
1,1,1,2,4,3,3,3,3,3,4,3,3,1,1,4,4,4,1,1,1
1,1,1,2,4,3,3,3,3,3,4,3,3,1,1,1,1,1,1,1,1
1,1,1,2,4,4,4,4,4,4,4,4,3,1,1,1,1,1,1,1,1
endlayer

layer
2,2,2,3,3,3,3,3,2,1,1,1,1,1,1,1,1,1,1,1,1
4,4,4,4,4,4,4,4,3,1,1,1,1,1,1,1,1,1,1,1,1
4,2,2,3,3,3,4,4,3,3,3,3,4,4,2,5,1,1,1,1,1
4,2,2,3,3,3,4,4,4,4,4,4,4,4,3,3,3,3,4,1,1
4,3,3,3,3,3,4,3,3,3,3,3,4,4,4,4,4,4,4,1,1
4,3,3,3,3,3,4,3,3,3,3,3,4,3,3,3,3,3,4,1,1
4,3,3,3,3,3,4,3,3,3,3,3,4,3,3,3,3,3,4,6,1
4,4,4,4,4,4,4,3,3,3,3,3,4,3,3,3,3,3,4,3,1
4,2,2,4,4,4,4,3,3,3,3,3,4,3,3,3,3,3,4,3,1
4,4,4,4,4,4,4,4,4,4,4,4,4,3,3,3,3,3,4,3,1
1,1,1,1,4,4,4,4,3,3,3,3,3,4,4,4,4,4,4,4,1
1,1,1,1,4,4,4,4,3,3,3,3,3,4,3,3,3,3,3,4,1
1,1,1,1,4,4,4,4,3,3,3,3,3,4,3,3,3,3,3,2,2
1,1,1,1,4,4,4,4,3,3,3,3,3,4,3,3,3,3,3,4,3
1,1,1,4,4,4,4,4,3,3,3,3,3,4,3,3,3,3,3,4,3
1,1,1,4,4,4,4,4,4,4,4,4,4,4,3,3,3,3,3,4,3
1,1,1,4,4,3,3,3,3,3,4,4,4,4,4,4,4,4,4,4,2
1,1,1,4,4,3,3,3,3,3,4,4,4,4,3,3,3,3,3,4,3
1,1,1,4,4,3,3,3,3,3,4,4,4,4,3,3,3,3,3,3,3
1,1,1,4,4,3,3,3,3,3,4,3,3,1,1,8,7,5,1,1,1
1,1,1,4,4,3,3,3,3,3,4,3,3,1,1,1,1,1,1,1,1
1,1,1,2,4,4,4,4,4,4,4,4,3,1,1,1,1,1,1,1,1
endlayer

layer
2,2,3,3,3,3,3,2,2,1,1,1,1,1,1,1,1,1,1,1,1
4,4,4,4,4,4,4,4,3,1,1,1,1,1,1,1,1,1,1,1,1
4,2,2,9,0,0,4,4,3,3,3,3,4,4,5,1,1,1,1,1,1
4,2,2,0,0,0,7,2,4,4,4,4,4,4,3,3,3,3,4,1,1
4,12,0,0,0,0,0,3,11,11,10,3,4,4,4,4,4,4,4,1,1
4,9,0,0,0,0,0,3,0,0,0,3,4,9,0,0,0,3,4,1,1
4,9,0,0,0,0,0,3,0,0,0,3,4,0,0,0,0,3,4,1,1
4,9,0,0,0,0,0,3,0,0,0,7,4,0,0,0,0,3,4,6,1
2,2,2,4,13,13,13,3,0,0,0,0,4,12,0,0,0,7,4,3,1
4,4,4,4,3,4,4,4,4,4,4,4,4,2,0,0,0,0,4,3,1
1,1,1,1,4,4,4,4,9,0,0,0,10,4,0,0,0,0,4,4,1
1,1,1,1,4,4,4,4,0,0,0,0,0,4,14,14,14,2,2,4,1
1,1,1,1,4,4,4,4,0,0,0,0,0,0,3,3,3,3,3,4,3
1,1,1,1,4,4,4,4,0,0,0,0,0,0,0,0,0,0,15,4,3
1,1,1,8,4,4,4,4,13,0,0,0,0,0,0,0,0,0,15,4,3
1,1,1,4,4,4,4,4,4,4,0,0,0,0,0,0,0,0,15,4,3
1,1,1,4,4,0,10,3,3,3,4,0,0,8,2,4,4,4,4,4,2
1,1,1,4,4,0,0,3,3,2,4,4,4,4,3,3,3,3,3,4,3
1,1,1,4,4,0,0,0,8,7,4,4,4,4,5,1,1,1,8,3,3
1,1,1,4,4,0,0,0,0,0,4,3,3,1,1,1,1,1,1,1,1
1,1,1,4,4,9,0,0,0,0,4,3,3,1,1,1,1,1,1,1,1
1,1,1,2,4,4,4,4,4,4,4,4,3,1,1,1,1,1,1,1,1
endlayer

layer
2,2,2,3,3,3,3,2,6,1,1,1,1,1,1,1,1,1,1,1,1
2,4,4,4,4,4,4,4,3,1,1,1,1,1,1,1,1,1,1,1,1
7,2,2,0,0,0,7,4,3,3,3,4,4,5,1,1,1,1,1,1,1
1,2,2,0,0,0,0,2,4,4,4,4,4,4,3,3,3,4,5,1,1
4,0,0,0,0,0,0,3,0,0,0,3,4,4,4,4,4,4,4,1,1
4,0,0,0,0,0,0,3,0,0,0,3,4,0,0,0,0,3,4,1,1
4,0,0,0,0,0,0,3,0,0,0,7,4,0,0,0,0,3,4,1,1
4,0,0,0,0,0,0,3,0,0,0,0,4,0,0,0,0,7,4,1,1
2,4,2,4,0,0,0,3,0,0,0,0,4,0,0,0,0,0,4,6,1
8,2,2,2,4,4,4,4,4,4,4,4,4,2,0,0,0,0,4,3,1
1,1,1,1,4,4,4,4,0,0,0,0,0,4,0,0,0,0,4,4,1
1,1,1,1,4,4,4,4,0,0,0,0,0,4,0,0,0,2,2,4,1
1,1,1,1,2,4,4,4,0,0,0,0,0,0,3,3,3,3,3,4,2
1,1,1,1,2,4,4,4,0,0,0,0,0,0,0,0,0,0,0,4,2
1,1,1,1,8,4,4,4,0,0,0,0,0,0,0,0,0,0,0,4,3
1,1,1,4,4,4,4,4,4,4,0,0,0,0,0,0,0,0,0,4,3
1,1,1,3,4,16,16,3,3,3,4,0,0,0,8,3,4,4,4,4,3
1,1,1,3,4,0,0,3,5,0,4,4,4,4,4,3,3,3,4,4,3
1,1,1,3,4,0,0,0,0,0,4,4,1,1,1,1,1,1,1,8,3
1,1,1,3,4,0,0,0,0,0,4,3,6,1,1,1,1,1,1,1,1
1,1,1,2,4,0,0,0,0,0,4,3,3,1,1,1,1,1,1,1,1
1,1,1,2,4,4,4,4,4,4,4,4,3,1,1,1,1,1,1,1,1
endlayer

layer
2,2,3,3,3,3,3,3,1,1,1,1,1,1,1,1,1,1,1,1,1
7,4,4,4,4,4,7,3,6,1,1,1,1,1,1,1,1,1,1,1,1
1,2,2,17,0,0,0,4,4,4,4,4,5,1,1,1,1,1,1,1,1
1,2,2,0,0,0,0,2,4,4,4,4,4,4,4,4,4,5,1,1,1
4,0,0,0,0,0,0,3,18,18,18,3,4,4,4,4,4,4,4,1,1
4,0,0,0,0,0,0,3,0,0,0,7,4,17,0,0,0,3,4,1,1
4,0,0,0,0,0,0,3,0,0,0,0,4,17,0,0,0,7,4,1,1
4,0,0,0,0,0,0,3,0,0,0,0,4,17,0,0,0,0,4,1,1
2,4,4,4,17,19,19,3,0,0,0,0,4,17,0,0,0,0,4,1,1
1,8,2,2,2,4,4,4,4,4,4,4,4,2,0,0,0,0,4,6,1
1,1,1,1,2,4,4,4,17,0,0,0,0,4,0,0,0,20,4,2,1
1,1,1,1,2,4,4,4,0,0,0,0,0,4,0,0,0,2,2,4,1
1,1,1,1,7,2,4,4,0,0,0,0,0,0,3,3,3,3,3,4,3
1,1,1,1,1,2,4,4,0,0,0,0,0,0,0,0,0,0,21,4,3
1,1,1,1,1,8,4,4,17,0,0,0,0,0,0,0,0,0,21,4,3
1,1,1,2,4,4,4,4,4,4,0,0,0,0,0,0,0,0,21,4,3
1,1,1,3,4,3,3,3,3,3,4,0,0,0,0,8,4,4,4,4,3
1,1,1,3,4,16,16,5,0,0,4,4,3,3,4,4,4,4,4,3,5
1,1,1,3,4,0,0,0,0,0,4,4,1,1,1,1,1,1,1,1,1
1,1,1,3,4,0,0,0,0,0,4,4,1,1,1,1,1,1,1,1,1
1,1,1,2,4,17,0,0,0,0,4,4,6,1,1,1,1,1,1,1,1
1,1,1,8,4,4,4,4,4,4,4,4,5,1,1,1,1,1,1,1,1
endlayer

layer
1,1,3,3,3,3,3,3,1,1,1,1,1,1,1,1,1,1,1,1,1
1,6,4,2,3,5,0,3,1,1,1,1,1,1,1,1,1,1,1,1,1
1,2,4,4,4,6,0,3,6,3,4,5,1,1,1,1,1,1,1,1,1
1,4,4,4,4,4,0,2,4,4,4,4,2,3,4,4,5,1,1,1,1
2,4,4,4,4,4,20,4,14,14,14,7,4,4,4,4,4,4,2,1,1
4,4,4,4,4,4,4,14,14,14,14,0,4,4,4,4,5,0,4,1,1
4,4,4,4,4,4,4,14,14,14,14,0,4,4,4,4,6,0,4,1,1
2,4,4,4,4,4,4,14,14,14,22,0,4,4,4,4,4,0,2,1,1
3,3,4,4,4,4,4,20,20,20,20,20,4,4,4,4,4,0,4,1,1
1,1,8,2,2,3,4,4,4,4,4,4,4,4,4,4,4,20,3,1,1
1,1,1,1,2,3,4,4,4,4,4,4,4,4,4,4,4,4,3,6,1
1,1,1,1,7,3,4,4,4,4,4,4,4,4,4,3,4,4,3,2,1
1,1,1,1,1,1,4,4,4,4,4,4,4,4,4,4,4,4,4,4,3
1,1,1,1,1,1,4,4,4,4,4,4,4,4,4,4,4,4,4,2,3
1,1,1,1,1,1,8,4,4,4,4,4,4,4,4,4,4,4,4,4,3
1,1,1,3,2,4,4,4,4,4,4,4,2,2,2,7,7,4,4,4,3
1,1,1,3,4,4,4,4,4,4,4,3,23,0,0,0,8,4,4,2,3
1,1,1,3,4,4,5,0,0,0,4,3,3,3,3,4,4,4,3,5,1
1,1,1,3,14,14,14,14,14,14,4,4,1,1,1,1,1,1,1,1,1
1,1,1,3,14,14,14,14,14,14,4,4,1,1,1,1,1,1,1,1,1
1,1,1,3,4,4,23,14,14,14,4,7,1,1,1,1,1,1,1,1,1
1,1,1,1,8,4,4,2,4,4,2,1,1,1,1,1,1,1,1,1,1
endlayer

layer
1,1,2,3,3,2,3,2,1,1,1,1,1,1,1,1,1,1,1,1,1
1,1,3,0,0,0,0,3,1,1,1,1,1,1,1,1,1,1,1,1,1
1,1,24,0,0,0,0,3,1,1,1,1,1,1,1,1,1,1,1,1,1
1,1,3,0,0,0,13,2,2,3,25,4,4,1,1,1,1,1,1,1,1
4,3,3,0,0,0,4,3,0,0,0,0,4,4,2,25,2,4,4,1,1
4,0,26,0,0,0,4,0,0,0,0,0,4,14,0,0,0,0,4,1,1
4,0,0,0,0,0,4,0,0,0,0,0,4,14,0,0,0,0,4,1,1
4,0,0,0,0,13,4,0,0,0,3,20,4,14,0,0,0,0,4,1,1
2,3,3,27,3,3,0,0,0,3,14,14,14,3,0,0,0,20,4,1,1
1,1,1,1,1,24,0,0,28,3,0,0,0,3,0,0,0,3,1,1,1
1,1,1,1,1,3,0,0,0,3,0,0,0,3,0,0,0,29,1,1,1
1,1,1,1,1,3,3,2,3,0,0,0,30,3,13,0,0,3,1,1,1
1,1,1,1,1,1,1,3,0,0,0,0,3,4,3,3,3,3,3,4,2
1,1,1,1,1,1,1,24,0,0,0,0,3,0,0,0,0,0,26,0,3
1,1,1,1,1,1,1,4,0,0,0,0,3,0,0,0,0,0,0,0,3
1,1,1,2,4,4,4,4,13,0,0,0,4,0,0,0,0,0,0,0,3
1,1,1,3,0,0,0,3,3,3,4,27,3,0,0,0,0,2,27,4,2
1,1,1,2,31,0,0,0,0,0,4,1,1,2,3,2,2,1,1,1,1
1,1,1,3,0,0,0,0,0,0,2,1,1,1,1,1,1,1,1,1,1
1,1,1,3,0,0,0,0,0,0,29,1,1,1,1,1,1,1,1,1,1
1,1,1,2,4,27,3,0,0,0,2,1,1,1,1,1,1,1,1,1,1
1,1,1,1,1,1,1,2,4,4,2,1,1,1,1,1,1,1,1,1,1
endlayer

layer
1,1,2,3,2,0,2,2,1,1,1,1,1,1,1,1,1,1,1,1,1
1,1,3,0,0,0,0,3,1,1,1,1,1,1,1,1,1,1,1,1,1
1,1,32,0,0,0,0,0,1,1,1,1,1,1,1,1,1,1,1,1,1
1,1,3,0,0,0,0,2,2,3,32,4,2,1,1,1,1,1,1,1,1
4,3,3,0,0,0,4,3,0,0,0,0,4,4,2,32,2,4,2,1,1
3,0,26,0,0,0,4,0,0,0,0,0,4,33,0,0,0,0,4,1,1
0,0,0,0,0,0,4,0,0,0,0,0,4,34,0,0,0,0,0,1,1
2,0,0,0,0,0,4,0,0,0,3,2,4,34,0,0,0,0,4,1,1
2,3,3,35,3,3,0,0,0,3,33,33,34,3,0,0,0,3,3,1,1
1,1,1,1,1,32,0,0,28,3,0,0,0,3,0,0,0,3,1,1,1
1,1,1,1,1,3,14,14,14,3,0,0,0,3,0,0,0,32,1,1,1
1,1,1,1,1,3,3,2,3,0,0,0,0,3,0,0,0,3,1,1,1
1,1,1,1,1,1,1,3,0,0,0,0,3,4,3,3,3,3,3,3,2
1,1,1,1,1,1,1,32,0,0,0,0,3,0,0,0,0,0,26,0,3
1,1,1,1,1,1,1,4,0,0,0,0,3,0,0,0,0,0,0,0,0
1,1,1,2,2,4,4,4,0,0,0,0,4,0,0,0,0,0,0,0,3
1,1,1,3,14,14,14,3,3,3,4,35,3,0,0,0,0,2,35,2,2
1,1,1,2,31,0,0,0,0,0,4,1,1,3,2,0,3,1,1,1,1
1,1,1,0,0,0,0,0,0,0,2,1,1,1,1,1,1,1,1,1,1
1,1,1,3,0,0,0,0,0,0,32,1,1,1,1,1,1,1,1,1,1
1,1,1,2,4,35,3,0,0,0,2,1,1,1,1,1,1,1,1,1,1
1,1,1,1,1,1,1,4,0,4,2,1,1,1,1,1,1,1,1,1,1
endlayer

layer
1,1,3,3,2,2,2,3,1,1,1,1,1,1,1,1,1,1,1,1,1
1,1,4,0,0,0,0,3,1,1,1,1,1,1,1,1,1,1,1,1,1
1,1,3,0,0,0,0,3,1,1,1,1,1,1,1,1,1,1,1,1,1
1,1,3,0,0,0,19,2,4,2,4,4,4,1,1,1,1,1,1,1,1
4,3,3,0,0,0,4,3,0,0,0,0,4,4,4,2,4,4,4,1,1
4,17,0,0,0,0,4,0,0,0,0,0,4,0,0,0,0,0,4,1,1
4,17,0,0,0,0,4,0,0,0,0,0,4,0,0,0,0,0,4,1,1
4,17,0,0,0,19,4,0,0,0,3,2,4,0,0,0,0,0,4,1,1
3,3,3,3,3,3,0,0,0,3,0,0,0,3,0,0,0,3,4,1,1
1,1,1,1,1,3,0,0,0,3,0,0,0,3,0,0,0,3,14,1,1
1,1,1,1,1,3,34,33,33,3,0,0,0,3,0,0,0,3,14,1,1
1,1,1,1,1,3,3,4,3,0,0,0,21,3,19,0,0,3,14,1,1
1,1,1,1,1,1,1,2,0,0,0,0,3,4,3,3,3,3,3,3,3
1,1,1,1,1,1,1,4,0,0,0,0,3,0,0,0,0,0,26,14,2
1,1,1,1,1,1,1,4,0,0,0,0,3,0,0,0,0,0,0,14,2
1,1,1,3,4,4,4,4,19,0,0,0,4,0,0,0,0,0,0,14,3
1,1,1,3,34,33,33,3,3,3,4,3,3,0,0,0,0,4,4,4,3
1,1,1,3,0,0,0,0,0,0,4,1,1,3,2,2,2,1,1,1,1
1,1,1,3,0,0,0,0,0,0,4,1,1,1,1,1,1,1,1,1,1
1,1,1,3,0,0,0,0,0,0,2,1,1,1,1,1,1,1,1,1,1
1,1,1,3,4,3,3,0,0,0,4,1,1,1,1,1,1,1,1,1,1
1,1,1,1,1,1,1,4,4,4,4,1,1,1,1,1,1,1,1,1,1
endlayer

layer
1,1,2,3,3,3,3,2,1,1,1,1,1,1,1,1,1,1,1,1,1
1,1,4,0,0,0,0,3,1,1,1,1,1,1,1,1,1,1,1,1,1
1,1,3,0,0,0,0,3,1,1,1,1,1,1,1,1,1,1,1,1,1
1,1,3,0,0,0,0,2,4,4,4,4,2,1,1,1,1,1,1,1,1
2,3,3,16,16,16,4,3,22,22,22,22,4,4,4,4,4,4,2,1,1
4,0,0,0,0,22,4,22,22,0,22,22,4,0,0,0,0,21,4,1,1
4,0,0,0,0,22,4,22,22,22,22,22,4,0,0,0,0,21,4,1,1
3,0,0,0,0,22,4,20,20,20,3,2,4,0,0,0,0,21,2,1,1
2,3,3,3,3,3,0,0,0,3,22,22,22,3,3,3,3,3,3,1,1
1,1,1,1,1,3,0,0,0,3,22,13,22,3,0,0,0,3,1,1,1
1,1,1,1,1,3,0,0,0,3,22,22,22,4,0,0,0,3,1,1,1
1,1,1,1,1,3,3,4,3,3,3,3,3,4,0,0,0,3,1,1,1
1,1,1,1,1,1,36,4,0,0,0,0,3,4,3,3,3,3,3,4,2
1,1,1,1,1,1,36,4,0,0,0,0,3,0,0,0,23,0,0,34,3
1,1,1,1,1,1,36,4,0,0,0,0,3,0,0,0,23,0,0,33,3
1,1,1,2,2,4,4,4,0,0,0,0,4,0,0,0,23,0,0,33,3
1,1,1,3,0,0,0,3,3,3,4,3,3,20,20,20,4,4,4,2,2
1,1,1,3,0,0,0,23,22,22,2,36,36,2,3,3,2,1,1,1,1
1,1,1,3,0,0,0,23,22,22,4,1,1,1,1,1,1,1,1,1,1
1,1,1,3,0,0,0,23,0,22,4,1,1,1,1,1,1,1,1,1,1
1,1,1,2,4,3,3,23,22,22,4,1,1,1,1,1,1,1,1,1,1
1,1,1,1,1,1,1,2,4,4,2,1,1,1,1,1,1,1,1,1,1
endlayer

layer
1,1,1,37,37,37,37,1,1,1,1,1,1,1,1,1,1,1,1,1,1
1,1,37,37,37,37,37,37,1,1,1,1,1,1,1,1,1,1,1,1,1
1,1,37,37,19,37,37,37,1,1,1,1,1,1,1,1,1,1,1,1,1
1,1,37,37,37,37,37,37,1,1,1,1,1,1,1,1,1,1,1,1,1
37,38,38,38,38,2,1,37,37,37,37,1,1,6,6,6,6,6,1,1,1
41,40,40,40,40,39,1,37,37,18,37,1,8,22,22,22,22,22,5,1,1
41,40,40,21,40,39,1,37,37,37,37,1,8,22,22,13,22,22,5,1,1
41,40,40,40,40,39,6,6,6,37,1,1,8,22,22,22,22,22,5,1,1
37,42,42,42,42,8,37,37,37,5,1,1,1,7,7,7,7,7,1,1,1
1,1,1,1,1,8,37,19,37,5,1,0,1,37,36,36,36,37,1,1,1
1,1,1,1,1,8,37,37,37,5,1,1,1,37,36,19,36,37,1,1,1
1,1,1,1,1,37,7,7,2,5,6,6,6,37,36,36,36,37,1,1,1
1,1,1,1,1,1,1,8,36,36,36,36,5,37,37,37,37,2,6,2,37
1,1,1,1,1,1,1,8,36,36,36,36,5,37,37,37,2,0,0,0,2
1,1,1,1,1,1,1,8,36,36,19,36,5,37,17,37,8,0,0,0,5
1,1,1,1,37,37,37,8,36,36,36,36,5,37,37,37,2,0,0,0,2
1,1,1,37,37,37,37,7,7,7,7,7,7,37,37,37,37,2,7,2,37
1,1,1,37,37,37,37,37,1,37,1,1,1,1,1,1,1,1,1,1,1
1,1,1,37,37,43,37,5,7,8,37,1,1,1,1,1,1,1,1,1,1
1,1,1,37,37,37,37,5,21,8,1,1,1,1,1,1,1,1,1,1,1
1,1,1,1,37,37,37,6,6,6,37,1,1,1,1,1,1,1,1,1,1
1,1,1,1,1,1,1,37,1,37,1,1,1,1,1,1,1,1,1,1,1
endlayer

layer
1,1,1,1,1,1,1,1,1,1,1,1,1,1,1,1,1,1,1,1,1
1,1,1,1,1,1,1,1,1,1,1,1,1,1,1,1,1,1,1,1,1
1,1,1,1,0,1,1,1,1,1,1,1,1,1,1,1,1,1,1,1,1
1,1,1,1,1,1,1,1,1,1,1,1,1,1,1,1,1,1,1,1,1
1,1,1,1,1,1,1,1,1,1,1,1,1,1,1,1,1,1,1,1,1
1,1,1,1,1,1,1,1,1,0,1,1,1,37,37,37,37,37,1,1,1
1,1,1,0,1,1,1,1,1,1,1,1,1,37,0,0,0,37,1,1,1
1,1,1,1,1,1,1,1,1,1,1,1,1,37,37,37,37,37,1,1,1
1,1,1,1,1,1,1,1,1,1,1,1,1,1,1,1,1,1,1,1,1
1,1,1,1,1,1,1,0,1,1,1,0,1,1,1,1,1,1,1,1,1
1,1,1,1,1,1,1,1,1,1,1,1,1,1,1,1,1,1,1,1,1
1,1,1,1,1,1,1,1,1,1,1,1,1,1,1,1,1,1,1,1,1
1,1,1,1,1,1,1,1,1,1,1,1,1,1,1,1,1,1,1,1,1
1,1,1,1,1,1,1,1,1,1,1,1,1,1,1,1,1,37,37,37,1
1,1,1,1,1,1,1,1,1,1,0,1,1,1,0,1,1,37,19,37,1
1,1,1,1,1,1,1,1,1,1,1,1,1,1,1,1,1,37,37,37,1
1,1,1,1,1,1,1,1,1,1,1,1,1,1,1,1,1,1,1,1,1
1,1,1,1,1,1,1,1,1,1,1,1,1,1,1,1,1,1,1,1,1
1,1,1,1,1,0,1,1,1,1,1,1,1,1,1,1,1,1,1,1,1
1,1,1,1,1,1,1,1,0,1,1,1,1,1,1,1,1,1,1,1,1
1,1,1,1,1,1,1,1,1,1,1,1,1,1,1,1,1,1,1,1,1
1,1,1,1,1,1,1,1,1,1,1,1,1,1,1,1,1,1,1,1,1
endlayer

