
# Created by Ruins mod version 16.5 Ingame Parser
# authoring Player: lafuller

weight=1
embed_into_distance=9
acceptable_target_blocks=
unacceptable_target_blocks=dirt,stone,flowing_lava,lava,ice,bedrock,netherrack,nether_brick,nether_brick_fence,soul_sand,quartz_ore,gravel,end_stone,obsidian,iron_bars,cloud,flesh,ash_block,slime_grass,slime_congealed,slime_dirt
biomesToSpawnIn=swampland,wetland,marsh,lush swamp
dimensions=22,10,9
allowable_overhang=0
max_leveling=4
leveling_buffer=-1
preserve_water=0
preserve_lava=0

rule1=0,100,preserveBlock
rule2=0,100,minecraft:log2-1
rule3=0,100,minecraft:trapdoor-3
rule4=0,100,minecraft:spruce_stairs-7
rule5=0,100,minecraft:spruce_fence-0
rule6=0,100,minecraft:fence-0
rule7=0,100,minecraft:spruce_stairs-4
rule8=0,100,minecraft:spruce_stairs-3
rule9=0,100,minecraft:ladder-5
rule10=0,100,minecraft:jungle_fence_gate-7
rule11=0,100,minecraft:oak_stairs-4
rule12=0,100,minecraft:spruce_stairs-5
rule13=0,100,minecraft:wooden_slab-8
rule14=0,100,minecraft:oak_stairs-7
rule15=0,100,minecraft:spruce_stairs-1
rule16=0,100,minecraft:spruce_fence_gate-0
rule17=0,100,minecraft:oak_stairs-5
rule18=0,100,minecraft:spruce_fence_gate-4
rule19=0,100,minecraft:double_wooden_slab-1
rule20=0,100,minecraft:oak_stairs-2
rule21=0,100,minecraft:wooden_slab-1
rule22=0,100,minecraft:jungle_door-1

rule23=0,100,IInventory;hopper;cooked_fish#3#1#0+red_mushroom#3#0#1-5,IInventory;hopper;fish#1#3#0+feather#3#0#1-5,IInventory;hopper;cooked_fish#1#0#0+glowstone_dust#3#0#1-5,IInventory;hopper;nether_wart#1#0#0+double_plant#3#1#1-5,IInventory;hopper;cooked_rabbit#2#0#0+redstone#5#0#1-5,IInventory;hopper;apple#2#0#0+gunpowder#4#0#1-5

rule24=0,100,minecraft:planks-0

rule25=0,100,IInventory;dropper;dye#4#0#4+name_tag#1#0#6-1,IInventory;dropper;coal#2#0#3+flint_and_steel#1#0#8-1,IInventory;dropper;lead#2#0#3+milk_bucket#1#0#8-1,IInventory;dropper;shears#1#0#5+glass_bottle#3#0#6-1,IInventory;dropper;golden_carrot#1#0#3-1,IInventory;dropper;speckled_melon#1#0#1+spruce_boat#1#0#6-1

rule26=0,100,minecraft:oak_stairs-6
rule27=0,100,minecraft:cauldron-0
rule28=0,100,minecraft:wooden_slab-9
rule29=0,100,minecraft:spruce_fence_gate-3
rule30=0,100,minecraft:jungle_door-8
rule31=0,100,IInventory;furnace;coal#2#0#1-3
rule32=0,100,minecraft:brewing_stand-0,air,air
rule33=0,100,minecraft:oak_stairs-3
rule34=0,100,minecraft:spruce_fence_gate-5
rule35=0,100,minecraft:spruce_stairs-6
rule36=0,100,minecraft:fence_gate-0
rule37=0,100,minecraft:spruce_fence_gate-1
rule38=0,100,minecraft:spruce_stairs-0
rule39=0,100,minecraft:dark_oak_stairs-6
rule40=0,100,minecraft:dark_oak_stairs-7
rule41=0,100,minecraft:wooden_slab-0
rule42=0,100,minecraft:spruce_stairs-2
rule43=0,100,minecraft:wooden_slab-11
rule44=0,100,minecraft:dark_oak_stairs-3
rule45=0,100,minecraft:dark_oak_fence-0
rule46=0,100,minecraft:dark_oak_stairs-5
rule47=0,100,minecraft:dark_oak_stairs-4
rule48=0,100,minecraft:dark_oak_stairs-0
rule49=0,100,minecraft:dark_oak_stairs-2
rule50=0,100,minecraft:trapdoor-13
rule51=0,100,minecraft:bookshelf-0,air,air
rule52=0,100,minecraft:double_wooden_slab-5
rule53=0,100,minecraft:trapdoor-12
rule54=0,100,minecraft:trapdoor-10
rule55=0,100,minecraft:planks-5
rule56=0,100,minecraft:spruce_fence_gate-2
rule57=0,100,minecraft:spruce_fence_gate-6
rule58=0,100,minecraft:carpet-7
rule59=0,100,minecraft:dark_oak_stairs-1
rule60=0,100,minecraft:wooden_slab-13
rule61=0,100,minecraft:wooden_slab-5
rule62=0,100,minecraft:trapdoor-9


layer
1,1,1,1,1,1,1,1,1
1,1,1,1,1,1,1,1,1
1,1,1,1,1,1,2,1,1
1,1,2,1,1,1,1,1,1
1,1,1,1,1,1,1,1,1
1,1,1,1,1,1,1,1,1
1,1,1,1,1,1,1,1,1
1,1,1,2,1,1,2,1,1
1,1,1,1,1,1,1,1,1
1,1,1,1,1,1,1,1,1
endlayer

layer
1,1,1,1,1,1,1,1,1
1,1,1,1,1,1,1,1,1
1,1,1,1,1,1,2,1,1
1,1,2,1,1,1,1,1,1
1,1,1,1,1,1,1,1,1
1,1,1,1,1,1,1,1,1
1,1,1,1,1,1,1,1,1
1,1,1,2,1,1,2,1,1
1,1,1,1,1,1,1,1,1
1,1,1,1,1,1,1,1,1
endlayer

layer
1,1,1,1,1,1,1,1,1
1,1,1,1,1,1,1,1,1
1,1,1,1,1,1,2,1,1
1,1,2,1,1,1,1,1,1
1,1,1,1,1,1,1,1,1
1,1,1,1,1,1,1,1,1
1,1,1,1,1,1,1,1,1
1,1,1,2,1,1,2,1,1
1,1,1,1,1,1,1,1,1
1,1,1,1,1,1,1,1,1
endlayer

layer
1,1,1,1,1,1,1,1,1
1,1,1,1,1,1,1,1,1
1,1,1,1,1,1,2,1,1
1,1,2,1,1,1,1,1,1
1,1,1,1,1,1,1,1,1
1,1,1,1,1,1,1,1,1
1,1,1,1,1,1,1,1,1
1,1,1,2,1,1,2,1,1
1,1,1,1,1,1,1,1,1
1,1,1,1,1,1,1,1,1
endlayer

layer
1,1,1,1,1,1,1,1,1
1,1,1,1,1,1,1,1,1
1,1,1,1,1,1,2,1,1
1,1,2,1,1,1,1,1,1
1,1,1,1,1,1,1,1,1
1,1,1,1,1,1,1,1,1
1,1,1,1,1,1,1,1,1
1,1,1,2,1,1,2,1,1
1,1,1,1,1,1,1,1,1
1,1,1,1,1,1,1,1,1
endlayer

layer
1,1,1,1,1,1,1,1,1
1,1,1,1,1,1,1,1,1
1,1,1,1,1,1,2,1,1
1,1,2,1,1,1,1,1,1
1,1,1,1,1,1,1,1,1
1,1,1,1,1,1,1,1,1
1,1,1,1,1,1,1,1,1
1,1,1,2,1,1,2,1,1
1,1,1,1,1,1,1,1,1
1,1,1,1,1,1,1,1,1
endlayer

layer
1,1,1,1,1,1,1,1,1
1,1,1,1,1,1,1,1,1
1,1,1,1,1,1,2,1,1
1,1,2,1,1,1,1,1,1
1,1,1,1,1,1,1,1,1
1,1,1,1,1,1,1,1,1
1,1,1,1,1,1,1,1,1
1,1,1,2,1,1,2,1,1
1,1,1,1,1,1,1,1,1
1,1,1,1,1,1,1,1,1
endlayer

layer
1,1,1,1,1,1,1,1,1
1,1,1,1,1,1,1,1,1
1,1,1,1,1,1,2,1,1
1,1,2,1,1,1,1,1,1
1,1,1,1,1,1,1,1,1
1,1,1,1,1,1,1,1,1
1,1,1,1,1,1,1,1,1
1,1,1,2,1,1,2,1,1
1,1,1,1,1,1,1,1,1
1,1,1,1,1,1,1,1,1
endlayer

layer
1,1,1,1,1,1,1,1,1
1,1,1,1,1,1,1,1,1
1,1,1,1,1,1,2,1,1
1,1,2,1,1,1,1,1,1
1,1,1,1,1,1,1,1,1
1,1,1,1,1,1,1,1,1
1,1,1,1,1,1,1,1,1
1,1,1,2,1,1,2,1,1
1,1,1,1,1,1,1,1,1
1,1,1,1,1,1,1,1,1
endlayer

layer
1,1,1,1,1,1,1,1,1
1,1,1,1,1,1,1,1,1
1,1,1,1,1,1,2,1,1
1,1,2,1,1,1,1,1,1
1,1,1,1,1,1,1,1,1
1,1,1,1,1,1,1,1,1
1,1,1,1,1,1,1,4,3
1,1,1,2,1,1,2,1,1
1,1,1,1,1,1,1,1,1
1,1,1,1,1,1,1,1,1
endlayer

layer
1,1,1,1,1,1,1,1,1
1,1,1,1,1,1,1,1,1
1,1,1,1,1,1,2,1,1
1,1,2,5,5,5,5,5,1
1,1,6,1,1,1,5,5,5
1,1,1,1,1,1,5,8,7
1,1,1,6,5,5,5,5,9
1,1,1,2,1,1,2,1,1
1,1,1,1,1,1,1,1,1
1,1,1,1,1,1,1,1,1
endlayer

layer
1,1,1,1,0,1,1,1,1
1,1,1,0,0,0,1,1,1
1,1,0,10,0,0,2,1,1
1,0,2,11,11,11,11,7,7
0,0,14,13,13,13,14,13,12
0,0,14,13,13,13,14,14,15
1,0,14,11,11,11,11,16,0
1,1,17,2,13,17,2,1,1
1,1,1,0,0,0,1,1,1
1,1,1,1,0,1,1,1,1
endlayer

layer
1,1,0,0,0,0,0,1,1
1,0,0,0,0,0,0,0,1
0,0,13,11,7,19,2,18,0
0,5,2,21,0,0,0,20,6
0,4,23,0,0,0,0,22,0
0,4,25,0,0,0,0,24,0
0,5,24,21,21,21,27,26,0
0,0,14,2,17,13,2,17,0
1,0,0,0,0,0,0,0,1
1,1,0,0,0,0,0,1,1
endlayer

layer
1,0,0,0,0,0,0,0,1
0,0,4,7,7,0,28,0,0
0,5,19,0,8,29,2,26,0
0,12,2,0,0,0,0,24,6
0,5,0,0,0,0,0,30,0
0,5,0,0,0,0,0,26,0
0,4,32,0,0,0,31,24,0
0,5,24,2,20,33,2,5,0
0,0,0,34,0,0,34,0,0
1,0,0,0,0,0,0,0,1
endlayer

layer
0,0,0,0,0,0,0,0,0
0,0,5,35,7,7,28,0,0
0,5,4,0,0,8,2,5,0
0,4,2,0,0,0,0,26,26
0,28,0,0,0,0,0,36,0
0,28,0,0,0,0,0,26,26
0,19,0,0,0,0,0,20,0
0,5,14,24,26,14,2,5,0
0,0,0,17,0,0,17,0,0
0,0,0,0,0,0,0,0,0
endlayer

layer
0,0,0,0,0,0,0,0,0
0,5,38,7,37,35,7,7,0
0,38,40,0,0,0,21,39,0
40,40,28,28,28,28,28,7,5
0,44,28,43,43,43,28,42,41
45,44,28,43,28,43,28,35,0
40,44,28,43,43,43,28,42,0
0,46,8,7,12,12,2,12,0
0,5,12,5,12,0,12,0,0
0,0,0,0,0,0,0,0,0
endlayer

layer
0,0,0,0,47,47,0,0,0
0,48,5,19,12,21,47,5,0
0,44,46,0,0,0,50,49,0
40,52,51,0,0,0,50,49,39
5,49,0,0,0,0,0,35,46
45,44,53,0,0,0,0,35,0
44,40,0,0,0,0,0,42,0
0,46,40,54,54,54,0,52,0
0,5,40,35,12,46,46,5,0
0,0,0,0,0,0,0,0,0
endlayer

layer
0,0,0,0,47,29,48,0,0
0,0,44,55,5,0,28,47,0
0,5,55,0,0,0,0,48,0
48,55,0,0,0,0,0,49,0
44,47,0,0,0,0,0,49,5
40,44,0,0,0,0,0,56,0
57,44,0,0,0,0,0,44,0
0,49,47,58,58,58,0,47,0
0,0,47,59,55,39,52,5,0
0,0,0,0,60,46,0,0,0
endlayer

layer
0,0,0,0,48,48,0,0,0
0,0,60,48,15,48,48,48,0
0,61,55,39,0,0,46,49,0
0,44,0,0,0,0,0,56,0
40,40,0,0,0,0,0,39,48
0,16,0,0,0,0,0,28,39
0,47,0,0,0,0,0,49,59
0,59,39,0,0,0,7,59,0
0,0,59,59,46,46,45,0,0
0,0,0,0,0,0,0,0,0
endlayer

layer
0,0,0,0,0,0,0,0,0
0,0,0,40,29,48,0,0,0
0,0,5,47,0,46,47,48,0
0,48,46,0,0,0,12,47,47
0,40,0,0,0,0,0,39,39
0,44,0,0,0,0,0,49,0
0,48,39,0,0,0,7,46,0
0,60,44,7,39,0,55,0,0
0,0,0,44,5,29,49,0,0
0,0,0,0,0,0,0,0,0
endlayer

layer
0,0,0,0,0,0,0,0,0
0,0,0,0,48,0,0,0,0
0,0,0,61,52,49,48,49,0
0,0,61,52,12,12,55,48,0
0,61,39,28,28,62,4,49,0
0,44,7,28,28,28,4,39,0
0,59,52,7,7,49,59,49,0
0,0,0,59,59,49,61,0,0
0,0,0,0,61,61,0,0,0
0,0,0,0,0,0,0,0,0
endlayer

layer
0,0,0,0,0,0,0,0,0
0,0,0,0,0,0,0,0,0
0,0,0,0,0,0,0,0,0
0,0,0,0,44,48,49,0,0
0,0,0,44,49,0,48,48,0
0,0,61,59,52,61,59,0,0
0,0,0,61,61,0,0,0,0
0,0,0,0,0,0,0,0,0
0,0,0,0,0,0,0,0,0
0,0,0,0,0,0,0,0,0
endlayer

