
# Created by Ruins mod version 16.7 Ingame Parser
# authoring Player: lafuller

weight=1
embed_into_distance=9
acceptable_target_blocks=flowing_water,water
unacceptable_target_blocks=
biomesToSpawnIn=swampland,wetland,marsh,lush swamp
dimensions=17,8,9
allowable_overhang=0
max_leveling=4
leveling_buffer=-1
preserve_water=0
preserve_lava=0

rule1=0,100,preserveBlock
rule2=0,100,minecraft:log2-1
rule3=0,100,minecraft:planks-1
rule4=0,100,minecraft:trapdoor-1
rule5=0,100,minecraft:trapdoor-0
rule6=0,100,minecraft:spruce_fence-0
rule7=0,100,minecraft:ladder-3
rule8=0,100,minecraft:wooden_slab-9
rule9=0,100,minecraft:spruce_stairs-6
rule10=0,100,minecraft:spruce_stairs-4
rule11=0,100,minecraft:spruce_stairs-7
rule12=0,100,minecraft:spruce_stairs-5
rule13=0,100,minecraft:wooden_slab-8
rule14=0,100,minecraft:planks-0
rule15=0,100,minecraft:trapdoor-8
rule16=0,100,minecraft:oak_stairs-4

layer
1,2,1,1,1,1,1,1,1
1,1,1,1,1,1,1,1,2
1,1,1,1,1,1,1,1,1
1,1,1,1,1,1,1,1,1
1,1,1,1,1,1,1,1,1
1,1,1,1,1,1,1,1,1
1,1,1,1,1,1,1,2,1
1,1,2,1,1,1,1,1,1
endlayer

layer
1,2,1,1,1,1,1,1,1
1,1,1,1,1,1,1,1,2
1,1,1,1,1,1,1,1,1
1,1,1,1,1,1,1,1,1
1,1,1,1,1,1,1,1,1
1,1,1,1,1,1,1,1,1
1,1,1,1,1,1,1,2,1
1,1,2,1,1,1,1,1,1
endlayer

layer
1,2,1,1,1,1,1,1,1
1,1,1,1,1,1,1,1,2
1,1,1,1,1,1,1,1,1
1,1,1,1,1,1,1,1,1
1,1,1,1,1,1,1,1,1
1,1,1,1,1,1,1,1,1
1,1,1,1,1,1,1,2,1
1,1,2,1,1,1,1,1,1
endlayer

layer
1,2,1,1,1,1,1,1,1
1,1,1,1,1,1,1,1,2
1,1,1,1,1,1,1,1,1
1,1,1,1,1,1,1,1,1
1,1,1,1,1,1,1,1,1
1,1,1,1,1,1,1,1,1
1,1,1,1,1,1,1,2,1
1,1,2,1,1,1,1,1,1
endlayer

layer
1,2,1,1,1,1,1,1,1
1,1,1,1,1,1,1,1,2
1,1,1,1,1,1,1,1,1
1,1,1,1,1,1,1,1,1
1,1,1,1,1,1,1,1,1
1,1,1,1,1,1,1,1,1
1,1,1,1,1,1,1,2,1
1,1,2,1,1,1,1,1,1
endlayer

layer
1,2,1,1,1,1,1,1,1
1,1,1,1,1,1,1,1,2
1,1,1,1,1,1,1,1,1
1,1,1,1,1,1,1,1,1
1,1,1,1,1,1,1,1,1
1,1,1,1,1,1,1,1,1
1,1,1,1,1,1,1,2,1
1,1,2,1,1,1,1,1,1
endlayer

layer
1,2,1,1,1,1,1,1,1
1,1,1,1,1,1,1,1,2
1,1,1,1,1,1,1,1,1
1,1,1,1,1,1,1,1,1
1,1,1,1,1,1,1,1,1
1,1,1,1,1,1,1,1,1
1,1,1,1,1,1,1,2,1
1,1,2,1,1,1,1,1,1
endlayer

layer
1,2,1,1,1,1,1,1,1
1,1,1,1,1,1,1,1,2
1,1,1,1,1,1,1,1,1
1,1,1,1,1,1,1,1,1
1,1,1,1,1,1,1,1,1
1,1,1,1,1,1,1,1,1
1,1,1,1,1,1,1,2,1
1,1,2,1,1,1,1,1,1
endlayer

layer
1,2,1,1,1,1,1,1,1
1,1,1,1,1,1,1,1,2
1,1,1,1,1,1,1,1,1
1,1,1,1,1,1,1,1,1
1,1,1,1,1,1,1,1,1
1,1,1,1,1,1,1,1,1
1,1,1,1,1,1,1,2,1
1,1,2,1,1,1,1,1,1
endlayer

layer
1,2,1,1,1,1,1,1,1
1,1,1,1,1,1,1,1,2
1,1,1,1,1,1,1,1,1
1,1,1,1,1,1,1,1,1
1,1,3,5,4,4,3,1,1
1,1,1,1,1,1,1,1,1
1,1,1,1,1,1,1,2,1
1,1,2,1,1,1,1,1,1
endlayer

layer
1,2,6,1,1,1,1,1,1
1,6,6,6,6,6,6,6,2
1,6,1,1,1,1,1,6,1
1,6,1,1,1,1,1,6,1
1,6,3,1,1,7,3,6,1
1,6,1,1,1,1,6,6,1
1,6,6,6,6,6,6,2,1
1,6,2,1,1,1,1,1,1
endlayer

layer
1,2,3,10,9,8,8,8,1
11,3,3,3,3,3,3,3,2
8,3,13,13,13,13,8,3,12
8,3,13,8,8,8,13,3,9
11,3,14,8,15,7,14,3,8
11,3,8,13,13,16,14,3,8
8,3,3,3,3,3,3,2,9
1,3,2,9,12,8,12,8,1
endlayer

layer
1,2,1,1,1,1,1,1,1
1,1,1,1,1,1,1,1,2
1,1,1,1,1,1,1,1,1
1,1,1,1,1,1,1,1,1
1,1,1,1,1,1,1,1,1
1,1,1,1,1,1,1,1,1
1,1,1,1,1,1,1,2,1
1,1,2,1,1,1,1,1,1
endlayer

layer
1,2,1,1,1,1,1,1,1
1,1,1,1,1,1,1,1,2
1,1,1,1,1,1,1,1,1
1,1,1,1,1,1,1,1,1
1,1,1,1,1,1,1,1,1
1,1,1,1,1,1,1,1,1
1,1,1,1,1,1,1,2,1
1,1,2,1,1,1,1,1,1
endlayer

layer
1,2,1,1,1,1,1,1,1
1,1,1,1,1,1,1,1,2
1,1,1,1,1,1,1,1,1
1,1,1,1,1,1,1,1,1
1,1,1,1,1,1,1,1,1
1,1,1,1,1,1,1,1,1
1,1,1,1,1,1,1,2,1
1,1,2,1,1,1,1,1,1
endlayer

layer
1,2,1,1,1,1,1,1,1
1,1,1,1,1,1,1,1,2
1,1,1,1,1,1,1,1,1
1,1,1,1,1,1,1,1,1
1,1,1,1,1,1,1,1,1
1,1,1,1,1,1,1,1,1
1,1,1,1,1,1,1,2,1
1,1,2,1,1,1,1,1,1
endlayer

layer
1,2,1,1,1,1,1,1,1
1,1,1,1,1,1,1,1,2
1,1,1,1,1,1,1,1,1
1,1,1,1,1,1,1,1,1
1,1,1,1,1,1,1,1,1
1,1,1,1,1,1,1,1,1
1,1,1,1,1,1,1,2,1
1,1,2,1,1,1,1,1,1
endlayer

