
# Created by Ruins mod version 16.5 Ingame Parser
# authoring Player: lafuller

weight=1
embed_into_distance=9
acceptable_target_blocks=
unacceptable_target_blocks=dirt,stone,flowing_lava,lava,ice,bedrock,netherrack,nether_brick,nether_brick_fence,soul_sand,quartz_ore,gravel,end_stone,obsidian,iron_bars,cloud,flesh,ash_block,slime_grass,slime_congealed,slime_dirt
biomesToSpawnIn=swampland,wetland,marsh,lush swamp
dimensions=21,9,11
allowable_overhang=0
max_leveling=4
leveling_buffer=-1
preserve_water=0
preserve_lava=0

rule1=0,100,preserveBlock
rule2=0,100,minecraft:log2-1
rule3=0,100,minecraft:trapdoor-0
rule4=0,100,minecraft:spruce_stairs-7
rule5=0,100,minecraft:planks-1
rule6=0,100,minecraft:spruce_fence-0
rule7=0,100,minecraft:trapdoor-3
rule8=0,100,minecraft:ladder-2
rule9=0,100,minecraft:fence-0
rule10=0,100,minecraft:oak_stairs-6
rule11=0,100,minecraft:oak_stairs-4
rule12=0,100,minecraft:oak_stairs-7
rule13=0,100,minecraft:spruce_stairs-2
rule14=0,100,minecraft:planks-0
rule15=0,100,minecraft:oak_stairs-0
rule16=0,100,minecraft:oak_stairs-5
rule17=0,100,minecraft:wooden_slab-9
rule18=0,100,minecraft:wooden_slab-8
rule19=0,100,minecraft:spruce_stairs-4
rule20=0,100,minecraft:cauldron-0
rule21=0,100,minecraft:sticky_piston-1

rule22=0,100,IInventory;hopper;baked_potato#3#0#0+brown_mushroom#1#0#1-3,IInventory;hopper;glowstone_dust#4#0#0-3,IInventory;hopper;redstone#2#0#0+glass_bottle#3#0#1-3,IInventory;hopper;book#1#0#0-3,IInventory;hopper;glowstone_dust#1#0#0+paper#4#0#1-3,IInventory;hopper;redstone#1#0#0+gunpowder#3#0#1-3

rule23=0,100,IInventory;dropper;leather#2#0#5-1,IInventory;dropper;coal#3#1#1+gunpowder#2#0#6-1,IInventory;dropper;torch#5#0#7-1,IInventory;dropper;glass_bottle#2#0#8-1,IInventory;dropper;rabbit_foot#1#0#2-1,IInventory;dropper;spruce_boat#1#0#5-1

rule24=0,100,minecraft:trapdoor-8
rule25=0,100,minecraft:jungle_door-1
rule26=0,100,minecraft:double_wooden_slab-0
rule27=0,100,minecraft:oak_stairs-2
rule28=0,100,minecraft:spruce_stairs-6
rule29=0,100,minecraft:spruce_stairs-0
rule30=0,100,minecraft:oak_stairs-1
rule31=0,100,IInventory;furnace;coal#2#0#1-5
rule32=0,100,minecraft:brewing_stand-0,air,air
rule33=0,100,minecraft:carpet-7
rule34=0,100,minecraft:spruce_stairs-3
rule35=0,100,minecraft:jungle_door-9
rule36=0,100,minecraft:ladder-3
rule37=0,100,minecraft:spruce_stairs-5
rule38=0,100,minecraft:bookshelf-0
rule39=0,100,minecraft:spruce_fence_gate-1
rule40=0,100,minecraft:spruce_fence_gate-4
rule41=0,100,minecraft:fence_gate-0
rule42=0,100,minecraft:spruce_fence_gate-2
rule43=0,100,minecraft:spruce_stairs-1
rule44=0,100,minecraft:wooden_slab-1
rule45=0,100,minecraft:dark_oak_stairs-4
rule46=0,100,minecraft:dark_oak_stairs-7
rule47=0,100,minecraft:wooden_slab-0
rule48=0,100,minecraft:wooden_slab-5
rule49=0,100,minecraft:dark_oak_stairs-6
rule50=0,100,minecraft:dark_oak_stairs-5
rule51=0,100,minecraft:planks-5
rule52=0,100,minecraft:dark_oak_stairs-2
rule53=0,100,minecraft:dark_oak_stairs-0
rule54=0,100,minecraft:crafting_table-0
rule55=0,100,minecraft:dark_oak_stairs-3
rule56=0,100,minecraft:dark_oak_stairs-1
rule57=0,100,minecraft:double_wooden_slab-1
rule58=0,100,minecraft:spruce_fence_gate-3
rule59=0,100,minecraft:wooden_slab-13
rule60=0,100,minecraft:double_wooden_slab-5

layer
1,1,1,1,1,1,1,1,1,1,1
1,1,1,1,1,1,1,1,1,1,1
1,1,2,1,1,1,1,2,1,1,1
1,1,1,1,1,1,1,1,1,1,1
1,1,1,1,1,1,1,1,1,1,1
1,1,1,1,1,1,1,1,1,1,1
1,1,2,1,1,1,1,2,1,1,1
1,1,1,1,1,1,1,1,1,1,1
1,1,1,1,1,1,1,1,1,1,1
endlayer

layer
1,1,1,1,1,1,1,1,1,1,1
1,1,1,1,1,1,1,1,1,1,1
1,1,2,1,1,1,1,2,1,1,1
1,1,1,1,1,1,1,1,1,1,1
1,1,1,1,1,1,1,1,1,1,1
1,1,1,1,1,1,1,1,1,1,1
1,1,2,1,1,1,1,2,1,1,1
1,1,1,1,1,1,1,1,1,1,1
1,1,1,1,1,1,1,1,1,1,1
endlayer

layer
1,1,1,1,1,1,1,1,1,1,1
1,1,1,1,1,1,1,1,1,1,1
1,1,2,1,1,1,1,2,1,1,1
1,1,1,1,1,1,1,1,1,1,1
1,1,1,1,1,1,1,1,1,1,1
1,1,1,1,1,1,1,1,1,1,1
1,1,2,1,1,1,1,2,1,1,1
1,1,1,1,1,1,1,1,1,1,1
1,1,1,1,1,1,1,1,1,1,1
endlayer

layer
1,1,1,1,1,1,1,1,1,1,1
1,1,1,1,1,1,1,1,1,1,1
1,1,2,1,1,1,1,2,1,1,1
1,1,1,1,1,1,1,1,1,1,1
1,1,1,1,1,1,1,1,1,1,1
1,1,1,1,1,1,1,1,1,1,1
1,1,2,1,1,1,1,2,1,1,1
1,1,1,1,1,1,1,1,1,1,1
1,1,1,1,1,1,1,1,1,1,1
endlayer

layer
1,1,1,1,1,1,1,1,1,1,1
1,1,1,1,1,1,1,1,1,1,1
1,1,2,1,1,1,1,2,1,1,1
1,1,1,1,1,1,1,1,1,1,1
1,1,1,1,1,1,1,1,1,1,1
1,1,1,1,1,1,1,1,1,1,1
1,1,2,1,1,1,1,2,1,1,1
1,1,1,1,1,1,1,1,1,1,1
1,1,1,1,1,1,1,1,1,1,1
endlayer

layer
1,1,1,1,1,1,1,1,1,1,1
1,1,1,1,1,1,1,1,1,1,1
1,1,2,1,1,1,1,2,1,1,1
1,1,1,1,1,1,1,1,1,1,1
1,1,1,1,1,1,1,1,1,1,1
1,1,1,1,1,1,1,1,1,1,1
1,1,2,1,1,1,1,2,1,1,1
1,1,1,1,1,1,1,1,1,1,1
1,1,1,1,1,1,1,1,1,1,1
endlayer

layer
1,1,1,1,1,1,1,1,1,1,1
1,1,1,1,1,1,1,1,1,1,1
1,1,2,1,1,1,1,2,1,1,1
1,1,1,1,1,1,1,1,1,1,1
1,1,1,1,1,1,1,1,1,1,1
1,1,1,1,1,1,1,1,1,1,1
1,1,2,1,1,1,1,2,1,1,1
1,1,1,1,1,1,1,1,1,1,1
1,1,1,1,1,1,1,1,1,1,1
endlayer

layer
1,1,1,1,1,1,1,1,1,1,1
1,1,1,1,1,1,1,1,1,1,1
1,1,2,1,1,1,1,2,1,1,1
1,1,1,1,1,1,1,1,1,1,1
1,1,1,1,1,1,1,1,1,1,1
1,1,1,1,1,1,1,1,1,1,1
1,1,2,1,1,1,1,2,1,1,1
1,1,1,1,1,1,1,1,1,1,1
1,1,1,1,1,1,1,1,1,1,1
endlayer

layer
1,1,1,1,1,1,1,1,1,1,1
1,1,1,1,1,1,1,1,1,1,1
1,1,2,1,1,1,1,2,1,1,1
1,1,1,1,1,1,1,1,1,1,1
1,1,1,1,1,1,1,1,1,1,1
1,1,1,1,1,1,1,1,1,1,1
1,1,2,1,1,1,1,2,1,1,1
1,1,1,1,1,1,1,1,1,1,1
1,1,1,1,1,1,1,1,1,1,1
endlayer

layer
1,1,1,1,1,1,1,1,1,1,1
1,1,1,1,1,1,1,1,1,1,1
1,1,2,1,1,1,1,2,1,1,1
1,1,1,1,1,1,1,1,1,4,3
1,1,1,1,1,1,1,6,6,5,3
1,1,1,1,1,1,1,6,1,7,1
1,1,2,1,1,1,1,2,1,1,1
1,1,1,1,1,1,1,1,1,1,1
1,1,1,1,1,1,1,1,1,1,1
endlayer

layer
1,1,1,1,1,1,1,1,1,1,1
1,1,1,6,6,6,1,1,1,1,1
1,1,2,6,6,6,6,2,6,1,1
1,1,9,6,6,6,6,6,6,5,8
1,1,6,6,1,1,1,6,6,6,0
1,1,6,6,1,1,1,6,6,0,1
1,1,2,6,6,6,6,2,1,1,1
1,1,1,1,1,1,1,1,1,1,1
1,1,1,1,1,1,1,1,1,1,1
endlayer

layer
1,1,1,1,1,1,1,1,1,1,1
1,1,6,6,11,10,1,1,1,1,1
1,6,2,11,12,10,11,2,6,0,1
1,1,12,16,16,16,16,15,14,13,0
1,1,18,10,17,17,17,10,14,13,0
1,1,12,10,17,17,17,11,16,0,1
1,6,2,11,11,11,11,2,0,0,1
1,1,6,18,18,18,18,1,1,1,1
1,1,1,1,1,1,1,1,1,1,1
endlayer

layer
1,1,1,0,19,6,0,0,1,1,1
1,1,0,11,14,14,11,11,0,1,1
1,9,2,23,22,21,20,2,11,0,1
0,12,24,0,0,0,0,0,14,0,0
0,12,24,0,0,0,0,0,25,0,0
0,12,24,0,0,0,0,0,26,0,0
1,9,2,27,0,0,0,2,10,0,1
1,1,9,14,0,0,5,28,0,1,1
1,1,1,0,16,16,16,0,1,1,1
endlayer

layer
1,1,0,0,29,19,6,0,0,1,1
1,0,9,5,30,30,11,29,0,0,1
0,11,2,0,0,32,31,2,28,0,0
0,34,33,0,0,0,0,0,14,0,0
0,4,33,0,0,0,0,0,35,0,0
0,34,33,0,0,0,0,0,27,0,0
0,37,2,0,0,0,36,2,13,0,0
1,0,37,29,0,0,38,28,0,0,1
1,1,0,0,16,30,37,6,0,1,1
endlayer

layer
1,0,0,0,0,0,13,0,0,0,1
0,0,9,29,39,39,5,6,0,0,0
0,34,2,0,0,0,0,2,13,0,0
0,5,0,0,0,0,0,0,27,40,0
0,42,0,0,0,0,0,0,41,0,0
0,5,0,0,0,0,0,0,13,0,0
0,5,2,0,0,0,36,2,28,0,0
0,6,43,19,0,0,38,37,0,0,0
1,0,0,0,16,43,43,28,0,0,1
endlayer

layer
0,0,0,17,0,0,19,0,0,0,0
0,0,45,45,37,37,19,44,0,0,0
0,46,2,0,0,0,37,45,29,0,0
0,45,0,0,0,0,0,37,15,47,0
48,5,0,0,0,0,0,4,10,10,0
0,46,0,0,0,0,0,4,49,47,0
0,34,2,0,0,0,36,2,49,0,0
0,0,37,29,0,0,5,51,50,0,0
0,0,0,37,39,37,43,28,0,0,0
endlayer

layer
0,0,0,34,29,44,0,0,0,0,0
0,0,45,45,51,51,52,0,0,0,0
0,55,51,50,54,38,45,53,0,0,0
0,51,50,44,44,44,44,45,29,0,0
0,51,51,44,47,47,44,49,13,0,0
0,43,45,44,47,47,44,44,49,0,0
0,48,34,34,44,44,36,51,56,0,0
0,0,55,49,44,44,57,51,52,0,0
0,0,0,55,37,43,50,52,0,0,0
endlayer

layer
0,0,0,0,53,0,0,0,0,0,0
0,0,53,51,45,45,52,0,0,0,0
0,0,46,0,0,38,51,0,0,0,0
0,0,51,3,0,0,0,52,0,0,0
0,53,51,3,0,0,0,49,52,0,0
0,0,46,3,0,0,0,46,56,0,0
0,0,50,29,0,0,36,51,0,0,0
0,0,55,51,45,45,45,52,0,0,0
0,0,0,56,50,50,56,0,0,0,0
endlayer

layer
0,0,0,0,0,0,0,0,0,0,0
0,0,0,0,45,53,0,0,0,0,0
0,0,48,53,50,50,52,0,0,0,0
0,0,55,0,0,0,46,53,0,0,0
0,0,46,0,0,0,0,52,0,0,0
0,0,55,0,0,0,0,55,0,0,0
0,0,0,49,0,0,0,52,0,0,0
0,0,0,55,58,50,56,0,0,0,0
0,0,0,0,0,0,0,0,0,0,0
endlayer

layer
0,0,0,0,0,0,0,0,0,0,0
0,0,0,0,0,0,0,0,0,0,0
0,0,0,55,45,52,0,0,0,0,0
0,0,0,51,0,17,52,0,0,0,0
0,0,0,59,0,0,17,53,0,0,0
0,0,0,56,19,19,49,52,0,0,0
0,0,0,55,59,50,52,0,0,0,0
0,0,0,0,48,56,0,0,0,0,0
0,0,0,0,0,0,0,0,0,0,0
endlayer

layer
0,0,0,0,0,0,0,0,0,0,0
0,0,0,0,0,0,0,0,0,0,0
0,0,0,0,48,0,0,0,0,0,0
0,0,0,0,60,48,0,0,0,0,0
0,0,0,48,59,46,48,0,0,0,0
0,0,0,0,51,52,48,0,0,0,0
0,0,0,0,48,48,0,0,0,0,0
0,0,0,0,0,0,0,0,0,0,0
0,0,0,0,0,0,0,0,0,0,0
endlayer

