
# Created by Ruins mod version 16.7 Ingame Parser
# authoring Player: lafuller

weight=1
embed_into_distance=17
acceptable_target_blocks=
unacceptable_target_blocks=flowing_water,water,flowing_lava,lava,ice,bedrock,netherrack,nether_brick,nether_brick_fence,soul_sand,quartz_ore,gravel,end_stone,obsidian,iron_bars,cloud,flesh,ash_block,slime_grass,slime_congealed,slime_dirt
dimensions=18,5,5
allowable_overhang=0
max_leveling=2
leveling_buffer=-1
preserve_water=0
preserve_lava=0

rule1=0,100,minecraft:planks-0
rule2=0,100,preserveBlock
rule3=0,100,minecraft:fence-0
rule4=0,100,minecraft:ladder-2
rule5=0,100,minecraft:double_wooden_slab-0
rule6=0,100,minecraft:wooden_slab-8
rule7=0,100,minecraft:wooden_slab-0

layer
1,1,1,1,1
2,2,2,2,1
2,2,2,2,1
2,2,2,2,1
1,1,1,1,1
endlayer

layer
1,3,0,3,2
1,0,0,0,3
1,0,0,0,0
1,0,0,0,3
1,3,0,3,2
endlayer

layer
2,3,0,3,2
2,0,0,0,3
1,4,0,0,0
2,0,0,0,3
2,3,0,3,2
endlayer

layer
2,1,1,1,2
2,0,0,0,1
1,4,0,0,1
2,0,0,0,1
2,1,1,1,2
endlayer

layer
2,2,2,2,2
2,0,0,0,2
1,4,0,0,2
2,0,0,0,2
2,2,2,2,2
endlayer

layer
2,2,2,2,2
2,0,0,0,2
1,4,0,0,2
2,0,0,0,2
2,2,2,2,2
endlayer

layer
2,2,2,2,2
2,0,0,0,2
1,4,0,0,2
2,0,0,0,2
2,2,2,2,2
endlayer

layer
2,2,2,2,2
2,0,0,0,2
1,4,0,0,2
2,0,0,0,2
2,2,2,2,2
endlayer

layer
2,2,2,2,2
2,0,0,0,2
1,4,0,0,2
2,0,0,0,2
2,2,2,2,2
endlayer

layer
2,2,2,2,2
2,0,0,0,2
1,4,0,0,2
2,0,0,0,2
2,2,2,2,2
endlayer

layer
2,2,2,2,2
2,0,0,0,2
1,4,0,0,2
2,0,0,0,2
2,2,2,2,2
endlayer

layer
2,2,2,2,2
2,0,0,0,2
1,4,0,0,2
2,0,0,0,2
2,2,2,2,2
endlayer

layer
2,2,2,2,2
2,0,0,0,2
1,4,0,0,2
2,0,0,0,2
2,2,2,2,2
endlayer

layer
2,2,2,2,2
2,0,0,0,2
1,4,0,0,2
2,0,0,0,2
2,2,2,2,2
endlayer

layer
2,2,2,2,2
2,0,0,0,2
1,4,0,0,2
2,0,0,0,2
2,2,2,2,2
endlayer

layer
2,5,2,5,2
2,6,0,6,2
2,6,0,6,2
2,6,0,6,2
2,5,2,5,2
endlayer

layer
2,0,0,0,2
7,7,7,7,7
0,0,0,0,0
7,7,7,7,7
2,0,0,0,2
endlayer

layer
2,0,0,0,2
0,0,0,0,0
0,0,0,0,0
0,0,0,0,0
2,0,0,0,2
endlayer

