
# Created by Ruins mod version 16.7 Ingame Parser
# authoring Player: lafuller

weight=1
embed_into_distance=4
acceptable_target_blocks=water
unacceptable_target_blocks=
biomesToSpawnIn=ocean,deep ocean,ocean oil field,kelp forest
dimensions=23,22,22
allowable_overhang=0
max_leveling=0
leveling_buffer=-1
preserve_water=0
preserve_lava=0

rule1=0,100,preserveBlock
rule2=0,100,minecraft:planks-5
rule3=0,100,minecraft:dark_oak_stairs-1
rule4=0,100,minecraft:dark_oak_stairs-3
rule5=1,100,minecraft:melon_block-0,pumpkin,air,air,air
rule6=1,100,minecraft:bookshelf-0,air,air
rule7=0,100,minecraft:spruce_stairs-1
rule8=1,100,minecraft:hay_block-8,air,air,air
rule9=1,100,minecraft:hay_block-0,air,air
rule10=1,100,minecraft:hay_block-4,air,air,air
rule11=0,100,minecraft:spruce_stairs-4
rule12=0,100,minecraft:spruce_stairs-6
rule13=0,100,minecraft:planks-1
rule14=0,100,minecraft:spruce_stairs-3
rule15=0,100,minecraft:wooden_slab-1
rule16=0,100,minecraft:spruce_stairs-0
rule17=0,100,minecraft:spruce_stairs-7
rule18=0,100,minecraft:spruce_stairs-5
rule19=0,100,ChestGenHook:chests/stronghold_crossing:5-3
rule20=0,100,minecraft:wooden_slab-9
rule21=0,100,minecraft:trapdoor-8
rule22=0,100,minecraft:trapdoor-9
rule23=0,100,minecraft:trapdoor-14
rule24=0,100,minecraft:trapdoor-13
rule25=0,100,minecraft:trapdoor-12
rule26=0,100,minecraft:log-0
rule27=0,100,minecraft:trapdoor-15
rule28=0,100,minecraft:ladder-4
rule29=0,100,minecraft:spruce_fence-0
rule30=0,100,minecraft:ladder-5
rule31=0,100,minecraft:wooden_slab-5
rule32=0,100,minecraft:dark_oak_fence-0
rule33=0,100,minecraft:dark_oak_stairs-4
rule34=0,100,minecraft:dark_oak_stairs-6
rule35=0,100,minecraft:double_wooden_slab-1
rule36=0,100,minecraft:spruce_door-1
rule37=0,100,minecraft:crafting_table-0
rule38=0,100,minecraft:carpet-8
rule39=0,100,minecraft:carpet-7
rule40=0,100,ChestGenHook:chests/stronghold_library:5-4
rule41=0,100,minecraft:spruce_door-9
rule42=0,100,minecraft:spruce_stairs-2
rule43=0,100,minecraft:dark_oak_stairs-0
rule44=0,100,minecraft:dark_oak_stairs-2
rule45=0,100,minecraft:wool-0
rule46=0,100,minecraft:trapdoor-0
rule47=0,100,minecraft:log-12
rule48=0,100,minecraft:log-8
rule49=0,100,minecraft:log-4

layer
1,1,1,1,1,1,1,1,1,1,1,1,1,1,1,1,1,1,1,1,1,1
1,1,1,1,1,1,1,1,1,1,1,1,1,1,1,1,1,1,1,1,1,1
1,1,1,1,1,1,1,1,1,1,1,1,1,1,1,1,1,1,1,1,1,1
1,1,1,1,1,1,1,1,1,1,1,1,1,1,1,1,1,1,1,1,1,1
1,1,1,1,1,1,1,1,1,1,1,1,1,1,1,1,1,1,1,1,1,1
1,1,1,1,1,1,1,1,1,1,1,1,1,1,1,1,1,1,1,1,1,1
1,1,1,1,1,1,1,1,1,1,1,1,1,1,1,1,1,1,1,1,1,1
1,1,1,1,1,1,1,1,1,1,1,1,1,1,2,1,1,1,1,1,1,1
1,1,1,1,1,1,1,1,1,1,1,1,2,2,1,1,1,1,1,1,1,1
1,1,1,1,1,1,1,1,1,1,1,2,2,2,1,1,1,1,1,1,1,1
1,1,1,1,1,1,1,1,1,1,2,2,2,1,1,1,1,1,1,1,1,1
1,1,1,1,1,1,1,1,1,2,2,2,1,1,1,1,1,1,1,1,1,1
1,1,1,1,1,1,1,1,2,2,2,1,1,1,1,1,1,1,1,1,1,1
1,1,1,1,1,1,1,2,2,2,1,1,1,1,1,1,1,1,1,1,1,1
1,1,1,1,1,1,2,2,2,1,1,1,1,1,1,1,1,1,1,1,1,1
1,1,1,1,1,1,2,2,1,1,1,1,1,1,1,1,1,1,1,1,1,1
1,1,1,1,1,1,1,1,1,1,1,1,1,1,1,1,1,1,1,1,1,1
1,1,1,1,1,1,1,1,1,1,1,1,1,1,1,1,1,1,1,1,1,1
1,1,1,1,1,1,1,1,1,1,1,1,1,1,1,1,1,1,1,1,1,1
1,1,1,1,1,1,1,1,1,1,1,1,1,1,1,1,1,1,1,1,1,1
1,1,1,1,1,1,1,1,1,1,1,1,1,1,1,1,1,1,1,1,1,1
1,1,1,1,1,1,1,1,1,1,1,1,1,1,1,1,1,1,1,1,1,1
endlayer

layer
1,1,1,1,1,1,1,1,1,1,1,1,1,1,1,1,1,1,1,1,1,1
1,1,1,1,1,1,1,1,1,1,1,1,1,1,1,1,1,1,1,1,1,1
1,1,1,1,1,1,1,1,1,1,1,1,1,1,1,1,1,1,1,1,1,1
1,1,1,1,1,1,1,1,1,1,1,1,1,1,1,1,1,1,1,1,1,1
1,1,1,1,1,1,1,1,1,1,1,1,1,1,1,1,1,1,1,1,1,1
1,1,1,1,1,1,1,1,1,1,1,1,1,1,1,1,2,1,1,1,1,1
1,1,1,1,1,1,1,1,1,1,1,1,1,1,2,2,1,1,1,1,1,1
1,1,1,1,1,1,1,1,1,1,1,1,2,2,2,2,1,1,1,1,1,1
1,1,1,1,1,1,1,1,1,1,1,2,2,2,2,1,1,1,1,1,1,1
1,1,1,1,1,1,1,1,1,1,2,2,2,2,2,1,1,1,1,1,1,1
1,1,1,1,1,1,1,1,1,2,2,2,2,2,1,1,1,1,1,1,1,1
1,1,1,1,1,1,1,1,2,2,2,2,2,1,1,1,1,1,1,1,1,1
1,1,1,1,1,1,1,2,2,2,2,2,1,1,1,1,1,1,1,1,1,1
1,1,1,1,1,1,2,2,2,2,2,1,1,1,1,1,1,1,1,1,1,1
1,1,1,1,1,2,2,2,2,2,1,1,1,1,1,1,1,1,1,1,1,1
1,1,1,1,1,2,2,2,2,1,1,1,1,1,1,1,1,1,1,1,1,1
1,1,1,1,1,2,2,2,1,1,1,1,1,1,1,1,1,1,1,1,1,1
1,1,1,1,1,1,1,1,1,1,1,1,1,1,1,1,1,1,1,1,1,1
1,1,1,1,1,1,1,1,1,1,1,1,1,1,1,1,1,1,1,1,1,1
1,1,1,1,1,1,1,1,1,1,1,1,1,1,1,1,1,1,1,1,1,1
1,1,1,1,1,1,1,1,1,1,1,1,1,1,1,1,1,1,1,1,1,1
1,1,1,1,1,1,1,1,1,1,1,1,1,1,1,1,1,1,1,1,1,1
endlayer

layer
1,1,1,1,1,1,1,1,1,1,1,1,1,1,1,1,1,1,1,1,1,1
1,1,1,1,1,1,1,1,1,1,1,1,1,1,1,1,1,1,1,1,1,1
1,1,1,1,1,1,1,1,1,1,1,1,1,1,1,1,1,1,1,1,1,1
1,1,1,1,1,1,1,1,1,1,1,1,1,1,1,1,1,1,1,1,1,1
1,1,1,1,1,1,1,1,1,1,1,1,1,1,1,1,1,2,1,1,1,1
1,1,1,1,1,1,1,1,1,1,1,1,1,1,1,2,2,1,1,1,1,1
1,1,1,1,1,1,1,1,1,1,1,1,2,2,2,2,2,1,1,1,1,1
1,1,1,1,1,1,1,1,1,1,1,2,2,2,2,2,1,1,1,1,1,1
1,1,1,1,1,1,1,1,1,1,2,2,2,2,2,2,1,1,1,1,1,1
1,1,1,1,1,1,1,1,1,2,2,2,2,2,2,2,1,1,1,1,1,1
1,1,1,1,1,1,1,1,2,2,2,2,2,2,2,1,1,1,1,1,1,1
1,1,1,1,1,1,1,2,2,2,2,2,2,2,1,1,1,1,1,1,1,1
1,1,1,1,1,1,2,2,2,2,2,2,2,1,1,1,1,1,1,1,1,1
1,1,1,1,1,2,2,2,2,2,2,2,1,1,1,1,1,1,1,1,1,1
1,1,1,1,2,2,2,2,2,2,2,1,1,1,1,1,1,1,1,1,1,1
1,1,1,1,2,2,2,2,2,2,1,1,1,1,1,1,1,1,1,1,1,1
1,1,1,1,2,2,2,2,2,1,1,1,1,1,1,1,1,1,1,1,1,1
1,1,1,1,2,2,2,2,1,1,1,1,1,1,1,1,1,1,1,1,1,1
1,1,1,1,1,1,1,1,1,1,1,1,1,1,1,1,1,1,1,1,1,1
1,1,1,1,1,1,1,1,1,1,1,1,1,1,1,1,1,1,1,1,1,1
1,1,1,1,1,1,1,1,1,1,1,1,1,1,1,1,1,1,1,1,1,1
1,1,1,1,1,1,1,1,1,1,1,1,1,1,1,1,1,1,1,1,1,1
endlayer

layer
1,1,1,1,1,1,1,1,1,1,1,1,1,1,1,1,1,1,1,1,1,1
1,1,1,1,1,1,1,1,1,1,1,1,1,1,1,1,1,1,1,1,1,1
1,1,1,1,1,1,1,1,1,1,1,1,1,1,1,1,1,1,1,1,1,1
1,1,1,1,1,1,1,1,1,1,1,1,1,1,1,1,1,2,1,1,1,1
1,1,1,1,1,1,1,1,1,1,1,1,1,1,1,2,2,2,2,1,1,1
1,1,1,1,1,1,1,1,1,1,1,1,1,2,3,3,3,2,1,1,1,1
1,1,1,1,1,1,1,1,1,1,1,2,2,5,5,0,4,2,1,1,1,1
1,1,1,1,1,1,1,1,1,1,2,5,5,5,0,0,4,1,1,1,1,1
1,1,1,1,1,1,1,1,1,2,5,5,5,0,0,0,2,1,1,1,1,1
1,1,1,1,1,1,1,1,2,5,5,5,0,0,6,2,1,1,1,1,1,1
1,1,1,1,1,1,1,2,5,5,5,0,0,6,6,2,1,1,1,1,1,1
1,1,1,1,1,1,2,2,5,0,0,6,6,6,2,1,1,1,1,1,1,1
1,1,1,1,1,2,2,7,0,0,0,6,6,2,1,1,1,1,1,1,1,1
1,1,1,1,2,8,0,0,0,0,6,6,2,1,1,1,1,1,1,1,1,1
1,1,1,2,10,9,0,0,0,0,6,2,1,1,1,1,1,1,1,1,1,1
1,1,1,2,8,10,9,8,0,0,2,1,1,1,1,1,1,1,1,1,1,1
1,1,1,2,9,9,8,10,9,2,1,1,1,1,1,1,1,1,1,1,1,1
1,1,1,2,8,10,9,8,2,1,1,1,1,1,1,1,1,1,1,1,1,1
1,1,1,1,2,2,2,2,1,1,1,1,1,1,1,1,1,1,1,1,1,1
1,1,1,1,1,1,1,1,1,1,1,1,1,1,1,1,1,1,1,1,1,1
1,1,1,1,1,1,1,1,1,1,1,1,1,1,1,1,1,1,1,1,1,1
1,1,1,1,1,1,1,1,1,1,1,1,1,1,1,1,1,1,1,1,1,1
endlayer

layer
1,1,1,1,1,1,1,1,1,1,1,1,1,1,1,1,1,1,1,1,1,1
1,1,1,1,1,1,1,1,1,1,1,1,1,1,1,1,1,1,1,1,1,1
1,1,1,1,1,1,1,1,1,1,1,1,1,1,1,1,1,1,11,1,1,1
1,1,1,1,1,1,1,1,1,1,1,1,1,1,1,1,11,13,13,12,1,1
1,1,1,1,1,1,1,1,1,1,1,1,1,11,13,7,7,14,13,1,1,1
1,1,1,1,1,1,1,1,1,1,1,11,13,5,5,0,0,14,12,1,1,1
1,1,1,1,1,1,1,1,1,1,11,15,5,5,5,0,0,14,1,1,1,1
1,1,1,1,1,1,1,1,1,11,15,5,5,5,0,0,0,13,1,1,1,1
1,1,1,1,1,1,1,1,11,15,5,5,5,0,0,0,16,12,1,1,1,1
1,1,1,1,1,1,1,11,15,5,5,0,0,0,0,0,13,1,1,1,1,1
1,1,1,1,1,1,17,13,5,5,0,0,0,0,6,15,12,1,1,1,1,1
1,1,1,1,1,17,13,7,0,0,0,0,6,6,15,12,1,1,1,1,1,1
1,1,1,1,17,13,13,0,0,0,0,6,6,15,12,1,1,1,1,1,1,1
1,1,1,17,15,0,0,0,0,0,0,6,15,12,1,1,1,1,1,1,1,1
1,1,17,15,10,0,0,0,0,0,0,15,12,1,1,1,1,1,1,1,1,1
1,1,13,10,9,0,0,0,0,0,15,12,1,1,1,1,1,1,1,1,1,1
1,1,13,8,8,10,9,8,10,15,12,1,1,1,1,1,1,1,1,1,1,1
1,1,13,10,10,9,8,9,15,12,1,1,1,1,1,1,1,1,1,1,1,1
1,1,17,13,9,8,10,15,18,1,1,1,1,1,1,1,1,1,1,1,1,1
1,1,1,18,13,13,13,18,1,1,1,1,1,1,1,1,1,1,1,1,1,1
1,1,1,1,1,1,1,1,1,1,1,1,1,1,1,1,1,1,1,1,1,1
1,1,1,1,1,1,1,1,1,1,1,1,1,1,1,1,1,1,1,1,1,1
endlayer

layer
1,1,1,1,1,1,1,1,1,1,1,1,1,1,1,1,1,1,1,1,1,1
1,1,1,1,1,1,1,1,1,1,1,1,1,1,1,1,1,1,1,1,1,1
1,1,1,1,1,1,1,1,1,1,1,1,1,1,1,1,1,11,11,13,1,1
1,1,1,1,1,1,1,1,1,1,1,1,1,1,1,11,7,0,19,13,1,1
1,1,1,1,1,1,1,1,1,1,1,1,11,13,13,0,0,0,0,12,1,1
1,1,1,1,1,1,1,1,1,1,11,13,13,5,0,0,0,0,14,1,1,1
1,1,1,1,1,1,1,1,1,17,13,1,5,5,0,0,0,0,12,1,1,1
1,1,1,1,1,1,1,1,11,13,1,5,5,0,0,0,0,13,1,1,1,1
1,1,1,1,1,1,1,11,13,0,5,0,0,0,0,0,0,13,1,1,1,1
1,1,1,1,1,1,17,13,0,0,0,0,0,0,0,0,16,12,1,1,1,1
1,1,1,1,1,17,13,7,0,0,0,0,0,0,0,0,13,1,1,1,1,1
1,1,1,1,17,13,13,0,0,0,0,0,0,0,0,13,12,1,1,1,1,1
1,1,1,17,13,13,13,0,0,0,0,0,0,0,13,12,1,1,1,1,1,1
1,1,1,13,0,0,0,0,0,0,0,0,0,13,12,1,1,1,1,1,1,1
1,1,13,0,0,0,0,0,0,0,0,0,13,18,1,1,1,1,1,1,1,1
1,1,13,0,0,0,0,0,0,0,0,13,18,1,1,1,1,1,1,1,1,1
1,17,8,9,0,0,0,0,0,0,13,12,1,1,1,1,1,1,1,1,1,1
1,17,10,8,9,10,0,0,0,13,12,1,1,1,1,1,1,1,1,1,1,1
1,1,13,9,9,8,9,0,13,18,1,1,1,1,1,1,1,1,1,1,1,1
1,1,13,13,8,9,13,13,1,1,1,1,1,1,1,1,1,1,1,1,1,1
1,1,1,1,18,18,1,1,1,1,1,1,1,1,1,1,1,1,1,1,1,1
1,1,1,1,1,1,1,1,1,1,1,1,1,1,1,1,1,1,1,1,1,1
endlayer

layer
1,1,1,1,1,1,1,1,1,1,1,1,1,1,1,1,1,1,1,1,1,1
1,1,1,1,1,1,1,1,1,1,1,1,1,1,1,1,1,1,1,11,1,1
1,1,1,1,1,1,1,1,1,1,1,1,1,1,1,1,11,13,13,13,12,1
1,1,1,1,1,1,1,1,1,1,1,1,1,1,11,13,0,0,0,13,1,1
1,1,1,1,1,1,1,1,1,1,1,11,13,13,13,0,0,0,0,13,1,1
1,1,1,1,1,1,1,1,1,1,13,13,13,20,20,0,0,0,0,12,1,1
1,1,1,1,1,1,1,1,1,13,13,20,20,20,20,0,0,0,13,1,1,1
1,1,1,1,1,1,1,1,13,13,20,20,20,20,20,20,0,13,12,1,1,1
1,1,1,1,1,1,1,13,13,20,20,20,20,20,20,20,21,13,1,1,1,1
1,1,1,1,1,1,13,15,20,20,20,20,20,20,20,20,21,13,1,1,1,1
1,1,1,1,1,13,13,22,20,20,20,20,20,20,20,20,15,12,1,1,1,1
1,1,1,1,13,13,13,22,20,20,20,20,20,20,20,13,13,1,1,1,1,1
1,1,1,13,13,13,13,0,20,20,20,20,20,20,13,13,1,1,1,1,1,1
1,1,17,13,0,0,0,20,20,20,20,20,20,13,13,1,1,1,1,1,1,1
1,1,13,0,0,0,0,0,20,20,20,20,13,13,1,1,1,1,1,1,1,1
1,11,13,0,0,0,0,0,0,20,20,13,13,1,1,1,1,1,1,1,1,1
1,13,0,0,0,0,0,0,0,20,13,13,1,1,1,1,1,1,1,1,1,1
1,13,8,9,0,0,0,0,0,13,13,1,1,1,1,1,1,1,1,1,1,1
1,17,13,10,8,0,0,0,13,13,1,1,1,1,1,1,1,1,1,1,1,1
1,1,13,13,9,0,13,13,18,1,1,1,1,1,1,1,1,1,1,1,1,1
1,1,1,18,13,13,12,1,1,1,1,1,1,1,1,1,1,1,1,1,1,1
1,1,1,1,1,1,1,1,1,1,1,1,1,1,1,1,1,1,1,1,1,1
endlayer

layer
1,1,1,1,1,1,1,1,1,1,1,1,1,1,1,1,1,1,1,1,1,1
1,1,1,1,1,1,1,1,1,1,1,1,1,1,1,1,1,1,11,13,13,1
1,1,1,1,1,1,1,1,1,1,1,1,1,1,1,11,13,13,13,13,13,1
1,1,1,1,1,1,1,1,1,1,1,23,23,11,13,13,0,0,0,13,12,1
1,1,1,1,1,1,1,1,1,1,23,2,2,2,13,13,0,0,0,13,1,1
1,1,1,1,1,1,1,1,1,24,2,0,0,0,14,13,0,0,0,13,1,1
1,1,1,1,1,1,1,1,24,2,0,0,0,0,14,7,0,0,13,12,1,1
1,1,1,1,1,1,1,24,2,0,0,0,0,0,0,14,23,13,13,1,1,1
1,1,1,1,1,1,24,2,0,0,0,0,0,0,0,0,0,2,12,1,1,1
1,1,1,1,1,24,2,0,0,0,0,0,26,0,0,0,0,2,25,1,1,1
1,1,1,1,1,13,2,0,0,0,0,0,0,0,0,0,0,2,25,1,1,1
1,1,1,1,13,13,13,0,0,0,0,0,0,0,0,0,2,25,1,1,1,1
1,1,1,13,13,13,13,13,0,0,0,0,0,0,0,2,27,1,1,1,1,1
1,1,13,13,13,13,13,13,13,0,0,0,0,0,2,27,1,1,1,1,1,1
1,17,13,13,13,13,13,13,13,13,28,0,0,2,27,1,1,1,1,1,1,1
1,13,13,13,13,13,13,13,13,13,13,2,2,27,1,1,1,1,1,1,1,1
17,13,13,13,13,13,13,13,13,13,13,13,27,1,1,1,1,1,1,1,1,1
17,13,13,13,13,13,13,13,13,13,13,1,1,1,1,1,1,1,1,1,1,1
1,13,13,13,13,13,13,13,13,13,1,1,1,1,1,1,1,1,1,1,1,1
1,29,13,13,13,13,13,13,13,1,1,1,1,1,1,1,1,1,1,1,1,1
1,1,29,13,13,13,13,18,1,1,1,1,1,1,1,1,1,1,1,1,1,1
1,1,1,1,18,18,1,1,1,1,1,1,1,1,1,1,1,1,1,1,1,1
endlayer

layer
1,1,1,1,1,1,1,1,1,1,1,1,1,1,1,1,1,1,1,1,11,1
1,1,1,1,1,1,1,1,1,1,1,1,1,1,1,1,1,1,11,13,13,12
1,1,1,1,1,1,1,1,1,1,1,1,1,1,1,29,13,17,18,13,13,1
1,1,1,1,1,1,1,1,1,1,1,1,1,29,2,2,0,0,0,17,12,1
1,1,1,1,1,1,1,1,1,1,1,0,0,2,13,13,0,0,0,18,1,1
1,1,1,1,1,1,1,1,1,1,0,0,0,0,0,14,7,0,0,13,1,1
1,1,1,1,1,1,1,1,1,0,0,0,0,0,0,0,14,13,2,29,1,1
1,1,1,1,1,1,1,1,0,0,0,0,0,0,0,0,15,13,2,1,1,1
1,1,1,1,1,1,1,0,0,0,0,0,0,0,0,0,0,2,29,1,1,1
1,1,1,1,1,1,0,0,0,0,0,0,26,0,0,0,0,0,1,1,1,1
1,1,1,1,1,2,31,0,0,0,0,0,30,0,0,0,0,0,1,1,1,1
1,1,1,1,13,13,13,0,0,0,0,0,0,0,0,0,0,1,1,1,1,1
1,1,1,13,13,13,13,13,0,0,0,0,0,0,0,0,1,1,1,1,1,1
1,1,13,13,13,13,13,13,13,0,0,0,0,0,0,1,1,1,1,1,1,1
1,13,13,13,13,13,13,13,13,13,28,0,0,0,1,1,1,1,1,1,1,1
11,13,13,13,13,13,20,13,13,13,13,31,0,1,1,1,1,1,1,1,1,1
13,13,13,13,13,13,13,13,13,13,13,2,1,1,1,1,1,1,1,1,1,1
13,13,13,13,13,13,13,13,13,13,13,1,1,1,1,1,1,1,1,1,1,1
1,13,13,13,13,13,13,13,13,13,1,1,1,1,1,1,1,1,1,1,1,1
1,32,13,13,13,13,13,13,13,1,1,1,1,1,1,1,1,1,1,1,1,1
1,1,32,13,13,13,13,13,1,1,1,1,1,1,1,1,1,1,1,1,1,1
1,1,1,1,13,13,18,1,1,1,1,1,1,1,1,1,1,1,1,1,1,1
endlayer

layer
1,1,1,1,1,1,1,1,1,1,1,1,1,1,1,1,1,1,1,33,13,20
1,1,1,1,1,1,1,1,1,1,1,1,1,1,1,1,29,33,2,13,13,13
1,1,1,1,1,1,1,1,1,1,1,1,1,1,29,29,2,13,13,13,13,34
1,1,1,1,1,1,1,1,1,1,1,1,1,29,29,31,15,15,35,13,2,1
1,1,1,1,1,1,1,1,1,1,1,0,0,29,0,0,15,15,15,13,34,1
1,1,1,1,1,1,1,1,1,1,0,0,0,0,0,0,0,15,15,2,29,1
1,1,1,1,1,1,1,1,1,0,0,0,0,0,0,0,0,0,31,29,1,1
1,1,1,1,1,1,1,1,0,0,0,0,0,0,0,0,0,0,29,29,1,1
1,1,1,1,1,1,1,0,0,0,0,0,0,0,0,0,0,29,29,1,1,1
1,1,1,1,1,1,0,0,0,0,0,0,26,0,0,0,0,0,1,1,1,1
1,1,1,1,29,2,0,0,0,0,0,0,30,0,0,0,0,0,1,1,1,1
1,1,1,29,13,0,32,0,0,0,0,0,0,0,0,0,0,1,1,1,1,1
1,1,1,13,0,0,0,32,0,0,0,0,0,0,0,0,1,1,1,1,1,1
1,1,13,13,0,0,0,0,32,0,0,0,0,0,0,1,1,1,1,1,1,1
1,13,13,13,13,0,0,32,0,32,0,0,0,0,1,1,1,1,1,1,1,1
13,0,0,0,36,0,0,0,0,0,0,0,0,1,1,1,1,1,1,1,1,1
13,0,0,0,0,13,0,0,0,0,0,2,1,1,1,1,1,1,1,1,1,1
13,0,0,0,0,37,13,28,0,0,13,29,1,1,1,1,1,1,1,1,1,1
29,13,0,0,0,0,0,13,13,13,29,1,1,1,1,1,1,1,1,1,1,1
1,13,40,0,39,39,38,13,13,1,1,1,1,1,1,1,1,1,1,1,1,1
1,1,13,13,39,39,38,13,1,1,1,1,1,1,1,1,1,1,1,1,1,1
1,1,1,29,13,13,13,1,1,1,1,1,1,1,1,1,1,1,1,1,1,1
endlayer

layer
1,1,1,1,1,1,1,1,1,1,1,1,1,1,1,1,1,1,29,29,4,13
1,1,1,1,1,1,1,1,1,1,1,1,1,1,1,1,29,29,29,15,15,3
1,1,1,1,1,1,1,1,1,1,1,1,1,1,1,0,29,0,0,0,15,29
1,1,1,1,1,1,1,1,1,1,1,1,1,0,0,0,0,0,32,0,29,29
1,1,1,1,1,1,1,1,1,1,1,0,0,0,0,0,0,0,0,0,29,1
1,1,1,1,1,1,1,1,1,1,0,0,0,0,0,0,0,0,0,29,29,1
1,1,1,1,1,1,1,1,1,0,0,0,0,0,0,0,0,0,0,0,1,1
1,1,1,1,1,1,1,1,0,0,0,0,0,0,0,0,0,0,0,1,1,1
1,1,1,1,1,1,1,0,0,0,0,0,0,0,0,0,0,0,0,1,1,1
1,1,1,1,1,1,0,0,0,0,0,0,26,0,0,0,0,0,1,1,1,1
1,1,1,1,1,0,0,0,0,0,0,0,30,0,0,0,0,0,1,1,1,1
1,1,1,1,31,0,0,0,0,0,0,0,0,0,0,0,0,1,1,1,1,1
1,1,29,31,0,0,0,0,0,0,0,0,0,0,0,0,1,1,1,1,1,1
1,1,13,2,0,0,0,0,0,0,0,0,0,0,0,1,1,1,1,1,1,1
1,13,13,13,13,0,0,32,0,0,0,0,0,0,1,1,1,1,1,1,1,1
7,0,0,0,41,0,0,0,0,0,0,0,0,1,1,1,1,1,1,1,1,1
13,0,0,0,0,13,0,0,0,0,0,0,1,1,1,1,1,1,1,1,1,1
16,0,0,0,0,0,13,28,0,0,31,1,1,1,1,1,1,1,1,1,1,1
32,7,0,0,0,0,0,13,2,31,1,1,1,1,1,1,1,1,1,1,1,1
1,13,0,0,0,0,0,13,13,29,1,1,1,1,1,1,1,1,1,1,1,1
1,29,13,14,0,0,0,13,1,1,1,1,1,1,1,1,1,1,1,1,1,1
1,1,1,32,42,13,14,1,1,1,1,1,1,1,1,1,1,1,1,1,1,1
endlayer

layer
1,1,1,1,1,1,1,1,1,1,1,1,1,1,1,1,1,1,1,0,0,31
1,1,1,1,1,1,1,1,1,1,1,1,1,1,1,1,1,0,0,0,0,0
1,1,1,1,1,1,1,1,1,1,1,1,1,1,1,0,0,0,0,0,0,0
1,1,1,1,1,1,1,1,1,1,1,1,1,0,0,0,0,0,32,0,0,1
1,1,1,1,1,1,1,1,1,1,1,0,0,0,0,0,0,0,0,0,0,1
1,1,1,1,1,1,1,1,1,1,0,0,0,0,0,0,0,0,0,0,1,1
1,1,1,1,1,1,1,1,1,0,0,0,0,0,0,0,0,0,0,0,1,1
1,1,1,1,1,1,1,1,0,0,0,0,0,0,0,0,0,0,0,1,1,1
1,1,1,1,1,1,1,0,0,0,0,0,0,0,0,0,0,0,0,1,1,1
1,1,1,1,1,1,0,0,0,0,0,0,26,0,0,0,0,0,1,1,1,1
1,1,1,1,1,0,0,0,0,0,0,0,30,0,0,0,0,0,1,1,1,1
1,1,1,1,0,0,0,0,0,0,0,0,0,0,0,0,0,1,1,1,1,1
1,1,1,0,0,0,0,0,0,0,0,0,0,0,0,0,1,1,1,1,1,1
1,29,43,43,0,0,0,0,0,0,0,0,0,0,0,1,1,1,1,1,1,1
1,2,13,13,13,0,0,32,0,0,0,0,0,0,1,1,1,1,1,1,1,1
16,20,0,0,17,0,0,0,0,0,0,0,0,1,1,1,1,1,1,1,1,1
13,20,0,0,0,13,0,0,0,0,0,0,1,1,1,1,1,1,1,1,1,1
13,20,0,0,0,0,13,28,0,0,0,1,1,1,1,1,1,1,1,1,1,1
32,13,0,0,0,0,0,13,44,0,1,1,1,1,1,1,1,1,1,1,1,1
1,13,0,0,0,0,0,13,44,1,1,1,1,1,1,1,1,1,1,1,1,1
1,29,13,13,20,20,20,2,29,1,1,1,1,1,1,1,1,1,1,1,1,1
1,1,1,32,13,13,42,1,1,1,1,1,1,1,1,1,1,1,1,1,1,1
endlayer

layer
1,1,1,1,1,1,1,1,1,1,1,1,1,1,1,1,1,1,1,0,0,0
1,1,1,1,1,1,1,1,1,1,1,1,1,1,1,1,1,0,0,0,0,0
1,1,1,1,1,1,1,1,1,1,1,1,1,1,1,0,0,0,0,0,0,0
1,1,1,1,1,1,1,1,1,1,1,1,1,0,0,0,0,0,32,0,0,1
1,1,1,1,1,1,1,1,1,1,1,0,0,0,0,0,0,0,0,0,0,1
1,1,1,1,1,1,1,1,1,1,0,0,0,0,0,0,0,0,0,0,1,1
1,1,1,1,1,1,1,1,1,0,0,0,0,0,0,0,0,0,0,0,1,1
1,1,1,1,1,1,1,1,0,0,0,0,0,0,0,0,0,0,0,1,1,1
1,1,1,1,1,1,1,0,0,0,0,0,0,0,0,0,0,0,0,1,1,1
1,1,1,1,1,1,0,0,0,0,0,0,26,0,0,0,0,0,1,1,1,1
1,1,1,1,1,0,0,0,0,0,0,0,30,0,0,0,0,0,1,1,1,1
1,1,1,1,0,0,0,0,0,0,0,0,0,0,0,0,0,1,1,1,1,1
1,1,1,0,0,0,0,0,0,0,0,0,0,0,0,0,1,1,1,1,1,1
1,1,0,0,0,0,0,0,0,0,0,0,0,0,0,1,1,1,1,1,1,1
1,43,2,16,0,0,0,32,0,0,0,0,0,0,1,1,1,1,1,1,1,1
1,13,13,13,42,0,0,0,0,0,0,0,0,1,1,1,1,1,1,1,1,1
14,13,13,13,13,13,0,0,0,0,0,0,1,1,1,1,1,1,1,1,1,1
14,13,13,13,13,13,16,0,0,0,0,1,1,1,1,1,1,1,1,1,1,1
1,14,13,13,13,13,13,0,0,0,1,1,1,1,1,1,1,1,1,1,1,1
1,14,13,13,13,13,13,2,0,1,1,1,1,1,1,1,1,1,1,1,1,1
1,1,7,7,13,13,13,44,1,1,1,1,1,1,1,1,1,1,1,1,1,1
1,1,1,1,7,7,1,1,1,1,1,1,1,1,1,1,1,1,1,1,1,1
endlayer

layer
1,1,1,1,1,1,1,1,1,1,1,1,1,1,1,1,1,1,1,0,0,0
1,1,1,1,1,1,1,1,1,1,1,1,1,1,1,1,1,0,0,0,0,0
1,1,1,1,1,1,1,1,1,1,1,1,1,1,1,0,0,0,0,0,0,0
1,1,1,1,1,1,1,1,1,1,1,1,1,0,0,0,0,0,32,0,0,1
1,1,1,1,1,1,1,1,1,1,1,1,0,0,0,0,0,0,0,0,0,1
1,1,1,1,1,1,1,1,1,1,1,0,0,0,0,0,0,0,0,0,1,1
1,1,1,1,1,1,1,1,1,1,0,0,0,0,0,0,0,0,0,0,1,1
1,1,1,1,1,1,1,1,0,0,0,0,0,0,0,0,0,0,0,1,1,1
1,1,1,1,1,1,1,0,0,0,0,0,0,0,0,0,0,0,0,1,1,1
1,1,1,1,1,1,0,0,0,0,0,0,26,0,0,0,0,0,1,1,1,1
1,1,1,1,1,0,0,0,0,0,0,0,30,0,0,0,0,1,1,1,1,1
1,1,1,1,0,0,0,0,0,0,0,0,0,0,0,0,1,1,1,1,1,1
1,1,1,0,0,0,0,0,0,0,0,0,0,0,0,1,1,1,1,1,1,1
1,1,0,0,0,0,0,0,0,0,0,0,0,0,0,1,1,1,1,1,1,1
1,32,32,0,0,0,0,32,0,0,0,0,0,0,1,1,1,1,1,1,1,1
32,43,0,0,0,0,0,0,0,0,0,0,0,1,1,1,1,1,1,1,1,1
32,42,0,0,0,32,0,0,0,0,0,0,1,1,1,1,1,1,1,1,1,1
32,16,0,0,0,0,0,0,0,0,0,1,1,1,1,1,1,1,1,1,1,1
32,32,42,0,0,0,0,0,0,0,1,1,1,1,1,1,1,1,1,1,1,1
1,32,32,16,0,0,0,32,0,1,1,1,1,1,1,1,1,1,1,1,1,1
1,1,32,32,42,16,44,32,1,1,1,1,1,1,1,1,1,1,1,1,1,1
1,1,1,32,32,32,32,1,1,1,1,1,1,1,1,1,1,1,1,1,1,1
endlayer

layer
1,1,1,1,1,1,1,1,1,1,1,1,1,1,1,1,1,1,1,1,1,1
1,1,1,1,1,1,1,1,1,1,1,1,1,1,1,1,1,1,0,0,0,1
1,1,1,1,1,1,1,1,1,1,1,1,1,1,1,1,0,0,0,0,0,1
1,1,1,1,1,1,1,1,1,1,1,1,1,1,0,0,0,0,32,0,0,1
1,1,1,1,1,1,1,1,1,1,1,1,0,0,0,0,0,0,0,0,1,1
1,1,1,1,1,1,1,1,1,1,1,0,0,0,0,0,0,0,0,0,1,1
1,1,1,1,1,1,1,1,1,1,0,0,0,0,0,0,0,0,0,1,1,1
1,1,1,1,1,1,1,1,1,0,0,0,0,0,0,0,0,0,0,1,1,1
1,1,1,1,1,1,1,1,0,0,0,0,0,0,0,0,0,0,1,1,1,1
1,1,1,1,1,1,1,0,0,0,0,0,26,0,0,0,0,0,1,1,1,1
1,1,1,1,1,0,0,0,0,0,0,0,30,0,0,0,0,1,1,1,1,1
1,1,1,1,0,0,0,0,0,0,0,0,0,0,0,0,1,1,1,1,1,1
1,1,1,0,0,0,0,0,0,0,0,0,0,0,0,1,1,1,1,1,1,1
1,1,0,0,0,0,0,0,0,0,0,0,0,0,1,1,1,1,1,1,1,1
1,0,0,0,0,0,0,32,0,0,0,0,0,1,1,1,1,1,1,1,1,1
0,0,0,0,0,0,0,0,0,0,0,0,1,1,1,1,1,1,1,1,1,1
0,0,0,0,0,46,0,0,0,0,0,0,1,1,1,1,1,1,1,1,1,1
0,0,0,0,0,0,0,0,0,0,0,1,1,1,1,1,1,1,1,1,1,1
1,0,0,0,0,0,0,0,0,0,1,1,1,1,1,1,1,1,1,1,1,1
1,0,0,0,0,0,0,0,0,1,1,1,1,1,1,1,1,1,1,1,1,1
1,1,0,0,0,0,0,0,1,1,1,1,1,1,1,1,1,1,1,1,1,1
1,1,1,1,0,0,0,1,1,1,1,1,1,1,1,1,1,1,1,1,1,1
endlayer

layer
1,1,1,1,1,1,1,1,1,1,1,1,1,1,1,1,1,1,1,1,1,1
1,1,1,1,1,1,1,1,1,1,1,1,1,1,1,1,1,1,1,1,1,1
1,1,1,1,1,1,1,1,1,1,1,1,1,1,1,1,1,0,0,0,1,1
1,1,1,1,1,1,1,1,1,1,1,1,1,1,1,0,0,0,29,0,1,1
1,1,1,1,1,1,1,1,1,1,1,1,1,0,0,0,0,0,0,0,1,1
1,1,1,1,1,1,1,1,1,1,1,1,0,0,0,0,0,0,0,1,1,1
1,1,1,1,1,1,1,1,1,1,0,0,0,0,0,0,0,0,0,1,1,1
1,1,1,1,1,1,1,1,1,0,0,0,0,0,0,0,0,0,1,1,1,1
1,1,1,1,1,1,1,1,0,0,0,0,0,0,0,0,0,0,1,1,1,1
1,1,1,1,1,1,1,0,0,0,0,0,26,0,0,0,0,1,1,1,1,1
1,1,1,1,1,1,0,0,0,0,0,0,30,0,0,0,1,1,1,1,1,1
1,1,1,1,0,0,0,0,0,0,0,0,0,0,0,0,1,1,1,1,1,1
1,1,1,0,0,0,0,0,0,0,0,0,0,0,0,1,1,1,1,1,1,1
1,1,0,0,0,0,0,0,0,0,0,0,0,0,1,1,1,1,1,1,1,1
1,0,0,0,0,0,0,29,0,0,0,0,0,1,1,1,1,1,1,1,1,1
0,0,0,0,0,0,0,0,0,0,0,0,1,1,1,1,1,1,1,1,1,1
0,0,0,0,0,0,0,0,0,0,0,1,1,1,1,1,1,1,1,1,1,1
0,0,0,0,0,0,0,0,0,0,0,1,1,1,1,1,1,1,1,1,1,1
1,0,0,0,0,0,0,0,0,0,1,1,1,1,1,1,1,1,1,1,1,1
1,0,0,0,0,0,0,0,0,1,1,1,1,1,1,1,1,1,1,1,1,1
1,1,0,0,0,0,0,0,1,1,1,1,1,1,1,1,1,1,1,1,1,1
1,1,1,1,0,0,0,1,1,1,1,1,1,1,1,1,1,1,1,1,1,1
endlayer

layer
1,1,1,1,1,1,1,1,1,1,1,1,1,1,1,45,45,1,1,1,1,1
1,1,1,1,1,1,1,1,1,1,1,1,1,1,1,1,1,45,1,1,1,1
1,1,1,1,1,1,1,1,1,1,1,1,1,1,1,1,1,1,45,1,1,1
1,1,1,1,1,1,1,1,1,1,1,1,1,1,1,1,0,0,29,45,1,1
1,1,1,1,1,1,1,1,1,1,1,1,1,1,0,0,0,0,0,1,45,1
1,1,1,1,1,1,1,1,1,1,1,1,1,0,0,0,0,0,0,1,1,45
1,1,1,1,1,1,1,1,1,1,1,0,0,0,0,0,0,0,1,1,1,45
1,1,1,1,1,1,1,1,1,1,0,0,0,0,0,0,0,0,1,1,1,1
1,1,1,1,1,1,1,1,1,0,0,0,0,0,0,0,0,1,1,1,1,1
1,1,1,1,1,1,1,1,0,0,0,0,26,0,0,0,1,1,1,1,1,1
1,1,1,1,1,1,1,0,0,0,0,0,30,0,0,0,1,1,1,1,1,1
1,1,1,1,1,0,0,0,0,0,0,0,0,0,0,1,1,1,1,1,1,1
1,1,1,1,0,0,0,0,0,0,0,0,0,0,1,1,1,1,1,1,1,1
1,1,0,0,0,0,0,0,0,0,0,0,0,1,1,1,1,1,1,1,1,1
1,0,0,0,0,0,0,29,0,0,0,0,1,1,1,1,1,1,1,1,1,1
0,0,0,0,0,0,0,0,0,0,0,1,1,1,1,1,1,1,1,1,1,1
0,0,0,0,0,0,0,0,0,0,0,1,1,1,1,1,1,1,1,1,1,1
0,0,0,0,0,0,0,0,0,0,1,1,1,1,1,1,1,1,1,1,1,1
1,0,0,0,0,0,0,0,0,0,1,1,1,1,1,1,1,1,1,1,1,1
1,0,0,0,0,0,0,0,0,1,1,1,1,1,1,1,1,1,1,1,1,1
1,1,0,0,0,0,0,0,1,1,1,1,1,1,1,1,1,1,1,1,1,1
1,1,1,1,0,0,0,1,1,1,1,1,1,1,1,1,1,1,1,1,1,1
endlayer

layer
1,1,1,1,1,1,1,1,1,1,1,1,1,1,1,29,29,1,1,1,1,1
1,1,1,1,1,1,1,1,1,1,1,1,1,1,1,1,29,29,1,1,1,1
1,1,1,1,1,1,1,1,1,1,1,1,1,1,1,1,1,29,29,1,1,1
1,1,1,1,1,1,1,1,1,45,45,1,1,1,1,1,1,1,29,29,1,1
1,1,1,1,1,1,1,1,1,45,45,45,1,1,1,0,0,0,1,29,29,1
1,1,1,1,1,1,1,1,1,1,1,45,45,0,0,0,0,0,1,1,29,29
1,1,1,1,1,1,1,1,1,1,1,0,45,45,0,0,0,0,1,1,1,29
1,1,1,1,1,1,1,1,1,1,0,0,0,45,45,0,0,1,1,1,1,1
1,1,1,1,1,1,1,1,1,0,0,0,0,0,45,45,0,1,1,1,1,1
1,1,1,1,1,1,1,1,0,0,0,0,26,0,0,45,45,1,1,1,1,1
1,1,1,1,1,1,1,0,0,0,0,0,30,0,0,0,45,45,1,1,1,1
1,1,1,1,1,45,0,0,0,0,0,0,0,0,0,1,1,45,45,1,1,1
1,1,1,1,0,0,45,0,0,0,0,0,0,0,1,1,1,45,45,1,1,1
1,1,1,0,0,0,0,45,0,0,0,0,0,1,1,1,1,1,1,1,1,1
1,1,0,0,0,0,0,29,45,0,0,0,1,1,1,1,1,1,1,1,1,1
1,0,0,0,0,0,0,0,0,45,0,1,1,1,1,1,1,1,1,1,1,1
0,0,0,0,0,0,0,0,0,0,45,1,1,1,1,1,1,1,1,1,1,1
1,0,0,0,0,0,0,0,0,0,1,1,1,1,1,1,1,1,1,1,1,1
1,0,0,0,0,0,0,0,0,1,1,1,1,1,1,1,1,1,1,1,1,1
1,1,0,0,0,0,0,0,1,1,1,1,1,1,1,1,1,1,1,1,1,1
1,1,1,0,0,0,0,1,1,1,1,1,1,1,1,1,1,1,1,1,1,1
1,1,1,1,1,0,1,1,1,1,1,1,1,1,1,1,1,1,1,1,1,1
endlayer

layer
1,1,1,1,1,1,1,1,1,1,1,1,1,1,1,1,1,1,1,1,1,1
1,1,1,1,1,1,1,1,1,1,1,1,1,1,1,1,1,1,1,1,1,1
1,1,1,1,1,1,1,1,1,1,1,1,1,1,1,1,1,1,1,1,1,1
1,1,1,1,1,1,1,1,45,45,1,1,1,1,1,1,1,1,29,1,1,1
1,1,1,1,1,1,1,1,1,45,45,1,1,1,1,1,1,1,1,1,1,1
1,1,1,1,1,1,1,1,1,1,45,45,1,1,0,0,0,1,1,1,1,1
1,1,1,1,1,1,1,1,1,1,1,45,45,0,0,0,0,1,1,1,1,1
1,1,1,1,1,1,1,1,1,1,1,0,45,45,0,0,0,1,1,1,1,1
1,1,1,1,1,1,1,1,1,1,0,0,0,45,45,0,1,1,1,1,1,1
1,1,1,1,1,1,1,1,1,0,0,0,26,0,45,45,1,1,1,1,1,1
1,1,1,1,1,1,1,1,0,0,0,0,30,0,0,45,45,1,1,1,1,1
1,1,1,1,1,29,1,0,0,0,0,0,0,0,1,1,45,45,1,1,1,1
1,1,1,1,1,29,29,0,0,0,0,0,0,1,1,1,1,45,45,1,1,1
1,1,1,1,0,0,29,29,0,0,0,0,1,1,1,1,1,1,45,1,1,1
1,1,1,0,0,0,0,29,29,0,0,1,1,1,1,1,1,1,1,1,1,1
1,1,0,0,0,0,0,0,29,29,1,1,1,1,1,1,1,1,1,1,1,1
1,0,0,0,0,0,0,0,0,29,29,1,1,1,1,1,1,1,1,1,1,1
1,0,0,0,0,0,0,0,0,1,1,1,1,1,1,1,1,1,1,1,1,1
1,1,0,0,0,0,0,0,1,1,1,1,1,1,1,1,1,1,1,1,1,1
1,1,1,0,0,0,0,1,1,1,1,1,1,1,1,1,1,1,1,1,1,1
1,1,1,1,0,0,1,1,1,1,1,1,1,1,1,1,1,1,1,1,1,1
1,1,1,1,1,1,1,1,1,1,1,1,1,1,1,1,1,1,1,1,1,1
endlayer

layer
1,1,1,1,1,1,1,1,1,1,1,1,1,1,1,1,1,1,1,1,1,1
1,1,1,1,1,1,1,1,1,1,1,1,1,1,1,1,1,1,1,1,1,1
1,1,1,1,1,1,1,1,1,1,1,1,1,1,1,1,1,1,1,1,1,1
1,1,1,1,1,1,1,1,1,29,1,1,1,1,1,1,1,1,29,1,1,1
1,1,1,1,1,1,1,1,48,47,29,1,1,1,1,1,1,1,1,1,1,1
1,1,1,1,1,1,1,1,1,47,47,29,1,1,1,1,1,1,1,1,1,1
1,1,1,1,1,1,1,1,1,29,47,47,29,0,0,0,1,1,1,1,1,1
1,1,1,1,1,1,1,1,1,1,29,47,47,29,0,0,1,1,1,1,1,1
1,1,1,1,1,1,1,1,1,1,29,15,47,47,29,0,1,1,1,1,1,1
1,1,1,1,1,1,1,1,1,0,29,15,26,47,47,29,1,1,1,1,1,1
1,1,1,1,1,1,1,1,0,0,0,15,30,15,47,47,29,1,1,1,1,1
1,1,1,1,1,1,1,0,0,0,0,0,29,29,29,47,47,29,1,1,1,1
1,1,1,1,1,1,0,0,0,0,0,0,0,1,1,29,47,47,29,1,1,1
1,1,1,1,1,0,0,0,0,0,0,0,1,1,1,1,1,49,1,1,1,1
1,1,1,1,0,0,0,29,0,0,0,1,1,1,1,1,1,1,1,1,1,1
1,1,1,0,0,0,0,0,0,0,1,1,1,1,1,1,1,1,1,1,1,1
1,1,0,0,0,0,0,0,0,1,1,1,1,1,1,1,1,1,1,1,1,1
1,1,0,0,0,0,0,0,1,1,1,1,1,1,1,1,1,1,1,1,1,1
1,1,1,0,0,0,0,1,1,1,1,1,1,1,1,1,1,1,1,1,1,1
1,1,1,1,0,0,1,1,1,1,1,1,1,1,1,1,1,1,1,1,1,1
1,1,1,1,1,1,1,1,1,1,1,1,1,1,1,1,1,1,1,1,1,1
1,1,1,1,1,1,1,1,1,1,1,1,1,1,1,1,1,1,1,1,1,1
endlayer

layer
1,1,1,1,1,1,1,1,1,1,1,1,1,1,1,1,1,1,1,1,1,1
1,1,1,1,1,1,1,1,1,1,1,1,1,1,1,1,1,1,1,1,1,1
1,1,1,1,1,1,1,1,1,1,1,1,1,1,1,1,1,1,1,1,1,1
1,1,1,1,1,1,1,1,1,1,1,1,1,1,1,1,1,1,1,1,1,1
1,1,1,1,1,1,1,1,1,1,1,1,1,1,1,1,1,1,1,1,1,1
1,1,1,1,1,1,1,1,1,1,1,1,1,1,1,1,1,1,1,1,1,1
1,1,1,1,1,1,1,1,1,1,1,1,1,1,1,1,1,1,1,1,1,1
1,1,1,1,1,1,1,1,1,1,1,29,29,0,0,1,1,1,1,1,1,1
1,1,1,1,1,1,1,1,1,1,29,0,0,0,0,1,1,1,1,1,1,1
1,1,1,1,1,1,1,1,1,1,29,0,26,0,29,1,1,1,1,1,1,1
1,1,1,1,1,1,1,1,1,0,29,29,0,0,29,1,1,1,1,1,1,1
1,1,1,1,1,1,1,1,0,0,0,29,29,29,1,1,1,1,1,1,1,1
1,1,1,1,1,1,1,0,0,0,0,0,1,1,1,1,1,1,1,1,1,1
1,1,1,1,1,1,0,0,0,0,0,1,1,1,1,1,1,1,1,1,1,1
1,1,1,1,1,0,0,29,0,0,1,1,1,1,1,1,1,1,1,1,1,1
1,1,1,1,0,0,0,0,0,1,1,1,1,1,1,1,1,1,1,1,1,1
1,1,1,0,0,0,0,0,1,1,1,1,1,1,1,1,1,1,1,1,1,1
1,1,1,0,0,0,0,1,1,1,1,1,1,1,1,1,1,1,1,1,1,1
1,1,1,1,0,0,1,1,1,1,1,1,1,1,1,1,1,1,1,1,1,1
1,1,1,1,1,1,1,1,1,1,1,1,1,1,1,1,1,1,1,1,1,1
1,1,1,1,1,1,1,1,1,1,1,1,1,1,1,1,1,1,1,1,1,1
1,1,1,1,1,1,1,1,1,1,1,1,1,1,1,1,1,1,1,1,1,1
endlayer

layer
1,1,1,1,1,1,1,1,1,1,1,1,1,1,1,1,1,1,1,1,1,1
1,1,1,1,1,1,1,1,1,1,1,1,1,1,1,1,1,1,1,1,1,1
1,1,1,1,1,1,1,1,1,1,1,1,1,1,1,1,1,1,1,1,1,1
1,1,1,1,1,1,1,1,1,1,1,1,1,1,1,1,1,1,1,1,1,1
1,1,1,1,1,1,1,1,1,1,1,1,1,1,1,1,1,1,1,1,1,1
1,1,1,1,1,1,1,1,1,1,1,1,1,1,1,1,1,1,1,1,1,1
1,1,1,1,1,1,1,1,1,1,1,1,1,1,1,1,1,1,1,1,1,1
1,1,1,1,1,1,1,1,1,1,1,1,1,1,1,1,1,1,1,1,1,1
1,1,1,1,1,1,1,1,1,1,1,0,0,0,1,1,1,1,1,1,1,1
1,1,1,1,1,1,1,1,1,1,1,0,26,0,1,1,1,1,1,1,1,1
1,1,1,1,1,1,1,1,1,1,0,0,0,0,1,1,1,1,1,1,1,1
1,1,1,1,1,1,1,1,1,0,0,0,1,1,1,1,1,1,1,1,1,1
1,1,1,1,1,1,1,1,0,0,0,1,1,1,1,1,1,1,1,1,1,1
1,1,1,1,1,1,1,0,0,0,1,1,1,1,1,1,1,1,1,1,1,1
1,1,1,1,1,1,0,0,0,1,1,1,1,1,1,1,1,1,1,1,1,1
1,1,1,1,1,1,0,0,1,1,1,1,1,1,1,1,1,1,1,1,1,1
1,1,1,1,1,1,1,1,1,1,1,1,1,1,1,1,1,1,1,1,1,1
1,1,1,1,1,1,1,1,1,1,1,1,1,1,1,1,1,1,1,1,1,1
1,1,1,1,1,1,1,1,1,1,1,1,1,1,1,1,1,1,1,1,1,1
1,1,1,1,1,1,1,1,1,1,1,1,1,1,1,1,1,1,1,1,1,1
1,1,1,1,1,1,1,1,1,1,1,1,1,1,1,1,1,1,1,1,1,1
1,1,1,1,1,1,1,1,1,1,1,1,1,1,1,1,1,1,1,1,1,1
endlayer

layer
1,1,1,1,1,1,1,1,1,1,1,1,1,1,1,1,1,1,1,1,1,1
1,1,1,1,1,1,1,1,1,1,1,1,1,1,1,1,1,1,1,1,1,1
1,1,1,1,1,1,1,1,1,1,1,1,1,1,1,1,1,1,1,1,1,1
1,1,1,1,1,1,1,1,1,1,1,1,1,1,1,1,1,1,1,1,1,1
1,1,1,1,1,1,1,1,1,1,1,1,1,1,1,1,1,1,1,1,1,1
1,1,1,1,1,1,1,1,1,1,1,1,1,1,1,1,1,1,1,1,1,1
1,1,1,1,1,1,1,1,1,1,1,1,1,1,1,1,1,1,1,1,1,1
1,1,1,1,1,1,1,1,1,1,1,1,1,1,1,1,1,1,1,1,1,1
1,1,1,1,1,1,1,1,1,1,1,1,1,1,1,1,1,1,1,1,1,1
1,1,1,1,1,1,1,1,1,1,1,1,26,1,1,1,1,1,1,1,1,1
1,1,1,1,1,1,1,1,1,1,1,0,1,1,1,1,1,1,1,1,1,1
1,1,1,1,1,1,1,1,1,1,0,1,1,1,1,1,1,1,1,1,1,1
1,1,1,1,1,1,1,1,1,0,1,1,1,1,1,1,1,1,1,1,1,1
1,1,1,1,1,1,1,1,1,1,1,1,1,1,1,1,1,1,1,1,1,1
1,1,1,1,1,1,1,1,1,1,1,1,1,1,1,1,1,1,1,1,1,1
1,1,1,1,1,1,1,1,1,1,1,1,1,1,1,1,1,1,1,1,1,1
1,1,1,1,1,1,1,1,1,1,1,1,1,1,1,1,1,1,1,1,1,1
1,1,1,1,1,1,1,1,1,1,1,1,1,1,1,1,1,1,1,1,1,1
1,1,1,1,1,1,1,1,1,1,1,1,1,1,1,1,1,1,1,1,1,1
1,1,1,1,1,1,1,1,1,1,1,1,1,1,1,1,1,1,1,1,1,1
1,1,1,1,1,1,1,1,1,1,1,1,1,1,1,1,1,1,1,1,1,1
1,1,1,1,1,1,1,1,1,1,1,1,1,1,1,1,1,1,1,1,1,1
endlayer

